Workbook
Name Laudo_P43: Infor_Pivos!$N$45

Sheet Infor. Reservatórios e C.Bombas
A1: Informações - Reservatórios e Casas de Bombas - KARITEL e RDM.
A2: Fazenda | B2: Módulo | C2: Reservatórios | D2: Pivôs Abastecidos | E2: Total Hectares Irrigados (há) | F2: Capacidade (m³) | G2: Vazão (m³/h) | H2: Autonomia (h) | I2: Total de Pivôs Abastecidos | J2: Média de Vazão (m³/h) por Pivô
A3: karitel | B3: Módulo 01 | C3: R0 | D3: 01 - 02 - 03 - 04 | E3: =SUM(Infor_Pivos!F3:F6) -> 486.5 | F3: 19153 | G3: =SUM(Infor_Pivos!I3:I6) -> 2242.46 | H3: =F3/G3 -> 8.5410665 | I3: 4 | J3: =G3/I3 -> 560.615
A4: karitel | B4: Módulo 01 | C4: R1 | D4: 05 - 06 - 15 - 16 | E4: =SUM(Infor_Pivos!F7:F8,Infor_Pivos!F17:F18) -> 600.04 | F4: 19153 | G4: =SUM(Infor_Pivos!I7:I8,Infor_Pivos!I17:I18) -> 2762.56 | H4: =F4/G4 -> 6.9330621 | I4: 4 | J4: =G4/I4 -> 690.64
A5: karitel | B5: Módulo 01 | C5: R2 | D5: 07 - 08 - 17 - 18 | E5: =SUM(Infor_Pivos!F9:F10,Infor_Pivos!F19:F20) -> 570.16 | F5: 35575.25 | G5: =SUM(Infor_Pivos!I9:I10,Infor_Pivos!I19:I20) -> 2715.04 | H5: =F5/G5 -> 13.10303 | I5: 4 | J5: =G5/I5 -> 678.76
A6: karitel | B6: Módulo 01 | C6: R3 | D6: 09 - 10 - 19 - 20 | E6: =SUM(Infor_Pivos!F11:F12,Infor_Pivos!F21:F22) -> 570.16 | F6: 54073 | G6: =SUM(Infor_Pivos!I21:I22,Infor_Pivos!I11:I12) -> 2715.49 | H6: =F6/G6 -> 19.912797 | I6: 4 | J6: =G6/I6 -> 678.8725
A7: karitel | B7: Módulo 01 | C7: R4 | D7: 21 - 22 | E7: =SUM(Infor_Pivos!F23:F24) -> 300.02 | F7: 19060.98 | G7: =SUM(Infor_Pivos!I23:I24) -> 1428.66 | H7: =F7/G7 -> 13.341859 | I7: 2 | J7: =G7/I7 -> 714.33
A8: karitel | B8: Módulo 01 | C8: R5 | D8: 11 - 12 13 | E8: =SUM(Infor_Pivos!F13:F15) -> 342.43 | F8: 20006 | G8: =SUM(Infor_Pivos!I13:I15) -> 1601.77 | H8: =F8/G8 -> 12.489933 | I8: 3 | J8: =G8/I8 -> 533.92333
A9: karitel | B9: Módulo 01 | C9: R6 | D9: 14 - 23 - 24 | E9: =SUM(Infor_Pivos!F16,Infor_Pivos!F26,Infor_Pivos!F25) -> 450.03 | F9: 17398 | G9: =SUM(Infor_Pivos!I16,Infor_Pivos!I25:I26) -> 1931.29 | H9: =F9/G9 -> 9.0084866 | I9: 3 | J9: =G9/I9 -> 643.76333
A10: karitel | B10: Módulo 01 | C10: R7 | D10: 25 - 26 - 27 - 28 - 29 | E10: =SUM(Infor_Pivos!F27:F31) -> 560.39 | F10: 74924 | G10: =SUM(Infor_Pivos!I27:I31) -> 2604.24 | H10: =F10/G10 -> 28.770006 | I10: 5 | J10: =G10/I10 -> 520.848
A11: karitel | B11: Módulo 01 | C11: C3Z3 | D11: 30 - 31 - 32 - 33 - 34 | E11: =SUM(Infor_Pivos!F32:F36) -> 725.73 | G11: =SUM(Infor_Pivos!I32:I36) -> 3271 | H11: =F10/G11 -> 22.905533 | I11: 5 | J11: =G11/I11 -> 654.2
A12: karitel | B12: Módulo 02 | C12: R8 | D12: 35 - 36 - 37 - 38 | E12: =SUM(Infor_Pivos!F37:F40) -> 514.08 | F12: 43203 | G12: =SUM(Infor_Pivos!I37:I40) -> 2593.37 | H12: =F12/G12 -> 16.659019 | I12: 4 | J12: =G12/I12 -> 648.3425
A13: karitel | B13: Módulo 02 | C13: R9 | D13: 41 - 42 - 43 | E13: =SUM(Infor_Pivos!F43:F45) -> 377.75 | F13: 27135 | G13: =SUM(Infor_Pivos!I43:I45) -> 1798.77 | H13: =F13/G13 -> 15.085308 | I13: 3 | J13: =G13/I13 -> 599.59
A14: karitel | B14: Módulo 02 | C14: R10 | D14: 39 - 40 | E14: =SUM(Infor_Pivos!F41:F42) -> 251.19 | F14: 18060 | G14: =SUM(Infor_Pivos!I41:I42) -> 1196.15 | H14: =F14/G14 -> 15.098441 | I14: 2 | J14: =G14/I14 -> 598.075
A15: karitel | B15: Módulo 02 | C15: R11 | D15: 45 - 46 - 47 - 48 - 49 | E15: =SUM(Infor_Pivos!F47:F51) -> 762.11 | F15: 62246 | G15: =SUM(Infor_Pivos!I47:I51) -> 3591.21 | H15: =F15/G15 -> 17.332877 | I15: 5 | J15: =G15/I15 -> 718.242
A16: karitel | B16: Módulo 02 | C16: R12 | D16: 52 - 73 - 74 | E16: =SUM(Infor_Pivos!F52:F60) -> 1131.66 | F16: 79396 | G16: =SUM(Infor_Pivos!I54,Infor_Pivos!I59:I60) -> 1990.76 | H16: =F16/G16 -> 39.882256 | I16: 3 | J16: =G16/I16 -> 663.58667
D17: Transposição | E17: ... | G17: 2100 | H17: =F16/G17 -> 37.807619 | I17: 3 | J17: =G17/I17 -> 700
A18: karitel | B18: Módulo 03 | C18: R13 | D18: 44 - 53 - 54 - 55 | E18: =SUM(Infor_Pivos!F55:F57,Infor_Pivos!F46) -> 437.8 | F18: 82650 | G18: =SUM(Infor_Pivos!I55:I57,Infor_Pivos!I46) -> 2261.11 | H18: =F18/(G18) -> 36.552844 | I18: 4 | J18: =G18/I18 -> 565.2775
A19: karitel | B19: Módulo 03 | C19: R14 | D19: 50 - 51 - 56 | E19: =SUM(Infor_Pivos!F52:F53,Infor_Pivos!F58) -> 440.12 | G19: =SUM(Infor_Pivos!I58,Infor_Pivos!I52:I53) -> 2019.91 | H19: =F18/G19 -> 40.917665 | I19: 3 | J19: =G19/I19 -> 673.30333
A20: karitel | B20: Módulo 03 | C20: R15 | D20: 57 - 58 - 59 - 60 - 66 | E20: 695.98 | F20: ... | G20: 3299.89 | H20: ... | I20: 5 | J20: =G20/I20 -> 659.978
A21: karitel | B21: Módulo 03 | C21: R16 | D21: 61 - 62 - 67 - 68 | E21: 447.1 | F21: ... | G21: 2129.04 | H21: ... | I21: 4 | J21: =G21/I21 -> 532.26
A22: karitel | B22: Módulo 03 | C22: R17 | D22: 69 - 70 - 71 - 72 | E22: 396.26 | F22: ... | G22: 1886.81 | H22: ... | I22: 4 | J22: =G22/I22 -> 471.7025
A23: RDM | B23: Módulo 01 | C23: RM1 | D23: 109 | E23: 102.1 | F23: ... | G23: =SUM(Infor_Pivos!I72) -> 382.14 | H23: ... | I23: 1 | J23: =G23/I23 -> 382.14
A24: RDM | B24: Módulo 01 | C24: RM2 | D24: 106 - 108 | E24: =SUM(Infor_Pivos!F66,Infor_Pivos!F71) -> 221.14 | F24: ... | G24: =SUM(Infor_Pivos!I66,Infor_Pivos!I71) -> 1053.04 | H24: ... | I24: 2 | J24: =G24/I24 -> 526.52
A25: RDM | B25: Módulo 01 | C25: RM3 | D25: 105 - 107 | E25: =SUM(Infor_Pivos!F65,Infor_Pivos!F70) -> 246.57 | F25: ... | G25: =SUM(Infor_Pivos!I70,Infor_Pivos!I65) -> 1174.15 | H25: ... | I25: 2 | J25: =G25/I25 -> 587.075
A26: RDM | B26: Módulo 01 | C26: RM4 | D26: 101 - 102 - 103 - 104 - 110 | E26: =SUM(Infor_Pivos!F61:F64,Infor_Pivos!F73) -> 675.37 | F26: ... | G26: =SUM(Infor_Pivos!I61:I64,Infor_Pivos!I73) -> 3201.74 | H26: ... | I26: 5 | J26: =G26/I26 -> 640.348
A27: RDM | B27: Módulo 02 | C27: RM5 | D27: 112 - 113 - 114 - 115 - 131 - 132 | E27: =SUM(Infor_Pivos!F74:F77) -> 432.18 | F27: ... | G27: =SUM(Infor_Pivos!I74:I77) -> 2057.15 | H27: ... | I27: 4 | J27: =G27/I27 -> 514.2875
A28: RDM | B28: Módulo 02 | C28: RM6 | D28: 116 - 117 - 118 - 119 128 - 129 - 130 | E28: =SUM(Infor_Pivos!F78:F81,Infor_Pivos!F91:F92) -> 708.9 | F28: ... | G28: =SUM(Infor_Pivos!I78:I81,Infor_Pivos!I90:I92) -> 4077.29 | H28: ... | I28: 7 | J28: =G28/I28 -> 582.47
A29: RDM | B29: Módulo 02 | C29: RM7 | D29: 120 - 121 - 122 - 123 124 - 125 - 126 - 127 - 133 | E29: =SUM(Infor_Pivos!F82:F89,Infor_Pivos!F93) -> 1080.98 | F29: ... | G29: =SUM(Infor_Pivos!I82:I89,Infor_Pivos!I93) -> 5126.49 | H29: ... | I29: 8 | J29: =G29/I29 -> 640.81125

Sheet Infor_Pivos
A1: informações - Pivôs (KARITEL e RDM). | L1: Coordenadas Geográficas | P1: Total | Q1: Pivôs | R1: Bombas/Poços
A2: Fazenda | B2: Módulo | D2: Marca | E2: Pivô | F2: Área (há) | G2: Demanda do Contrato (kWh) | H2: Nº Contrato | I2: Vazão (m³/h) | J2: Potência (cv) | K2: Energia (kwh) | L2: Latitude | M2: Longitude | N2: Endereço do laudo | O2: Demanda Atual | P2: =SUBTOTAL(9,K2:K1048576,'Infor. Cap.. Elev.. e Poços '!I2:I1048576) -> 36333.879 | Q2: =SUBTOTAL(9,K2:K1048576) -> 13951.15 | R2: =SUBTOTAL(9,'Infor. Cap.. Elev.. e Poços '!I2:I1048576) -> 22382.729
A3: Karitel | B3: Módulo 01 | C3: R0 | D3: Valley | E3: P01 | F3: 150.01 | G3: 10300 | H3: 7024725710 | I3: 714.33 | J3: 200 | K3: =J3*0.745699872 -> 149.13997 | L3: -14.79213 | M3: -45.611436 | N3: https://santacolombaagropecuaria.sharepoint.com/sites/arquivos/Documentos%20Compartilhados/Sistema%20de%20Irrigacao/Suporte%20Irrigação/Leonardo/Teste%20de%20uniformidade/Teste%20de%20uniformidade%20e%20aplicação%20%20PC%2001.pdf
A4: Karitel | B4: Módulo 01 | C4: R0 | D4: Valley | E4: P02 | F4: 123.72 | G4: 10300 | H4: 7024725710 | I4: 523.8 | J4: 200 | K4: =J4*0.745699872 -> 149.13997 | L4: -14.800458 | M4: -45.602376 | N4: https://santacolombaagropecuaria.sharepoint.com/sites/arquivos/Documentos%20Compartilhados/Sistema%20de%20Irrigacao/Suporte%20Irrigação/Leonardo/Teste%20de%20uniformidade/Teste%20de%20uniformidade%20e%20aplicação%20%20PC%2002.pdf
A5: Karitel | B5: Módulo 01 | C5: R0 | D5: Valley | E5: P03 | F5: 150.01 | G5: 10300 | H5: 7024725710 | I5: 714.33 | J5: 200 | K5: =J5*0.745699872 -> 149.13997 | L5: -14.789199 | M5: -45.597432 | N5: https://santacolombaagropecuaria.sharepoint.com/sites/arquivos/Documentos%20Compartilhados/Sistema%20de%20Irrigacao/Suporte%20Irrigação/Leonardo/Teste%20de%20uniformidade/Teste%20de%20uniformidade%20e%20aplicação%20%20PC%2003.pdf
A6: Karitel | B6: Módulo 01 | C6: R0 | D6: Valley | E6: P04 | F6: 62.76 | G6: 10300 | H6: 7024725710 | I6: 290 | J6: 40 | K6: =J6*0.745699872 -> 29.827995 | L6: -14.798516 | M6: -45.592061 | N6: https://santacolombaagropecuaria.sharepoint.com/sites/arquivos/Documentos%20Compartilhados/Sistema%20de%20Irrigacao/Suporte%20Irrigação/Leonardo/Teste%20de%20uniformidade/Teste%20de%20uniformidade%20e%20aplicação%20%20PC%2004.pdf
A7: Karitel | B7: Módulo 01 | C7: R1 | D7: Valley | E7: P05 | F7: 150.01 | G7: 10300 | H7: 7024725710 | I7: 692.9 | J7: 250 | K7: =J7*0.745699872 -> 186.42497 | L7: -14.785655 | M7: -45.581152 | N7: https://santacolombaagropecuaria.sharepoint.com/sites/arquivos/Documentos%20Compartilhados/Sistema%20de%20Irrigacao/Suporte%20Irrigação/Leonardo/Teste%20de%20uniformidade/Teste%20de%20uniformidade%20e%20aplicação%20%20PC%2005.pdf
A8: Karitel | B8: Módulo 01 | C8: R1 | D8: Valley | E8: P06 | F8: 150.01 | G8: 10300 | H8: 7024725710 | I8: 641 | J8: 250 | K8: =J8*0.745699872 -> 186.42497 | L8: -14.78299 | M8: -45.568395 | N8: https://santacolombaagropecuaria.sharepoint.com/sites/arquivos/Documentos%20Compartilhados/Sistema%20de%20Irrigacao/Suporte%20Irrigação/Leonardo/Teste%20de%20uniformidade/Teste%20de%20uniformidade%20e%20aplicação%20%20PC%2006.pdf
A9: Karitel | B9: Módulo 01 | C9: R2 | D9: Valley | E9: P07 | F9: 120.13 | G9: 10300 | H9: 7024725710 | I9: 572.05 | J9: 250 | K9: =J9*0.745699872 -> 186.42497 | L9: -14.796394 | M9: -45.57552 | N9: https://santacolombaagropecuaria.sharepoint.com/sites/arquivos/Documentos%20Compartilhados/Sistema%20de%20Irrigacao/Suporte%20Irrigação/Leonardo/Teste%20de%20uniformidade/Teste%20de%20uniformidade%20e%20aplicação%20%20PC%2007.pdf
A10: Karitel | B10: Módulo 01 | C10: R2 | D10: Valley | E10: P08 | F10: 150.01 | G10: 10300 | H10: 7024725710 | I10: 714.33 | J10: 250 | K10: =J10*0.745699872 -> 186.42497 | L10: -14.794658 | M10: -45.563234 | N10: https://santacolombaagropecuaria.sharepoint.com/sites/arquivos/Documentos%20Compartilhados/Sistema%20de%20Irrigacao/Suporte%20Irrigação/Leonardo/Teste%20de%20uniformidade/Teste%20de%20uniformidade%20e%20aplicação%20%20PC%2008.pdf
A11: Karitel | B11: Módulo 01 | C11: R3 | D11: Valley | E11: P09 | F11: 120.13 | G11: 10300 | H11: 7024725710 | I11: 572.5 | J11: 200 | K11: =J11*0.745699872 -> 149.13997 | L11: -14.807818 | M11: -45.575728 | N11: https://santacolombaagropecuaria.sharepoint.com/sites/arquivos/Documentos%20Compartilhados/Sistema%20de%20Irrigacao/Suporte%20Irrigação/Leonardo/Teste%20de%20uniformidade/Teste%20de%20uniformidade%20e%20aplicação%20%20PC%2009.pdf
A12: Karitel | B12: Módulo 01 | C12: R3 | D12: Valley | E12: P10 | F12: 150.01 | G12: 10300 | H12: 7024725710 | I12: 714.33 | J12: 250 | K12: =J12*0.745699872 -> 186.42497 | L12: -14.80736 | M12: -45.563332 | N12: https://santacolombaagropecuaria.sharepoint.com/sites/arquivos/Documentos%20Compartilhados/Sistema%20de%20Irrigacao/Suporte%20Irrigação/Leonardo/Teste%20de%20uniformidade/Teste%20de%20uniformidade%20e%20aplicação%20%20PC%2010.pdf
A13: Karitel | B13: Módulo 01 | C13: R5 | D13: Valley | E13: P11 | F13: 121.12 | G13: 10300 | H13: 7024725710 | I13: 547.92 | J13: 200 | K13: =J13*0.745699872 -> 149.13997 | L13: -14.819573 | M13: -45.572437 | N13: https://santacolombaagropecuaria.sharepoint.com/sites/arquivos/Documentos%20Compartilhados/Sistema%20de%20Irrigacao/Suporte%20Irrigação/Leonardo/Teste%20de%20uniformidade/Teste%20de%20uniformidade%20e%20aplicação%20%20PC%2011.pdf
A14: Karitel | B14: Módulo 01 | C14: R5 | D14: Valley | E14: P12 | F14: 150.01 | G14: 10300 | H14: 7024725710 | I14: 714.33 | J14: 250 | K14: =J14*0.745699872 -> 186.42497 | L14: -14.81965 | M14: -45.560029 | N14: https://santacolombaagropecuaria.sharepoint.com/sites/arquivos/Documentos%20Compartilhados/Sistema%20de%20Irrigacao/Suporte%20Irrigação/Leonardo/Teste%20de%20uniformidade/Teste%20de%20uniformidade%20e%20aplicação%20%20PC%2012.pdf
A15: Karitel | B15: Módulo 01 | C15: R5 | D15: Valley | E15: P13 | F15: 71.3 | G15: 10300 | H15: 7024725710 | I15: 339.52 | J15: 75 | K15: 111.9 | L15: -14.829589 | M15: -45.571125 | N15: https://santacolombaagropecuaria.sharepoint.com/sites/arquivos/Documentos%20Compartilhados/Sistema%20de%20Irrigacao/Suporte%20Irrigação/Leonardo/Teste%20de%20uniformidade/Teste%20de%20uniformidade%20e%20aplicação%20%20PC%2013.pdf
A16: Karitel | B16: Módulo 01 | C16: R6 | D16: Valley | E16: P14 | F16: 150.01 | G16: 10300 | H16: 7024725710 | I16: 614.33 | J16: 75 | K16: =J16*0.745699872 -> 55.92749 | L16: -14.832346 | M16: -45.56043 | N16: https://santacolombaagropecuaria.sharepoint.com/sites/arquivos/Documentos%20Compartilhados/Sistema%20de%20Irrigacao/Suporte%20Irrigação/Leonardo/Teste%20de%20uniformidade/Teste%20de%20uniformidade%20e%20aplicação%20%20PC%2014.pdf
A17: Karitel | B17: Módulo 01 | C17: R1 | D17: Valley | E17: P15 | F17: 150.01 | G17: 10300 | H17: 7024725710 | I17: 714.33 | J17: 200 | K17: =J17*0.745699872 -> 149.13997 | L17: -14.779365 | M17: -45.552633
A18: Karitel | B18: Módulo 01 | C18: R1 | D18: Valley | E18: P16 | F18: 150.01 | G18: 10300 | H18: 7024725710 | I18: 714.33 | J18: 250 | K18: =J18*0.745699872 -> 186.42497 | L18: -14.776664 | M18: -45.539959
A19: Karitel | B19: Módulo 01 | C19: R2 | D19: Valley | E19: P17 | F19: 150.01 | G19: 10300 | H19: 7024725710 | I19: 714.33 | J19: 200 | K19: =J19*0.745699872 -> 149.13997 | L19: -14.791848 | M19: -45.550203
A20: Karitel | B20: Módulo 01 | C20: R2 | D20: Valley | E20: P18 | F20: 150.01 | G20: 10300 | H20: 7024725710 | I20: 714.33 | J20: 200 | K20: =J20*0.745699872 -> 149.13997 | L20: -14.789002 | M20: -45.537645
A21: Karitel | B21: Módulo 01 | C21: R3 | D21: Valley | E21: P19 | F21: 150.01 | G21: 10300 | H21: 7024725710 | I21: 714.33 | J21: 200 | K21: =J21*0.745699872 -> 149.13997 | L21: -14.804517 | M21: -45.54925
A22: Karitel | B22: Módulo 01 | C22: R3 | D22: Valley | E22: P20 | F22: 150.01 | G22: 10300 | H22: 7024725710 | I22: 714.33 | J22: 100 | K22: =J22*0.745699872 -> 74.569987 | L22: -14.801826 | M22: -45.536487
A23: Karitel | B23: Módulo 01 | C23: R4 | D23: Valley | E23: P21 | F23: 150.01 | G23: 10300 | H23: 7024725710 | I23: 714.33 | J23: 200 | K23: =J23*0.745699872 -> 149.13997 | L23: -14.815567 | M23: -45.542795
A24: Karitel | B24: Módulo 01 | C24: R4 | D24: Valley | E24: P22 | F24: 150.01 | G24: 10300 | H24: 7024725710 | I24: 714.33 | J24: 200 | K24: =J24*0.745699872 -> 149.13997 | L24: -14.813829 | M24: -45.529871
A25: Karitel | B25: Módulo 01 | C25: R6 | D25: Valley | E25: P23 | F25: 150.01 | G25: 10300 | H25: 7024725710 | I25: 602.63 | J25: 200 | K25: =J25*0.745699872 -> 149.13997 | L25: -14.827243 | M25: -45.548141 | N25: https://santacolombaagropecuaria.sharepoint.com/sites/arquivos/Documentos%20Compartilhados/Sistema%20de%20Irrigacao/Suporte%20Irrigação/Leonardo/Teste%20de%20uniformidade/Teste%20de%20uniformidade%20e%20aplicação%20%20PC%2023.pdf
A26: Karitel | B26: Módulo 01 | C26: R6 | D26: Valley | E26: P24 | F26: 150.01 | G26: 10300 | H26: 7024725710 | I26: 714.33 | J26: 250 | K26: =J26*0.745699872 -> 186.42497 | L26: -14.825834 | M26: -45.535102 | N26: https://santacolombaagropecuaria.sharepoint.com/sites/arquivos/Documentos%20Compartilhados/Sistema%20de%20Irrigacao/Suporte%20Irrigação/Leonardo/Teste%20de%20uniformidade/Teste%20de%20uniformidade%20e%20aplicação%20%20PC%2024.pdf
A27: Karitel | B27: Módulo 01 | C27: R7 | D27: Valley | E27: P25 | F27: 99.7 | G27: 10300 | H27: 7024725710 | I27: 474.76 | J27: 100 | K27: =J27*0.745699872 -> 74.569987 | L27: -14.840578 | M27: -45.542062
A28: Karitel | B28: Módulo 01 | C28: R7 | D28: Valley | E28: P26 | F28: 150.01 | G28: 10300 | H28: 7024725710 | I28: 650.04 | J28: 250 | K28: =J28*0.745699872 -> 186.42497 | L28: -14.843101 | M28: -45.553607 | N28: https://santacolombaagropecuaria.sharepoint.com/sites/arquivos/Documentos%20Compartilhados/Sistema%20de%20Irrigacao/Suporte%20Irrigação/Leonardo/Teste%20de%20uniformidade/Teste%20de%20uniformidade%20e%20aplicação%20%20PC%2026.pdf
A29: Karitel | B29: Módulo 01 | C29: R7 | D29: Valley | E29: P27 | F29: 99.14 | G29: 10300 | H29: 7024725710 | I29: 472.1 | J29: 100 | K29: =J29*0.745699872 -> 74.569987 | L29: -14.851144 | M29: -45.545209
A30: Karitel | B30: Módulo 01 | C30: R7 | D30: Valley | E30: P28 | F30: 132.99 | G30: 10300 | H30: 7024725710 | I30: 633.29 | J30: 200 | K30: =J30*0.745699872 -> 149.13997 | L30: -14.848383 | M30: -45.528575
A31: Karitel | B31: Módulo 01 | C31: R7 | D31: Valley | E31: P29 | F31: 78.55 | G31: 10300 | H31: 7024725710 | I31: 374.05 | J31: 100 | K31: =J31*0.745699872 -> 74.569987 | L31: -14.855983 | M31: -45.536571
A32: Karitel | B32: Módulo 01 | C32: C3Z3/R7 | D32: Valley | E32: P30 | F32: 150.01 | G32: 10300 | H32: 7024725710 | I32: 664.33 | J32: 121.74 | K32: =J32*0.745699872 -> 90.781502 | L32: -14.843509 | M32: -45.515537 | N32: https://santacolombaagropecuaria.sharepoint.com/sites/arquivos/Documentos%20Compartilhados/Sistema%20de%20Irrigacao/Suporte%20Irrigação/Leonardo/Teste%20de%20uniformidade/Teste%20de%20uniformidade%20e%20aplicação%20%20PC%2030.pdf
A33: Karitel | B33: Módulo 01 | C33: C3Z3/R7 | D33: Valley | E33: P31 | F33: 150.01 | G33: 10300 | H33: 7024725710 | I33: 645.04 | J33: 125 | K33: =J33*0.745699872 -> 93.212484 | L33: -14.85603 | M33: -45.517614 | N33: https://santacolombaagropecuaria.sharepoint.com/sites/arquivos/Documentos%20Compartilhados/Sistema%20de%20Irrigacao/Suporte%20Irrigação/Leonardo/Teste%20de%20uniformidade/Teste%20de%20uniformidade%20e%20aplicação%20%20PC%2031.pdf
A34: Karitel | B34: Módulo 01 | C34: C3Z3/R7 | D34: Valley | E34: P32 | F34: 138.03 | G34: 10300 | H34: 7024725710 | I34: 657.29 | J34: 125 | K34: =J34*0.745699872 -> 93.212484 | L34: -14.866817 | M34: -45.532033 | N34: https://santacolombaagropecuaria.sharepoint.com/sites/arquivos/Documentos%20Compartilhados/Sistema%20de%20Irrigacao/Suporte%20Irrigação/Leonardo/Teste%20de%20uniformidade/Teste%20de%20uniformidade%20e%20aplicação%20%20PC%2032.pdf
A35: Karitel | B35: Módulo 01 | C35: C3Z3/R7 | D35: Valley | E35: P33 | F35: 137.67 | G35: 10300 | H35: 7024725710 | I35: 590.01 | J35: 147 | K35: =J35*0.745699872 -> 109.61788 | L35: -14.863366 | M35: -45.507425 | N35: https://santacolombaagropecuaria.sharepoint.com/sites/arquivos/Documentos%20Compartilhados/Sistema%20de%20Irrigacao/Suporte%20Irrigação/Leonardo/Teste%20de%20uniformidade/Teste%20de%20uniformidade%20e%20aplicação%20%20PC%2033.pdf
A36: Karitel | B36: Módulo 01 | C36: C3Z3/R7 | D36: Valley | E36: P34 | F36: 150.01 | G36: 10300 | H36: 7024725710 | I36: 714.33 | J36: 150 | K36: =J36*0.745699872 -> 111.85498 | L36: -14.876819 | M36: -45.523262
A37: Karitel | B37: Módulo 02 | C37: R8 | D37: Lindsay | E37: P35 | F37: 150.54 | G37: 10300 | H37: 7024725710 | I37: 641.68 | J37: 235 | K37: =J37*0.745699872 -> 175.23947 | L37: -14.769886 | M37: -45.572876 | N37: https://santacolombaagropecuaria.sharepoint.com/sites/arquivos/Documentos%20Compartilhados/Sistema%20de%20Irrigacao/Suporte%20Irrigação/Leonardo/Teste%20de%20uniformidade/Teste%20de%20uniformidade%20e%20aplicação%20%20PC%2035.pdf
A38: Karitel | B38: Módulo 02 | C38: R8 | D38: Lindsay | E38: P36 | F38: 150.54 | G38: 10300 | H38: 7024725710 | I38: 716.86 | J38: 220 | K38: =J38*0.745699872 -> 164.05397 | L38: -14.766458 | M38: -45.559539
A39: Karitel | B39: Módulo 02 | C39: R8 | D39: Lindsay | E39: P37 | F39: 72 | G39: 10300 | H39: 7024725710 | I39: 517.97 | J39: 150 | K39: =J39*0.745699872 -> 111.85498 | L39: -14.758314 | M39: -45.571952
A40: Karitel | B40: Módulo 02 | C40: R8 | D40: Lindsay | E40: P38 | F40: 141 | G40: 10300 | H40: 7024725710 | I40: 716.86 | J40: 221 | K40: =J40*0.745699872 -> 164.79967 | L40: -14.75355 | M40: -45.560303
...

Sheet Infor. Cap.. Elev.. e Poços 
A1: informações - Captacões, Elevatórias e Poços (KARITEL e RDM). | J1: Coordenadas Geográficas | M1: Total | N1: Pivôs | O1: Bombas/Poços
A2: Fazenda | B2: Módulo | C2: C. Bomba/Poço | D2: Bomba | E2: Contrato | F2: Nº Contrato | G2: Vazão (m³/h) | H2: Potência (cv)/(hp) | I2: Energia (kwh) | J2: Latitude | K2: Longitude | L2: Demanda Atual | M2: =SUBTOTAL(9,I2:I1048576,Infor_Pivos!K2:K1048576) -> 36333.879 | N2: =SUBTOTAL(9,Infor_Pivos!K2:K1048576) -> 13951.15 | O2: =SUBTOTAL(9,I2:I1048576) -> 22382.729
A3: KARITEL | B3: Módulo 01 | C3: Primavera 01 | D3: B1 | E3: 10300 | F3: 7024725710 | G3: 803 | H3: =I3/0.745699872 -> 246.74806 | I3: 184
A4: KARITEL | B4: Módulo 01 | C4: Primavera 01 | D4: B2 | E4: 10300 | F4: 7024725710 | G4: 803 | H4: =I4/0.745699872 -> 246.74806 | I4: 184
A5: KARITEL | B5: Módulo 01 | C5: Primavera 01 | D5: B3 | E5: 10300 | F5: 7024725710 | G5: 803 | H5: =I5/0.745699872 -> 246.74806 | I5: 184
A6: KARITEL | B6: Módulo 01 | C6: Primavera 02 | D6: B1 | E6: 10300 | F6: 7024725710 | G6: 786 | H6: =I6/0.745699872 -> 246.74806 | I6: 184
A7: KARITEL | B7: Módulo 01 | C7: Primavera 02 | D7: B2 | E7: 10300 | F7: 7024725710 | G7: 786 | H7: =I7/0.745699872 -> 246.74806 | I7: 184
A8: KARITEL | B8: Módulo 01 | C8: Primavera 02 | D8: B3 | E8: 10300 | F8: 7024725710 | G8: 786 | H8: =I8/0.745699872 -> 246.74806 | I8: 184
A9: KARITEL | B9: Módulo 01 | C9: Primavera 02 | D9: B4 | E9: 10300 | F9: 7024725710 | G9: 786 | H9: =I9/0.745699872 -> 246.74806 | I9: 184
A10: KARITEL | B10: Módulo 01 | C10: Primavera 02 | D10: B5 | E10: 10300 | F10: 7024725710 | G10: 786 | H10: =I10/0.745699872 -> 246.74806 | I10: 184
A11: KARITEL | B11: Módulo 01 | C11: Bom Nome | D11: B1 | E11: 10300 | F11: 7024725710 | G11: 560 | H11: =I11/0.745699872 -> 246.74806 | I11: 184
A12: KARITEL | B12: Módulo 01 | C12: Bom Nome | D12: B2 | E12: 10300 | F12: 7024725710 | G12: 560 | H12: =I12/0.745699872 -> 246.74806 | I12: 184
A13: KARITEL | B13: Módulo 01 | C13: Bom Nome | D13: B3 | E13: 10300 | F13: 7024725710 | G13: 560 | H13: =I13/0.745699872 -> 246.74806 | I13: 184
A14: KARITEL | B14: Módulo 01 | C14: Bom Nome | D14: B4 | E14: 10300 | F14: 7024725710 | G14: 560 | H14: =I14/0.745699872 -> 246.74806 | I14: 184
... A87: KARITEL | B87: Módulo 02 | C87: Elevatória G e K | D87: B24 | E87: 5711 | F87: 7044455980 | G87: 542 | H87: =I87/0.745699872 -> 246.74806 | I87: 184
A88: KARITEL | B88: Módulo 02 | C88: R12 - Transposição | D88: B1 | E88: 5711 | F88: 7044455980 | G88: 700 | H88: 100 | I88: =H88*0.745699872 -> 74.569987
A89: KARITEL | B89: Módulo 02 | C89: R12 - Transposição | D89: B2 | E89: 5711 | F89: 7044455980 | G89: 700 | H89: 100 | I89: =H89*0.745699872 -> 74.569987
A90: KARITEL | B90: Módulo 02 | C90: R12 - Transposição | D90: B3 | E90: 5711 | F90: 7044455980 | G90: 700 | H90: 100 | I90: =H90*0.745699872 -> 74.569987
A91: KARITEL | B91: Módulo 02 | C91: Balça - M2/M1 | D91: B1/B2 | E91: 5711 | F91: 7044455980 | G91: 6500 | H91: 300 | I91: =H91*0.745699872 -> 223.70996
A92: KARITEL | B92: Módulo 02 | C92: Balça - R16 | D92: B1/B2 | E92: 5711 | F92: 7044455980 | G92: 3500 | H92: 150 | I92: =H92*0.745699872 -> 111.85498
A93: RDM | B93: Módulo 01 | C93: PRM 01 | D93: B1 | E93: 2160 | F93: 212156183 | G93: 500 | H93: 280 | I93: =H93*0.745699872 -> 208.79596
A94: RDM | B94: Módulo 01 | C94: PRM 02 | D94: B1 | E94: 2160 | F94: 212156183 | G94: 500 | H94: 280 | I94: =H94*0.745699872 -> 208.79596
A95: RDM | B95: Módulo 01 | C95: PRM 03 | D95: B1 | E95: 2160 | F95: 212156183 | G95: 500 | H95: 280 | I95: =H95*0.745699872 -> 208.79596
A96: RDM | B96: Módulo 01 | C96: PRM 04 | D96: B1 | E96: 700 | F96: 209723891 | G96: 500 | H96: 280 | I96: =H96*0.745699872 -> 208.79596
A97: RDM | B97: Módulo 01 | C97: PRM 05 | D97: B1 | E97: 2160 | F97: 212156183 | G97: 135 | H97: 115 | I97: =H97*0.745699872 -> 85.755485
A98: RDM | B98: Módulo 01 | C98: PRM 06 | D98: B1 | E98: 2160 | F98: 212156183 | G98: 395 | H98: 280 | I98: =H98*0.745699872 -> 208.79596
A99: RDM | B99: Módulo 02 | C99: PRM 07 | D99: B1 | E99: 2160 | F99: 212156183 | G99: 233 | H99: 130 | I99: =H99*0.745699872 -> 96.940983
... A106: KARITEL | B106: Módulo 03 | C106: PK 10 | D106: B1 | E106: 5711 | F106: 7044455980 | G106: 280 | H106: 280 | I106: =H106*0.745699872 -> 208.79596
A107: KARITEL | B107: Módulo 03 | C107: PK 11 | D107: B1 | E107: 5711 | F107: 7044455980 | G107: ??? | H107: 280 | I107: =H107*0.745699872 -> 208.79596
A108: KARITEL | B108: Módulo 03 | C108: PK 12 | D108: B1 | E108: 5711 | F108: 7044455980 | G108: 374 | H108: 330 | I108: =H108*0.745699872 -> 246.08096
A109: KARITEL | B109: Módulo 03 | C109: PK 13 | D109: B1 | E109: 5711 | F109: 7044455980 | G109: 394.5 | H109: 330 | I109: =H109*0.745699872 -> 246.08096
A110: KARITEL | B110: Módulo 03 | C110: PK 14 | D110: B1 | E110: 5711 | F110: 7044455980 | G110: 366 | H110: 280 | I110: =H110*0.745699872 -> 208.79596
A111: KARITEL | B111: Módulo 03 | C111: PK 15 | D111: B1 | E111: 5711 | F111: 7044455980 | G111: 205 | H111: 180 | I111: =H111*0.745699872 -> 134.22598
A112: KARITEL | B112: Módulo 03 | C112: PK 16 | D112: B1 | E112: 5711 | F112: 7044455980 | G112: 242 | H112: 180 | I112: =H112*0.745699872 -> 134.22598
