Workbook

Sheet 21 02 2022
A1: Atendimento de irrigação (Imapacto - Problemas Mecânicos) - Semana 21/02/2022
A3: Data | B3: 44613 | C3: 44614 | D3: 44615 | E3: 44616 | F3: 44617 | G3: 44618 | H3: 44619
A4: Pivô | B4: =TEXT(B3,"ddd") -> seg | C4: =TEXT(C3,"ddd") -> ter | D4: =TEXT(D3,"ddd") -> qua | E4: =TEXT(E3,"ddd") -> qui | F4: =TEXT(F3,"ddd") -> sex | G4: =TEXT(G3,"ddd") -> sáb | H4: =TEXT(H3,"ddd") -> dom | J4: Parâmetros
A5: Pivô 01 | J5: Redutor | K5: =COUNTIF($B$5:$H$93,J5) -> 1 | L5: =K5/$K$15 -> 0.16666667
A6: Pivô 02 | J6: Motorredutor | K6: =COUNTIF($B$5:$H$93,J6) -> 1 | L6: =K6/$K$15 -> 0.16666667
A7: Pivô 03 | J7: Castanha | K7: =COUNTIF($B$5:$H$93,J7) -> 0 | L7: =K7/$K$15 -> 0
A8: Pivô 04 | J8: Vedação | K8: =COUNTIF($B$5:$H$93,J8) -> 0 | L8: =K8/$K$15 -> 0
A9: Pivô 05 | J9: Pneu | K9: =COUNTIF($B$5:$H$93,J9) -> 0 | L9: =K9/$K$15 -> 0
A10: Pivô 06 | J10: Sucção | K10: =COUNTIF($B$5:$H$93,J10) -> 0 | L10: =K10/$K$15 -> 0
A11: Pivô 07 | J11: Bomba | K11: =COUNTIF($B$5:$H$93,J11) -> 2 | L11: =K11/$K$15 -> 0.33333333
A12: Pivô 08 | J12: Mangote | K12: =COUNTIF($B$5:$H$93,J12) -> 0 | L12: =K12/$K$15 -> 0
A13: Pivô 09 | J13: Canal/Reservatório | K13: =COUNTIF($B$5:$H$93,J13) -> 0 | L13: =K13/$K$15 -> 0
A14: Pivô 10 | J14: Adutora | K14: =COUNTIF($B$5:$H$93,J14) -> 2 | L14: =K14/$K$15 -> 0.33333333
A15: Pivô 11 | J15: Total | K15: =SUM(K5:K14) -> 6
A16: Pivô 12
A17: Pivô 13
A18: Pivô 14
A19: Pivô 15
A20: Pivô 16
A21: Pivô 17
A22: Pivô 18
A23: Pivô 19
A24: Pivô 20
A25: Pivô 21
A26: Pivô 22
A27: Pivô 23
... A36: Pivô 32
A37: Pivô 33 | F37: Motorredutor
A38: Pivô 34
A39: Pivô 35
A40: Pivô 36
A41: Pivô 37
A42: Pivô 38 | G42: Bomba | H42: Bomba
A43: Pivô 39
A44: Pivô 40
A45: Pivô 41
A46: Pivô 42 | E46: Redutor
A47: Pivô 43
A48: Pivô 44
A49: Pivô 45
...

Sheet 28 02 2022 
A1: Atendimento de irrigação (Imapacto - Problemas Mecânicos) - Semana 28/02/2022
A3: Data | B3: 44620 | C3: =B3+1 -> 44621 | D3: =C3+1 -> 44622 | E3: =D3+1 -> 44623 | F3: =E3+1 -> 44624 | G3: =F3+1 -> 44625 | H3: =G3+1 -> 44626
A4: Pivô | B4: =TEXT(B3,"ddd") -> seg | C4: =TEXT(C3,"ddd") -> ter | D4: =TEXT(D3,"ddd") -> qua | E4: =TEXT(E3,"ddd") -> qui | F4: =TEXT(F3,"ddd") -> sex | G4: =TEXT(G3,"ddd") -> sáb | H4: =TEXT(H3,"ddd") -> dom | J4: Parâmetros
A5: Pivô 01 | J5: Redutor | K5: =COUNTIF($B$5:$H$93,J5) -> 2 | L5: =K5/$K$15 -> 0.11764706
A6: Pivô 02 | J6: Motorredutor | K6: =COUNTIF($B$5:$H$93,J6) -> 0 | L6: =K6/$K$15 -> 0
A7: Pivô 03 | J7: Castanha | K7: =COUNTIF($B$5:$H$93,J7) -> 0 | L7: =K7/$K$15 -> 0
A8: Pivô 04 | J8: Vedação | K8: =COUNTIF($B$5:$H$93,J8) -> 0 | L8: =K8/$K$15 -> 0
A9: Pivô 05 | D9: Pneu | J9: Pneu | K9: =COUNTIF($B$5:$H$93,J9) -> 2 | L9: =K9/$K$15 -> 0.11764706
A10: Pivô 06 | J10: Estrutura | K10: =COUNTIF($B$5:$H$93,J10) -> 10 | L10: =K10/$K$15 -> 0.58823529
A11: Pivô 07 | J11: Bomba/Sucção | K11: =COUNTIF($B$5:$H$93,J11) -> 1 | L11: =K11/$K$15 -> 0.058823529
A12: Pivô 08 | J12: Mangote | K12: =COUNTIF($B$5:$H$93,J12) -> 0 | L12: =K12/$K$15 -> 0
A13: Pivô 09 | J13: Canal/Reservatório | K13: =COUNTIF($B$5:$H$93,J13) -> 0 | L13: =K13/$K$15 -> 0
A14: Pivô 10 | J14: Adutora | K14: =COUNTIF($B$5:$H$93,J14) -> 2 | L14: =K14/$K$15 -> 0.11764706
A15: Pivô 11 | J15: Total | K15: =SUM(K5:K14) -> 17
A16: Pivô 12
A17: Pivô 13
A18: Pivô 14
A19: Pivô 15
A20: Pivô 16 | B20: Estrutura | C20: Estrutura | D20: Estrutura
A21: Pivô 17
A22: Pivô 18
A23: Pivô 19
A24: Pivô 20
A25: Pivô 21
A26: Pivô 22
A27: Pivô 23
A28: Pivô 24
A29: Pivô 25 | C29: Pneu
A30: Pivô 26
A31: Pivô 27
A32: Pivô 28
A33: Pivô 29
A34: Pivô 30 | D34: Adutora | E34: Adutora
A35: Pivô 31
A36: Pivô 32 | C36: Redutor
A37: Pivô 33
A38: Pivô 34
A39: Pivô 35
A40: Pivô 36
A41: Pivô 37
...

Sheet 07 03 2022
A1: Atendimento de irrigação (Imapacto - Problemas Mecânicos) - Semana 07/03/2022
A3: Data | B3: 44627 | C3: =B3+1 -> 44628 | D3: =C3+1 -> 44629 | E3: =D3+1 -> 44630 | F3: =E3+1 -> 44631 | G3: =F3+1 -> 44632 | H3: =G3+1 -> 44633
A4: Pivô | B4: =TEXT(B3,"ddd") -> seg | C4: =TEXT(C3,"ddd") -> ter | D4: =TEXT(D3,"ddd") -> qua | E4: =TEXT(E3,"ddd") -> qui | F4: =TEXT(F3,"ddd") -> sex | G4: =TEXT(G3,"ddd") -> sáb | H4: =TEXT(H3,"ddd") -> dom | J4: Parâmetros
A5: Pivô 01 | J5: Redutor | K5: =COUNTIF($B$5:$H$93,J5) -> 2 | L5: =K5/$K$15 -> 0.2
A6: Pivô 02 | J6: Motorredutor | K6: =COUNTIF($B$5:$H$93,J6) -> 0 | L6: =K6/$K$15 -> 0
A7: Pivô 03 | J7: Castanha | K7: =COUNTIF($B$5:$H$93,J7) -> 0 | L7: =K7/$K$15 -> 0
A8: Pivô 04 | J8: Vedação | K8: =COUNTIF($B$5:$H$93,J8) -> 0 | L8: =K8/$K$15 -> 0
A9: Pivô 05 | J9: Pneu | K9: =COUNTIF($B$5:$H$93,J9) -> 2 | L9: =K9/$K$15 -> 0.2
A10: Pivô 06 | J10: Estrutura | K10: =COUNTIF($B$5:$H$93,J10) -> 5 | L10: =K10/$K$15 -> 0.5
A11: Pivô 07 | J11: Bomba/Sucção | K11: =COUNTIF($B$5:$H$93,J11) -> 0 | L11: =K11/$K$15 -> 0
A12: Pivô 08 | J12: Mangote | K12: =COUNTIF($B$5:$H$93,J12) -> 1 | L12: =K12/$K$15 -> 0.1
A13: Pivô 09 | J13: Canal/Reservatório | K13: =COUNTIF($B$5:$H$93,J13) -> 0 | L13: =K13/$K$15 -> 0
A14: Pivô 10 | J14: Adutora | K14: =COUNTIF($B$5:$H$93,J14) -> 0 | L14: =K14/$K$15 -> 0
A15: Pivô 11 | J15: Total | K15: =SUM(K5:K14) -> 10
A16: Pivô 12
A17: Pivô 13
A18: Pivô 14
A19: Pivô 15
A20: Pivô 16
A21: Pivô 17
A22: Pivô 18 | B22: Mangote
A23: Pivô 19
A24: Pivô 20
A25: Pivô 21
A26: Pivô 22 | F26: Redutor
A27: Pivô 23
A28: Pivô 24
A29: Pivô 25 | D29: Pneu | E29: Pneu
A30: Pivô 26
A31: Pivô 27
A32: Pivô 28
A33: Pivô 29
A34: Pivô 30
A35: Pivô 31
A36: Pivô 32
A37: Pivô 33
A38: Pivô 34
A39: Pivô 35
A40: Pivô 36
A41: Pivô 37
...

Sheet 14 03 2022
A1: Atendimento de irrigação (Imapacto - Problemas Mecânicos) - Semana 14/03/2022
A3: Data | B3: 44634 | C3: =B3+1 -> 44635 | D3: =C3+1 -> 44636 | E3: =D3+1 -> 44637 | F3: =E3+1 -> 44638 | G3: =F3+1 -> 44639 | H3: =G3+1 -> 44640
A4: Pivô | B4: =TEXT(B3,"ddd") -> seg | C4: =TEXT(C3,"ddd") -> ter | D4: =TEXT(D3,"ddd") -> qua | E4: =TEXT(E3,"ddd") -> qui | F4: =TEXT(F3,"ddd") -> sex | G4: =TEXT(G3,"ddd") -> sáb | H4: =TEXT(H3,"ddd") -> dom | J4: Parâmetros
A5: Pivô 01 | J5: Redutor | K5: =COUNTIF($B$5:$H$93,J5) -> 0 | L5: =K5/$K$15 -> 0
A6: Pivô 02 | J6: Motorredutor | K6: =COUNTIF($B$5:$H$93,J6) -> 3 | L6: =K6/$K$15 -> 0.15
A7: Pivô 03 | J7: Castanha | K7: =COUNTIF($B$5:$H$93,J7) -> 0 | L7: =K7/$K$15 -> 0
A8: Pivô 04 | J8: Vedação | K8: =COUNTIF($B$5:$H$93,J8) -> 1 | L8: =K8/$K$15 -> 0.05
A9: Pivô 05 | J9: Pneu | K9: =COUNTIF($B$5:$H$93,J9) -> 4 | L9: =K9/$K$15 -> 0.2
A10: Pivô 06 | J10: Estrutura | K10: =COUNTIF($B$5:$H$93,J10) -> 11 | L10: =K10/$K$15 -> 0.55
A11: Pivô 07 | J11: Bomba/Sucção | K11: =COUNTIF($B$5:$H$93,J11) -> 1 | L11: =K11/$K$15 -> 0.05
A12: Pivô 08 | J12: Mangote | K12: =COUNTIF($B$5:$H$93,J12) -> 0 | L12: =K12/$K$15 -> 0
A13: Pivô 09 | J13: Canal/Reservatório | K13: =COUNTIF($B$5:$H$93,J13) -> 0 | L13: =K13/$K$15 -> 0
A14: Pivô 10 | J14: Adutora | K14: =COUNTIF($B$5:$H$93,J14) -> 0 | L14: =K14/$K$15 -> 0
A15: Pivô 11 | J15: Total | K15: =SUM(K5:K14) -> 20
A16: Pivô 12
A17: Pivô 13
A18: Pivô 14
A19: Pivô 15
A20: Pivô 16
A21: Pivô 17
A22: Pivô 18
A23: Pivô 19
A24: Pivô 20
A25: Pivô 21
A26: Pivô 22
A27: Pivô 23
... A32: Pivô 28
A33: Pivô 29 | B33: Vedação
A34: Pivô 30
A35: Pivô 31
A36: Pivô 32
A37: Pivô 33 | B37: Bomba/Sucção
A38: Pivô 34
A39: Pivô 35 | H39: Pneu
A40: Pivô 36
A41: Pivô 37
A42: Pivô 38
A43: Pivô 39
A44: Pivô 40
A45: Pivô 41
...

Sheet 21 03 2022
A1: Atendimento de irrigação (Imapacto - Problemas Mecânicos) - Semana 21/03/2022
A3: Data | B3: 44641 | C3: =B3+1 -> 44642 | D3: =C3+1 -> 44643 | E3: =D3+1 -> 44644 | F3: =E3+1 -> 44645 | G3: =F3+1 -> 44646 | H3: =G3+1 -> 44647
A4: Pivô | B4: =TEXT(B3,"ddd") -> seg | C4: =TEXT(C3,"ddd") -> ter | D4: =TEXT(D3,"ddd") -> qua | E4: =TEXT(E3,"ddd") -> qui | F4: =TEXT(F3,"ddd") -> sex | G4: =TEXT(G3,"ddd") -> sáb | H4: =TEXT(H3,"ddd") -> dom | J4: Parâmetros
A5: Pivô 01 | J5: Redutor | K5: =COUNTIF($B$5:$H$93,J5) -> 0 | L5: =K5/$K$15 -> 0
A6: Pivô 02 | J6: Motorredutor | K6: =COUNTIF($B$5:$H$93,J6) -> 0 | L6: =K6/$K$15 -> 0
A7: Pivô 03 | J7: Castanha | K7: =COUNTIF($B$5:$H$93,J7) -> 0 | L7: =K7/$K$15 -> 0
A8: Pivô 04 | J8: Vedação | K8: =COUNTIF($B$5:$H$93,J8) -> 0 | L8: =K8/$K$15 -> 0
A9: Pivô 05 | B9: Mangote | J9: Pneu | K9: =COUNTIF($B$5:$H$93,J9) -> 1 | L9: =K9/$K$15 -> 0.066666667
A10: Pivô 06 | J10: Estrutura | K10: =COUNTIF($B$5:$H$93,J10) -> 11 | L10: =K10/$K$15 -> 0.73333333
A11: Pivô 07 | J11: Bomba/Sucção | K11: =COUNTIF($B$5:$H$93,J11) -> 0 | L11: =K11/$K$15 -> 0
A12: Pivô 08 | J12: Mangote | K12: =COUNTIF($B$5:$H$93,J12) -> 3 | L12: =K12/$K$15 -> 0.2
A13: Pivô 09 | J13: Canal/Reservatório | K13: =COUNTIF($B$5:$H$93,J13) -> 0 | L13: =K13/$K$15 -> 0
A14: Pivô 10 | J14: Adutora | K14: =COUNTIF($B$5:$H$93,J14) -> 0 | L14: =K14/$K$15 -> 0
A15: Pivô 11 | J15: Total | K15: =SUM(K5:K14) -> 15
A16: Pivô 12
A17: Pivô 13
A18: Pivô 14
A19: Pivô 15
A20: Pivô 16 | E20: Mangote
A21: Pivô 17
A22: Pivô 18
A23: Pivô 19
A24: Pivô 20
A25: Pivô 21
A26: Pivô 22
A27: Pivô 23
A28: Pivô 24
A29: Pivô 25
A30: Pivô 26 | G30: Pneu
A31: Pivô 27
A32: Pivô 28 | E32: Mangote
A33: Pivô 29
A34: Pivô 30
A35: Pivô 31
A36: Pivô 32
A37: Pivô 33
A38: Pivô 34
A39: Pivô 35
A40: Pivô 36
A41: Pivô 37
...

Sheet 28 03 2022
A1: Atendimento de irrigação (Imapacto - Problemas Mecânicos) - Semana 28/03/2022
A3: Data | B3: 44648 | C3: =B3+1 -> 44649 | D3: =C3+1 -> 44650 | E3: =D3+1 -> 44651 | F3: =E3+1 -> 44652 | G3: =F3+1 -> 44653 | H3: =G3+1 -> 44654
A4: Pivô | B4: =TEXT(B3,"ddd") -> seg | C4: =TEXT(C3,"ddd") -> ter | D4: =TEXT(D3,"ddd") -> qua | E4: =TEXT(E3,"ddd") -> qui | F4: =TEXT(F3,"ddd") -> sex | G4: =TEXT(G3,"ddd") -> sáb | H4: =TEXT(H3,"ddd") -> dom | J4: Parâmetros
A5: Pivô 01 | J5: Redutor | K5: =COUNTIF($B$5:$H$93,J5) -> 0 | L5: =K5/$K$15 -> 0
A6: Pivô 02 | J6: Motorredutor | K6: =COUNTIF($B$5:$H$93,J6) -> 1 | L6: =K6/$K$15 -> 0.071428571
A7: Pivô 03 | J7: Castanha | K7: =COUNTIF($B$5:$H$93,J7) -> 0 | L7: =K7/$K$15 -> 0
A8: Pivô 04 | J8: Vedação | K8: =COUNTIF($B$5:$H$93,J8) -> 0 | L8: =K8/$K$15 -> 0
A9: Pivô 05 | J9: Pneu | K9: =COUNTIF($B$5:$H$93,J9) -> 1 | L9: =K9/$K$15 -> 0.071428571
A10: Pivô 06 | H10: Adutora | J10: Estrutura | K10: =COUNTIF($B$5:$H$93,J10) -> 11 | L10: =K10/$K$15 -> 0.78571429
A11: Pivô 07 | H11: Motorredutor | J11: Bomba/Sucção | K11: =COUNTIF($B$5:$H$93,J11) -> 0 | L11: =K11/$K$15 -> 0
A12: Pivô 08 | J12: Mangote | K12: =COUNTIF($B$5:$H$93,J12) -> 0 | L12: =K12/$K$15 -> 0
A13: Pivô 09 | J13: Canal/Reservatório | K13: =COUNTIF($B$5:$H$93,J13) -> 0 | L13: =K13/$K$15 -> 0
A14: Pivô 10 | J14: Adutora | K14: =COUNTIF($B$5:$H$93,J14) -> 1 | L14: =K14/$K$15 -> 0.071428571
A15: Pivô 11 | J15: Total | K15: =SUM(K5:K14) -> 14
A16: Pivô 12
A17: Pivô 13
A18: Pivô 14
A19: Pivô 15
A20: Pivô 16
A21: Pivô 17
A22: Pivô 18 | G22: Pneu
A23: Pivô 19
A24: Pivô 20
A25: Pivô 21
A26: Pivô 22
A27: Pivô 23
A28: Pivô 24 | C28: Estrutura
A29: Pivô 25
A30: Pivô 26 | C30: Estrutura
A31: Pivô 27
A32: Pivô 28
A33: Pivô 29
A34: Pivô 30
A35: Pivô 31
A36: Pivô 32 | C36: Estrutura
A37: Pivô 33
A38: Pivô 34 | C38: Estrutura
A39: Pivô 35
A40: Pivô 36
A41: Pivô 37
...

Sheet 04 04 2022
A1: Atendimento de irrigação (Imapacto - Problemas Mecânicos) - Semana 04/04/2022
A3: Data | B3: 44655 | C3: =B3+1 -> 44656 | D3: =C3+1 -> 44657 | E3: =D3+1 -> 44658 | F3: =E3+1 -> 44659 | G3: =F3+1 -> 44660 | H3: =G3+1 -> 44661
A4: Pivô | B4: =TEXT(B3,"ddd") -> seg | C4: =TEXT(C3,"ddd") -> ter | D4: =TEXT(D3,"ddd") -> qua | E4: =TEXT(E3,"ddd") -> qui | F4: =TEXT(F3,"ddd") -> sex | G4: =TEXT(G3,"ddd") -> sáb | H4: =TEXT(H3,"ddd") -> dom | J4: Parâmetros
A5: Pivô 01 | J5: Redutor | K5: =COUNTIF($B$5:$H$93,J5) -> 0 | L5: =K5/$K$15 -> 0
A6: Pivô 02 | J6: Motorredutor | K6: =COUNTIF($B$5:$H$93,J6) -> 1 | L6: =K6/$K$15 -> 0.058823529
A7: Pivô 03 | J7: Castanha | K7: =COUNTIF($B$5:$H$93,J7) -> 0 | L7: =K7/$K$15 -> 0
A8: Pivô 04 | J8: Vedação | K8: =COUNTIF($B$5:$H$93,J8) -> 1 | L8: =K8/$K$15 -> 0.058823529
A9: Pivô 05 | J9: Pneu | K9: =COUNTIF($B$5:$H$93,J9) -> 1 | L9: =K9/$K$15 -> 0.058823529
A10: Pivô 06 | B10: Adutora | C10: Adutora | J10: Estrutura | K10: =COUNTIF($B$5:$H$93,J10) -> 11 | L10: =K10/$K$15 -> 0.64705882
A11: Pivô 07 | J11: Bomba/Sucção | K11: =COUNTIF($B$5:$H$93,J11) -> 1 | L11: =K11/$K$15 -> 0.058823529
A12: Pivô 08 | J12: Mangote | K12: =COUNTIF($B$5:$H$93,J12) -> 0 | L12: =K12/$K$15 -> 0
A13: Pivô 09 | J13: Canal/Reservatório | K13: =COUNTIF($B$5:$H$93,J13) -> 0 | L13: =K13/$K$15 -> 0
A14: Pivô 10 | J14: Adutora | K14: =COUNTIF($B$5:$H$93,J14) -> 2 | L14: =K14/$K$15 -> 0.11764706
A15: Pivô 11 | J15: Total | K15: =SUM(K5:K14) -> 17
A16: Pivô 12
A17: Pivô 13
A18: Pivô 14
A19: Pivô 15
A20: Pivô 16
A21: Pivô 17
A22: Pivô 18 | E22: Vedação
A23: Pivô 19
A24: Pivô 20
A25: Pivô 21
A26: Pivô 22
A27: Pivô 23 | F27: Estrutura
A28: Pivô 24 | E28: Estrutura
A29: Pivô 25 | F29: Bomba/Sucção
A30: Pivô 26
A31: Pivô 27
A32: Pivô 28 | C32: Estrutura
A33: Pivô 29
A34: Pivô 30 | E34: Estrutura
A35: Pivô 31
A36: Pivô 32
A37: Pivô 33 | C37: Pneu | E37: Estrutura
A38: Pivô 34
A39: Pivô 35
A40: Pivô 36
A41: Pivô 37
...

Sheet 11 04 2022
A1: Atendimento de irrigação (Imapacto - Problemas Mecânicos) - Semana 04/04/2022
A3: Data | B3: 44662 | C3: =B3+1 -> 44663 | D3: =C3+1 -> 44664 | E3: =D3+1 -> 44665 | F3: =E3+1 -> 44666 | G3: =F3+1 -> 44667 | H3: =G3+1 -> 44668
A4: Pivô | B4: =TEXT(B3,"ddd") -> seg | C4: =TEXT(C3,"ddd") -> ter | D4: =TEXT(D3,"ddd") -> qua | E4: =TEXT(E3,"ddd") -> qui | F4: =TEXT(F3,"ddd") -> sex | G4: =TEXT(G3,"ddd") -> sáb | H4: =TEXT(H3,"ddd") -> dom | J4: Parâmetros
A5: Pivô 01 | J5: Redutor | K5: =COUNTIF($B$5:$H$93,J5) -> 2 | L5: =K5/$K$15 -> 0.086956522
A6: Pivô 02 | J6: Motorredutor | K6: =COUNTIF($B$5:$H$93,J6) -> 0 | L6: =K6/$K$15 -> 0
A7: Pivô 03 | J7: Castanha | K7: =COUNTIF($B$5:$H$93,J7) -> 0 | L7: =K7/$K$15 -> 0
A8: Pivô 04 | J8: Vedação | K8: =COUNTIF($B$5:$H$93,J8) -> 2 | L8: =K8/$K$15 -> 0.086956522
A9: Pivô 05 | J9: Pneu | K9: =COUNTIF($B$5:$H$93,J9) -> 2 | L9: =K9/$K$15 -> 0.086956522
A10: Pivô 06 | J10: Estrutura | K10: =COUNTIF($B$5:$H$93,J10) -> 15 | L10: =K10/$K$15 -> 0.65217391
A11: Pivô 07 | E11: Pneu | J11: Bomba/Sucção | K11: =COUNTIF($B$5:$H$93,J11) -> 0 | L11: =K11/$K$15 -> 0
A12: Pivô 08 | B12: Redutor | J12: Mangote | K12: =COUNTIF($B$5:$H$93,J12) -> 0 | L12: =K12/$K$15 -> 0
A13: Pivô 09 | B13: Redutor | J13: Canal/Reservatório | K13: =COUNTIF($B$5:$H$93,J13) -> 0 | L13: =K13/$K$15 -> 0
A14: Pivô 10 | J14: Adutora | K14: =COUNTIF($B$5:$H$93,J14) -> 2 | L14: =K14/$K$15 -> 0.086956522
A15: Pivô 11 | J15: Total | K15: =SUM(K5:K14) -> 23
A16: Pivô 12
A17: Pivô 13
A18: Pivô 14
A19: Pivô 15
A20: Pivô 16
A21: Pivô 17
A22: Pivô 18
A23: Pivô 19
A24: Pivô 20
A25: Pivô 21
A26: Pivô 22 | B26: Vedação
A27: Pivô 23 | C27: Vedação
A28: Pivô 24 | D28: Pneu
A29: Pivô 25
A30: Pivô 26 | D30: Estrutura
A31: Pivô 27
A32: Pivô 28 | D32: Estrutura
A33: Pivô 29
A34: Pivô 30 | E34: Estrutura | F34: Estrutura | G34: Adutora | H34: Adutora
A35: Pivô 31 | D35: Estrutura
A36: Pivô 32 | C36: Estrutura | E36: Estrutura
A37: Pivô 33 | C37: Estrutura | E37: Estrutura
A38: Pivô 34 | D38: Estrutura
A39: Pivô 35
A40: Pivô 36
A41: Pivô 37
...

Sheet 18 04 2022
A1: Atendimento de irrigação (Imapacto - Problemas Mecânicos) - Semana 04/04/2022
A3: Data | B3: 44669 | C3: =B3+1 -> 44670 | D3: =C3+1 -> 44671 | E3: =D3+1 -> 44672 | F3: =E3+1 -> 44673 | G3: =F3+1 -> 44674 | H3: =G3+1 -> 44675
A4: Pivô | B4: =TEXT(B3,"ddd") -> seg | C4: =TEXT(C3,"ddd") -> ter | D4: =TEXT(D3,"ddd") -> qua | E4: =TEXT(E3,"ddd") -> qui | F4: =TEXT(F3,"ddd") -> sex | G4: =TEXT(G3,"ddd") -> sáb | H4: =TEXT(H3,"ddd") -> dom | J4: Parâmetros
A5: Pivô 01 | J5: Redutor | K5: =COUNTIF($B$5:$H$93,J5) -> 4 | L5: =K5/$K$15 -> 0.16
A6: Pivô 02 | J6: Motorredutor | K6: =COUNTIF($B$5:$H$93,J6) -> 1 | L6: =K6/$K$15 -> 0.04
A7: Pivô 03 | J7: Castanha | K7: =COUNTIF($B$5:$H$93,J7) -> 0 | L7: =K7/$K$15 -> 0
A8: Pivô 04 | J8: Vedação | K8: =COUNTIF($B$5:$H$93,J8) -> 3 | L8: =K8/$K$15 -> 0.12
A9: Pivô 05 | J9: Pneu | K9: =COUNTIF($B$5:$H$93,J9) -> 4 | L9: =K9/$K$15 -> 0.16
A10: Pivô 06 | J10: Estrutura | K10: =COUNTIF($B$5:$H$93,J10) -> 5 | L10: =K10/$K$15 -> 0.2
A11: Pivô 07 | C11: Canal/Reservatório | D11: Redutor | F11: Pneu | J11: Bomba/Sucção | K11: =COUNTIF($B$5:$H$93,J11) -> 1 | L11: =K11/$K$15 -> 0.04
A12: Pivô 08 | G12: Redutor | J12: Mangote | K12: =COUNTIF($B$5:$H$93,J12) -> 0 | L12: =K12/$K$15 -> 0
A13: Pivô 09 | J13: Canal/Reservatório | K13: =COUNTIF($B$5:$H$93,J13) -> 6 | L13: =K13/$K$15 -> 0.24
A14: Pivô 10 | G14: Redutor | H14: Bomba/Sucção | J14: Adutora | K14: =COUNTIF($B$5:$H$93,J14) -> 1 | L14: =K14/$K$15 -> 0.04
A15: Pivô 11 | J15: Total | K15: =SUM(K5:K14) -> 25
A16: Pivô 12
A17: Pivô 13
A18: Pivô 14
A19: Pivô 15
A20: Pivô 16
A21: Pivô 17 | B21: Canal/Reservatório
A22: Pivô 18 | C22: Canal/Reservatório
A23: Pivô 19 | C23: Motorredutor
A24: Pivô 20
A25: Pivô 21
A26: Pivô 22
A27: Pivô 23 | H27: Canal/Reservatório
A28: Pivô 24 | E28: Vedação | F28: Vedação | G28: Canal/Reservatório | H28: Canal/Reservatório
A29: Pivô 25 | C29: Pneu
A30: Pivô 26 | E30: Estrutura
A31: Pivô 27 | D31: Estrutura
A32: Pivô 28 | B32: Redutor
A33: Pivô 29 | E33: Adutora
A34: Pivô 30 | F34: Estrutura
A35: Pivô 31
A36: Pivô 32 | E36: Estrutura
A37: Pivô 33 | C37: Vedação
A38: Pivô 34 | B38: Estrutura
A39: Pivô 35
A40: Pivô 36
A41: Pivô 37
...

Sheet 25 04 2023
A1: Atendimento de irrigação (Imapacto - Problemas Mecânicos) - Semana 25/04/2022
A3: Data | B3: 44676 | C3: =B3+1 -> 44677 | D3: =C3+1 -> 44678 | E3: =D3+1 -> 44679 | F3: =E3+1 -> 44680 | G3: =F3+1 -> 44681 | H3: =G3+1 -> 44682
A4: Pivô | B4: =TEXT(B3,"ddd") -> seg | C4: =TEXT(C3,"ddd") -> ter | D4: =TEXT(D3,"ddd") -> qua | E4: =TEXT(E3,"ddd") -> qui | F4: =TEXT(F3,"ddd") -> sex | G4: =TEXT(G3,"ddd") -> sáb | H4: =TEXT(H3,"ddd") -> dom | J4: Parâmetros
A5: Pivô 01 | J5: Redutor | K5: =COUNTIF($B$5:$H$93,J5) -> 3 | L5: =K5/$K$15 -> 0.10714286
A6: Pivô 02 | E6: Redutor | G6: Bomba/Sucção | J6: Motorredutor | K6: =COUNTIF($B$5:$H$93,J6) -> 0 | L6: =K6/$K$15 -> 0
A7: Pivô 03 | J7: Castanha | K7: =COUNTIF($B$5:$H$93,J7) -> 1 | L7: =K7/$K$15 -> 0.035714286
A8: Pivô 04 | J8: Vedação | K8: =COUNTIF($B$5:$H$93,J8) -> 2 | L8: =K8/$K$15 -> 0.071428571
A9: Pivô 05 | J9: Pneu | K9: =COUNTIF($B$5:$H$93,J9) -> 1 | L9: =K9/$K$15 -> 0.035714286
A10: Pivô 06 | J10: Estrutura | K10: =COUNTIF($B$5:$H$93,J10) -> 0 | L10: =K10/$K$15 -> 0
A11: Pivô 07 | J11: Bomba/Sucção | K11: =COUNTIF($B$5:$H$93,J11) -> 13 | L11: =K11/$K$15 -> 0.46428571
A12: Pivô 08 | J12: Mangote | K12: =COUNTIF($B$5:$H$93,J12) -> 0 | L12: =K12/$K$15 -> 0
A13: Pivô 09 | J13: Canal/Reservatório | K13: =COUNTIF($B$5:$H$93,J13) -> 8 | L13: =K13/$K$15 -> 0.28571429
A14: Pivô 10 | C14: Bomba/Sucção | D14: Bomba/Sucção | E14: Bomba/Sucção | F14: Bomba/Sucção | J14: Adutora | K14: =COUNTIF($B$5:$H$93,J14) -> 0 | L14: =K14/$K$15 -> 0
A15: Pivô 11 | B15: Vedação | J15: Total | K15: =SUM(K5:K14) -> 28
A16: Pivô 12
A17: Pivô 13
A18: Pivô 14
A19: Pivô 15
A20: Pivô 16 | D20: Vedação
A21: Pivô 17
A22: Pivô 18
A23: Pivô 19
A24: Pivô 20
A25: Pivô 21
A26: Pivô 22
A27: Pivô 23 | C27: Canal/Reservatório | D27: Canal/Reservatório | E27: Canal/Reservatório | H27: Bomba/Sucção
A28: Pivô 24 | D28: Canal/Reservatório | E28: Canal/Reservatório | H28: Bomba/Sucção
A29: Pivô 25 | D29: Redutor | H29: Castanha
A30: Pivô 26
A31: Pivô 27
A32: Pivô 28
A33: Pivô 29
A34: Pivô 30
A35: Pivô 31
A36: Pivô 32 | F36: Canal/Reservatório
A37: Pivô 33 | F37: Canal/Reservatório
A38: Pivô 34
A39: Pivô 35
A40: Pivô 36 | B40: Redutor
A41: Pivô 37
...

Sheet 02 05 2022
A1: Atendimento de irrigação (Imapacto - Problemas Mecânicos) - Semana 02/05/2022
A3: Data | B3: 44683 | C3: =B3+1 -> 44684 | D3: =C3+1 -> 44685 | E3: =D3+1 -> 44686 | F3: =E3+1 -> 44687 | G3: =F3+1 -> 44688 | H3: =G3+1 -> 44689
A4: Pivô | B4: =TEXT(B3,"ddd") -> seg | C4: =TEXT(C3,"ddd") -> ter | D4: =TEXT(D3,"ddd") -> qua | E4: =TEXT(E3,"ddd") -> qui | F4: =TEXT(F3,"ddd") -> sex | G4: =TEXT(G3,"ddd") -> sáb | H4: =TEXT(H3,"ddd") -> dom | J4: Parâmetros
A5: Pivô 01 | F5: Canal/Reservatório | J5: Redutor | K5: =COUNTIF($B$5:$H$93,J5) -> 2 | L5: =K5/$K$15 -> 0.125
A6: Pivô 02 | J6: Motorredutor | K6: =COUNTIF($B$5:$H$93,J6) -> 0 | L6: =K6/$K$15 -> 0
A7: Pivô 03 | F7: Canal/Reservatório | J7: Castanha | K7: =COUNTIF($B$5:$H$93,J7) -> 2 | L7: =K7/$K$15 -> 0.125
A8: Pivô 04 | J8: Vedação | K8: =COUNTIF($B$5:$H$93,J8) -> 0 | L8: =K8/$K$15 -> 0
A9: Pivô 05 | J9: Pneu | K9: =COUNTIF($B$5:$H$93,J9) -> 5 | L9: =K9/$K$15 -> 0.3125
A10: Pivô 06 | G10: Pneu | J10: Estrutura | K10: =COUNTIF($B$5:$H$93,J10) -> 0 | L10: =K10/$K$15 -> 0
A11: Pivô 07 | F11: Pneu | J11: Bomba/Sucção | K11: =COUNTIF($B$5:$H$93,J11) -> 5 | L11: =K11/$K$15 -> 0.3125
A12: Pivô 08 | J12: Mangote | K12: =COUNTIF($B$5:$H$93,J12) -> 0 | L12: =K12/$K$15 -> 0
A13: Pivô 09 | J13: Canal/Reservatório | K13: =COUNTIF($B$5:$H$93,J13) -> 2 | L13: =K13/$K$15 -> 0.125
A14: Pivô 10 | J14: Adutora | K14: =COUNTIF($B$5:$H$93,J14) -> 0 | L14: =K14/$K$15 -> 0
A15: Pivô 11 | J15: Total | K15: =SUM(K5:K14) -> 16
A16: Pivô 12
A17: Pivô 13
A18: Pivô 14 | B18: Bomba/Sucção | C18: Bomba/Sucção | D18: Bomba/Sucção
A19: Pivô 15
A20: Pivô 16
A21: Pivô 17
A22: Pivô 18
A23: Pivô 19
A24: Pivô 20
A25: Pivô 21
A26: Pivô 22 | F26: Pneu
A27: Pivô 23 | B27: Bomba/Sucção
A28: Pivô 24 | B28: Bomba/Sucção
A29: Pivô 25
A30: Pivô 26
A31: Pivô 27
A32: Pivô 28 | D32: Castanha
A33: Pivô 29
A34: Pivô 30
A35: Pivô 31
A36: Pivô 32 | B36: Castanha
A37: Pivô 33
A38: Pivô 34
A39: Pivô 35
A40: Pivô 36
A41: Pivô 37
...

Sheet 09 05 2022
A1: Atendimento de irrigação (Imapacto - Problemas Mecânicos) - Semana 09/05/2022
A3: Data | B3: 44690 | C3: =B3+1 -> 44691 | D3: =C3+1 -> 44692 | E3: =D3+1 -> 44693 | F3: =E3+1 -> 44694 | G3: =F3+1 -> 44695 | H3: =G3+1 -> 44696
A4: Pivô | B4: =TEXT(B3,"ddd") -> seg | C4: =TEXT(C3,"ddd") -> ter | D4: =TEXT(D3,"ddd") -> qua | E4: =TEXT(E3,"ddd") -> qui | F4: =TEXT(F3,"ddd") -> sex | G4: =TEXT(G3,"ddd") -> sáb | H4: =TEXT(H3,"ddd") -> dom | J4: Parâmetros
A5: Pivô 01 | F5: Canal/Reservatório | J5: Redutor | K5: =COUNTIF($B$5:$H$93,J5) -> 1 | L5: =K5/$K$15 -> 0.14285714
A6: Pivô 02 | E6: Canal/Reservatório | J6: Motorredutor | K6: =COUNTIF($B$5:$H$93,J6) -> 0 | L6: =K6/$K$15 -> 0
A7: Pivô 03 | F7: Canal/Reservatório | J7: Castanha | K7: =COUNTIF($B$5:$H$93,J7) -> 0 | L7: =K7/$K$15 -> 0
A8: Pivô 04 | J8: Vedação | K8: =COUNTIF($B$5:$H$93,J8) -> 0 | L8: =K8/$K$15 -> 0
A9: Pivô 05 | J9: Pneu | K9: =COUNTIF($B$5:$H$93,J9) -> 0 | L9: =K9/$K$15 -> 0
A10: Pivô 06 | J10: Estrutura | K10: =COUNTIF($B$5:$H$93,J10) -> 0 | L10: =K10/$K$15 -> 0
A11: Pivô 07 | J11: Bomba/Sucção | K11: =COUNTIF($B$5:$H$93,J11) -> 0 | L11: =K11/$K$15 -> 0
A12: Pivô 08 | J12: Mangote | K12: =COUNTIF($B$5:$H$93,J12) -> 0 | L12: =K12/$K$15 -> 0
A13: Pivô 09 | J13: Canal/Reservatório | K13: =COUNTIF($B$5:$H$93,J13) -> 3 | L13: =K13/$K$15 -> 0.42857143
A14: Pivô 10 | J14: Adutora | K14: =COUNTIF($B$5:$H$93,J14) -> 3 | L14: =K14/$K$15 -> 0.42857143
A15: Pivô 11 | J15: Total | K15: =SUM(K5:K14) -> 7
A16: Pivô 12
A17: Pivô 13
A18: Pivô 14
A19: Pivô 15
A20: Pivô 16
A21: Pivô 17
A22: Pivô 18
A23: Pivô 19
A24: Pivô 20
A25: Pivô 21
A26: Pivô 22
A27: Pivô 23 | B27: Redutor
A28: Pivô 24
A29: Pivô 25
A30: Pivô 26
A31: Pivô 27
A32: Pivô 28
A33: Pivô 29
A34: Pivô 30 | E34: Adutora | F34: Adutora | G34: Adutora
A35: Pivô 31
A36: Pivô 32
A37: Pivô 33
A38: Pivô 34
A39: Pivô 35
A40: Pivô 36
A41: Pivô 37
...

Sheet 16 05 2022 
A1: Atendimento de irrigação (Imapacto - Problemas Mecânicos) - Semana 16/05/2022
A3: Data | B3: 44697 | C3: =B3+1 -> 44698 | D3: =C3+1 -> 44699 | E3: =D3+1 -> 44700 | F3: =E3+1 -> 44701 | G3: =F3+1 -> 44702 | H3: =G3+1 -> 44703
A4: Pivô | B4: =TEXT(B3,"ddd") -> seg | C4: =TEXT(C3,"ddd") -> ter | D4: =TEXT(D3,"ddd") -> qua | E4: =TEXT(E3,"ddd") -> qui | F4: =TEXT(F3,"ddd") -> sex | G4: =TEXT(G3,"ddd") -> sáb | H4: =TEXT(H3,"ddd") -> dom | J4: Parâmetros
A5: Pivô 01 | J5: Redutor | K5: =COUNTIF($B$5:$H$93,J5) -> 3 | L5: =K5/$K$15 -> 0.42857143
A6: Pivô 02 | J6: Motorredutor | K6: =COUNTIF($B$5:$H$93,J6) -> 0 | L6: =K6/$K$15 -> 0
A7: Pivô 03 | J7: Castanha | K7: =COUNTIF($B$5:$H$93,J7) -> 2 | L7: =K7/$K$15 -> 0.28571429
A8: Pivô 04 | J8: Vedação | K8: =COUNTIF($B$5:$H$93,J8) -> 1 | L8: =K8/$K$15 -> 0.14285714
A9: Pivô 05 | J9: Pneu | K9: =COUNTIF($B$5:$H$93,J9) -> 1 | L9: =K9/$K$15 -> 0.14285714
A10: Pivô 06 | J10: Estrutura | K10: =COUNTIF($B$5:$H$93,J10) -> 0 | L10: =K10/$K$15 -> 0
A11: Pivô 07 | J11: Bomba/Sucção | K11: =COUNTIF($B$5:$H$93,J11) -> 0 | L11: =K11/$K$15 -> 0
A12: Pivô 08 | J12: Mangote | K12: =COUNTIF($B$5:$H$93,J12) -> 0 | L12: =K12/$K$15 -> 0
A13: Pivô 09 | J13: Canal/Reservatório | K13: =COUNTIF($B$5:$H$93,J13) -> 0 | L13: =K13/$K$15 -> 0
A14: Pivô 10 | J14: Adutora | K14: =COUNTIF($B$5:$H$93,J14) -> 0 | L14: =K14/$K$15 -> 0
A15: Pivô 11 | J15: Total | K15: =SUM(K5:K14) -> 7
A16: Pivô 12 | B16: Castanha | G16: Pneu | H16: Redutor
A17: Pivô 13
A18: Pivô 14
A19: Pivô 15
A20: Pivô 16
A21: Pivô 17
A22: Pivô 18
A23: Pivô 19
A24: Pivô 20 | G24: Vedação
A25: Pivô 21
A26: Pivô 22
A27: Pivô 23
A28: Pivô 24
A29: Pivô 25 | G29: Redutor
A30: Pivô 26
A31: Pivô 27
A32: Pivô 28
A33: Pivô 29
A34: Pivô 30
A35: Pivô 31
A36: Pivô 32
A37: Pivô 33
A38: Pivô 34
A39: Pivô 35
A40: Pivô 36
A41: Pivô 37
...

Sheet 23 05 2022  
A1: Atendimento de irrigação (Imapacto - Problemas Mecânicos) - Semana 23/05/2022
A3: Data | B3: 44704 | C3: =B3+1 -> 44705 | D3: =C3+1 -> 44706 | E3: =D3+1 -> 44707 | F3: =E3+1 -> 44708 | G3: =F3+1 -> 44709 | H3: =G3+1 -> 44710
A4: Pivô | B4: =TEXT(B3,"ddd") -> seg | C4: =TEXT(C3,"ddd") -> ter | D4: =TEXT(D3,"ddd") -> qua | E4: =TEXT(E3,"ddd") -> qui | F4: =TEXT(F3,"ddd") -> sex | G4: =TEXT(G3,"ddd") -> sáb | H4: =TEXT(H3,"ddd") -> dom | J4: Parâmetros
A5: Pivô 01 | J5: Redutor | K5: =COUNTIF($B$5:$H$93,J5) -> 4 | L5: =K5/$K$15 -> 0.2
A6: Pivô 02 | J6: Motorredutor | K6: =COUNTIF($B$5:$H$93,J6) -> 2 | L6: =K6/$K$15 -> 0.1
A7: Pivô 03 | E7: Vedação | J7: Castanha | K7: =COUNTIF($B$5:$H$93,J7) -> 1 | L7: =K7/$K$15 -> 0.05
A8: Pivô 04 | J8: Vedação | K8: =COUNTIF($B$5:$H$93,J8) -> 4 | L8: =K8/$K$15 -> 0.2
A9: Pivô 05 | C9: Vedação | J9: Pneu | K9: =COUNTIF($B$5:$H$93,J9) -> 1 | L9: =K9/$K$15 -> 0.05
A10: Pivô 06 | J10: Estrutura | K10: =COUNTIF($B$5:$H$93,J10) -> 0 | L10: =K10/$K$15 -> 0
A11: Pivô 07 | J11: Bomba/Sucção | K11: =COUNTIF($B$5:$H$93,J11) -> 7 | L11: =K11/$K$15 -> 0.35
A12: Pivô 08 | J12: Mangote | K12: =COUNTIF($B$5:$H$93,J12) -> 0 | L12: =K12/$K$15 -> 0
A13: Pivô 09 | J13: Canal/Reservatório | K13: =COUNTIF($B$5:$H$93,J13) -> 0 | L13: =K13/$K$15 -> 0
A14: Pivô 10 | J14: Adutora | K14: =COUNTIF($B$5:$H$93,J14) -> 1 | L14: =K14/$K$15 -> 0.05
A15: Pivô 11 | D15: Castanha | J15: Total | K15: =SUM(K5:K14) -> 20
A16: Pivô 12 | B16: Redutor | C16: Redutor
A17: Pivô 13
A18: Pivô 14
A19: Pivô 15 | B19: Vedação
A20: Pivô 16
A21: Pivô 17
A22: Pivô 18
A23: Pivô 19
A24: Pivô 20 | G24: Motorredutor | H24: Motorredutor
A25: Pivô 21
A26: Pivô 22 | D26: Vedação
A27: Pivô 23
A28: Pivô 24
A29: Pivô 25 | B29: Redutor | D29: Adutora | G29: Redutor
A30: Pivô 26
A31: Pivô 27
A32: Pivô 28
A33: Pivô 29
A34: Pivô 30
A35: Pivô 31
A36: Pivô 32
A37: Pivô 33
A38: Pivô 34
A39: Pivô 35
A40: Pivô 36 | B40: Pneu
A41: Pivô 37
...

Sheet 30 05 2022   
A1: Atendimento de irrigação (Imapacto - Problemas Mecânicos) - Semana 30/05/2022
A3: Data | B3: 44711 | C3: =B3+1 -> 44712 | D3: =C3+1 -> 44713 | E3: =D3+1 -> 44714 | F3: =E3+1 -> 44715 | G3: =F3+1 -> 44716 | H3: =G3+1 -> 44717
A4: Pivô | B4: =TEXT(B3,"ddd") -> seg | C4: =TEXT(C3,"ddd") -> ter | D4: =TEXT(D3,"ddd") -> qua | E4: =TEXT(E3,"ddd") -> qui | F4: =TEXT(F3,"ddd") -> sex | G4: =TEXT(G3,"ddd") -> sáb | H4: =TEXT(H3,"ddd") -> dom | J4: Parâmetros
A5: Pivô 01 | J5: Redutor | K5: =COUNTIF($B$5:$H$93,J5) -> 5 | L5: =K5/$K$15 -> 1
A6: Pivô 02 | J6: Motorredutor | K6: =COUNTIF($B$5:$H$93,J6) -> 0 | L6: =K6/$K$15 -> 0
A7: Pivô 03 | J7: Castanha | K7: =COUNTIF($B$5:$H$93,J7) -> 0 | L7: =K7/$K$15 -> 0
A8: Pivô 04 | J8: Vedação | K8: =COUNTIF($B$5:$H$93,J8) -> 0 | L8: =K8/$K$15 -> 0
A9: Pivô 05 | B9: Redutor | J9: Pneu | K9: =COUNTIF($B$5:$H$93,J9) -> 0 | L9: =K9/$K$15 -> 0
A10: Pivô 06 | J10: Estrutura | K10: =COUNTIF($B$5:$H$93,J10) -> 0 | L10: =K10/$K$15 -> 0
A11: Pivô 07 | J11: Bomba/Sucção | K11: =COUNTIF($B$5:$H$93,J11) -> 0 | L11: =K11/$K$15 -> 0
A12: Pivô 08 | J12: Mangote | K12: =COUNTIF($B$5:$H$93,J12) -> 0 | L12: =K12/$K$15 -> 0
A13: Pivô 09 | B13: Redutor | J13: Canal/Reservatório | K13: =COUNTIF($B$5:$H$93,J13) -> 0 | L13: =K13/$K$15 -> 0
A14: Pivô 10 | J14: Adutora | K14: =COUNTIF($B$5:$H$93,J14) -> 0 | L14: =K14/$K$15 -> 0
A15: Pivô 11 | J15: Total | K15: =SUM(K5:K14) -> 5
A16: Pivô 12
A17: Pivô 13
A18: Pivô 14
A19: Pivô 15
A20: Pivô 16
A21: Pivô 17
A22: Pivô 18
A23: Pivô 19
A24: Pivô 20
A25: Pivô 21
A26: Pivô 22
A27: Pivô 23
A28: Pivô 24 | H28: Redutor
A29: Pivô 25 | B29: Redutor
A30: Pivô 26
A31: Pivô 27
A32: Pivô 28
A33: Pivô 29
A34: Pivô 30
A35: Pivô 31
A36: Pivô 32
A37: Pivô 33
A38: Pivô 34
A39: Pivô 35
A40: Pivô 36 | E40: Redutor
A41: Pivô 37
...

Sheet 06 06 2022
A1: Atendimento de irrigação (Imapacto - Problemas Mecânicos) - Semana 06/06/2022
A3: Data | B3: 44718 | C3: =B3+1 -> 44719 | D3: =C3+1 -> 44720 | E3: =D3+1 -> 44721 | F3: =E3+1 -> 44722 | G3: =F3+1 -> 44723 | H3: =G3+1 -> 44724
A4: Pivô | B4: =TEXT(B3,"ddd") -> seg | C4: =TEXT(C3,"ddd") -> ter | D4: =TEXT(D3,"ddd") -> qua | E4: =TEXT(E3,"ddd") -> qui | F4: =TEXT(F3,"ddd") -> sex | G4: =TEXT(G3,"ddd") -> sáb | H4: =TEXT(H3,"ddd") -> dom | J4: Parâmetros
A5: Pivô 01 | J5: Redutor | K5: =COUNTIF($B$5:$H$93,J5) -> 0 | L5: =K5/$K$15 -> 0
A6: Pivô 02 | J6: Motorredutor | K6: =COUNTIF($B$5:$H$93,J6) -> 0 | L6: =K6/$K$15 -> 0
A7: Pivô 03 | J7: Castanha | K7: =COUNTIF($B$5:$H$93,J7) -> 0 | L7: =K7/$K$15 -> 0
A8: Pivô 04 | J8: Vedação | K8: =COUNTIF($B$5:$H$93,J8) -> 0 | L8: =K8/$K$15 -> 0
A9: Pivô 05 | J9: Pneu | K9: =COUNTIF($B$5:$H$93,J9) -> 0 | L9: =K9/$K$15 -> 0
A10: Pivô 06 | J10: Estrutura | K10: =COUNTIF($B$5:$H$93,J10) -> 0 | L10: =K10/$K$15 -> 0
A11: Pivô 07 | J11: Bomba/Sucção | K11: =COUNTIF($B$5:$H$93,J11) -> 0 | L11: =K11/$K$15 -> 0
A12: Pivô 08 | J12: Mangote | K12: =COUNTIF($B$5:$H$93,J12) -> 1 | L12: =K12/$K$15 -> 0.5
A13: Pivô 09 | J13: Canal/Reservatório | K13: =COUNTIF($B$5:$H$93,J13) -> 0 | L13: =K13/$K$15 -> 0
A14: Pivô 10 | J14: Adutora | K14: =COUNTIF($B$5:$H$93,J14) -> 1 | L14: =K14/$K$15 -> 0.5
A15: Pivô 11 | J15: Total | K15: =SUM(K5:K14) -> 2
A16: Pivô 12
A17: Pivô 13
A18: Pivô 14
A19: Pivô 15
A20: Pivô 16 | E20: Adutora
A21: Pivô 17
A22: Pivô 18
A23: Pivô 19
A24: Pivô 20
A25: Pivô 21
A26: Pivô 22
A27: Pivô 23
A28: Pivô 24
A29: Pivô 25
A30: Pivô 26
A31: Pivô 27
A32: Pivô 28
... A61: Pivô 73
A62: Pivô 74 | D62: Mangote
A63: Pivô 101
A64: Pivô 102
A65: Pivô 103
A66: Pivô 104
A67: Pivô 105
A68: Pivô 106
A69: Pivô 107
...

Sheet 13 06 2022   
A1: Atendimento de irrigação (Imapacto - Problemas Mecânicos) - Semana 13/06/2022
A3: Data | B3: 44725 | C3: =B3+1 -> 44726 | D3: =C3+1 -> 44727 | E3: =D3+1 -> 44728 | F3: =E3+1 -> 44729 | G3: =F3+1 -> 44730 | H3: =G3+1 -> 44731
A4: Pivô | B4: =TEXT(B3,"ddd") -> seg | C4: =TEXT(C3,"ddd") -> ter | D4: =TEXT(D3,"ddd") -> qua | E4: =TEXT(E3,"ddd") -> qui | F4: =TEXT(F3,"ddd") -> sex | G4: =TEXT(G3,"ddd") -> sáb | H4: =TEXT(H3,"ddd") -> dom | J4: Parâmetros
A5: Pivô 01 | J5: Redutor | K5: =COUNTIF($B$5:$H$93,J5) -> 2 | L5: =K5/$K$15 -> 0.5
A6: Pivô 02 | J6: Motorredutor | K6: =COUNTIF($B$5:$H$93,J6) -> 1 | L6: =K6/$K$15 -> 0.25
A7: Pivô 03 | J7: Castanha | K7: =COUNTIF($B$5:$H$93,J7) -> 0 | L7: =K7/$K$15 -> 0
A8: Pivô 04 | H8: Motorredutor | J8: Vedação | K8: =COUNTIF($B$5:$H$93,J8) -> 0 | L8: =K8/$K$15 -> 0
A9: Pivô 05 | J9: Pneu | K9: =COUNTIF($B$5:$H$93,J9) -> 0 | L9: =K9/$K$15 -> 0
A10: Pivô 06 | J10: Estrutura | K10: =COUNTIF($B$5:$H$93,J10) -> 0 | L10: =K10/$K$15 -> 0
A11: Pivô 07 | J11: Bomba/Sucção | K11: =COUNTIF($B$5:$H$93,J11) -> 1 | L11: =K11/$K$15 -> 0.25
A12: Pivô 08 | J12: Mangote | K12: =COUNTIF($B$5:$H$93,J12) -> 0 | L12: =K12/$K$15 -> 0
A13: Pivô 09 | J13: Canal/Reservatório | K13: =COUNTIF($B$5:$H$93,J13) -> 0 | L13: =K13/$K$15 -> 0
A14: Pivô 10 | J14: Adutora | K14: =COUNTIF($B$5:$H$93,J14) -> 0 | L14: =K14/$K$15 -> 0
A15: Pivô 11 | J15: Total | K15: =SUM(K5:K14) -> 4
A16: Pivô 12
A17: Pivô 13
A18: Pivô 14 | C18: Redutor
A19: Pivô 15
A20: Pivô 16
A21: Pivô 17
A22: Pivô 18
A23: Pivô 19
A24: Pivô 20
A25: Pivô 21
A26: Pivô 22
A27: Pivô 23
A28: Pivô 24 | E28: Bomba/Sucção
A29: Pivô 25
A30: Pivô 26
A31: Pivô 27
A32: Pivô 28
A33: Pivô 29
A34: Pivô 30
A35: Pivô 31
A36: Pivô 32
A37: Pivô 33
A38: Pivô 34
A39: Pivô 35
A40: Pivô 36
... A83: Pivô 121
...

Sheet 20 06 2022   
A1: Atendimento de irrigação (Imapacto - Problemas Mecânicos) - Semana 20/06/2022
A3: Data | B3: 44732 | C3: =B3+1 -> 44733 | D3: =C3+1 -> 44734 | E3: =D3+1 -> 44735 | F3: =E3+1 -> 44736 | G3: =F3+1 -> 44737 | H3: =G3+1 -> 44738
A4: Pivô | B4: =TEXT(B3,"ddd") -> seg | C4: =TEXT(C3,"ddd") -> ter | D4: =TEXT(D3,"ddd") -> qua | E4: =TEXT(E3,"ddd") -> qui | F4: =TEXT(F3,"ddd") -> sex | G4: =TEXT(G3,"ddd") -> sáb | H4: =TEXT(H3,"ddd") -> dom | J4: Parâmetros
A5: Pivô 01 | J5: Redutor | K5: =COUNTIF($B$5:$H$93,J5) -> 3 | L5: =K5/$K$15 -> 0.375
A6: Pivô 02 | J6: Motorredutor | K6: =COUNTIF($B$5:$H$93,J6) -> 0 | L6: =K6/$K$15 -> 0
A7: Pivô 03 | J7: Castanha | K7: =COUNTIF($B$5:$H$93,J7) -> 1 | L7: =K7/$K$15 -> 0.125
A8: Pivô 04 | J8: Vedação | K8: =COUNTIF($B$5:$H$93,J8) -> 0 | L8: =K8/$K$15 -> 0
A9: Pivô 05 | J9: Pneu | K9: =COUNTIF($B$5:$H$93,J9) -> 2 | L9: =K9/$K$15 -> 0.25
A10: Pivô 06 | J10: Estrutura | K10: =COUNTIF($B$5:$H$93,J10) -> 0 | L10: =K10/$K$15 -> 0
A11: Pivô 07 | J11: Bomba/Sucção | K11: =COUNTIF($B$5:$H$93,J11) -> 0 | L11: =K11/$K$15 -> 0
A12: Pivô 08 | J12: Mangote | K12: =COUNTIF($B$5:$H$93,J12) -> 0 | L12: =K12/$K$15 -> 0
A13: Pivô 09 | D13: Pneu | J13: Canal/Reservatório | K13: =COUNTIF($B$5:$H$93,J13) -> 0 | L13: =K13/$K$15 -> 0
A14: Pivô 10 | J14: Adutora | K14: =COUNTIF($B$5:$H$93,J14) -> 2 | L14: =K14/$K$15 -> 0.25
A15: Pivô 11 | J15: Total | K15: =SUM(K5:K14) -> 8
A16: Pivô 12
A17: Pivô 13
A18: Pivô 14
A19: Pivô 15
A20: Pivô 16 | F20: Redutor
A21: Pivô 17
A22: Pivô 18
A23: Pivô 19 | D23: Castanha
A24: Pivô 20
A25: Pivô 21
A26: Pivô 22
A27: Pivô 23
A28: Pivô 24
A29: Pivô 25 | C29: Redutor | E29: Redutor
A30: Pivô 26
A31: Pivô 27
A32: Pivô 28
A33: Pivô 29
A34: Pivô 30
A35: Pivô 31
A36: Pivô 32
A37: Pivô 33
A38: Pivô 34
A39: Pivô 35
A40: Pivô 36
A41: Pivô 37
...

Sheet 27 06 2022  
A1: Atendimento de irrigação (Imapacto - Problemas Mecânicos) - Semana 27/06/2022
A3: Data | B3: 44739 | C3: =B3+1 -> 44740 | D3: =C3+1 -> 44741 | E3: =D3+1 -> 44742 | F3: =E3+1 -> 44743 | G3: =F3+1 -> 44744 | H3: =G3+1 -> 44745
A4: Pivô | B4: =TEXT(B3,"ddd") -> seg | C4: =TEXT(C3,"ddd") -> ter | D4: =TEXT(D3,"ddd") -> qua | E4: =TEXT(E3,"ddd") -> qui | F4: =TEXT(F3,"ddd") -> sex | G4: =TEXT(G3,"ddd") -> sáb | H4: =TEXT(H3,"ddd") -> dom | J4: Parâmetros
A5: Pivô 01 | B5: Redutor | J5: Redutor | K5: =COUNTIF($B$5:$H$93,J5) -> 3 | L5: =K5/$K$15 -> 0.5
A6: Pivô 02 | J6: Motorredutor | K6: =COUNTIF($B$5:$H$93,J6) -> 0 | L6: =K6/$K$15 -> 0
A7: Pivô 03 | J7: Castanha | K7: =COUNTIF($B$5:$H$93,J7) -> 0 | L7: =K7/$K$15 -> 0
A8: Pivô 04 | J8: Vedação | K8: =COUNTIF($B$5:$H$93,J8) -> 0 | L8: =K8/$K$15 -> 0
A9: Pivô 05 | J9: Pneu | K9: =COUNTIF($B$5:$H$93,J9) -> 1 | L9: =K9/$K$15 -> 0.16666667
A10: Pivô 06 | J10: Estrutura | K10: =COUNTIF($B$5:$H$93,J10) -> 0 | L10: =K10/$K$15 -> 0
A11: Pivô 07 | J11: Bomba/Sucção | K11: =COUNTIF($B$5:$H$93,J11) -> 0 | L11: =K11/$K$15 -> 0
A12: Pivô 08 | J12: Mangote | K12: =COUNTIF($B$5:$H$93,J12) -> 0 | L12: =K12/$K$15 -> 0
A13: Pivô 09 | J13: Canal/Reservatório | K13: =COUNTIF($B$5:$H$93,J13) -> 0 | L13: =K13/$K$15 -> 0
A14: Pivô 10 | J14: Adutora | K14: =COUNTIF($B$5:$H$93,J14) -> 2 | L14: =K14/$K$15 -> 0.33333333
A15: Pivô 11 | J15: Total | K15: =SUM(K5:K14) -> 6
A16: Pivô 12
A17: Pivô 13
A18: Pivô 14 | G18: Redutor
A19: Pivô 15
A20: Pivô 16 | B20: Redutor
A21: Pivô 17
A22: Pivô 18
A23: Pivô 19
A24: Pivô 20
A25: Pivô 21
A26: Pivô 22
A27: Pivô 23
A28: Pivô 24
A29: Pivô 25
A30: Pivô 26
A31: Pivô 27
A32: Pivô 28
... A51: Pivô 47
A52: Pivô 48 | E52: Adutora | F52: Adutora
A53: Pivô 49
A54: Pivô 50
A55: Pivô 51
A56: Pivô 52
A57: Pivô 53
A58: Pivô 54
A59: Pivô 55
...

Sheet Acumulado
A2: Parâmetros | B2: 44613 | C2: 44620 | D2: 44627 | E2: 44634 | F2: 44641 | G2: 44648 | H2: 44655 | I2: 44662 | J2: 44669 | K2: 44676 | L2: 44683 | M2: 44690 | N2: 44697 | O2: 44704 | P2: 44711 | Q2: 44718 | R2: 44725 | S2: 44732 | T2: 44739 | U2: Total | V2: Percentual
A3: Redutor | B3: ='21 02 2022'!K5 -> 1 | C3: ='28 02 2022 '!K5 -> 2 | D3: ='07 03 2022'!K5 -> 2 | E3: ='14 03 2022'!K5 -> 0 | F3: ='21 03 2022'!K5 -> 0 | G3: ='28 03 2022'!K5 -> 0 | H3: ='04 04 2022'!K5 -> 0 | I3: ='11 04 2022'!K5 -> 2 | J3: ='18 04 2022'!K5 -> 4 | K3: ='25 04 2023'!K5 -> 3 | L3: ='02 05 2022'!K5 -> 2 | M3: ='09 05 2022'!K5 -> 1 | N3: ='16 05 2022 '!K5 -> 3 | O3: ='23 05 2022 '!K5 -> 4 | P3: ='30 05 2022 '!K5 -> 5 | Q3: ='06 06 2022'!K5 -> 0 | R3: ='13 06 2022 '!K5 -> 2 | S3: ='20 06 2022 '!K5 -> 3 | T3: ='27 06 2022 '!K5 -> 3 | U3: =SUM(B3:T3) -> 37 | V3: =U3/$U$13 -> 0.148
A4: Motorredutor | B4: ='21 02 2022'!K6 -> 1 | C4: ='28 02 2022 '!K6 -> 0 | D4: ='07 03 2022'!K6 -> 0 | E4: ='14 03 2022'!K6 -> 3 | F4: ='21 03 2022'!K6 -> 0 | G4: ='28 03 2022'!K6 -> 1 | H4: ='04 04 2022'!K6 -> 1 | I4: ='11 04 2022'!K6 -> 0 | J4: ='18 04 2022'!K6 -> 1 | K4: ='25 04 2023'!K6 -> 0 | L4: ='02 05 2022'!K6 -> 0 | M4: ='09 05 2022'!K6 -> 0 | N4: ='16 05 2022 '!K6 -> 0 | O4: ='23 05 2022 '!K6 -> 2 | P4: ='30 05 2022 '!K6 -> 0 | Q4: ='06 06 2022'!K6 -> 0 | R4: ='13 06 2022 '!K6 -> 1 | S4: ='20 06 2022 '!K6 -> 0 | T4: ='27 06 2022 '!K6 -> 0 | U4: =SUM(B4:T4) -> 10 | V4: =U4/$U$13 -> 0.04
A5: Castanha | B5: ='21 02 2022'!K7 -> 0 | C5: ='28 02 2022 '!K7 -> 0 | D5: ='07 03 2022'!K7 -> 0 | E5: ='14 03 2022'!K7 -> 0 | F5: ='21 03 2022'!K7 -> 0 | G5: ='28 03 2022'!K7 -> 0 | H5: ='04 04 2022'!K7 -> 0 | I5: ='11 04 2022'!K7 -> 0 | J5: ='18 04 2022'!K7 -> 0 | K5: ='25 04 2023'!K7 -> 1 | L5: ='02 05 2022'!K7 -> 2 | M5: ='09 05 2022'!K7 -> 0 | N5: ='16 05 2022 '!K7 -> 2 | O5: ='23 05 2022 '!K7 -> 1 | P5: ='30 05 2022 '!K7 -> 0 | Q5: ='06 06 2022'!K7 -> 0 | R5: ='13 06 2022 '!K7 -> 0 | S5: ='20 06 2022 '!K7 -> 1 | T5: ='27 06 2022 '!K7 -> 0 | U5: =SUM(B5:T5) -> 7 | V5: =U5/$U$13 -> 0.028
A6: Vedação | B6: ='21 02 2022'!K8 -> 0 | C6: ='28 02 2022 '!K8 -> 0 | D6: ='07 03 2022'!K8 -> 0 | E6: ='14 03 2022'!K8 -> 1 | F6: ='21 03 2022'!K8 -> 0 | G6: ='28 03 2022'!K8 -> 0 | H6: ='04 04 2022'!K8 -> 1 | I6: ='11 04 2022'!K8 -> 2 | J6: ='18 04 2022'!K8 -> 3 | K6: ='25 04 2023'!K8 -> 2 | L6: ='02 05 2022'!K8 -> 0 | M6: ='09 05 2022'!K8 -> 0 | N6: ='16 05 2022 '!K8 -> 1 | O6: ='23 05 2022 '!K8 -> 4 | P6: ='30 05 2022 '!K8 -> 0 | Q6: ='06 06 2022'!K8 -> 0 | R6: ='13 06 2022 '!K8 -> 0 | S6: ='20 06 2022 '!K8 -> 0 | T6: ='27 06 2022 '!K8 -> 0 | U6: =SUM(B6:T6) -> 14 | V6: =U6/$U$13 -> 0.056
A7: Pneu | B7: ='21 02 2022'!K9 -> 0 | C7: ='28 02 2022 '!K9 -> 2 | D7: ='07 03 2022'!K9 -> 2 | E7: ='14 03 2022'!K9 -> 4 | F7: ='21 03 2022'!K9 -> 1 | G7: ='28 03 2022'!K9 -> 1 | H7: ='04 04 2022'!K9 -> 1 | I7: ='11 04 2022'!K9 -> 2 | J7: ='18 04 2022'!K9 -> 4 | K7: ='25 04 2023'!K9 -> 1 | L7: ='02 05 2022'!K9 -> 5 | M7: ='09 05 2022'!K9 -> 0 | N7: ='16 05 2022 '!K9 -> 1 | O7: ='23 05 2022 '!K9 -> 1 | P7: ='30 05 2022 '!K9 -> 0 | Q7: ='06 06 2022'!K9 -> 0 | R7: ='13 06 2022 '!K9 -> 0 | S7: ='20 06 2022 '!K9 -> 2 | T7: ='27 06 2022 '!K9 -> 1 | U7: =SUM(B7:T7) -> 28 | V7: =U7/$U$13 -> 0.112
A8: Estrutura | B8: ='21 02 2022'!K10 -> 0 | C8: ='28 02 2022 '!K10 -> 10 | D8: ='07 03 2022'!K10 -> 5 | E8: ='14 03 2022'!K10 -> 11 | F8: ='21 03 2022'!K10 -> 11 | G8: ='28 03 2022'!K10 -> 11 | H8: ='04 04 2022'!K10 -> 11 | I8: ='11 04 2022'!K10 -> 15 | J8: ='18 04 2022'!K10 -> 5 | K8: ='25 04 2023'!K10 -> 0 | L8: ='02 05 2022'!K10 -> 0 | M8: ='09 05 2022'!K10 -> 0 | N8: ='16 05 2022 '!K10 -> 0 | O8: ='23 05 2022 '!K10 -> 0 | P8: ='30 05 2022 '!K10 -> 0 | Q8: ='06 06 2022'!K10 -> 0 | R8: ='13 06 2022 '!K10 -> 0 | S8: ='20 06 2022 '!K10 -> 0 | T8: ='27 06 2022 '!K10 -> 0 | U8: =SUM(B8:T8) -> 79 | V8: =U8/$U$13 -> 0.316
A9: Bomba/Sucção | B9: ='21 02 2022'!K11 -> 2 | C9: ='28 02 2022 '!K11 -> 1 | D9: ='07 03 2022'!K11 -> 0 | E9: ='14 03 2022'!K11 -> 1 | F9: ='21 03 2022'!K11 -> 0 | G9: ='28 03 2022'!K11 -> 0 | H9: ='04 04 2022'!K11 -> 1 | I9: ='11 04 2022'!K11 -> 0 | J9: ='18 04 2022'!K11 -> 1 | K9: ='25 04 2023'!K11 -> 13 | L9: ='02 05 2022'!K11 -> 5 | M9: ='09 05 2022'!K11 -> 0 | N9: ='16 05 2022 '!K11 -> 0 | O9: ='23 05 2022 '!K11 -> 7 | P9: ='30 05 2022 '!K11 -> 0 | Q9: ='06 06 2022'!K11 -> 0 | R9: ='13 06 2022 '!K11 -> 1 | S9: ='20 06 2022 '!K11 -> 0 | T9: ='27 06 2022 '!K11 -> 0 | U9: =SUM(B9:T9) -> 32 | V9: =U9/$U$13 -> 0.128
A10: Mangote | B10: ='21 02 2022'!K12 -> 0 | C10: ='28 02 2022 '!K12 -> 0 | D10: ='07 03 2022'!K12 -> 1 | E10: ='14 03 2022'!K12 -> 0 | F10: ='21 03 2022'!K12 -> 3 | G10: ='28 03 2022'!K12 -> 0 | H10: ='04 04 2022'!K12 -> 0 | I10: ='11 04 2022'!K12 -> 0 | J10: ='18 04 2022'!K12 -> 0 | K10: ='25 04 2023'!K12 -> 0 | L10: ='02 05 2022'!K12 -> 0 | M10: ='09 05 2022'!K12 -> 0 | N10: ='16 05 2022 '!K12 -> 0 | O10: ='23 05 2022 '!K12 -> 0 | P10: ='30 05 2022 '!K12 -> 0 | Q10: ='06 06 2022'!K12 -> 1 | R10: ='13 06 2022 '!K12 -> 0 | S10: ='20 06 2022 '!K12 -> 0 | T10: ='27 06 2022 '!K12 -> 0 | U10: =SUM(B10:T10) -> 5 | V10: =U10/$U$13 -> 0.02
A11: Canal/Reservatório | B11: ='21 02 2022'!K13 -> 0 | C11: ='28 02 2022 '!K13 -> 0 | D11: ='07 03 2022'!K13 -> 0 | E11: ='14 03 2022'!K13 -> 0 | F11: ='21 03 2022'!K13 -> 0 | G11: ='28 03 2022'!K13 -> 0 | H11: ='04 04 2022'!K13 -> 0 | I11: ='11 04 2022'!K13 -> 0 | J11: ='18 04 2022'!K13 -> 6 | K11: ='25 04 2023'!K13 -> 8 | L11: ='02 05 2022'!K13 -> 2 | M11: ='09 05 2022'!K13 -> 3 | N11: ='16 05 2022 '!K13 -> 0 | O11: ='23 05 2022 '!K13 -> 0 | P11: ='30 05 2022 '!K13 -> 0 | Q11: ='06 06 2022'!K13 -> 0 | R11: ='13 06 2022 '!K13 -> 0 | S11: ='20 06 2022 '!K13 -> 0 | T11: ='27 06 2022 '!K13 -> 0 | U11: =SUM(B11:T11) -> 19 | V11: =U11/$U$13 -> 0.076
A12: Adutora | B12: ='21 02 2022'!K14 -> 2 | C12: ='28 02 2022 '!K14 -> 2 | D12: ='07 03 2022'!K14 -> 0 | E12: ='14 03 2022'!K14 -> 0 | F12: ='21 03 2022'!K14 -> 0 | G12: ='28 03 2022'!K14 -> 1 | H12: ='04 04 2022'!K14 -> 2 | I12: ='11 04 2022'!K14 -> 2 | J12: ='18 04 2022'!K14 -> 1 | K12: ='25 04 2023'!K14 -> 0 | L12: ='02 05 2022'!K14 -> 0 | M12: ='09 05 2022'!K14 -> 3 | N12: ='16 05 2022 '!K14 -> 0 | O12: ='23 05 2022 '!K14 -> 1 | P12: ='30 05 2022 '!K14 -> 0 | Q12: ='06 06 2022'!K14 -> 1 | R12: ='13 06 2022 '!K14 -> 0 | S12: ='20 06 2022 '!K14 -> 2 | T12: ='27 06 2022 '!K14 -> 2 | U12: =SUM(B12:T12) -> 19 | V12: =U12/$U$13 -> 0.076
A13: Total | B13: =SUM(B3:B12) -> 6 | C13: =SUM(C3:C12) -> 17 | D13: =SUM(D3:D12) -> 10 | E13: =SUM(E3:E12) -> 20 | F13: =SUM(F3:F12) -> 15 | G13: =SUM(G3:G12) -> 14 | H13: =SUM(H3:H12) -> 17 | I13: =SUM(I3:I12) -> 23 | ... U13: =SUM(U3:U12) -> 250
