Workbook
Name PesquisarQuem: OFFSET('[1]Pesquisa de nome'!$A$3,,,COUNT('[1]Pesquisa de nome'!$B:$B),1)

Sheet 17122020
C3: 44182 | D3: =C3+1 -> 44183 | E3: =D3+1 -> 44184 | F3: =E3+1 -> 44185 | G3: =F3+1 -> 44186 | H3: =G3+1 -> 44187 | I3: =H3+1 -> 44188 | J3: =I3+1 -> 44189
B4: Pivô | C4: =TEXT(C3,"ddd") -> qui | D4: =TEXT(D3,"ddd") -> sex | E4: =TEXT(E3,"ddd") -> sáb | F4: =TEXT(F3,"ddd") -> dom | G4: =TEXT(G3,"ddd") -> seg | H4: =TEXT(H3,"ddd") -> ter | I4: =TEXT(I3,"ddd") -> qua | J4: =TEXT(J3,"ddd") -> qui | L4: Parametros
B5: 1 | C5: Feito | D5: Feito | F5: Chuva | G5: Energia | H5: Feito | I5: Feito | L5: Feito | M5: =COUNTIF($C$5:$J$60,L5) -> 81
B6: 2 | L6: Mecânico | M6: =COUNTIF($C$5:$J$60,L6) -> 12
B7: 3 | L7: Elétrico | M7: =COUNTIF($C$5:$J$60,L7) -> 3
B8: 4 | C8: Mecânico | E8: Feito | F8: Chuva | I8: Feito | L8: Energia | M8: =COUNTIF($C$5:$J$60,L8) -> 12
B9: 5 | C9: Feito | E9: Feito | I9: Chuva | L9: Chuva | M9: =COUNTIF($C$5:$J$60,L9) -> 24
B10: 6 | C10: Feito | E10: Feito | H10: Feito | L10: Operação | M10: =COUNTIF($C$5:$J$60,L10) -> 2
B11: 7 | C11: Mecânico | F11: Chuva | I11: Chuva | M11: =SUM(M5:M10) -> 134
B12: 8 | C12: Feito | E12: Feito | H12: Feito
B13: 9 | C13: Operação | D13: Feito | F13: Chuva | H13: Feito
B14: 10 | E14: Feito | I14: Chuva
B15: 11 | C15: Feito | E15: Feito | H15: Feito
B16: 12 | C16: Feito | F16: Chuva | H16: Feito
B17: 13 | D17: Feito | E17: Feito | G17: Energia | H17: Feito | I17: Feito | J17: Feito
B18: 14 | C18: Feito | D18: Feito | E18: Feito | I18: Chuva
B19: 15 | D19: Feito | F19: Chuva
B20: 16 | G20: Energia
B21: 17 | D21: Mecânico | F21: Feito | G21: Energia
B22: 18
B23: 19 | D23: Mecânico | E23: Mecânico | F23: Mecânico | G23: Mecânico | I23: Feito | J23: Feito
B24: 20
B25: 21 | C25: Feito | E25: Elétrico | H25: Feito
B26: 22
B27: 23 | D27: Feito | F27: Chuva | I27: Chuva
B28: 24
B29: 25 | C29: Feito | D29: Feito | E29: Feito | F29: Feito | G29: Energia | H29: Feito | I29: Feito
B30: 26 | D30: Feito | E30: Feito | I30: Chuva
B31: 27 | D31: Feito | F31: Chuva | I31: Chuva
B32: 28
B33: 29 | C33: Feito | D33: Feito | E33: Feito | F33: Chuva
B34: 30
B35: 31 | F35: Chuva
B36: 32
B37: 33 | C37: Feito | F37: Chuva
B38: 34 | E38: Mecânico | F38: Mecânico
B39: 35
B40: 36 | D40: Feito | E40: Mecânico | F40: Mecânico
B41: 37 | D41: Feito | F41: Chuva
B42: 38 | D42: Feito | F42: Chuva
...

Sheet 25122020
C3: 44190 | D3: =C3+1 -> 44191 | E3: =D3+1 -> 44192 | F3: =E3+1 -> 44193 | G3: =F3+1 -> 44194 | H3: =G3+1 -> 44195 | I3: =H3+1 -> 44196 | J3: =I3+1 -> 44197
B4: Pivô | C4: =TEXT(C3,"ddd") -> sex | D4: =TEXT(D3,"ddd") -> sáb | E4: =TEXT(E3,"ddd") -> dom | F4: =TEXT(F3,"ddd") -> seg | G4: =TEXT(G3,"ddd") -> ter | H4: =TEXT(H3,"ddd") -> qua | I4: =TEXT(I3,"ddd") -> qui | J4: =TEXT(J3,"ddd") -> sex | L4: Parametros
B5: 1 | F5: Mecânico | H5: Elétrico | L5: Feito | M5: =COUNTIF($C$5:$J$60,L5) -> 101
B6: 2 | L6: Mecânico | M6: =COUNTIF($C$5:$J$60,L6) -> 10
B7: 3 | L7: Elétrico | M7: =COUNTIF($C$5:$J$60,L7) -> 6
B8: 4 | F8: Feito | G8: Feito | H8: Feito | I8: Feito | J8: Feito | L8: Energia | M8: =COUNTIF($C$5:$J$60,L8) -> 2
B9: 5 | E9: Feito | G9: Feito | I9: Feito | L9: Chuva | M9: =COUNTIF($C$5:$J$60,L9) -> 0
B10: 6 | F10: Operação | H10: Feito | J10: Feito | L10: Operação | M10: =COUNTIF($C$5:$J$60,L10) -> 7
B11: 7 | E11: Feito | G11: Feito | I11: Feito | M11: =SUM(M5:M10) -> 126
B12: 8 | F12: Feito | H12: Operação | J12: Feito
B13: 9 | E13: Feito | G13: Feito
B14: 10 | F14: Feito | H14: Feito | J14: Mecânico
B15: 11 | E15: Feito | G15: Feito | I15: Feito
B16: 12 | F16: Feito | G16: Feito | H16: Feito | J16: Feito
B17: 13 | E17: Feito | G17: Feito | I17: Feito
B18: 14 | F18: Operação | G18: Feito | H18: Feito | I18: Feito
B19: 15 | E19: Feito | G19: Mecânico | H19: Mecânico | J19: Elétrico
B20: 16
B21: 17 | F21: Feito | G21: Operação | H21: Feito | J21: Feito
B22: 18
B23: 19 | D23: Feito | E23: Feito | I23: Feito
B24: 20
B25: 21 | F25: Mecânico | G25: Elétrico | I25: Energia | J25: Elétrico
B26: 22
B27: 23 | E27: Feito | I27: Energia | J27: Elétrico
B28: 24 | I28: Feito | J28: Mecânico
B29: 25 | E29: Feito | F29: Feito | G29: Feito | H29: Feito | I29: Feito | J29: Feito
B30: 26 | E30: Feito | G30: Feito
B31: 27 | E31: Feito | G31: Feito
B32: 28
B33: 29 | E33: Feito | F33: Feito | H33: Feito | I33: Operação | J33: Feito
B34: 30 | H34: Mecânico | I34: Mecânico | J34: Mecânico
B35: 31
B36: 32
B37: 33 | J37: Feito
B38: 34 | H38: Operação | I38: Feito | J38: Feito
B39: 35
B40: 36 | E40: Feito | G40: Elétrico | I40: Feito
B41: 37 | F41: Feito | H41: Feito | J41: Feito
B42: 38 | F42: Feito | H42: Feito | J42: Feito
...

Sheet 02012021 
C3: 44198 | D3: =C3+1 -> 44199 | E3: =D3+1 -> 44200 | F3: =E3+1 -> 44201 | G3: =F3+1 -> 44202 | H3: =G3+1 -> 44203 | I3: =H3+1 -> 44204 | J3: =I3+1 -> 44205
B4: Pivô | C4: =TEXT(C3,"ddd") -> sáb | D4: =TEXT(D3,"ddd") -> dom | E4: =TEXT(E3,"ddd") -> seg | F4: =TEXT(F3,"ddd") -> ter | G4: =TEXT(G3,"ddd") -> qua | H4: =TEXT(H3,"ddd") -> qui | I4: =TEXT(I3,"ddd") -> sex | J4: =TEXT(J3,"ddd") -> sáb | L4: Parametros
B5: 1 | C5: Chuva | H5: Mecânico | I5: Mecânico | L5: Feito | M5: =COUNTIF($C$5:$J$60,L5) -> 38
B6: 2 | H6: Feito | I6: Feito | L6: Mecânico | M6: =COUNTIF($C$5:$J$60,L6) -> 12
B7: 3 | F7: Feito | G7: Feito | H7: Operação | L7: Elétrico | M7: =COUNTIF($C$5:$J$60,L7) -> 12
B8: 4 | D8: Chuva | G8: Feito | H8: Mecânico | L8: Energia | M8: =COUNTIF($C$5:$J$60,L8) -> 0
B9: 5 | C9: Chuva | L9: Chuva | M9: =COUNTIF($C$5:$J$60,L9) -> 39
B10: 6 | D10: Chuva | L10: Operação | M10: =COUNTIF($C$5:$J$60,L10) -> 8
B11: 7 | I11: Feito | M11: =SUM(M5:M10) -> 109
B12: 8 | H12: Operação | I12: Mecânico
B13: 9 | C13: Chuva | D13: Chuva | F13: Feito | G13: Feito
B14: 10 | H14: Operação
B15: 11 | C15: Chuva
B16: 12 | D16: Chuva | G16: Feito | H16: Operação | I16: Feito
B17: 13 | C17: Chuva | G17: Feito | I17: Feito
B18: 14 | D18: Chuva | H18: Elétrico
B19: 15 | D19: Chuva | G19: Elétrico | I19: Elétrico
B20: 16
B21: 17 | D21: Chuva
B22: 18
B23: 19 | C23: Chuva
B24: 20 | I24: Operação
B25: 21
B26: 22 | H26: Operação | I26: Operação
B27: 23 | C27: Chuva
B28: 24 | C28: Chuva | D28: Chuva | G28: Mecânico | H28: Feito | I28: Feito
B29: 25 | C29: Chuva | D29: Chuva | H29: Feito | I29: Feito
B30: 26 | C30: Chuva
B31: 27 | C31: Chuva | G31: Feito
B32: 28 | D32: Chuva | G32: Mecânico | I32: Mecânico
B33: 29 | C33: Chuva | H33: Feito | I33: Feito
B34: 30 | C34: Mecânico | D34: Mecânico | G34: Mecânico | H34: Feito | I34: Feito
B35: 31 | C35: Chuva
B36: 32 | G36: Feito | H36: Feito | I36: Feito
B37: 33
B38: 34 | C38: Chuva | D38: Chuva | G38: Feito | H38: Mecânico | I38: Mecânico
B39: 35
B40: 36 | C40: Chuva | H40: Feito
B41: 37 | D41: Chuva | H41: Feito
B42: 38
...

Sheet 14012021
C3: 44210 | D3: =C3+1 -> 44211 | E3: =D3+1 -> 44212 | F3: =E3+1 -> 44213 | G3: =F3+1 -> 44214 | H3: =G3+1 -> 44215 | I3: =H3+1 -> 44216 | J3: =I3+1 -> 44217
B4: Pivô | C4: =TEXT(C3,"ddd") -> qui | D4: =TEXT(D3,"ddd") -> sex | E4: =TEXT(E3,"ddd") -> sáb | F4: =TEXT(F3,"ddd") -> dom | G4: =TEXT(G3,"ddd") -> seg | H4: =TEXT(H3,"ddd") -> ter | I4: =TEXT(I3,"ddd") -> qua | J4: =TEXT(J3,"ddd") -> qui | L4: Parametros
B5: 1 | C5: Mecânico | L5: Feito | M5: =COUNTIF($C$5:$J$60,L5) -> 38
B6: 2 | L6: Mecânico | M6: =COUNTIF($C$5:$J$60,L6) -> 13
B7: 3 | L7: Elétrico | M7: =COUNTIF($C$5:$J$60,L7) -> 9
B8: 4 | H8: Feito | J8: Feito | L8: Energia | M8: =COUNTIF($C$5:$J$60,L8) -> 0
B9: 5 | J9: Feito | L9: Chuva | M9: =COUNTIF($C$5:$J$60,L9) -> 0
B10: 6 | I10: Mecânico | L10: Operação | M10: =COUNTIF($C$5:$J$60,L10) -> 1
B11: 7 | I11: Feito | M11: =SUM(M5:M10) -> 61
B12: 8 | J12: Feito
B13: 9 | I13: Feito | J13: Feito
B14: 10 | G14: Feito | H14: Feito | I14: Elétrico
B15: 11 | I15: Feito | J15: Feito
B16: 12 | G16: Feito | H16: Feito | J16: Feito
B17: 13 | I17: Feito
B18: 14 | H18: Feito | I18: Feito | J18: Elétrico
B19: 15 | J19: Mecânico
B20: 16 | C20: Mecânico | H20: Mecânico | I20: Mecânico | J20: Mecânico
B21: 17
B22: 18 | C22: Mecânico | H22: Feito | J22: Feito
B23: 19
B24: 20 | C24: Feito | J24: Feito
B25: 21
B26: 22 | I26: Elétrico
B27: 23
B28: 24
B29: 25 | H29: Feito | I29: Feito | J29: Feito
B30: 26
B31: 27 | J31: Mecânico
B32: 28 | C32: Mecânico
B33: 29 | H33: Feito | J33: Feito
B34: 30 | I34: Mecânico
B35: 31
B36: 32 | I36: Feito
B37: 33
B38: 34 | C38: Mecânico
B39: 35
B40: 36 | H40: Elétrico | J40: Elétrico
B41: 37 | I41: Feito
B42: 38
...

Sheet 22012021
C3: 44218 | D3: =C3+1 -> 44219 | E3: =D3+1 -> 44220 | F3: =E3+1 -> 44221 | G3: =F3+1 -> 44222 | H3: =G3+1 -> 44223 | I3: =H3+1 -> 44224 | J3: =I3+1 -> 44225
B4: Pivô | C4: =TEXT(C3,"ddd") -> sex | D4: =TEXT(D3,"ddd") -> sáb | E4: =TEXT(E3,"ddd") -> dom | F4: =TEXT(F3,"ddd") -> seg | G4: =TEXT(G3,"ddd") -> ter | H4: =TEXT(H3,"ddd") -> qua | I4: =TEXT(I3,"ddd") -> qui | J4: =TEXT(J3,"ddd") -> sex | L4: Parametros
B5: 1 | C5: Mecânico | F5: Mecânico | J5: Operação | L5: Feito | M5: =COUNTIF($C$5:$J$60,L5) -> 118
B6: 2 | I6: Feito | L6: Mecânico | M6: =COUNTIF($C$5:$J$60,L6) -> 19
B7: 3 | L7: Elétrico | M7: =COUNTIF($C$5:$J$60,L7) -> 4
B8: 4 | D8: Feito | F8: Feito | L8: Energia | M8: =COUNTIF($C$5:$J$60,L8) -> 19
B9: 5 | D9: Feito | F9: Feito | H9: Feito | J9: Operação | L9: Chuva | M9: =COUNTIF($C$5:$J$60,L9) -> 0
B10: 6 | C10: Feito | E10: Feito | F10: Feito | G10: Feito | I10: Feito | L10: Operação | M10: =COUNTIF($C$5:$J$60,L10) -> 19
B11: 7 | C11: Feito | E11: Feito | G11: Energia | I11: Feito | M11: =SUM(M5:M10) -> 179
B12: 8 | D12: Feito | F12: Mecânico | H12: Feito | I12: Feito | J12: Feito
B13: 9 | C13: Feito | E13: Feito | G13: Mecânico | J13: Operação
B14: 10 | C14: Mecânico | E14: Mecânico | G14: Operação | I14: Feito
B15: 11 | C15: Feito | E15: Feito | G15: Feito | I15: Feito
B16: 12 | D16: Feito | F16: Feito | H16: Feito | J16: Operação
B17: 13 | C17: Feito | E17: Feito | G17: Feito | I17: Feito
B18: 14 | D18: Elétrico | F18: Feito | H18: Operação | J18: Feito
B19: 15
B20: 16 | C20: Feito | F20: Feito | I20: Mecânico
B21: 17 | F21: Feito | G21: Feito | H21: Feito | I21: Feito | J21: Feito
B22: 18 | E22: Feito | H22: Feito | I22: Feito
B23: 19 | F23: Feito | G23: Feito | H23: Feito | I23: Energia | J23: Energia
B24: 20 | E24: Feito | H24: Energia | J24: Operação
B25: 21 | E25: Feito | F25: Mecânico | G25: Energia | H25: Energia | I25: Energia | J25: Energia
B26: 22 | C26: Elétrico | D26: Elétrico | F26: Mecânico | I26: Feito
B27: 23 | E27: Feito | F27: Feito | G27: Feito | H27: Operação | I27: Feito | J27: Feito
B28: 24 | E28: Feito | H28: Operação
B29: 25 | C29: Feito | D29: Feito | E29: Feito | F29: Feito | G29: Feito | H29: Mecânico | I29: Mecânico | J29: Energia
B30: 26 | D30: Feito | E30: Mecânico | F30: Feito | G30: Feito | H30: Feito | I30: Feito | J30: Feito
B31: 27
B32: 28 | H32: Feito
B33: 29 | D33: Feito | F33: Feito | H33: Feito | J33: Operação
B34: 30 | D34: Mecânico | G34: Feito | I34: Operação
B35: 31 | J35: Feito
B36: 32 | C36: Feito | F36: Mecânico | J36: Operação
B37: 33
B38: 34 | H38: Mecânico | I38: Operação
B39: 35
B40: 36 | D40: Feito | F40: Feito | H40: Feito | I40: Feito
B41: 37 | C41: Feito | E41: Feito | G41: Feito
B42: 38 | H42: Feito | I42: Feito | J42: Feito
...

Sheet 30012021
C3: 44226 | D3: =C3+1 -> 44227 | E3: =D3+1 -> 44228 | F3: =E3+1 -> 44229 | G3: =F3+1 -> 44230 | H3: =G3+1 -> 44231 | I3: =H3+1 -> 44232 | J3: =I3+1 -> 44233
B4: Pivô | C4: =TEXT(C3,"ddd") -> sáb | D4: =TEXT(D3,"ddd") -> dom | E4: =TEXT(E3,"ddd") -> seg | F4: =TEXT(F3,"ddd") -> ter | G4: =TEXT(G3,"ddd") -> qua | H4: =TEXT(H3,"ddd") -> qui | I4: =TEXT(I3,"ddd") -> sex | J4: =TEXT(J3,"ddd") -> sáb | L4: Parametros
B5: 1 | D5: Operação | G5: Feito | L5: Feito | M5: =COUNTIF($C$5:$J$60,L5) -> 122
B6: 2 | G6: Mecânico | L6: Mecânico | M6: =COUNTIF($C$5:$J$60,L6) -> 12
B7: 3 | L7: Elétrico | M7: =COUNTIF($C$5:$J$60,L7) -> 0
B8: 4 | I8: Operação | J8: Feito | L8: Energia | M8: =COUNTIF($C$5:$J$60,L8) -> 18
B9: 5 | D9: Feito | G9: Feito | I9: Feito | L9: Chuva | M9: =COUNTIF($C$5:$J$60,L9) -> 2
B10: 6 | C10: Feito | F10: Feito | H10: Feito | J10: Feito | L10: Operação | M10: =COUNTIF($C$5:$J$60,L10) -> 21
B11: 7 | C11: Feito | F11: Feito | I11: Feito | M11: =SUM(M5:M10) -> 175
B12: 8 | D12: Mecânico | F12: Feito | H12: Feito | J12: Feito
B13: 9 | D13: Mecânico | F13: Operação | H13: Feito | J13: Feito
B14: 10 | C14: Operação | G14: Feito | I14: Feito
B15: 11 | C15: Feito | F15: Feito | H15: Feito | J15: Feito
B16: 12 | D16: Feito | G16: Feito | I16: Feito
B17: 13 | C17: Feito | D17: Feito | F17: Feito | G17: Feito | H17: Feito | I17: Feito | J17: Feito
B18: 14 | D18: Feito | G18: Mecânico | J18: Feito
B19: 15 | I19: Feito
B20: 16 | C20: Operação | G20: Feito
B21: 17 | C21: Feito | D21: Feito | F21: Feito | J21: Feito
B22: 18 | D22: Operação | E22: Feito | J22: Feito
B23: 19 | C23: Energia | D23: Feito | F23: Operação
B24: 20 | F24: Operação
B25: 21 | C25: Energia | D25: Energia | E25: Feito | F25: Energia | J25: Feito
B26: 22 | D26: Feito | G26: Feito
B27: 23 | C27: Feito | D27: Feito | G27: Feito
B28: 24 | C28: Operação | H28: Operação
B29: 25 | C29: Feito | D29: Energia | E29: Feito | F29: Energia | H29: Feito | I29: Feito | J29: Chuva
B30: 26 | C30: Feito | D30: Feito | G30: Operação | J30: Feito
B31: 27 | J31: Mecânico
B32: 28 | C32: Operação | G32: Feito
B33: 29 | D33: Feito | G33: Feito | H33: Feito
B34: 30 | C34: Feito | F34: Mecânico | G34: Operação | J34: Feito
B35: 31 | D35: Mecânico | E35: Feito | F35: Mecânico | G35: Feito | H35: Feito | J35: Feito
B36: 32 | F36: Feito | H36: Chuva
B37: 33
B38: 34 | C38: Feito | G38: Feito | H38: Feito
B39: 35
B40: 36 | C40: Feito | F40: Feito | I40: Mecânico
B41: 37
B42: 38 | C42: Feito | D42: Feito | F42: Feito | H42: Feito | J42: Feito
...

Sheet 07022021
C3: 44234 | D3: =C3+1 -> 44235 | E3: =D3+1 -> 44236 | F3: =E3+1 -> 44237 | G3: =F3+1 -> 44238 | H3: =G3+1 -> 44239 | I3: =H3+1 -> 44240 | J3: =I3+1 -> 44241
B4: Pivô | C4: =TEXT(C3,"ddd") -> dom | D4: =TEXT(D3,"ddd") -> seg | E4: =TEXT(E3,"ddd") -> ter | F4: =TEXT(F3,"ddd") -> qua | G4: =TEXT(G3,"ddd") -> qui | H4: =TEXT(H3,"ddd") -> sex | I4: =TEXT(I3,"ddd") -> sáb | J4: =TEXT(J3,"ddd") -> dom | L4: Parametros
B5: 1 | C5: Operação | L5: Feito | M5: =COUNTIF($C$5:$J$60,L5) -> 10
B6: 2 | C6: Chuva | I6: Feito | L6: Mecânico | M6: =COUNTIF($C$5:$J$60,L6) -> 2
B7: 3 | L7: Elétrico | M7: =COUNTIF($C$5:$J$60,L7) -> 1
B8: 4 | L8: Energia | M8: =COUNTIF($C$5:$J$60,L8) -> 0
B9: 5 | C9: Chuva | L9: Chuva | M9: =COUNTIF($C$5:$J$60,L9) -> 26
B10: 6 | L10: Operação | M10: =COUNTIF($C$5:$J$60,L10) -> 1
B11: 7 | C11: Chuva | M11: =SUM(M5:M10) -> 40
B12: 8
B13: 9
B14: 10 | C14: Chuva
B15: 11
B16: 12 | C16: Chuva
B17: 13 | C17: Feito
B18: 14
B19: 15 | C19: Chuva
B20: 16 | C20: Feito
B21: 17 | I21: Feito
B22: 18
B23: 19 | C23: Chuva
B24: 20 | C24: Chuva
B25: 21
B26: 22
B27: 23 | C27: Chuva
B28: 24
B29: 25 | C29: Chuva | I29: Feito
B30: 26
B31: 27 | C31: Chuva
B32: 28
B33: 29 | C33: Feito
B34: 30
B35: 31 | C35: Chuva
B36: 32
B37: 33
B38: 34 | C38: Chuva
B39: 35 | C39: Chuva
B40: 36 | C40: Chuva
B41: 37
B42: 38 | I42: Feito
...

Sheet 15022021
C3: 44242 | D3: =C3+1 -> 44243 | E3: =D3+1 -> 44244 | F3: =E3+1 -> 44245 | G3: =F3+1 -> 44246 | H3: =G3+1 -> 44247 | I3: =H3+1 -> 44248 | J3: =I3+1 -> 44249
B4: Pivô | C4: =TEXT(C3,"ddd") -> seg | D4: =TEXT(D3,"ddd") -> ter | E4: =TEXT(E3,"ddd") -> qua | F4: =TEXT(F3,"ddd") -> qui | G4: =TEXT(G3,"ddd") -> sex | H4: =TEXT(H3,"ddd") -> sáb | I4: =TEXT(I3,"ddd") -> dom | J4: =TEXT(J3,"ddd") -> seg | L4: Parametros
B5: 1 | L5: Feito | M5: =COUNTIF($C$5:$J$60,L5) -> 9
B6: 2 | C6: Feito | J6: Feito | L6: Mecânico | M6: =COUNTIF($C$5:$J$60,L6) -> 6
B7: 3 | E7: Feito | F7: Feito | L7: Elétrico | M7: =COUNTIF($C$5:$J$60,L7) -> 0
B8: 4 | L8: Energia | M8: =COUNTIF($C$5:$J$60,L8) -> 0
B9: 5 | L9: Chuva | M9: =COUNTIF($C$5:$J$60,L9) -> 1
B10: 6 | L10: Operação | M10: =COUNTIF($C$5:$J$60,L10) -> 2
B11: 7 | M11: =SUM(M5:M10) -> 18
B12: 8
B13: 9
B14: 10
B15: 11
B16: 12
B17: 13
B18: 14
B19: 15
B20: 16
B21: 17
B22: 18 | J22: Feito
B23: 19 | C23: Chuva | G23: Feito
B24: 20 | F24: Operação
B25: 21
B26: 22
B27: 23
B28: 24 | E28: Mecânico
B29: 25 | C29: Feito
B30: 26
B31: 27
B32: 28
B33: 29 | C33: Feito | D33: Feito
B34: 30
B35: 31
B36: 32 | C36: Mecânico | D36: Mecânico | E36: Mecânico | F36: Mecânico | G36: Mecânico | J36: Operação
B37: 33
B38: 34
B39: 35
B40: 36
B41: 37
B42: 38
...

Sheet 24022021
C3: 44250 | D3: =C3+1 -> 44251 | E3: =D3+1 -> 44252 | F3: =E3+1 -> 44253 | G3: =F3+1 -> 44254 | H3: =G3+1 -> 44255 | I3: =H3+1 -> 44256 | J3: =I3+1 -> 44257
B4: Pivô | C4: =TEXT(C3,"ddd") -> ter | D4: =TEXT(D3,"ddd") -> qua | E4: =TEXT(E3,"ddd") -> qui | F4: =TEXT(F3,"ddd") -> sex | G4: =TEXT(G3,"ddd") -> sáb | H4: =TEXT(H3,"ddd") -> dom | I4: =TEXT(I3,"ddd") -> seg | J4: =TEXT(J3,"ddd") -> ter | L4: Parametros
B5: 1 | L5: Feito | M5: =COUNTIF($C$5:$J$60,L5) -> 14
B6: 2 | C6: Feito | J6: Feito | L6: Mecânico | M6: =COUNTIF($C$5:$J$60,L6) -> 1
B7: 3 | D7: Chuva | E7: Feito | I7: Feito | L7: Elétrico | M7: =COUNTIF($C$5:$J$60,L7) -> 1
B8: 4 | L8: Energia | M8: =COUNTIF($C$5:$J$60,L8) -> 0
B9: 5 | L9: Chuva | M9: =COUNTIF($C$5:$J$60,L9) -> 1
B10: 6 | L10: Operação | M10: =COUNTIF($C$5:$J$60,L10) -> 0
B11: 7 | M11: =SUM(M5:M10) -> 17
B12: 8
B13: 9
B14: 10
B15: 11
B16: 12
B17: 13
B18: 14
B19: 15
B20: 16 | D20: Feito | E20: Feito
B21: 17
B22: 18 | C22: Feito
B23: 19
B24: 20
B25: 21
B26: 22 | D26: Feito | E26: Feito
B27: 23
B28: 24 | F28: Mecânico | J28: Elétrico
B29: 25 | D29: Feito
B30: 26
B31: 27
B32: 28 | F32: Feito
B33: 29 | D33: Feito | I33: Feito
B34: 30
B35: 31
B36: 32 | C36: Feito
B37: 33
B38: 34
B39: 35
B40: 36
B41: 37
B42: 38
...

Sheet 03032021
C3: 44258 | D3: =C3+1 -> 44259 | E3: =D3+1 -> 44260 | F3: =E3+1 -> 44261 | G3: =F3+1 -> 44262 | H3: =G3+1 -> 44263 | I3: =H3+1 -> 44264 | J3: =I3+1 -> 44265
B4: Pivô | C4: =TEXT(C3,"ddd") -> qua | D4: =TEXT(D3,"ddd") -> qui | E4: =TEXT(E3,"ddd") -> sex | F4: =TEXT(F3,"ddd") -> sáb | G4: =TEXT(G3,"ddd") -> dom | H4: =TEXT(H3,"ddd") -> seg | I4: =TEXT(I3,"ddd") -> ter | J4: =TEXT(J3,"ddd") -> qua | L4: Parametros
B5: 1 | D5: Feito | G5: Feito | L5: Feito | M5: =COUNTIF($C$5:$J$60,L5) -> 75
B6: 2 | C6: Feito | E6: Operação | G6: Feito | J6: Feito | L6: Mecânico | M6: =COUNTIF($C$5:$J$60,L6) -> 12
B7: 3 | D7: Feito | E7: Feito | F7: Feito | H7: Feito | L7: Elétrico | M7: =COUNTIF($C$5:$J$60,L7) -> 15
B8: 4 | D8: Feito | E8: Feito | F8: Feito | G8: Feito | H8: Feito | J8: Chuva | L8: Energia | M8: =COUNTIF($C$5:$J$60,L8) -> 2
B9: 5 | L9: Chuva | M9: =COUNTIF($C$5:$J$60,L9) -> 11
B10: 6 | L10: Operação | M10: =COUNTIF($C$5:$J$60,L10) -> 12
B11: 7 | M11: =SUM(M5:M10) -> 127
B12: 8
B13: 9
B14: 10
B15: 11
B16: 12
B17: 13 | D17: Feito | E17: Feito | F17: Feito | G17: Feito
B18: 14 | D18: Feito | F18: Mecânico | H18: Mecânico | I18: Chuva | J18: Feito
B19: 15 | E19: Feito
B20: 16 | E20: Feito | F20: Feito
B21: 17 | D21: Feito | F21: Elétrico
B22: 18 | D22: Operação | E22: Mecânico | F22: Mecânico | G22: Feito
B23: 19 | E23: Feito | H23: Chuva
B24: 20 | D24: Operação | G24: Feito
B25: 21 | D25: Elétrico | F25: Elétrico
B26: 22 | E26: Feito | H26: Chuva | J26: Feito
B27: 23 | C27: Feito | F27: Elétrico | H27: Chuva
B28: 24 | C28: Mecânico | G28: Feito
B29: 25 | C29: Feito | D29: Feito | E29: Feito | F29: Feito | G29: Feito | H29: Operação | J29: Chuva
B30: 26 | C30: Feito | F30: Operação
B31: 27 | E31: Feito
B32: 28 | D32: Feito | G32: Feito | H32: Operação | I32: Chuva | J32: Feito
B33: 29 | D33: Feito | F33: Feito
B34: 30 | C34: Feito | E34: Feito | G34: Feito
B35: 31
B36: 32 | D36: Elétrico | E36: Operação | G36: Feito
B37: 33
B38: 34 | F38: Operação | H38: Feito
B39: 35
B40: 36
B41: 37 | G41: Feito | H41: Feito | J41: Feito
B42: 38 | E42: Feito
...

Sheet 11032021
C3: 44266 | D3: =C3+1 -> 44267 | E3: =D3+1 -> 44268 | F3: =E3+1 -> 44269 | G3: =F3+1 -> 44270 | H3: =G3+1 -> 44271 | I3: =H3+1 -> 44272 | J3: =I3+1 -> 44273
B4: Pivô | C4: =TEXT(C3,"ddd") -> qui | D4: =TEXT(D3,"ddd") -> sex | E4: =TEXT(E3,"ddd") -> sáb | F4: =TEXT(F3,"ddd") -> dom | G4: =TEXT(G3,"ddd") -> seg | H4: =TEXT(H3,"ddd") -> ter | I4: =TEXT(I3,"ddd") -> qua | J4: =TEXT(J3,"ddd") -> qui | L4: Parametros
B5: 1 | F5: Feito | H5: Feito | J5: Feito | L5: Feito | M5: =COUNTIF($C$5:$J$60,L5) -> 93
B6: 2 | G6: Mecânico | L6: Mecânico | M6: =COUNTIF($C$5:$J$60,L6) -> 9
B7: 3 | C7: Feito | F7: Feito | I7: Feito | L7: Elétrico | M7: =COUNTIF($C$5:$J$60,L7) -> 8
B8: 4 | D8: Feito | E8: Feito | F8: Feito | G8: Feito | H8: Feito | I8: Feito | J8: Feito | L8: Energia | M8: =COUNTIF($C$5:$J$60,L8) -> 9
B9: 5 | J9: Operação | L9: Chuva | M9: =COUNTIF($C$5:$J$60,L9) -> 0
B10: 6 | L10: Operação | M10: =COUNTIF($C$5:$J$60,L10) -> 11
B11: 7 | M11: =SUM(M5:M10) -> 130
B12: 8
B13: 9
B14: 10
B15: 11
B16: 12
B17: 13 | F17: Mecânico | G17: Mecânico | H17: Elétrico | J17: Feito
B18: 14 | C18: Feito | G18: Feito | I18: Feito
B19: 15 | G19: Feito | J19: Feito
B20: 16 | F20: Feito | G20: Feito | I20: Mecânico | J20: Mecânico
B21: 17 | H21: Feito
B22: 18 | F22: Feito | J22: Mecânico
B23: 19 | F23: Feito | H23: Operação | I23: Feito
B24: 20 | D24: Feito | G24: Feito | J24: Feito
B25: 21 | D25: Feito | H25: Energia
B26: 22 | C26: Feito | G26: Feito | J26: Feito
B27: 23 | H27: Energia
B28: 24 | C28: Feito | G28: Feito | I28: Mecânico
B29: 25 | C29: Feito | D29: Feito | F29: Feito | G29: Feito | H29: Feito | I29: Feito | J29: Feito
B30: 26 | H30: Energia
B31: 27 | G31: Feito | J31: Feito
B32: 28 | G32: Feito | J32: Feito
B33: 29 | D33: Feito | F33: Feito | H33: Feito | I33: Feito | J33: Feito
B34: 30 | F34: Feito | H34: Energia | J34: Operação
B35: 31
B36: 32 | F36: Feito | G36: Feito | I36: Feito | J36: Feito
B37: 33
B38: 34 | F38: Feito | H38: Energia | J38: Feito
B39: 35 | H39: Elétrico | I39: Feito | J39: Elétrico
B40: 36
B41: 37 | D41: Feito | E41: Feito | F41: Feito | G41: Feito | H41: Feito | I41: Feito | J41: Feito
B42: 38 | G42: Feito | J42: Operação
...

Sheet 19 03 2021
C3: 44274 | D3: =C3+1 -> 44275 | E3: =D3+1 -> 44276 | F3: =E3+1 -> 44277 | G3: =F3+1 -> 44278 | H3: =G3+1 -> 44279 | I3: =H3+1 -> 44280 | J3: =I3+1 -> 44281
B4: Pivô | C4: =TEXT(C3,"ddd") -> sex | D4: =TEXT(D3,"ddd") -> sáb | E4: =TEXT(E3,"ddd") -> dom | F4: =TEXT(F3,"ddd") -> seg | G4: =TEXT(G3,"ddd") -> ter | H4: =TEXT(H3,"ddd") -> qua | I4: =TEXT(I3,"ddd") -> qui | J4: =TEXT(J3,"ddd") -> sex | L4: Parametros
B5: 1 | D5: Feito | F5: Feito | J5: Feito | L5: Feito | M5: =COUNTIF($C$5:$J$60,L5) -> 113
B6: 2 | C6: Feito | D6: Feito | E6: Feito | F6: Mecânico | G6: Feito | H6: Operação | J6: Feito | L6: Mecânico | M6: =COUNTIF($C$5:$J$60,L6) -> 23
B7: 3 | C7: Feito | H7: Feito | I7: Feito | L7: Elétrico | M7: =COUNTIF($C$5:$J$60,L7) -> 18
B8: 4 | C8: Mecânico | D8: Feito | E8: Feito | G8: Feito | I8: Feito | J8: Feito | L8: Energia | M8: =COUNTIF($C$5:$J$60,L8) -> 0
B9: 5 | I9: Feito | L9: Chuva | M9: =COUNTIF($C$5:$J$60,L9) -> 0
B10: 6 | D10: Elétrico | I10: Feito | L10: Operação | M10: =COUNTIF($C$5:$J$60,L10) -> 37
B11: 7 | D11: Feito | M11: =SUM(M5:M10) -> 191
B12: 8 | G12: Operação
B13: 9
B14: 10
B15: 11
B16: 12 | I16: Feito | J16: Feito
B17: 13 | D17: Feito
B18: 14 | C18: Mecânico | E18: Feito | H18: Operação | J18: Operação
B19: 15 | C19: Operação | E19: Feito | H19: Feito
B20: 16 | C20: Mecânico | D20: Mecânico | E20: Mecânico | F20: Mecânico | G20: Mecânico | H20: Mecânico | I20: Mecânico | J20: Mecânico
B21: 17 | C21: Feito | E21: Feito | G21: Feito | H21: Feito
B22: 18 | D22: Feito | G22: Feito | J22: Feito
B23: 19 | C23: Feito | F23: Operação | G23: Operação | J23: Feito
B24: 20 | E24: Operação | H24: Feito
B25: 21 | C25: Elétrico | G25: Elétrico | I25: Elétrico
B26: 22 | E26: Operação | I26: Feito
B27: 23 | C27: Elétrico | F27: Elétrico | I27: Elétrico
B28: 24 | D28: Operação | G28: Operação | I28: Operação | J28: Feito
B29: 25 | C29: Feito | D29: Feito | E29: Feito | F29: Feito | G29: Feito | H29: Feito | I29: Feito | J29: Feito
B30: 26 | C30: Feito | F30: Feito | I30: Feito
B31: 27 | C31: Operação | F31: Feito | I31: Feito
B32: 28 | E32: Feito | H32: Operação | I32: Feito | J32: Operação
B33: 29 | C33: Feito | D33: Feito | E33: Feito | F33: Mecânico | G33: Operação | H33: Feito | I33: Feito | J33: Feito
B34: 30 | D34: Operação | E34: Mecânico | F34: Mecânico | G34: Mecânico | H34: Mecânico | I34: Mecânico | J34: Feito
B35: 31
B36: 32 | D36: Feito | E36: Feito | G36: Feito | H36: Mecânico | I36: Mecânico | J36: Mecânico
B37: 33 | I37: Elétrico | J37: Feito
B38: 34 | D38: Operação | G38: Feito | J38: Feito
B39: 35 | C39: Mecânico | D39: Elétrico | E39: Elétrico | F39: Feito | G39: Feito | H39: Feito | I39: Feito | J39: Feito
B40: 36 | D40: Mecânico | F40: Feito | G40: Elétrico | H40: Operação | I40: Feito | J40: Feito
B41: 37 | D41: Operação | E41: Feito | J41: Feito
B42: 38 | E42: Feito | H42: Operação
...

Sheet 27 03 2021
C3: 44282 | D3: =C3+1 -> 44283 | E3: =D3+1 -> 44284 | F3: =E3+1 -> 44285 | G3: =F3+1 -> 44286 | H3: =G3+1 -> 44287 | I3: =H3+1 -> 44288 | J3: =I3+1 -> 44289
B4: Pivô | C4: =TEXT(C3,"ddd") -> sáb | D4: =TEXT(D3,"ddd") -> dom | E4: =TEXT(E3,"ddd") -> seg | F4: =TEXT(F3,"ddd") -> ter | G4: =TEXT(G3,"ddd") -> qua | H4: =TEXT(H3,"ddd") -> qui | I4: =TEXT(I3,"ddd") -> sex | J4: =TEXT(J3,"ddd") -> sáb | L4: Parametros
B5: 1 | D5: Elétrico | G5: Elétrico | J5: Feito | L5: Feito | M5: =COUNTIF($C$5:$J$60,L5) -> 139
B6: 2 | C6: Feito | D6: Feito | E6: Feito | F6: Feito | G6: Feito | H6: Feito | I6: Feito | J6: Feito | L6: Mecânico | M6: =COUNTIF($C$5:$J$60,L6) -> 23
B7: 3 | D7: Feito | F7: Feito | G7: Feito | L7: Elétrico | M7: =COUNTIF($C$5:$J$60,L7) -> 5
B8: 4 | E8: Mecânico | G8: Feito | H8: Feito | I8: Feito | L8: Energia | M8: =COUNTIF($C$5:$J$60,L8) -> 0
B9: 5 | D9: Feito | G9: Mecânico | H9: Mecânico | I9: Mecânico | L9: Chuva | M9: =COUNTIF($C$5:$J$60,L9) -> 0
B10: 6 | C10: Feito | I10: Mecânico | J10: Mecânico | L10: Operação | M10: =COUNTIF($C$5:$J$60,L10) -> 47
B11: 7 | J11: Feito | M11: =SUM(M5:M10) -> 214
B12: 8
B13: 9
B14: 10
B15: 11
B16: 12
B17: 13
B18: 14 | C18: Feito | E18: Feito | I18: Feito
B19: 15 | D19: Mecânico | G19: Feito | H19: Operação | J19: Feito
B20: 16 | C20: Mecânico | D20: Mecânico | E20: Mecânico | F20: Mecânico | G20: Mecânico | H20: Mecânico | I20: Operação | J20: Feito
B21: 17 | C21: Feito | F21: Feito | I21: Feito
B22: 18 | E22: Operação | H22: Mecânico | I22: Mecânico | J22: Mecânico
B23: 19 | E23: Feito | F23: Feito | H23: Operação | I23: Feito
B24: 20 | C24: Mecânico | I24: Feito
B25: 21 | D25: Operação | G25: Elétrico | J25: Feito
B26: 22 | D26: Feito | E26: Feito | F26: Feito | H26: Operação
B27: 23 | D27: Operação | E27: Feito | G27: Elétrico | J27: Feito
B28: 24 | D28: Feito | G28: Operação | J28: Feito
B29: 25 | C29: Feito | D29: Feito | E29: Feito | F29: Feito | H29: Feito | I29: Feito | J29: Feito
B30: 26 | D30: Feito | J30: Feito
B31: 27 | C31: Operação | E31: Operação | J31: Feito
B32: 28 | E32: Operação | F32: Operação | G32: Feito | H32: Feito | I32: Mecânico | J32: Mecânico
B33: 29 | C33: Feito | D33: Feito | E33: Feito | F33: Feito | G33: Feito | H33: Feito | I33: Feito | J33: Feito
B34: 30 | C34: Feito | D34: Feito | F34: Feito | H34: Feito | J34: Feito
B35: 31 | C35: Feito | D35: Feito | E35: Mecânico | F35: Mecânico | G35: Feito | H35: Feito | I35: Feito | J35: Feito
B36: 32 | C36: Feito | E36: Feito | F36: Feito | H36: Feito | I36: Feito | J36: Mecânico
B37: 33 | C37: Feito | D37: Feito | E37: Feito | F37: Feito | G37: Feito | I37: Feito
B38: 34 | C38: Mecânico | E38: Feito | F38: Feito | H38: Feito | J38: Feito
B39: 35 | C39: Feito | D39: Feito | E39: Feito | F39: Feito | G39: Feito | H39: Feito | I39: Feito | J39: Feito
B40: 36 | C40: Feito | D40: Feito | E40: Feito | F40: Feito | G40: Feito | H40: Feito | I40: Feito | J40: Feito
B41: 37 | F41: Feito | J41: Feito
B42: 38 | C42: Feito | F42: Feito | H42: Operação | I42: Feito
...

Sheet 04 04 2021
C3: 44290 | D3: =C3+1 -> 44291 | E3: =D3+1 -> 44292 | F3: =E3+1 -> 44293 | G3: =F3+1 -> 44294 | H3: =G3+1 -> 44295 | I3: =H3+1 -> 44296 | J3: =I3+1 -> 44297
B4: Pivô | C4: =TEXT(C3,"ddd") -> dom | D4: =TEXT(D3,"ddd") -> seg | E4: =TEXT(E3,"ddd") -> ter | F4: =TEXT(F3,"ddd") -> qua | G4: =TEXT(G3,"ddd") -> qui | H4: =TEXT(H3,"ddd") -> sex | I4: =TEXT(I3,"ddd") -> sáb | J4: =TEXT(J3,"ddd") -> dom | L4: Parametros
B5: 1 | E5: Feito | L5: Feito | M5: =COUNTIF($C$5:$J$60,L5) -> 49
B6: 2 | C6: Mecânico | D6: Feito | E6: Feito | F6: Chuva | G6: Chuva | L6: Mecânico | M6: =COUNTIF($C$5:$J$60,L6) -> 41
B7: 3 | C7: Mecânico | E7: Mecânico | F7: Chuva | I7: Operação | L7: Elétrico | M7: =COUNTIF($C$5:$J$60,L7) -> 7
B8: 4 | D8: Feito | J8: Mecânico | L8: Energia | M8: =COUNTIF($C$5:$J$60,L8) -> 0
B9: 5 | C9: Feito | E9: Feito | L9: Chuva | M9: =COUNTIF($C$5:$J$60,L9) -> 34
B10: 6 | C10: Feito | D10: Mecânico | E10: Mecânico | H10: Mecânico | I10: Elétrico | J10: Mecânico | L10: Operação | M10: =COUNTIF($C$5:$J$60,L10) -> 15
B11: 7 | C11: Feito | M11: =SUM(M5:M10) -> 146
B12: 8 | C12: Feito
B13: 9
B14: 10
B15: 11
B16: 12
B17: 13
B18: 14
B19: 15 | E19: Feito | F19: Chuva
B20: 16 | D20: Feito | E20: Feito | F20: Chuva | H20: Mecânico | I20: Mecânico | J20: Mecânico
B21: 17 | D21: Feito
B22: 18 | C22: Mecânico | D22: Mecânico
B23: 19 | C23: Feito | F23: Chuva | H23: Mecânico | I23: Mecânico | J23: Mecânico
B24: 20 | C24: Mecânico | I24: Operação | J24: Operação
B25: 21 | D25: Mecânico | E25: Feito
B26: 22 | C26: Mecânico | D26: Mecânico | E26: Feito | G26: Chuva | I26: Operação | J26: Operação
B27: 23 | E27: Feito | G27: Chuva
B28: 24 | E28: Feito | G28: Chuva | I28: Operação | J28: Operação
B29: 25 | D29: Operação | E29: Feito | G29: Chuva
B30: 26 | E30: Operação | F30: Chuva
B31: 27 | D31: Operação | E31: Operação | G31: Chuva
B32: 28 | C32: Mecânico | D32: Mecânico | E32: Mecânico | H32: Mecânico | I32: Mecânico | J32: Mecânico
B33: 29 | C33: Feito | D33: Feito | E33: Feito | J33: Elétrico
B34: 30 | D34: Feito | F34: Chuva | H34: Elétrico | I34: Mecânico
B35: 31 | C35: Mecânico | D35: Feito | E35: Feito | G35: Chuva | H35: Elétrico | I35: Elétrico | J35: Elétrico
B36: 32 | C36: Feito | D36: Feito | F36: Chuva | H36: Mecânico | I36: Mecânico | J36: Operação
B37: 33 | C37: Mecânico | E37: Mecânico | F37: Chuva
B38: 34 | D38: Feito | G38: Chuva
B39: 35 | C39: Feito | D39: Feito | E39: Feito | F39: Chuva
B40: 36 | C40: Feito | E40: Feito | G40: Chuva
B41: 37 | F41: Chuva | G41: Chuva
B42: 38 | D42: Feito | G42: Chuva
...

Sheet 12 04 2021
C3: 44298 | D3: =C3+1 -> 44299 | E3: =D3+1 -> 44300 | F3: =E3+1 -> 44301 | G3: =F3+1 -> 44302 | H3: =G3+1 -> 44303 | I3: =H3+1 -> 44304 | J3: =I3+1 -> 44305
B4: Pivô | C4: =TEXT(C3,"ddd") -> seg | D4: =TEXT(D3,"ddd") -> ter | E4: =TEXT(E3,"ddd") -> qua | F4: =TEXT(F3,"ddd") -> qui | G4: =TEXT(G3,"ddd") -> sex | H4: =TEXT(H3,"ddd") -> sáb | I4: =TEXT(I3,"ddd") -> dom | J4: =TEXT(J3,"ddd") -> seg | L4: Parametros
B5: 1 | J5: Chuva | L5: Feito | M5: =COUNTIF($C$5:$J$60,L5) -> 20
B6: 2 | C6: Feito | D6: Feito | J6: Chuva | L6: Mecânico | M6: =COUNTIF($C$5:$J$60,L6) -> 6
B7: 3 | C7: Feito | J7: Chuva | L7: Elétrico | M7: =COUNTIF($C$5:$J$60,L7) -> 1
B8: 4 | C8: Feito | D8: Feito | J8: Chuva | L8: Energia | M8: =COUNTIF($C$5:$J$60,L8) -> 0
B9: 5 | C9: Feito | L9: Chuva | M9: =COUNTIF($C$5:$J$60,L9) -> 38
B10: 6 | C10: Mecânico | J10: Chuva | L10: Operação | M10: =COUNTIF($C$5:$J$60,L10) -> 12
B11: 7 | J11: Chuva | M11: =SUM(M5:M10) -> 77
B12: 8 | J12: Chuva
B13: 9 | J13: Chuva
B14: 10 | J14: Chuva
B15: 11 | J15: Chuva
B16: 12 | J16: Chuva
B17: 13 | J17: Chuva
B18: 14 | J18: Chuva
B19: 15 | C19: Feito | J19: Chuva
B20: 16 | C20: Mecânico | J20: Chuva
B21: 17 | C21: Feito | J21: Chuva
B22: 18 | C22: Feito | D22: Feito | J22: Chuva
B23: 19 | J23: Chuva
B24: 20 | C24: Operação | D24: Operação | J24: Chuva
B25: 21 | J25: Chuva
B26: 22 | C26: Operação | D26: Operação | J26: Chuva
B27: 23 | C27: Feito | J27: Chuva
B28: 24 | C28: Operação | D28: Operação | J28: Chuva
B29: 25 | D29: Feito | J29: Chuva
B30: 26 | C30: Feito | J30: Chuva
B31: 27 | J31: Chuva
B32: 28 | C32: Mecânico | J32: Chuva
B33: 29 | D33: Mecânico | J33: Chuva
B34: 30 | C34: Elétrico | J34: Chuva
B35: 31 | D35: Mecânico | J35: Chuva
B36: 32 | C36: Mecânico | J36: Chuva
B37: 33 | C37: Feito | J37: Chuva
B38: 34 | D38: Feito | J38: Chuva
B39: 35 | J39: Chuva
B40: 36 | J40: Chuva
B41: 37 | J41: Chuva
B42: 38 | C42: Feito | J42: Chuva
...

Sheet 30 04 2021
B3: 44316 | C3: =B3+1 -> 44317 | D3: =C3+1 -> 44318 | E3: =D3+1 -> 44319 | F3: =E3+1 -> 44320 | G3: =F3+1 -> 44321 | H3: =G3+1 -> 44322 | I3: =H3+1 -> 44323
A4: Pivô | B4: =TEXT(B3,"ddd") -> sex | C4: =TEXT(C3,"ddd") -> sáb | D4: =TEXT(D3,"ddd") -> dom | E4: =TEXT(E3,"ddd") -> seg | F4: =TEXT(F3,"ddd") -> ter | G4: =TEXT(G3,"ddd") -> qua | H4: =TEXT(H3,"ddd") -> qui | I4: =TEXT(I3,"ddd") -> sex | K4: Parametros
A5: 1 | K5: Feito | L5: =COUNTIF($B$5:$I$60,K5) -> 86
A6: 2 | F6: Feito | K6: Mecânico | L6: =COUNTIF($B$5:$I$60,K6) -> 7
A7: 3 | F7: Feito | G7: Feito | I7: Feito | K7: Elétrico | L7: =COUNTIF($B$5:$I$60,K7) -> 4
A8: 4 | B8: Operação | F8: Feito | H8: Elétrico | I8: Feito | K8: Energia | L8: =COUNTIF($B$5:$I$60,K8) -> 0
A9: 5 | B9: Feito | F9: Operação | G9: Feito | H9: Feito | I9: Feito | K9: Chuva | L9: =COUNTIF($B$5:$I$60,K9) -> 0
A10: 6 | F10: Operação | K10: Operação | L10: =COUNTIF($B$5:$I$60,K10) -> 45
A11: 7 | C11: Feito | D11: Feito | F11: Feito | G11: Feito | H11: Feito | L11: =SUM(L5:L10) -> 142
A12: 8 | B12: Operação | C12: Feito | D12: Feito | E12: Operação | F12: Feito | G12: Feito
A13: 9 | B13: Operação | E13: Feito | F13: Feito | G13: Feito | H13: Mecânico | I13: Feito
A14: 10 | G14: Feito
A15: 11
A16: 12
A17: 13
A18: 14
A19: 15 | B19: Feito | E19: Operação | H19: Operação
A20: 16 | D20: Mecânico | E20: Feito | F20: Operação
A21: 17 | B21: Feito | E21: Operação | H21: Feito
A22: 18 | C22: Operação | D22: Operação | I22: Feito
A23: 19 | D23: Feito | G23: Mecânico
A24: 20 | C24: Operação | D24: Operação | F24: Operação
A25: 21 | D25: Feito | G25: Feito
A26: 22 | D26: Elétrico | G26: Elétrico
A27: 23 | B27: Feito | E27: Operação | H27: Feito
A28: 24 | B28: Operação | C28: Operação | D28: Operação | F28: Operação
A29: 25 | B29: Feito | D29: Feito | E29: Feito | G29: Feito | H29: Feito | I29: Feito
A30: 26 | C30: Feito | F30: Feito | I30: Feito
A31: 27 | C31: Feito | F31: Operação | G31: Operação
A32: 28 | D32: Feito
A33: 29 | B33: Feito | D33: Feito | F33: Feito | H33: Elétrico | I33: Feito
A34: 30
A35: 31 | C35: Feito | F35: Feito | I35: Feito
A36: 32 | B36: Feito | C36: Feito | E36: Feito | F36: Mecânico | H36: Feito | I36: Mecânico
A37: 33 | B37: Feito | E37: Feito | H37: Mecânico | I37: Feito
A38: 34
A39: 35 | C39: Feito | G39: Feito | H39: Operação
A40: 36 | B40: Feito | E40: Feito | F40: Operação | I40: Feito
A41: 37 | B41: Feito | F41: Feito | H41: Feito
A42: 38 | B42: Feito | E42: Operação | H42: Operação | I42: Feito
...

Sheet 08 05 2021
B3: 44324 | C3: =B3+1 -> 44325 | D3: =C3+1 -> 44326 | E3: =D3+1 -> 44327 | F3: =E3+1 -> 44328 | G3: =F3+1 -> 44329 | H3: =G3+1 -> 44330 | I3: =H3+1 -> 44331
A4: Pivô | B4: =TEXT(B3,"ddd") -> sáb | C4: =TEXT(C3,"ddd") -> dom | D4: =TEXT(D3,"ddd") -> seg | E4: =TEXT(E3,"ddd") -> ter | F4: =TEXT(F3,"ddd") -> qua | G4: =TEXT(G3,"ddd") -> qui | H4: =TEXT(H3,"ddd") -> sex | I4: =TEXT(I3,"ddd") -> sáb | K4: Parametros
A5: 1 | E5: Operação | F5: Operação | G5: Feito | H5: Feito | I5: Feito | K5: Feito | L5: =COUNTIF($B$5:$I$60,K5) -> 109
A6: 2 | C6: Feito | I6: Feito | K6: Mecânico | L6: =COUNTIF($B$5:$I$60,K6) -> 19
A7: 3 | B7: Feito | D7: Feito | E7: Feito | K7: Elétrico | L7: =COUNTIF($B$5:$I$60,K7) -> 3
A8: 4 | B8: Feito | C8: Feito | D8: Feito | E8: Feito | F8: Feito | G8: Feito | K8: Energia | L8: =COUNTIF($B$5:$I$60,K8) -> 0
A9: 5 | D9: Feito | G9: Operação | H9: Feito | I9: Feito | K9: Chuva | L9: =COUNTIF($B$5:$I$60,K9) -> 0
A10: 6 | B10: Mecânico | D10: Feito | E10: Feito | F10: Mecânico | I10: Feito | K10: Operação | L10: =COUNTIF($B$5:$I$60,K10) -> 37
A11: 7 | D11: Feito | G11: Feito | H11: Operação | L11: =SUM(L5:L10) -> 168
A12: 8 | B12: Feito | D12: Feito | G12: Feito | H12: Operação | I12: Feito
A13: 9 | B13: Feito | C13: Feito | D13: Feito | E13: Feito | F13: Mecânico | G13: Mecânico | H13: Feito
A14: 10 | D14: Operação | E14: Elétrico | F14: Feito | G14: Elétrico | H14: Feito | I14: Mecânico
A15: 11 | D15: Operação | I15: Operação
A16: 12
A17: 13
A18: 14
A19: 15 | C19: Feito | F19: Feito
A20: 16 | B20: Feito | D20: Mecânico | E20: Feito | H20: Feito
A21: 17 | C21: Feito | F21: Feito
A22: 18 | D22: Mecânico | G22: Operação
A23: 19 | C23: Feito | F23: Mecânico
A24: 20 | B24: Feito | E24: Mecânico | H24: Feito
A25: 21 | C25: Feito | F25: Operação
A26: 22 | D26: Feito | H26: Feito
A27: 23 | D27: Operação | H27: Feito
A28: 24 | B28: Feito | C28: Operação | F28: Feito
A29: 25 | B29: Feito | C29: Feito | D29: Operação | E29: Operação | F29: Operação | G29: Feito | H29: Feito | I29: Mecânico
A30: 26 | D30: Feito | F30: Operação | G30: Operação | H30: Operação
A31: 27 | B31: Feito | E31: Feito
A32: 28 | B32: Mecânico | F32: Feito
A33: 29 | B33: Feito | C33: Feito | E33: Operação | F33: Operação | G33: Operação | I33: Operação
A34: 30 | E34: Mecânico | F34: Mecânico | G34: Mecânico | H34: Operação
A35: 31 | D35: Feito | I35: Operação
A36: 32 | B36: Mecânico | C36: Mecânico | D36: Mecânico | E36: Feito
A37: 33 | D37: Feito | G37: Operação | I37: Operação
A38: 34
A39: 35 | B39: Operação | D39: Operação | F39: Operação | H39: Feito
A40: 36 | C40: Feito | E40: Operação | G40: Operação | I40: Feito
A41: 37 | B41: Feito | D41: Feito | F41: Feito
A42: 38 | D42: Feito | G42: Feito
...

Sheet 16 05 2021
B3: 44332 | C3: =B3+1 -> 44333 | D3: =C3+1 -> 44334 | E3: =D3+1 -> 44335 | F3: =E3+1 -> 44336 | G3: =F3+1 -> 44337 | H3: =G3+1 -> 44338 | I3: =H3+1 -> 44339
A4: Pivô | B4: =TEXT(B3,"ddd") -> dom | C4: =TEXT(C3,"ddd") -> seg | D4: =TEXT(D3,"ddd") -> ter | E4: =TEXT(E3,"ddd") -> qua | F4: =TEXT(F3,"ddd") -> qui | G4: =TEXT(G3,"ddd") -> sex | H4: =TEXT(H3,"ddd") -> sáb | I4: =TEXT(I3,"ddd") -> dom | K4: Parametros
A5: 1 | B5: Feito | C5: Feito | I5: Feito | K5: Feito | L5: =COUNTIF($B$5:$I$60,K5) -> 113
A6: 2 | G6: Feito | K6: Mecânico | L6: =COUNTIF($B$5:$I$60,K6) -> 6
A7: 3 | B7: Feito | C7: Feito | H7: Feito | I7: Feito | K7: Elétrico | L7: =COUNTIF($B$5:$I$60,K7) -> 5
A8: 4 | B8: Feito | C8: Feito | F8: Feito | G8: Feito | K8: Energia | L8: =COUNTIF($B$5:$I$60,K8) -> 0
A9: 5 | C9: Feito | D9: Feito | F9: Feito | G9: Feito | I9: Feito | K9: Chuva | L9: =COUNTIF($B$5:$I$60,K9) -> 0
A10: 6 | C10: Feito | D10: Feito | E10: Feito | I10: Feito | K10: Operação | L10: =COUNTIF($B$5:$I$60,K10) -> 41
A11: 7 | B11: Feito | D11: Feito | E11: Feito | L11: =SUM(L5:L10) -> 165
A12: 8 | D12: Operação | E12: Feito | F12: Feito
A13: 9 | B13: Feito | D13: Operação | E13: Operação | G13: Feito
A14: 10 | B14: Feito | C14: Elétrico | D14: Feito | E14: Feito | H14: Feito | I14: Feito
A15: 11 | B15: Feito | C15: Feito | D15: Feito | E15: Feito | F15: Feito | G15: Feito | H15: Feito
A16: 12 | B16: Feito | D16: Feito | H16: Mecânico
A17: 13 | G17: Operação
A18: 14 | E18: Operação | F18: Feito | I18: Feito
A19: 15 | C19: Feito | G19: Elétrico | H19: Elétrico
A20: 16 | D20: Operação | H20: Mecânico
A21: 17 | B21: Feito | F21: Operação
A22: 18 | C22: Feito | G22: Feito
A23: 19 | B23: Feito | F23: Feito
A24: 20 | D24: Operação | E24: Feito | H24: Operação
A25: 21 | B25: Operação | F25: Mecânico
A26: 22 | D26: Mecânico | E26: Feito | H26: Feito
A27: 23 | D27: Feito | H27: Elétrico
A28: 24 | C28: Operação | H28: Feito
A29: 25 | B29: Feito | C29: Feito | D29: Operação | E29: Feito | F29: Feito | G29: Feito | H29: Feito | I29: Feito
A30: 26 | B30: Operação | C30: Operação | D30: Operação | E30: Operação | F30: Feito
A31: 27 | C31: Operação | D31: Operação | E31: Operação | F31: Feito | G31: Feito
A32: 28 | H32: Mecânico
A33: 29 | C33: Feito | E33: Feito | F33: Feito | G33: Feito | I33: Operação
A34: 30 | B34: Operação | C34: Feito | D34: Operação | E34: Operação | F34: Operação | G34: Operação | H34: Feito | I34: Operação
A35: 31 | D35: Operação | G35: Feito
A36: 32 | D36: Operação | E36: Operação
A37: 33 | C37: Feito | F37: Feito | I37: Feito
A38: 34 | F38: Operação | H38: Feito
A39: 35 | B39: Feito | C39: Feito | D39: Feito | E39: Operação | I39: Feito
A40: 36 | C40: Operação | D40: Feito | H40: Mecânico
A41: 37 | B41: Feito | F41: Feito
A42: 38 | B42: Feito | D42: Feito | E42: Operação | F42: Operação
...

Sheet 24 05 2021
B3: 44340 | C3: =B3+1 -> 44341 | D3: =C3+1 -> 44342 | E3: =D3+1 -> 44343 | F3: =E3+1 -> 44344 | G3: =F3+1 -> 44345 | H3: =G3+1 -> 44346 | I3: =H3+1 -> 44347
A4: Pivô | B4: =TEXT(B3,"ddd") -> seg | C4: =TEXT(C3,"ddd") -> ter | D4: =TEXT(D3,"ddd") -> qua | E4: =TEXT(E3,"ddd") -> qui | F4: =TEXT(F3,"ddd") -> sex | G4: =TEXT(G3,"ddd") -> sáb | H4: =TEXT(H3,"ddd") -> dom | I4: =TEXT(I3,"ddd") -> seg | K4: Parametros
A5: 1 | D5: Feito | F5: Operação | G5: Feito | K5: Feito | L5: =COUNTIF($B$5:$I$60,K5) -> 119
A6: 2 | E6: Feito | K6: Mecânico | L6: =COUNTIF($B$5:$I$60,K6) -> 9
A7: 3 | F7: Feito | G7: Operação | K7: Elétrico | L7: =COUNTIF($B$5:$I$60,K7) -> 1
A8: 4 | C8: Feito | D8: Feito | I8: Feito | K8: Energia | L8: =COUNTIF($B$5:$I$60,K8) -> 0
A9: 5 | C9: Operação | E9: Feito | F9: Feito | H9: Feito | K9: Chuva | L9: =COUNTIF($B$5:$I$60,K9) -> 0
A10: 6 | B10: Mecânico | C10: Feito | E10: Feito | G10: Feito | I10: Feito | K10: Operação | L10: =COUNTIF($B$5:$I$60,K10) -> 20
A11: 7 | B11: Feito | F11: Feito | H11: Feito | L11: =SUM(L5:L10) -> 149
A12: 8 | C12: Feito | E12: Feito | G12: Feito | I12: Feito
A13: 9 | B13: Feito | F13: Feito
A14: 10 | C14: Feito | E14: Feito | H14: Feito
A15: 11 | B15: Feito | D15: Feito | E15: Feito | H15: Feito
A16: 12 | B16: Feito | C16: Operação | D16: Feito | E16: Feito | F16: Feito | G16: Feito | H16: Feito | I16: Feito
A17: 13 | E17: Feito | F17: Operação | G17: Feito | H17: Feito | I17: Feito
A18: 14 | C18: Operação
A19: 15 | E19: Feito
A20: 16 | F20: Mecânico
A21: 17 | C21: Feito
A22: 18 | B22: Operação | G22: Feito
A23: 19 | C23: Feito | I23: Feito
A24: 20 | E24: Operação
A25: 21 | C25: Operação
A26: 22 | E26: Mecânico
A27: 23 | E27: Operação
A28: 24 | F28: Feito
A29: 25 | B29: Feito | C29: Feito | D29: Feito | E29: Feito | F29: Feito | G29: Feito | H29: Mecânico | I29: Mecânico
A30: 26 | B30: Feito | G30: Feito
A31: 27 | G31: Feito
A32: 28 | C32: Mecânico | D32: Mecânico | H32: Feito
A33: 29 | C33: Feito | E33: Feito | G33: Feito | I33: Feito
A34: 30 | B34: Feito | C34: Feito | D34: Operação | E34: Feito | F34: Feito | G34: Feito | H34: Feito
A35: 31 | B35: Feito | C35: Feito | E35: Feito | G35: Feito | I35: Feito
A36: 32 | B36: Feito | C36: Feito | I36: Feito
A37: 33 | D37: Feito | F37: Operação | H37: Feito
A38: 34 | G38: Feito | H38: Feito | I38: Feito
A39: 35 | D39: Feito | G39: Feito
A40: 36 | B40: Feito | C40: Feito | E40: Operação | I40: Feito
A41: 37 | C41: Feito | H41: Feito
A42: 38 | B42: Operação | I42: Operação
...

Sheet 01 06 2021
B3: 44348 | C3: =B3+1 -> 44349 | D3: =C3+1 -> 44350 | E3: =D3+1 -> 44351 | F3: =E3+1 -> 44352 | G3: =F3+1 -> 44353 | H3: =G3+1 -> 44354 | I3: =H3+1 -> 44355
A4: Pivô | B4: =TEXT(B3,"ddd") -> ter | C4: =TEXT(C3,"ddd") -> qua | D4: =TEXT(D3,"ddd") -> qui | E4: =TEXT(E3,"ddd") -> sex | F4: =TEXT(F3,"ddd") -> sáb | G4: =TEXT(G3,"ddd") -> dom | H4: =TEXT(H3,"ddd") -> seg | I4: =TEXT(I3,"ddd") -> ter | K4: Parametros
A5: 1 | B5: Feito | E5: Feito | H5: Feito | K5: Feito | L5: =COUNTIF($B$5:$I$60,K5) -> 113
A6: 2 | B6: Feito | F6: Feito | K6: Mecânico | L6: =COUNTIF($B$5:$I$60,K6) -> 7
A7: 3 | D7: Operação | E7: Feito | I7: Feito | K7: Elétrico | L7: =COUNTIF($B$5:$I$60,K7) -> 0
A8: 4 | F8: Feito | K8: Energia | L8: =COUNTIF($B$5:$I$60,K8) -> 0
A9: 5 | B9: Feito | D9: Feito | F9: Mecânico | H9: Feito | K9: Chuva | L9: =COUNTIF($B$5:$I$60,K9) -> 0
A10: 6 | C10: Feito | D10: Feito | E10: Feito | G10: Feito | H10: Feito | I10: Feito | K10: Operação | L10: =COUNTIF($B$5:$I$60,K10) -> 26
A11: 7 | C11: Feito | E11: Feito | G11: Feito | H11: Feito | I11: Feito | L11: =SUM(L5:L10) -> 146
A12: 8 | D12: Feito | E12: Feito | F12: Feito | H12: Feito
A13: 9 | B13: Feito | E13: Feito | F13: Feito
A14: 10 | C14: Feito | G14: Feito
A15: 11 | C15: Operação | D15: Feito | G15: Feito
A16: 12 | C16: Feito | E16: Feito | H16: Feito
A17: 13 | B17: Feito | C17: Feito | D17: Operação | E17: Feito | F17: Feito | G17: Feito | H17: Feito | I17: Operação
A18: 14 | B18: Mecânico | D18: Feito | E18: Feito | F18: Feito | G18: Mecânico | H18: Operação | I18: Operação
A19: 15 | C19: Feito | H19: Feito
A20: 16 | D20: Operação | I20: Operação
A21: 17 | B21: Feito | G21: Feito
A22: 18 | D22: Feito | I22: Feito
A23: 19 | F23: Feito
A24: 20 | C24: Feito | H24: Feito
A25: 21 | B25: Operação | G25: Feito
A26: 22 | C26: Feito | H26: Mecânico
A27: 23 | B27: Mecânico | C27: Mecânico | G27: Feito
A28: 24 | D28: Feito
A29: 25 | B29: Feito | C29: Feito | D29: Feito | E29: Feito | F29: Feito | G29: Feito | H29: Feito | I29: Feito
A30: 26 | E30: Feito
A31: 27 | D31: Feito | I31: Feito
A32: 28
A33: 29 | C33: Feito | E33: Feito | G33: Feito | I33: Operação
A34: 30 | B34: Operação | C34: Feito | D34: Feito | G34: Feito | I34: Feito
A35: 31 | C35: Operação | E35: Feito | H35: Feito
A36: 32 | B36: Feito
A37: 33 | B37: Feito | D37: Feito | F37: Feito
A38: 34 | C38: Operação | D38: Feito
A39: 35 | C39: Feito | G39: Feito
A40: 36 | E40: Feito | I40: Feito
A41: 37 | E41: Feito
A42: 38 | C42: Feito | H42: Operação
...

Sheet 09 06 2021
B3: 44356 | C3: =B3+1 -> 44357 | D3: =C3+1 -> 44358 | E3: =D3+1 -> 44359 | F3: =E3+1 -> 44360 | G3: =F3+1 -> 44361 | H3: =G3+1 -> 44362 | I3: =H3+1 -> 44363
A4: Pivô | B4: =TEXT(B3,"ddd") -> qua | C4: =TEXT(C3,"ddd") -> qui | D4: =TEXT(D3,"ddd") -> sex | E4: =TEXT(E3,"ddd") -> sáb | F4: =TEXT(F3,"ddd") -> dom | G4: =TEXT(G3,"ddd") -> seg | H4: =TEXT(H3,"ddd") -> ter | I4: =TEXT(I3,"ddd") -> qua | K4: Parametros
A5: 1 | C5: Feito | F5: Feito | I5: Feito | K5: Feito | L5: =COUNTIF($B$5:$I$60,K5) -> 92
A6: 2 | B6: Feito | F6: Feito | K6: Mecânico | L6: =COUNTIF($B$5:$I$60,K6) -> 5
A7: 3 | E7: Feito | K7: Elétrico | L7: =COUNTIF($B$5:$I$60,K7) -> 4
A8: 4 | C8: Operação | D8: Feito | G8: Feito | K8: Energia | L8: =COUNTIF($B$5:$I$60,K8) -> 7
A9: 5 | B9: Feito | D9: Feito | F9: Feito | H9: Chuva | K9: Chuva | L9: =COUNTIF($B$5:$I$60,K9) -> 7
A10: 6 | B10: Operação | D10: Feito | F10: Feito | H10: Chuva | K10: Operação | L10: =COUNTIF($B$5:$I$60,K10) -> 14
A11: 7 | B11: Feito | D11: Feito | F11: Feito | H11: Chuva | L11: =SUM(L5:L10) -> 129
A12: 8 | B12: Feito | C12: Feito | E12: Feito | G12: Feito | H12: Feito
A13: 9 | B13: Feito | C13: Feito | E13: Feito | H13: Feito | I13: Feito
A14: 10 | C14: Feito | D14: Feito | H14: Chuva
A15: 11 | C15: Feito | F15: Feito
A16: 12 | B16: Feito | C16: Feito | D16: Feito | H16: Chuva
A17: 13 | C17: Feito | E17: Feito | F17: Feito | I17: Feito
A18: 14 | B18: Operação | C18: Feito | D18: Feito | E18: Feito | F18: Feito | G18: Feito | H18: Chuva
A19: 15 | E19: Feito
A20: 16 | F20: Feito
A21: 17 | D21: Operação | I21: Operação
A22: 18 | G22: Operação
A23: 19 | C23: Feito | H23: Mecânico
A24: 20 | E24: Feito
A25: 21 | D25: Operação | I25: Energia
A26: 22 | F26: Feito
A27: 23 | D27: Operação | H27: Energia
A28: 24
A29: 25 | B29: Feito | C29: Feito | D29: Feito | E29: Feito | F29: Feito | G29: Feito | H29: Feito
A30: 26 | B30: Feito | G30: Feito
A31: 27 | F31: Feito
A32: 28
A33: 29 | C33: Mecânico | E33: Feito | G33: Elétrico | I33: Elétrico
A34: 30 | B34: Feito | E34: Mecânico | G34: Feito | H34: Feito | I34: Feito
A35: 31 | C35: Feito
A36: 32
A37: 33
A38: 34 | C38: Mecânico | E38: Feito | F38: Feito | G38: Operação | H38: Operação | I38: Feito
A39: 35 | D39: Feito | H39: Chuva
A40: 36 | E40: Feito | I40: Feito
A41: 37 | B41: Feito | E41: Feito | I41: Feito
A42: 38 | F42: Feito
...

Sheet 17 06 2021
B3: 44364 | C3: =B3+1 -> 44365 | D3: =C3+1 -> 44366 | E3: =D3+1 -> 44367 | F3: =E3+1 -> 44368 | G3: =F3+1 -> 44369 | H3: =G3+1 -> 44370 | I3: =H3+1 -> 44371
A4: Pivô | B4: =TEXT(B3,"ddd") -> qui | C4: =TEXT(C3,"ddd") -> sex | D4: =TEXT(D3,"ddd") -> sáb | E4: =TEXT(E3,"ddd") -> dom | F4: =TEXT(F3,"ddd") -> seg | G4: =TEXT(G3,"ddd") -> ter | H4: =TEXT(H3,"ddd") -> qua | I4: =TEXT(I3,"ddd") -> qui | K4: Parametros
A5: 1 | D5: Feito | K5: Feito | L5: =COUNTIF($B$5:$I$60,K5) -> 93
A6: 2 | H6: Feito | K6: Mecânico | L6: =COUNTIF($B$5:$I$60,K6) -> 5
A7: 3 | B7: Operação | E7: Feito | I7: Feito | K7: Elétrico | L7: =COUNTIF($B$5:$I$60,K7) -> 3
A8: 4 | C8: Feito | G8: Feito | K8: Energia | L8: =COUNTIF($B$5:$I$60,K8) -> 0
A9: 5 | B9: Feito | D9: Feito | G9: Feito | K9: Chuva | L9: =COUNTIF($B$5:$I$60,K9) -> 0
A10: 6 | B10: Feito | D10: Feito | F10: Feito | K10: Operação | L10: =COUNTIF($B$5:$I$60,K10) -> 14
A11: 7 | B11: Feito | D11: Feito | F11: Feito | H11: Feito | L11: =SUM(L5:L10) -> 115
A12: 8 | C12: Feito | E12: Feito | G12: Feito | I12: Feito
A13: 9 | D13: Feito | F13: Feito | G13: Feito | H13: Feito
A14: 10 | B14: Feito | C14: Feito | E14: Feito | H14: Feito | I14: Feito
A15: 11 | B15: Feito | F15: Feito | G15: Feito
A16: 12 | D16: Mecânico
A17: 13 | E17: Feito | H17: Feito
A18: 14 | B18: Feito | E18: Feito | H18: Mecânico
A19: 15 | B19: Operação | G19: Feito
A20: 16 | C20: Operação
A21: 17 | E21: Feito
A22: 18
A23: 19 | E23: Feito
A24: 20 | C24: Feito
A25: 21 | F25: Feito
A26: 22 | D26: Feito
A27: 23 | E27: Feito
A28: 24
A29: 25 | B29: Feito | D29: Feito | E29: Feito | F29: Feito | G29: Feito | H29: Feito | I29: Feito
A30: 26 | E30: Feito
A31: 27 | C31: Feito | G31: Feito
A32: 28
A33: 29 | B33: Elétrico | C33: Feito | F33: Feito | I33: Feito
A34: 30 | B34: Feito | D34: Feito | G34: Operação | H34: Feito
A35: 31
A36: 32
A37: 33 | H37: Operação | I37: Mecânico
A38: 34 | B38: Operação | C38: Operação | D38: Operação | E38: Feito | F38: Feito | G38: Feito | I38: Feito
A39: 35 | D39: Elétrico | H39: Feito
A40: 36 | E40: Feito | I40: Feito
A41: 37 | E41: Feito
A42: 38 | D42: Feito | I42: Feito
...

Sheet 25 06 2021 
B3: 44372 | C3: =B3+1 -> 44373 | D3: =C3+1 -> 44374 | E3: =D3+1 -> 44375 | F3: =E3+1 -> 44376 | G3: =F3+1 -> 44377 | H3: =G3+1 -> 44378 | I3: =H3+1 -> 44379
A4: Pivô | B4: =TEXT(B3,"ddd") -> sex | C4: =TEXT(C3,"ddd") -> sáb | D4: =TEXT(D3,"ddd") -> dom | E4: =TEXT(E3,"ddd") -> seg | F4: =TEXT(F3,"ddd") -> ter | G4: =TEXT(G3,"ddd") -> qua | H4: =TEXT(H3,"ddd") -> qui | I4: =TEXT(I3,"ddd") -> sex | K4: Parametros
A5: 1 | B5: Feito | E5: Feito | H5: Feito | K5: Feito | L5: =COUNTIF($B$5:$I$60,K5) -> 95
A6: 2 | H6: Feito | K6: Mecânico | L6: =COUNTIF($B$5:$I$60,K6) -> 9
A7: 3 | D7: Feito | K7: Elétrico | L7: =COUNTIF($B$5:$I$60,K7) -> 5
A8: 4 | C8: Feito | H8: Feito | K8: Energia | L8: =COUNTIF($B$5:$I$60,K8) -> 0
A9: 5 | C9: Feito | G9: Mecânico | K9: Chuva | L9: =COUNTIF($B$5:$I$60,K9) -> 0
A10: 6 | C10: Feito | G10: Operação | K10: Operação | L10: =COUNTIF($B$5:$I$60,K10) -> 15
A11: 7 | B11: Feito | D11: Feito | G11: Feito | L11: =SUM(L5:L10) -> 124
A12: 8 | C12: Feito | E12: Feito | G12: Feito | I12: Feito
A13: 9 | B13: Feito | C13: Feito | E13: Feito | F13: Mecânico | G13: Mecânico | H13: Operação | I13: Feito
A14: 10 | B14: Feito | F14: Feito | G14: Feito | H14: Feito
A15: 11 | B15: Feito | E15: Feito | F15: Feito | H15: Feito
A16: 12 | B16: Feito | G16: Feito | H16: Feito | I16: Feito
A17: 13 | D17: Feito | H17: Feito | I17: Feito
A18: 14 | E18: Feito | G18: Feito | H18: Feito
A19: 15 | D19: Feito | I19: Operação
A20: 16
A21: 17 | C21: Feito | H21: Feito
A22: 18
A23: 19 | B23: Mecânico | G23: Operação | H23: Operação
A24: 20
A25: 21 | D25: Feito | I25: Operação
A26: 22
A27: 23 | C27: Feito | H27: Operação
A28: 24
A29: 25 | B29: Feito | D29: Feito | F29: Feito | G29: Feito | H29: Feito
A30: 26 | C30: Feito | I30: Operação
A31: 27 | D31: Elétrico | I31: Feito
A32: 28
A33: 29 | B33: Feito | D33: Feito | G33: Feito
A34: 30 | B34: Feito | E34: Feito | G34: Feito | I34: Feito
A35: 31 | I35: Operação
A36: 32
A37: 33
A38: 34 | C38: Feito | E38: Feito | F38: Feito | I38: Feito
A39: 35 | B39: Feito | C39: Feito | G39: Feito | I39: Feito
A40: 36 | E40: Mecânico | I40: Feito
A41: 37 | B41: Feito | G41: Feito
A42: 38 | G42: Feito
...

Sheet 03 07 2021
B3: 44380 | C3: =B3+1 -> 44381 | D3: =C3+1 -> 44382 | E3: =D3+1 -> 44383 | F3: =E3+1 -> 44384 | G3: =F3+1 -> 44385 | H3: =G3+1 -> 44386 | I3: =H3+1 -> 44387
A4: Pivô | B4: =TEXT(B3,"ddd") -> sáb | C4: =TEXT(C3,"ddd") -> dom | D4: =TEXT(D3,"ddd") -> seg | E4: =TEXT(E3,"ddd") -> ter | F4: =TEXT(F3,"ddd") -> qua | G4: =TEXT(G3,"ddd") -> qui | H4: =TEXT(H3,"ddd") -> sex | I4: =TEXT(I3,"ddd") -> sáb | K4: Parametros
A5: 1 | C5: Feito | F5: Feito | I5: Feito | K5: Feito | L5: =COUNTIF($B$5:$I$60,K5) -> 80
A6: 2 | H6: Operação | K6: Mecânico | L6: =COUNTIF($B$5:$I$60,K6) -> 5
A7: 3 | F7: Operação | K7: Elétrico | L7: =COUNTIF($B$5:$I$60,K7) -> 3
A8: 4 | D8: Feito | F8: Operação | G8: Feito | K8: Energia | L8: =COUNTIF($B$5:$I$60,K8) -> 0
A9: 5 | C9: Feito | G9: Feito | K9: Chuva | L9: =COUNTIF($B$5:$I$60,K9) -> 0
A10: 6 | C10: Feito | G10: Operação | K10: Operação | L10: =COUNTIF($B$5:$I$60,K10) -> 22
A11: 7 | B11: Feito | E11: Feito | H11: Feito | L11: =SUM(L5:L10) -> 110
A12: 8 | D12: Feito | G12: Operação
A13: 9 | C13: Feito | E13: Feito | G13: Operação | I13: Feito
A14: 10 | B14: Feito | D14: Feito | E14: Feito | F14: Feito | H14: Feito
A15: 11 | D15: Feito | E15: Mecânico | F15: Feito | I15: Feito
A16: 12 | E16: Feito | G16: Feito
A17: 13 | E17: Feito | H17: Feito
A18: 14 | C18: Feito | F18: Feito | I18: Feito
A19: 15 | F19: Operação
A20: 16
A21: 17 | D21: Feito | I21: Feito
A22: 18
A23: 19 | E23: Mecânico
A24: 20
A25: 21 | G25: Operação
A26: 22
A27: 23 | E27: Operação
A28: 24
A29: 25 | B29: Feito | D29: Feito | E29: Operação | F29: Feito | G29: Feito | H29: Feito | I29: Feito
A30: 26
A31: 27 | E31: Feito | I31: Feito
A32: 28
A33: 29 | B33: Feito | D33: Feito | G33: Feito | I33: Feito
A34: 30 | D34: Feito | F34: Feito | G34: Feito | H34: Feito
A35: 31 | H35: Operação
A36: 32
A37: 33 | F37: Operação | G37: Operação
A38: 34 | D38: Feito | H38: Feito
A39: 35 | C39: Feito | H39: Feito
A40: 36 | F40: Feito | I40: Feito
A41: 37 | D41: Feito | G41: Feito
A42: 38 | E42: Feito | I42: Feito
...

Sheet 11 07 2021 
B3: 44388 | C3: =B3+1 -> 44389 | D3: =C3+1 -> 44390 | E3: =D3+1 -> 44391 | F3: =E3+1 -> 44392 | G3: =F3+1 -> 44393 | H3: =G3+1 -> 44394 | I3: =H3+1 -> 44395
A4: Pivô | B4: =TEXT(B3,"ddd") -> dom | C4: =TEXT(C3,"ddd") -> seg | D4: =TEXT(D3,"ddd") -> ter | E4: =TEXT(E3,"ddd") -> qua | F4: =TEXT(F3,"ddd") -> qui | G4: =TEXT(G3,"ddd") -> sex | H4: =TEXT(H3,"ddd") -> sáb | I4: =TEXT(I3,"ddd") -> dom | K4: Parametros
A5: 1 | D5: Feito | G5: Feito | K5: Feito | L5: =COUNTIF($B$5:$I$60,K5) -> 79
A6: 2 | D6: Operação | E6: Operação | F6: Operação | H6: Feito | I6: Feito | K6: Mecânico | L6: =COUNTIF($B$5:$I$60,K6) -> 7
A7: 3 | C7: Operação | E7: Operação | H7: Operação | K7: Elétrico | L7: =COUNTIF($B$5:$I$60,K7) -> 3
A8: 4 | D8: Feito | K8: Energia | L8: =COUNTIF($B$5:$I$60,K8) -> 0
A9: 5 | B9: Feito | E9: Feito | G9: Feito | I9: Feito | K9: Chuva | L9: =COUNTIF($B$5:$I$60,K9) -> 0
A10: 6 | B10: Feito | E10: Feito | G10: Mecânico | K10: Operação | L10: =COUNTIF($B$5:$I$60,K10) -> 30
A11: 7 | D11: Feito | H11: Operação | L11: =SUM(L5:L10) -> 119
A12: 8 | B12: Feito | F12: Feito
A13: 9 | C13: Feito | E13: Feito | G13: Feito | H13: Feito
A14: 10 | B14: Feito | D14: Feito | F14: Feito | I14: Feito
A15: 11 | C15: Feito | E15: Feito | G15: Feito | H15: Feito
A16: 12 | B16: Feito | C16: Operação | D16: Operação | E16: Feito | F16: Feito | H16: Feito
A17: 13 | B17: Feito | E17: Feito | F17: Feito | H17: Feito | I17: Feito
A18: 14 | C18: Operação | D18: Mecânico | E18: Feito | G18: Feito | I18: Feito
A19: 15 | C19: Feito | H19: Feito
A20: 16
A21: 17
A22: 18
A23: 19 | B23: Mecânico
A24: 20
A25: 21
A26: 22
A27: 23
A28: 24
A29: 25 | B29: Feito | C29: Operação | D29: Feito | E29: Feito | F29: Feito | G29: Feito | H29: Feito | I29: Feito
A30: 26
A31: 27 | E31: Feito | I31: Feito
A32: 28
A33: 29 | D33: Feito | F33: Operação | G33: Feito | I33: Feito
A34: 30 | B34: Feito | D34: Feito | F34: Mecânico | G34: Feito | I34: Feito
A35: 31 | B35: Operação | E35: Operação | F35: Feito | G35: Operação | I35: Feito
A36: 32
A37: 33 | B37: Feito | G37: Operação | I37: Operação
A38: 34 | D38: Operação | H38: Mecânico
A39: 35 | D39: Feito | H39: Feito
A40: 36 | F40: Operação | G40: Operação
A41: 37 | B41: Feito
A42: 38 | F42: Feito
...

Sheet 19 07 2021
B3: 44396 | C3: =B3+1 -> 44397 | D3: =C3+1 -> 44398 | E3: =D3+1 -> 44399 | F3: =E3+1 -> 44400 | G3: =F3+1 -> 44401 | H3: =G3+1 -> 44402 | I3: =H3+1 -> 44403
A4: Pivô | B4: =TEXT(B3,"ddd") -> seg | C4: =TEXT(C3,"ddd") -> ter | D4: =TEXT(D3,"ddd") -> qua | E4: =TEXT(E3,"ddd") -> qui | F4: =TEXT(F3,"ddd") -> sex | G4: =TEXT(G3,"ddd") -> sáb | H4: =TEXT(H3,"ddd") -> dom | I4: =TEXT(I3,"ddd") -> seg | K4: Parametros
A5: 1 | B5: Mecânico | K5: Feito | L5: =COUNTIF($B$5:$I$60,K5) -> 92
A6: 2 | B6: Operação | C6: Feito | D6: Feito | E6: Feito | F6: Feito | G6: Feito | H6: Feito | K6: Mecânico | L6: =COUNTIF($B$5:$I$60,K6) -> 8
A7: 3 | C7: Operação | D7: Feito | E7: Feito | F7: Feito | G7: Feito | H7: Feito | I7: Feito | K7: Elétrico | L7: =COUNTIF($B$5:$I$60,K7) -> 2
A8: 4 | C8: Feito | K8: Energia | L8: =COUNTIF($B$5:$I$60,K8) -> 3
A9: 5 | E9: Operação | I9: Feito | K9: Chuva | L9: =COUNTIF($B$5:$I$60,K9) -> 0
A10: 6 | B10: Operação | D10: Feito | G10: Feito | K10: Operação | L10: =COUNTIF($B$5:$I$60,K10) -> 20
A11: 7 | D11: Operação | H11: Feito | L11: =SUM(L5:L10) -> 125
A12: 8 | B12: Feito | F12: Feito | I12: Feito
A13: 9 | B13: Feito | E13: Feito | H13: Feito
A14: 10 | C14: Feito | E14: Operação | G14: Feito
A15: 11 | B15: Operação | C15: Feito | D15: Feito | F15: Feito | H15: Feito
A16: 12 | B16: Feito | D16: Feito | F16: Feito | H16: Feito
A17: 13 | B17: Feito | C17: Feito | D17: Feito | E17: Feito | F17: Feito | G17: Feito | H17: Feito | I17: Feito
A18: 14 | B18: Operação | C18: Feito | D18: Mecânico | F18: Feito | H18: Feito | I18: Feito
A19: 15
A20: 16
A21: 17
A22: 18
A23: 19
A24: 20
A25: 21
A26: 22
A27: 23
A28: 24
A29: 25 | B29: Feito | C29: Feito | D29: Feito | E29: Feito | F29: Feito | G29: Feito | H29: Feito | I29: Feito
A30: 26
A31: 27 | E31: Feito
A32: 28
A33: 29 | C33: Feito | D33: Feito | E33: Feito | F33: Feito | G33: Feito | H33: Feito | I33: Feito
A34: 30 | C34: Feito | E34: Operação | F34: Feito | G34: Feito | H34: Feito | I34: Feito
A35: 31 | B35: Feito | C35: Operação | D35: Feito | E35: Feito | F35: Feito | G35: Feito | H35: Feito | I35: Mecânico
A36: 32
A37: 33 | C37: Operação | D37: Operação | E37: Operação | F37: Operação | G37: Mecânico | H37: Feito | I37: Feito
A38: 34 | D38: Elétrico | E38: Elétrico | G38: Feito
A39: 35 | D39: Operação | H39: Feito
A40: 36 | B40: Feito | F40: Mecânico | I40: Mecânico
A41: 37 | D41: Operação
A42: 38
...

Sheet 27 07 2021
B3: 44404 | C3: =B3+1 -> 44405 | D3: =C3+1 -> 44406 | E3: =D3+1 -> 44407 | F3: =E3+1 -> 44408 | G3: =F3+1 -> 44409 | H3: =G3+1 -> 44410 | I3: =H3+1 -> 44411
A4: Pivô | B4: =TEXT(B3,"ddd") -> ter | C4: =TEXT(C3,"ddd") -> qua | D4: =TEXT(D3,"ddd") -> qui | E4: =TEXT(E3,"ddd") -> sex | F4: =TEXT(F3,"ddd") -> sáb | G4: =TEXT(G3,"ddd") -> dom | H4: =TEXT(H3,"ddd") -> seg | I4: =TEXT(I3,"ddd") -> ter | K4: Parametros
A5: 1 | K5: Feito | L5: =COUNTIF($B$5:$I$60,K5) -> 83
A6: 2 | C6: Feito | F6: Feito | H6: Feito | K6: Mecânico | L6: =COUNTIF($B$5:$I$60,K6) -> 2
A7: 3 | D7: Feito | F7: Feito | H7: Feito | K7: Elétrico | L7: =COUNTIF($B$5:$I$60,K7) -> 0
A8: 4 | D8: Feito | F8: Feito | I8: Operação | K8: Energia | L8: =COUNTIF($B$5:$I$60,K8) -> 0
A9: 5 | E9: Feito | K9: Chuva | L9: =COUNTIF($B$5:$I$60,K9) -> 0
A10: 6 | D10: Operação | E10: Operação | K10: Operação | L10: =COUNTIF($B$5:$I$60,K10) -> 18
A11: 7 | D11: Operação | G11: Feito | L11: =SUM(L5:L10) -> 103
A12: 8 | D12: Feito | G12: Feito
A13: 9 | C13: Operação | F13: Feito
