Workbook
Name PesquisarQuem: OFFSET('[1]Pesquisa de nome'!$A$3,,,COUNT('[1]Pesquisa de nome'!$B:$B),1)
Name SegmentaçãodeDados_Ano: #N/A
Name SegmentaçãodeDados_Ano1: #N/A
Name SegmentaçãodeDados_Mês: #N/A
Name SegmentaçãodeDados_Periodo: #N/A
Name SegmentaçãodeDados_Periodo1: #N/A
Name SegmentaçãodeDados_Semana: #N/A
Name SegmentaçãodeDados_Semana1: #N/A

Sheet Base de Dados
A1: Parametros | B1: Contagem | C1: Porcentagem | D1: Semana | E1: Ano | F1: Periodo
A2: Feito | B2: 81 | C2: 0.60447761 | D2: 44182 | E2: =YEAR(D2) -> 2020 | F2: =IF(MONTH(D2)<=6,"1ª Semestre","2ª Semestre") -> 2ª Semestre
A3: Mecânico | B3: 12 | C3: 0.089552239 | D3: 44182 | E3: =YEAR(D3) -> 2020 | F3: =IF(MONTH(D3)<=6,"1ª Semestre","2ª Semestre") -> 2ª Semestre
A4: Elétrico | B4: 3 | C4: 0.02238806 | D4: 44182 | E4: =YEAR(D4) -> 2020 | F4: =IF(MONTH(D4)<=6,"1ª Semestre","2ª Semestre") -> 2ª Semestre
A5: Energia | B5: 12 | C5: 0.089552239 | D5: 44182 | E5: =YEAR(D5) -> 2020 | F5: =IF(MONTH(D5)<=6,"1ª Semestre","2ª Semestre") -> 2ª Semestre
A6: Chuva | B6: 24 | C6: 0.17910448 | D6: 44182 | E6: =YEAR(D6) -> 2020 | F6: =IF(MONTH(D6)<=6,"1ª Semestre","2ª Semestre") -> 2ª Semestre
A7: Operação | B7: 2 | C7: 0.014925373 | D7: 44182 | E7: =YEAR(D7) -> 2020 | F7: =IF(MONTH(D7)<=6,"1ª Semestre","2ª Semestre") -> 2ª Semestre
A8: Feito | B8: 101 | C8: 0.8015873 | D8: 44190 | E8: =YEAR(D8) -> 2020 | F8: =IF(MONTH(D8)<=6,"1ª Semestre","2ª Semestre") -> 2ª Semestre
A9: Mecânico | B9: 10 | C9: 0.079365079 | D9: 44190 | E9: =YEAR(D9) -> 2020 | F9: =IF(MONTH(D9)<=6,"1ª Semestre","2ª Semestre") -> 2ª Semestre
A10: Elétrico | B10: 6 | C10: 0.047619048 | D10: 44190 | E10: =YEAR(D10) -> 2020 | F10: =IF(MONTH(D10)<=6,"1ª Semestre","2ª Semestre") -> 2ª Semestre
A11: Energia | B11: 2 | C11: 0.015873016 | D11: 44190 | E11: =YEAR(D11) -> 2020 | F11: =IF(MONTH(D11)<=6,"1ª Semestre","2ª Semestre") -> 2ª Semestre
A12: Chuva | B12: 0 | C12: 0 | D12: 44190 | E12: =YEAR(D12) -> 2020 | F12: =IF(MONTH(D12)<=6,"1ª Semestre","2ª Semestre") -> 2ª Semestre
A13: Operação | B13: 7 | C13: 0.055555556 | D13: 44190 | E13: =YEAR(D13) -> 2020 | F13: =IF(MONTH(D13)<=6,"1ª Semestre","2ª Semestre") -> 2ª Semestre
... A427: Operação | B427: 8 | C427: 0.052287582 | D427: 44746 | E427: =YEAR(D427) -> 2022 | F427: =IF(MONTH(D427)<=6,"1ª Semestre","2ª Semestre") -> 2ª Semestre

Sheet Acumulado
C2: 44182 | D2: 44190 | E2: 44198 | F2: 44210 | G2: 44218 | H2: 44226 | I2: 44234 | J2: 44242 | K2: 44251 | L2: 44258 | M2: 44266 | N2: 44274 | O2: 44282 | P2: 44290 | Q2: 44298 | R2: 44316 | S2: 44324 | T2: 44332 | U2: 44340 | V2: 44348 | W2: 44356 | X2: 44364 | Y2: 44372 | Z2: 44380 | AA2: 44394 | AB2: 44404 | AC2: 44412 | AD2: 44420 | AE2: 44428 | AF2: 44436 | AG2: 44444 | AH2: 44452 | AI2: 44460 | AJ2: 44466 | AK2: 44473 | AL2: 44480 | AM2: 44487 | AN2: 44494 | AO2: 44501 | AP2: 44508 | AQ2: 44515 | AR2: 44522 | AS2: 44529 | AT2: 44571 | AU2: 44578 | AV2: 44585 | AW2: 44592 | AX2: 44599 | AY2: 44606 | AZ2: 44613 | BA2: 44620 | BB2: 44627 | BC2: 44634 | BD2: 44641 | BE2: 44648 | BF2: 44655 | BG2: 44662 | BH2: 44669 | BI2: 44676 | BJ2: 44683 | BK2: 44690 | BL2: 44697 | BM2: 44704 | BN2: 44711 | BO2: 44718 | BP2: 44725 | BQ2: 44732 | BR2: 44739 | BS2: 44746
B3: Feito | C3: =COUNTIF($C$5:$J$60,B3) -> 0 | D3: =COUNTIF($C$5:$J$60,C3) -> 4 | E3: =COUNTIF($C$5:$J$60,D3) -> 5 | F3: =COUNTIF($C$5:$J$60,E3) -> 7 | G3: =COUNTIF($C$5:$J$60,F3) -> 1 | H3: =COUNTIF($C$5:$J$60,G3) -> 0 | I3: =COUNTIF($C$5:$J$60,H3) -> 4 | J3: =COUNTIF($C$5:$J$60,I3) -> 5 | ... Q3: =COUNTIF($C$5:$J$60,P3) -> 1 | R3: =COUNTIF($B$5:$I$60,Q3) -> 0 | S3: =COUNTIF($B$5:$I$60,R3) -> 4 | T3: =COUNTIF($B$5:$I$60,S3) -> 5 | U3: =COUNTIF($B$5:$I$60,T3) -> 7 | V3: =COUNTIF($B$5:$I$60,U3) -> 0 | W3: =COUNTIF($B$5:$I$60,V3) -> 4 | X3: =COUNTIF($B$5:$I$60,W3) -> 5 | Y3: =COUNTIF($B$5:$I$60,X3) -> 7 | ... AH3: =COUNTIF($B$5:$I$60,AG3) -> 0 | AI3: =COUNTIF($C$5:$I$60,AH3) -> 4 | AJ3: =COUNTIF($B$5:$I$60,AI3) -> 5 | AK3: =COUNTIF($B$5:$I$60,AJ3) -> 7 | AL3: =COUNTIF($B$5:$I$60,AK3) -> 0 | AM3: =COUNTIF($B$5:$I$60,AL3) -> 4 | AN3: =COUNTIF($B$5:$I$60,AM3) -> 5 | AO3: =COUNTIF($B$5:$I$60,AN3) -> 7 | AP3: =COUNTIF($B$5:$I$60,AO3) -> 0 | AQ3: =COUNTIF($B$5:$I$60,AP3) -> 4 | ... AT3: =COUNTIF($B$5:$I$60,AS3) -> 0 | AU3: =COUNTIF($B$5:$I$95,AT3) -> 4 | AV3: =COUNTIF($B$5:$H$95,AU3) -> 5 | AW3: =COUNTIF($B$5:$H$95,AV3) -> 5 | AX3: =COUNTIF($B$5:$H$95,AW3) -> 5 | AY3: =COUNTIF($B$5:$H$95,AX3) -> 5 | AZ3: =COUNTIF($B$5:$H$95,AY3) -> 5 | BA3: ='28 02 2022'!K5 -> 137 | BB3: ='07 03 2022'!K5 -> 149 | BC3: ='14 03 2022'!K5 -> 105 | BD3: ='21 03 2022'!K5 -> 161 | BE3: ='28 03 2022'!K5 -> 173 | BF3: ='04 04 2022'!K5 -> 209 | BG3: =COUNTIF($B$5:$H$95,BF3) -> 0 | BH3: =COUNTIF($B$5:$H$95,BG3) -> 4 | BI3: =COUNTIF($B$5:$H$95,BH3) -> 5 | BJ3: =COUNTIF($B$5:$H$95,BI3) -> 5 | BK3: ='09 05 2022'!K5 -> 227 | BL3: ='16 05 2022'!K5 -> 199 | BM3: ='23 05 2022 '!K5 -> 197 | BN3: ='30 05 2022 '!K5 -> 196 | BO3: ='06 06 2022 '!K5 -> 187 | BP3: ='13 06 2022 '!K5 -> 171 | BQ3: ='20 06 2022 '!K5 -> 149 | BR3: ='27 06 2022 '!K5 -> 127 | BS3: ='04 07 2022'!K5 -> 140
B4: Mecânico | C4: =COUNTIF($C$5:$J$60,B4) -> 0 | D4: =COUNTIF($C$5:$J$60,C4) -> 4 | E4: =COUNTIF($C$5:$J$60,D4) -> 5 | F4: =COUNTIF($C$5:$J$60,E4) -> 7 | G4: =COUNTIF($C$5:$J$60,F4) -> 1 | H4: =COUNTIF($C$5:$J$60,G4) -> 0 | I4: =COUNTIF($C$5:$J$60,H4) -> 4 | J4: =COUNTIF($C$5:$J$60,I4) -> 5 | ... Q4: =COUNTIF($C$5:$J$60,P4) -> 1 | R4: =COUNTIF($B$5:$I$60,Q4) -> 0 | S4: =COUNTIF($B$5:$I$60,R4) -> 4 | T4: =COUNTIF($B$5:$I$60,S4) -> 5 | U4: =COUNTIF($B$5:$I$60,T4) -> 7 | V4: =COUNTIF($B$5:$I$60,U4) -> 0 | W4: =COUNTIF($B$5:$I$60,V4) -> 4 | X4: =COUNTIF($B$5:$I$60,W4) -> 5 | Y4: =COUNTIF($B$5:$I$60,X4) -> 7 | ... AH4: =COUNTIF($B$5:$I$60,AG4) -> 0 | AI4: =COUNTIF($C$5:$I$60,AH4) -> 4 | AJ4: =COUNTIF($B$5:$I$60,AI4) -> 5 | AK4: =COUNTIF($B$5:$I$60,AJ4) -> 7 | AL4: =COUNTIF($B$5:$I$60,AK4) -> 0 | AM4: =COUNTIF($B$5:$I$60,AL4) -> 4 | AN4: =COUNTIF($B$5:$I$60,AM4) -> 5 | AO4: =COUNTIF($B$5:$I$60,AN4) -> 7 | AP4: =COUNTIF($B$5:$I$60,AO4) -> 0 | AQ4: =COUNTIF($B$5:$I$60,AP4) -> 4 | ... AU4: =COUNTIF($B$5:$I$60,AT4) -> 4 | AV4: =COUNTIF($B$5:$H$95,AU4) -> 5 | AW4: =COUNTIF($B$5:$H$95,AV4) -> 5 | AX4: =COUNTIF($B$5:$H$95,AW4) -> 5 | AY4: =COUNTIF($B$5:$H$95,AX4) -> 5 | AZ4: =COUNTIF($B$5:$H$95,AY4) -> 5 | BA4: ='28 02 2022'!K6 -> 17 | BB4: ='07 03 2022'!K6 -> 10 | BC4: ='14 03 2022'!K6 -> 18 | BD4: ='21 03 2022'!K6 -> 16 | BE4: ='28 03 2022'!K6 -> 15 | BF4: ='04 04 2022'!K6 -> 17 | BG4: =COUNTIF($B$5:$H$95,BF4) -> 0 | BH4: =COUNTIF($B$5:$H$95,BG4) -> 4 | BI4: =COUNTIF($B$5:$H$95,BH4) -> 5 | BJ4: =COUNTIF($B$5:$H$95,BI4) -> 5 | BK4: ='09 05 2022'!K6 -> 7 | BL4: ='16 05 2022'!K6 -> 7 | BM4: ='23 05 2022 '!K6 -> 20 | BN4: ='30 05 2022 '!K6 -> 5 | BO4: ='06 06 2022 '!K6 -> 4 | BP4: ='13 06 2022 '!K6 -> 4 | BQ4: ='20 06 2022 '!K6 -> 8 | BR4: ='27 06 2022 '!K6 -> 9 | BS4: ='04 07 2022'!K6 -> 1
B5: Elétrico | C5: =COUNTIF($C$5:$J$60,B5) -> 0 | D5: =COUNTIF($C$5:$J$60,C5) -> 4 | E5: =COUNTIF($C$5:$J$60,D5) -> 5 | F5: =COUNTIF($C$5:$J$60,E5) -> 8 | G5: =COUNTIF($C$5:$J$60,F5) -> 7 | H5: =COUNTIF($C$5:$J$60,G5) -> 2 | I5: =COUNTIF($C$5:$J$60,H5) -> 3 | J5: =COUNTIF($C$5:$J$60,I5) -> 4 | ... Q5: =COUNTIF($C$5:$J$60,P5) -> 2 | R5: =COUNTIF($B$5:$I$60,Q5) -> 2 | S5: =COUNTIF($B$5:$I$60,R5) -> 2 | T5: =COUNTIF($B$5:$I$60,S5) -> 2 | U5: =COUNTIF($B$5:$I$60,T5) -> 2 | V5: =COUNTIF($B$5:$I$60,U5) -> 2 | W5: =COUNTIF($B$5:$I$60,V5) -> 2 | X5: =COUNTIF($B$5:$I$60,W5) -> 2 | Y5: =COUNTIF($B$5:$I$60,X5) -> 2 | ... AH5: =COUNTIF($B$5:$I$60,AG5) -> 2 | AI5: =COUNTIF($C$5:$I$60,AH5) -> 2 | AJ5: =COUNTIF($B$5:$I$60,AI5) -> 2 | AK5: =COUNTIF($B$5:$I$60,AJ5) -> 2 | AL5: =COUNTIF($B$5:$I$60,AK5) -> 2 | AM5: =COUNTIF($B$5:$I$60,AL5) -> 2 | AN5: =COUNTIF($B$5:$I$60,AM5) -> 2 | AO5: =COUNTIF($B$5:$I$60,AN5) -> 2 | AP5: =COUNTIF($B$5:$I$60,AO5) -> 2 | AQ5: =COUNTIF($B$5:$I$60,AP5) -> 2 | ... AU5: =COUNTIF($B$5:$I$60,AT5) -> 2 | AV5: =COUNTIF($B$5:$H$95,AU5) -> 2 | AW5: =COUNTIF($B$5:$H$95,AV5) -> 2 | AX5: =COUNTIF($B$5:$H$95,AW5) -> 2 | AY5: =COUNTIF($B$5:$H$95,AX5) -> 2 | AZ5: =COUNTIF($B$5:$H$95,AY5) -> 2 | BA5: ='28 02 2022'!K7 -> 14 | BB5: ='07 03 2022'!K7 -> 7 | BC5: ='14 03 2022'!K7 -> 13 | BD5: ='21 03 2022'!K7 -> 6 | BE5: ='28 03 2022'!K7 -> 7 | BF5: ='04 04 2022'!K7 -> 7 | BG5: =COUNTIF($B$5:$H$95,BF5) -> 1 | BH5: =COUNTIF($B$5:$H$95,BG5) -> 0 | BI5: =COUNTIF($B$5:$H$95,BH5) -> 4 | BJ5: =COUNTIF($B$5:$H$95,BI5) -> 5 | BK5: ='09 05 2022'!K7 -> 3 | BL5: ='16 05 2022'!K7 -> 8 | BM5: ='23 05 2022 '!K7 -> 5 | BN5: ='30 05 2022 '!K7 -> 7 | BO5: ='06 06 2022 '!K7 -> 6 | BP5: ='13 06 2022 '!K7 -> 13 | BQ5: ='20 06 2022 '!K7 -> 2 | BR5: ='27 06 2022 '!K7 -> 4 | BS5: ='04 07 2022'!K7 -> 4
B6: Energia | C6: =COUNTIF($C$5:$J$60,B6) -> 0 | D6: =COUNTIF($C$5:$J$60,C6) -> 4 | E6: =COUNTIF($C$5:$J$60,D6) -> 6 | F6: =COUNTIF($C$5:$J$60,E6) -> 3 | G6: =COUNTIF($C$5:$J$60,F6) -> 4 | H6: =COUNTIF($C$5:$J$60,G6) -> 7 | I6: =COUNTIF($C$5:$J$60,H6) -> 3 | J6: =COUNTIF($C$5:$J$60,I6) -> 4 | ... Q6: =COUNTIF($C$5:$J$60,P6) -> 8 | R6: =COUNTIF($B$5:$I$60,Q6) -> 4 | S6: =COUNTIF($B$5:$I$60,R6) -> 6 | T6: =COUNTIF($B$5:$I$60,S6) -> 3 | U6: =COUNTIF($B$5:$I$60,T6) -> 3 | V6: =COUNTIF($B$5:$I$60,U6) -> 3 | W6: =COUNTIF($B$5:$I$60,V6) -> 3 | X6: =COUNTIF($B$5:$I$60,W6) -> 3 | Y6: =COUNTIF($B$5:$I$60,X6) -> 3 | ... AH6: =COUNTIF($B$5:$I$60,AG6) -> 3 | AI6: =COUNTIF($C$5:$I$60,AH6) -> 3 | AJ6: =COUNTIF($B$5:$I$60,AI6) -> 3 | AK6: =COUNTIF($B$5:$I$60,AJ6) -> 3 | AL6: =COUNTIF($B$5:$I$60,AK6) -> 3 | AM6: =COUNTIF($B$5:$I$60,AL6) -> 3 | AN6: =COUNTIF($B$5:$I$60,AM6) -> 3 | AO6: =COUNTIF($B$5:$I$60,AN6) -> 3 | AP6: =COUNTIF($B$5:$I$60,AO6) -> 3 | AQ6: =COUNTIF($B$5:$I$60,AP6) -> 3 | ... AU6: =COUNTIF($B$5:$I$60,AT6) -> 3 | AV6: =COUNTIF($B$5:$H$95,AU6) -> 1 | AW6: =COUNTIF($B$5:$H$95,AV6) -> 0 | AX6: =COUNTIF($B$5:$H$95,AW6) -> 4 | AY6: =COUNTIF($B$5:$H$95,AX6) -> 6 | AZ6: =COUNTIF($B$5:$H$95,AY6) -> 2 | BA6: ='28 02 2022'!K8 -> 0 | BB6: ='07 03 2022'!K8 -> 0 | BC6: ='14 03 2022'!K8 -> 5 | BD6: ='21 03 2022'!K8 -> 0 | BE6: ='28 03 2022'!K8 -> 4 | BF6: ='04 04 2022'!K8 -> 0 | BG6: =COUNTIF($B$5:$H$95,BF6) -> 4 | BH6: =COUNTIF($B$5:$H$95,BG6) -> 6 | BI6: =COUNTIF($B$5:$H$95,BH6) -> 2 | BJ6: =COUNTIF($B$5:$H$95,BI6) -> 1 | BK6: ='09 05 2022'!K8 -> 0 | BL6: ='16 05 2022'!K8 -> 0 | BM6: ='23 05 2022 '!K8 -> 0 | BN6: ='30 05 2022 '!K8 -> 0 | BO6: ='06 06 2022 '!K8 -> 0 | BP6: ='13 06 2022 '!K8 -> 0 | BQ6: ='20 06 2022 '!K8 -> 5 | BR6: ='27 06 2022 '!K8 -> 0 | BS6: ='04 07 2022'!K8 -> 0
B7: Chuva | C7: =COUNTIF($C$5:$J$60,B7) -> 0 | D7: =COUNTIF($C$5:$J$60,C7) -> 4 | E7: =COUNTIF($C$5:$J$60,D7) -> 8 | F7: =COUNTIF($C$5:$J$60,E7) -> 5 | G7: =COUNTIF($C$5:$J$60,F7) -> 5 | H7: =COUNTIF($C$5:$J$60,G7) -> 6 | I7: =COUNTIF($C$5:$J$60,H7) -> 3 | J7: =COUNTIF($C$5:$J$60,I7) -> 5 | ... Q7: =COUNTIF($C$5:$J$60,P7) -> 6 | R7: =COUNTIF($B$5:$I$60,Q7) -> 3 | S7: =COUNTIF($B$5:$I$60,R7) -> 4 | T7: =COUNTIF($B$5:$I$60,S7) -> 5 | U7: =COUNTIF($B$5:$I$60,T7) -> 5 | V7: =COUNTIF($B$5:$I$60,U7) -> 5 | W7: =COUNTIF($B$5:$I$60,V7) -> 5 | X7: =COUNTIF($B$5:$I$60,W7) -> 5 | Y7: =COUNTIF($B$5:$I$60,X7) -> 5 | Z7: 0 | AA7: =COUNTIF($B$5:$I$60,Z7) -> 4 | AB7: =COUNTIF($B$5:$I$60,AA7) -> 5 | AC7: =COUNTIF($B$5:$I$60,AB7) -> 5 | AD7: =COUNTIF($B$5:$I$60,AC7) -> 5 | AE7: 0 | AF7: =COUNTIF($B$5:$I$60,AE7) -> 4 | AG7: =COUNTIF($B$5:$I$60,AF7) -> 5 | AH7: =COUNTIF($B$5:$I$60,AG7) -> 5 | AI7: =COUNTIF($C$5:$I$60,AH7) -> 5 | AJ7: =COUNTIF($B$5:$I$60,AI7) -> 5 | AK7: =COUNTIF($B$5:$I$60,AJ7) -> 5 | AL7: =COUNTIF($B$5:$I$60,AK7) -> 5 | AM7: =COUNTIF($B$5:$I$60,AL7) -> 5 | AN7: =COUNTIF($B$5:$I$60,AM7) -> 5 | AO7: =COUNTIF($B$5:$I$60,AN7) -> 5 | AP7: =COUNTIF($B$5:$I$60,AO7) -> 5 | AQ7: =COUNTIF($B$5:$I$60,AP7) -> 5 | ... AU7: =COUNTIF($B$5:$I$60,AT7) -> 5 | AV7: =COUNTIF($B$5:$H$95,AU7) -> 5 | AW7: =COUNTIF($B$5:$H$95,AV7) -> 5 | AX7: =COUNTIF($B$5:$H$95,AW7) -> 5 | AY7: =COUNTIF($B$5:$H$95,AX7) -> 5 | AZ7: =COUNTIF($B$5:$H$95,AY7) -> 5 | BA7: ='28 02 2022'!K9 -> 17 | BB7: ='07 03 2022'!K9 -> 0 | BC7: ='14 03 2022'!K9 -> 5 | BD7: ='21 03 2022'!K9 -> 0 | BE7: ='28 03 2022'!K9 -> 0 | BF7: ='04 04 2022'!K9 -> 0 | BG7: =COUNTIF($B$5:$H$95,BF7) -> 4 | BH7: =COUNTIF($B$5:$H$95,BG7) -> 5 | BI7: =COUNTIF($B$5:$H$95,BH7) -> 5 | BJ7: =COUNTIF($B$5:$H$95,BI7) -> 5 | BK7: ='09 05 2022'!K9 -> 0 | BL7: ='16 05 2022'!K9 -> 0 | BM7: ='23 05 2022 '!K9 -> 0 | BN7: ='30 05 2022 '!K9 -> 0 | BO7: ='06 06 2022 '!K9 -> 0 | BP7: ='13 06 2022 '!K9 -> 0 | BQ7: ='20 06 2022 '!K9 -> 0 | BR7: ='27 06 2022 '!K9 -> 0 | BS7: ='04 07 2022'!K9 -> 0
B8: Operação | C8: =COUNTIF($C$5:$J$60,B8) -> 0 | D8: =COUNTIF($C$5:$J$60,C8) -> 4 | E8: =COUNTIF($C$5:$J$60,D8) -> 7 | F8: =COUNTIF($C$5:$J$60,E8) -> 3 | G8: =COUNTIF($C$5:$J$60,F8) -> 6 | H8: =COUNTIF($C$5:$J$60,G8) -> 4 | I8: =COUNTIF($C$5:$J$60,H8) -> 8 | J8: =COUNTIF($C$5:$J$60,I8) -> 3 | ... Q8: =COUNTIF($C$5:$J$60,P8) -> 6 | R8: =COUNTIF($B$5:$I$60,Q8) -> 3 | S8: =COUNTIF($B$5:$I$60,R8) -> 5 | T8: =COUNTIF($B$5:$I$60,S8) -> 3 | U8: =COUNTIF($B$5:$I$60,T8) -> 5 | V8: =COUNTIF($B$5:$I$60,U8) -> 3 | W8: =COUNTIF($B$5:$I$60,V8) -> 5 | X8: =COUNTIF($B$5:$I$60,W8) -> 3 | Y8: =COUNTIF($B$5:$I$60,X8) -> 5 | ... AH8: =COUNTIF($B$5:$I$60,AG8) -> 3 | AI8: =COUNTIF($C$5:$I$60,AH8) -> 5 | AJ8: =COUNTIF($B$5:$I$60,AI8) -> 3 | AK8: =COUNTIF($B$5:$I$60,AJ8) -> 5 | AL8: =COUNTIF($B$5:$I$60,AK8) -> 3 | AM8: =COUNTIF($B$5:$I$60,AL8) -> 5 | AN8: =COUNTIF($B$5:$I$60,AM8) -> 3 | AO8: =COUNTIF($B$5:$I$60,AN8) -> 5 | AP8: =COUNTIF($B$5:$I$60,AO8) -> 3 | AQ8: =COUNTIF($B$5:$I$60,AP8) -> 5 | ... AU8: =COUNTIF($B$5:$I$60,AT8) -> 5 | AV8: =COUNTIF($B$5:$H$95,AU8) -> 3 | AW8: =COUNTIF($B$5:$H$95,AV8) -> 2 | AX8: =COUNTIF($B$5:$H$95,AW8) -> 1 | AY8: =COUNTIF($B$5:$H$95,AX8) -> 0 | AZ8: =COUNTIF($B$5:$H$95,AY8) -> 4 | BA8: ='28 02 2022'!K10 -> 16 | BB8: ='07 03 2022'!K10 -> 19 | BC8: ='14 03 2022'!K10 -> 11 | BD8: ='21 03 2022'!K10 -> 12 | BE8: ='28 03 2022'!K10 -> 6 | BF8: ='04 04 2022'!K10 -> 6 | BG8: =COUNTIF($B$5:$H$95,BF8) -> 3 | BH8: =COUNTIF($B$5:$H$95,BG8) -> 2 | BI8: =COUNTIF($B$5:$H$95,BH8) -> 1 | BJ8: =COUNTIF($B$5:$H$95,BI8) -> 0 | BK8: ='09 05 2022'!K10 -> 11 | BL8: ='16 05 2022'!K10 -> 11 | BM8: ='23 05 2022 '!K10 -> 11 | BN8: ='30 05 2022 '!K10 -> 9 | BO8: ='06 06 2022 '!K10 -> 6 | BP8: ='13 06 2022 '!K10 -> 11 | BQ8: ='20 06 2022 '!K10 -> 7 | BR8: ='27 06 2022 '!K10 -> 9 | BS8: ='04 07 2022'!K10 -> 8
AA12: Feito
AA13: Mecânico
AA14: Elétrico
AA15: Energia
AA16: Chuva
AA17: Operação
AB24: =600*3 -> 1800
AB25: 600

Sheet 17 12 2020
C3: 44182 | D3: =C3+1 -> 44183 | E3: =D3+1 -> 44184 | F3: =E3+1 -> 44185 | G3: =F3+1 -> 44186 | H3: =G3+1 -> 44187 | I3: =H3+1 -> 44188 | J3: =I3+1 -> 44189
B4: Pivô | C4: =TEXT(C3,"ddd") -> qui | D4: =TEXT(D3,"ddd") -> sex | E4: =TEXT(E3,"ddd") -> sáb | F4: =TEXT(F3,"ddd") -> dom | G4: =TEXT(G3,"ddd") -> seg | H4: =TEXT(H3,"ddd") -> ter | I4: =TEXT(I3,"ddd") -> qua | J4: =TEXT(J3,"ddd") -> qui | L4: Parametros | M4: Contagem | N4: Porcentagem | O4: Semana
B5: 1 | C5: Feito | D5: Feito | F5: Chuva | G5: Energia | H5: Feito | I5: Feito | L5: Feito | M5: =COUNTIF($C$5:$J$60,L5) -> 81 | N5: =M5/$M$11 -> 0.60447761 | O5: 44182
B6: 2 | L6: Mecânico | M6: =COUNTIF($C$5:$J$60,L6) -> 12 | N6: =M6/$M$11 -> 0.089552239
B7: 3 | L7: Elétrico | M7: =COUNTIF($C$5:$J$60,L7) -> 3 | N7: =M7/$M$11 -> 0.02238806
B8: 4 | C8: Mecânico | E8: Feito | F8: Chuva | I8: Feito | L8: Energia | M8: =COUNTIF($C$5:$J$60,L8) -> 12 | N8: =M8/$M$11 -> 0.089552239
B9: 5 | C9: Feito | E9: Feito | I9: Chuva | L9: Chuva | M9: =COUNTIF($C$5:$J$60,L9) -> 24 | N9: =M9/$M$11 -> 0.17910448
B10: 6 | C10: Feito | E10: Feito | H10: Feito | L10: Operação | M10: =COUNTIF($C$5:$J$60,L10) -> 2 | N10: =M10/$M$11 -> 0.014925373
B11: 7 | C11: Mecânico | F11: Chuva | I11: Chuva | M11: =SUM(M5:M10) -> 134
B12: 8 | C12: Feito | E12: Feito | H12: Feito
B13: 9 | C13: Operação | D13: Feito | F13: Chuva | H13: Feito
B14: 10 | E14: Feito | I14: Chuva
B15: 11 | C15: Feito | E15: Feito | H15: Feito
B16: 12 | C16: Feito | F16: Chuva | H16: Feito
B17: 13 | D17: Feito | E17: Feito | G17: Energia | H17: Feito | I17: Feito | J17: Feito
B18: 14 | C18: Feito | D18: Feito | E18: Feito | I18: Chuva
B19: 15 | D19: Feito | F19: Chuva
B20: 16 | G20: Energia
B21: 17 | D21: Mecânico | F21: Feito | G21: Energia
B22: 18
B23: 19 | D23: Mecânico | E23: Mecânico | F23: Mecânico | G23: Mecânico | I23: Feito | J23: Feito
B24: 20
B25: 21 | C25: Feito | E25: Elétrico | H25: Feito
B26: 22
B27: 23 | D27: Feito | F27: Chuva | I27: Chuva
B28: 24
B29: 25 | C29: Feito | D29: Feito | E29: Feito | F29: Feito | G29: Energia | H29: Feito | I29: Feito
B30: 26 | D30: Feito | E30: Feito | I30: Chuva
B31: 27 | D31: Feito | F31: Chuva | I31: Chuva
B32: 28
B33: 29 | C33: Feito | D33: Feito | E33: Feito | F33: Chuva
B34: 30
B35: 31 | F35: Chuva
B36: 32
B37: 33 | C37: Feito | F37: Chuva
B38: 34 | E38: Mecânico | F38: Mecânico
B39: 35
B40: 36 | D40: Feito | E40: Mecânico | F40: Mecânico
B41: 37 | D41: Feito | F41: Chuva
B42: 38 | D42: Feito | F42: Chuva
...

Sheet 25 12 2020
C3: 44190 | D3: =C3+1 -> 44191 | E3: =D3+1 -> 44192 | F3: =E3+1 -> 44193 | G3: =F3+1 -> 44194 | H3: =G3+1 -> 44195 | I3: =H3+1 -> 44196 | J3: =I3+1 -> 44197
B4: Pivô | C4: =TEXT(C3,"ddd") -> sex | D4: =TEXT(D3,"ddd") -> sáb | E4: =TEXT(E3,"ddd") -> dom | F4: =TEXT(F3,"ddd") -> seg | G4: =TEXT(G3,"ddd") -> ter | H4: =TEXT(H3,"ddd") -> qua | I4: =TEXT(I3,"ddd") -> qui | J4: =TEXT(J3,"ddd") -> sex | L4: Parametros | M4: Contagem | N4: Porcentagem | O4: Semana
B5: 1 | F5: Mecânico | H5: Elétrico | L5: Feito | M5: =COUNTIF($C$5:$J$60,L5) -> 101 | N5: =M5/$M$11 -> 0.8015873 | O5: 44190
B6: 2 | L6: Mecânico | M6: =COUNTIF($C$5:$J$60,L6) -> 10 | N6: =M6/$M$11 -> 0.079365079
B7: 3 | L7: Elétrico | M7: =COUNTIF($C$5:$J$60,L7) -> 6 | N7: =M7/$M$11 -> 0.047619048
B8: 4 | F8: Feito | G8: Feito | H8: Feito | I8: Feito | J8: Feito | L8: Energia | M8: =COUNTIF($C$5:$J$60,L8) -> 2 | N8: =M8/$M$11 -> 0.015873016
B9: 5 | E9: Feito | G9: Feito | I9: Feito | L9: Chuva | M9: =COUNTIF($C$5:$J$60,L9) -> 0 | N9: =M9/$M$11 -> 0
B10: 6 | F10: Operação | H10: Feito | J10: Feito | L10: Operação | M10: =COUNTIF($C$5:$J$60,L10) -> 7 | N10: =M10/$M$11 -> 0.055555556
B11: 7 | E11: Feito | G11: Feito | I11: Feito | M11: =SUM(M5:M10) -> 126
B12: 8 | F12: Feito | H12: Operação | J12: Feito
B13: 9 | E13: Feito | G13: Feito
B14: 10 | F14: Feito | H14: Feito | J14: Mecânico
B15: 11 | E15: Feito | G15: Feito | I15: Feito
B16: 12 | F16: Feito | G16: Feito | H16: Feito | J16: Feito
B17: 13 | E17: Feito | G17: Feito | I17: Feito
B18: 14 | F18: Operação | G18: Feito | H18: Feito | I18: Feito
B19: 15 | E19: Feito | G19: Mecânico | H19: Mecânico | J19: Elétrico
B20: 16
B21: 17 | F21: Feito | G21: Operação | H21: Feito | J21: Feito
B22: 18
B23: 19 | D23: Feito | E23: Feito | I23: Feito
B24: 20
B25: 21 | F25: Mecânico | G25: Elétrico | I25: Energia | J25: Elétrico
B26: 22
B27: 23 | E27: Feito | I27: Energia | J27: Elétrico
B28: 24 | I28: Feito | J28: Mecânico
B29: 25 | E29: Feito | F29: Feito | G29: Feito | H29: Feito | I29: Feito | J29: Feito
B30: 26 | E30: Feito | G30: Feito
B31: 27 | E31: Feito | G31: Feito
B32: 28
B33: 29 | E33: Feito | F33: Feito | H33: Feito | I33: Operação | J33: Feito
B34: 30 | H34: Mecânico | I34: Mecânico | J34: Mecânico
B35: 31
B36: 32
B37: 33 | J37: Feito
B38: 34 | H38: Operação | I38: Feito | J38: Feito
B39: 35
B40: 36 | E40: Feito | G40: Elétrico | I40: Feito
B41: 37 | F41: Feito | H41: Feito | J41: Feito
B42: 38 | F42: Feito | H42: Feito | J42: Feito
...

Sheet 02 01 2021 
C3: 44198 | D3: =C3+1 -> 44199 | E3: =D3+1 -> 44200 | F3: =E3+1 -> 44201 | G3: =F3+1 -> 44202 | H3: =G3+1 -> 44203 | I3: =H3+1 -> 44204 | J3: =I3+1 -> 44205
B4: Pivô | C4: =TEXT(C3,"ddd") -> sáb | D4: =TEXT(D3,"ddd") -> dom | E4: =TEXT(E3,"ddd") -> seg | F4: =TEXT(F3,"ddd") -> ter | G4: =TEXT(G3,"ddd") -> qua | H4: =TEXT(H3,"ddd") -> qui | I4: =TEXT(I3,"ddd") -> sex | J4: =TEXT(J3,"ddd") -> sáb | L4: Parametros | M4: Contagem | N4: Porcentagem | O4: Semana
B5: 1 | C5: Chuva | H5: Mecânico | I5: Mecânico | L5: Feito | M5: =COUNTIF($C$5:$J$60,L5) -> 38 | N5: =M5/$M$11 -> 0.34862385 | O5: 44198
B6: 2 | H6: Feito | I6: Feito | L6: Mecânico | M6: =COUNTIF($C$5:$J$60,L6) -> 12 | N6: =M6/$M$11 -> 0.11009174
B7: 3 | F7: Feito | G7: Feito | H7: Operação | L7: Elétrico | M7: =COUNTIF($C$5:$J$60,L7) -> 12 | N7: =M7/$M$11 -> 0.11009174
B8: 4 | D8: Chuva | G8: Feito | H8: Mecânico | L8: Energia | M8: =COUNTIF($C$5:$J$60,L8) -> 0 | N8: =M8/$M$11 -> 0
B9: 5 | C9: Chuva | L9: Chuva | M9: =COUNTIF($C$5:$J$60,L9) -> 39 | N9: =M9/$M$11 -> 0.35779817
B10: 6 | D10: Chuva | L10: Operação | M10: =COUNTIF($C$5:$J$60,L10) -> 8 | N10: =M10/$M$11 -> 0.073394495
B11: 7 | I11: Feito | M11: =SUM(M5:M10) -> 109
B12: 8 | H12: Operação | I12: Mecânico
B13: 9 | C13: Chuva | D13: Chuva | F13: Feito | G13: Feito
B14: 10 | H14: Operação
B15: 11 | C15: Chuva
B16: 12 | D16: Chuva | G16: Feito | H16: Operação | I16: Feito
B17: 13 | C17: Chuva | G17: Feito | I17: Feito
B18: 14 | D18: Chuva | H18: Elétrico
B19: 15 | D19: Chuva | G19: Elétrico | I19: Elétrico
B20: 16
B21: 17 | D21: Chuva
B22: 18
B23: 19 | C23: Chuva
B24: 20 | I24: Operação
B25: 21
B26: 22 | H26: Operação | I26: Operação
B27: 23 | C27: Chuva
B28: 24 | C28: Chuva | D28: Chuva | G28: Mecânico | H28: Feito | I28: Feito
B29: 25 | C29: Chuva | D29: Chuva | H29: Feito | I29: Feito
B30: 26 | C30: Chuva
B31: 27 | C31: Chuva | G31: Feito
B32: 28 | D32: Chuva | G32: Mecânico | I32: Mecânico
B33: 29 | C33: Chuva | H33: Feito | I33: Feito
B34: 30 | C34: Mecânico | D34: Mecânico | G34: Mecânico | H34: Feito | I34: Feito
B35: 31 | C35: Chuva
B36: 32 | G36: Feito | H36: Feito | I36: Feito
B37: 33
B38: 34 | C38: Chuva | D38: Chuva | G38: Feito | H38: Mecânico | I38: Mecânico
B39: 35
B40: 36 | C40: Chuva | H40: Feito
B41: 37 | D41: Chuva | H41: Feito
B42: 38
...

Sheet 14 01 2021
C3: 44210 | D3: =C3+1 -> 44211 | E3: =D3+1 -> 44212 | F3: =E3+1 -> 44213 | G3: =F3+1 -> 44214 | H3: =G3+1 -> 44215 | I3: =H3+1 -> 44216 | J3: =I3+1 -> 44217
B4: Pivô | C4: =TEXT(C3,"ddd") -> qui | D4: =TEXT(D3,"ddd") -> sex | E4: =TEXT(E3,"ddd") -> sáb | F4: =TEXT(F3,"ddd") -> dom | G4: =TEXT(G3,"ddd") -> seg | H4: =TEXT(H3,"ddd") -> ter | I4: =TEXT(I3,"ddd") -> qua | J4: =TEXT(J3,"ddd") -> qui | L4: Parametros | M4: Contagem | N4: Porcentagem | O4: Semana
B5: 1 | C5: Mecânico | L5: Feito | M5: =COUNTIF($C$5:$J$60,L5) -> 38 | N5: =M5/$M$11 -> 0.62295082 | O5: 44210
B6: 2 | L6: Mecânico | M6: =COUNTIF($C$5:$J$60,L6) -> 13 | N6: =M6/$M$11 -> 0.21311475
B7: 3 | L7: Elétrico | M7: =COUNTIF($C$5:$J$60,L7) -> 9 | N7: =M7/$M$11 -> 0.14754098
B8: 4 | H8: Feito | J8: Feito | L8: Energia | M8: =COUNTIF($C$5:$J$60,L8) -> 0 | N8: =M8/$M$11 -> 0
B9: 5 | J9: Feito | L9: Chuva | M9: =COUNTIF($C$5:$J$60,L9) -> 0 | N9: =M9/$M$11 -> 0
B10: 6 | I10: Mecânico | L10: Operação | M10: =COUNTIF($C$5:$J$60,L10) -> 1 | N10: =M10/$M$11 -> 0.016393443
B11: 7 | I11: Feito | M11: =SUM(M5:M10) -> 61
B12: 8 | J12: Feito
B13: 9 | I13: Feito | J13: Feito
B14: 10 | G14: Feito | H14: Feito | I14: Elétrico
B15: 11 | I15: Feito | J15: Feito
B16: 12 | G16: Feito | H16: Feito | J16: Feito
B17: 13 | I17: Feito
B18: 14 | H18: Feito | I18: Feito | J18: Elétrico
B19: 15 | J19: Mecânico
B20: 16 | C20: Mecânico | H20: Mecânico | I20: Mecânico | J20: Mecânico
B21: 17
B22: 18 | C22: Mecânico | H22: Feito | J22: Feito
B23: 19
B24: 20 | C24: Feito | J24: Feito
B25: 21
B26: 22 | I26: Elétrico
B27: 23
B28: 24
B29: 25 | H29: Feito | I29: Feito | J29: Feito
B30: 26
B31: 27 | J31: Mecânico
B32: 28 | C32: Mecânico
B33: 29 | H33: Feito | J33: Feito
B34: 30 | I34: Mecânico
B35: 31
B36: 32 | I36: Feito
B37: 33
B38: 34 | C38: Mecânico
B39: 35
B40: 36 | H40: Elétrico | J40: Elétrico
B41: 37 | I41: Feito
B42: 38
...

Sheet 22 01 2021
C3: 44218 | D3: =C3+1 -> 44219 | E3: =D3+1 -> 44220 | F3: =E3+1 -> 44221 | G3: =F3+1 -> 44222 | H3: =G3+1 -> 44223 | I3: =H3+1 -> 44224 | J3: =I3+1 -> 44225
B4: Pivô | C4: =TEXT(C3,"ddd") -> sex | D4: =TEXT(D3,"ddd") -> sáb | E4: =TEXT(E3,"ddd") -> dom | F4: =TEXT(F3,"ddd") -> seg | G4: =TEXT(G3,"ddd") -> ter | H4: =TEXT(H3,"ddd") -> qua | I4: =TEXT(I3,"ddd") -> qui | J4: =TEXT(J3,"ddd") -> sex | L4: Parametros | M4: Contagem | N4: Porcentagem | O4: Semana
B5: 1 | C5: Mecânico | F5: Mecânico | J5: Operação | L5: Feito | M5: =COUNTIF($C$5:$J$60,L5) -> 118 | N5: =M5/$M$11 -> 0.65921788 | O5: 44218
B6: 2 | I6: Feito | L6: Mecânico | M6: =COUNTIF($C$5:$J$60,L6) -> 19 | N6: =M6/$M$11 -> 0.10614525
B7: 3 | L7: Elétrico | M7: =COUNTIF($C$5:$J$60,L7) -> 4 | N7: =M7/$M$11 -> 0.022346369
B8: 4 | D8: Feito | F8: Feito | L8: Energia | M8: =COUNTIF($C$5:$J$60,L8) -> 19 | N8: =M8/$M$11 -> 0.10614525
B9: 5 | D9: Feito | F9: Feito | H9: Feito | J9: Operação | L9: Chuva | M9: =COUNTIF($C$5:$J$60,L9) -> 0 | N9: =M9/$M$11 -> 0
B10: 6 | C10: Feito | E10: Feito | F10: Feito | G10: Feito | I10: Feito | L10: Operação | M10: =COUNTIF($C$5:$J$60,L10) -> 19 | N10: =M10/$M$11 -> 0.10614525
B11: 7 | C11: Feito | E11: Feito | G11: Energia | I11: Feito | M11: =SUM(M5:M10) -> 179
B12: 8 | D12: Feito | F12: Mecânico | H12: Feito | I12: Feito | J12: Feito
B13: 9 | C13: Feito | E13: Feito | G13: Mecânico | J13: Operação
B14: 10 | C14: Mecânico | E14: Mecânico | G14: Operação | I14: Feito
B15: 11 | C15: Feito | E15: Feito | G15: Feito | I15: Feito
B16: 12 | D16: Feito | F16: Feito | H16: Feito | J16: Operação
B17: 13 | C17: Feito | E17: Feito | G17: Feito | I17: Feito
B18: 14 | D18: Elétrico | F18: Feito | H18: Operação | J18: Feito
B19: 15
B20: 16 | C20: Feito | F20: Feito | I20: Mecânico
B21: 17 | F21: Feito | G21: Feito | H21: Feito | I21: Feito | J21: Feito
B22: 18 | E22: Feito | H22: Feito | I22: Feito
B23: 19 | F23: Feito | G23: Feito | H23: Feito | I23: Energia | J23: Energia
B24: 20 | E24: Feito | H24: Energia | J24: Operação
B25: 21 | E25: Feito | F25: Mecânico | G25: Energia | H25: Energia | I25: Energia | J25: Energia
B26: 22 | C26: Elétrico | D26: Elétrico | F26: Mecânico | I26: Feito
B27: 23 | E27: Feito | F27: Feito | G27: Feito | H27: Operação | I27: Feito | J27: Feito
B28: 24 | E28: Feito | H28: Operação
B29: 25 | C29: Feito | D29: Feito | E29: Feito | F29: Feito | G29: Feito | H29: Mecânico | I29: Mecânico | J29: Energia
B30: 26 | D30: Feito | E30: Mecânico | F30: Feito | G30: Feito | H30: Feito | I30: Feito | J30: Feito
B31: 27
B32: 28 | H32: Feito
B33: 29 | D33: Feito | F33: Feito | H33: Feito | J33: Operação
B34: 30 | D34: Mecânico | G34: Feito | I34: Operação
B35: 31 | J35: Feito
B36: 32 | C36: Feito | F36: Mecânico | J36: Operação
B37: 33
B38: 34 | H38: Mecânico | I38: Operação
B39: 35
B40: 36 | D40: Feito | F40: Feito | H40: Feito | I40: Feito
B41: 37 | C41: Feito | E41: Feito | G41: Feito
B42: 38 | H42: Feito | I42: Feito | J42: Feito
...

Sheet 30 01 2021
C3: 44226 | D3: =C3+1 -> 44227 | E3: =D3+1 -> 44228 | F3: =E3+1 -> 44229 | G3: =F3+1 -> 44230 | H3: =G3+1 -> 44231 | I3: =H3+1 -> 44232 | J3: =I3+1 -> 44233
B4: Pivô | C4: =TEXT(C3,"ddd") -> sáb | D4: =TEXT(D3,"ddd") -> dom | E4: =TEXT(E3,"ddd") -> seg | F4: =TEXT(F3,"ddd") -> ter | G4: =TEXT(G3,"ddd") -> qua | H4: =TEXT(H3,"ddd") -> qui | I4: =TEXT(I3,"ddd") -> sex | J4: =TEXT(J3,"ddd") -> sáb | L4: Parametros | M4: Contagem | N4: Porcentagem | O4: Semana
B5: 1 | D5: Operação | G5: Feito | L5: Feito | M5: =COUNTIF($C$5:$J$60,L5) -> 122 | N5: =M5/$M$11 -> 0.69714286 | O5: 44226
B6: 2 | G6: Mecânico | L6: Mecânico | M6: =COUNTIF($C$5:$J$60,L6) -> 12 | N6: =M6/$M$11 -> 0.068571429
B7: 3 | L7: Elétrico | M7: =COUNTIF($C$5:$J$60,L7) -> 0 | N7: =M7/$M$11 -> 0
B8: 4 | I8: Operação | J8: Feito | L8: Energia | M8: =COUNTIF($C$5:$J$60,L8) -> 18 | N8: =M8/$M$11 -> 0.10285714
B9: 5 | D9: Feito | G9: Feito | I9: Feito | L9: Chuva | M9: =COUNTIF($C$5:$J$60,L9) -> 2 | N9: =M9/$M$11 -> 0.011428571
B10: 6 | C10: Feito | F10: Feito | H10: Feito | J10: Feito | L10: Operação | M10: =COUNTIF($C$5:$J$60,L10) -> 21 | N10: =M10/$M$11 -> 0.12
B11: 7 | C11: Feito | F11: Feito | I11: Feito | M11: =SUM(M5:M10) -> 175
B12: 8 | D12: Mecânico | F12: Feito | H12: Feito | J12: Feito
B13: 9 | D13: Mecânico | F13: Operação | H13: Feito | J13: Feito
B14: 10 | C14: Operação | G14: Feito | I14: Feito
B15: 11 | C15: Feito | F15: Feito | H15: Feito | J15: Feito
B16: 12 | D16: Feito | G16: Feito | I16: Feito
B17: 13 | C17: Feito | D17: Feito | F17: Feito | G17: Feito | H17: Feito | I17: Feito | J17: Feito
B18: 14 | D18: Feito | G18: Mecânico | J18: Feito
B19: 15 | I19: Feito
B20: 16 | C20: Operação | G20: Feito
B21: 17 | C21: Feito | D21: Feito | F21: Feito | J21: Feito
B22: 18 | D22: Operação | E22: Feito | J22: Feito
B23: 19 | C23: Energia | D23: Feito | F23: Operação
B24: 20 | F24: Operação
B25: 21 | C25: Energia | D25: Energia | E25: Feito | F25: Energia | J25: Feito
B26: 22 | D26: Feito | G26: Feito
B27: 23 | C27: Feito | D27: Feito | G27: Feito
B28: 24 | C28: Operação | H28: Operação
B29: 25 | C29: Feito | D29: Energia | E29: Feito | F29: Energia | H29: Feito | I29: Feito | J29: Chuva
B30: 26 | C30: Feito | D30: Feito | G30: Operação | J30: Feito
B31: 27 | J31: Mecânico
B32: 28 | C32: Operação | G32: Feito
B33: 29 | D33: Feito | G33: Feito | H33: Feito
B34: 30 | C34: Feito | F34: Mecânico | G34: Operação | J34: Feito
B35: 31 | D35: Mecânico | E35: Feito | F35: Mecânico | G35: Feito | H35: Feito | J35: Feito
B36: 32 | F36: Feito | H36: Chuva
B37: 33
B38: 34 | C38: Feito | G38: Feito | H38: Feito
B39: 35
B40: 36 | C40: Feito | F40: Feito | I40: Mecânico
B41: 37
B42: 38 | C42: Feito | D42: Feito | F42: Feito | H42: Feito | J42: Feito
...

Sheet 07 02 2021
C3: 44234 | D3: =C3+1 -> 44235 | E3: =D3+1 -> 44236 | F3: =E3+1 -> 44237 | G3: =F3+1 -> 44238 | H3: =G3+1 -> 44239 | I3: =H3+1 -> 44240 | J3: =I3+1 -> 44241
B4: Pivô | C4: =TEXT(C3,"ddd") -> dom | D4: =TEXT(D3,"ddd") -> seg | E4: =TEXT(E3,"ddd") -> ter | F4: =TEXT(F3,"ddd") -> qua | G4: =TEXT(G3,"ddd") -> qui | H4: =TEXT(H3,"ddd") -> sex | I4: =TEXT(I3,"ddd") -> sáb | J4: =TEXT(J3,"ddd") -> dom | L4: Parametros | M4: Contagem | N4: Porcentagem | O4: Semana
B5: 1 | C5: Operação | L5: Feito | M5: =COUNTIF($C$5:$J$60,L5) -> 10 | N5: =M5/$M$11 -> 0.25 | O5: 44234
B6: 2 | C6: Chuva | I6: Feito | L6: Mecânico | M6: =COUNTIF($C$5:$J$60,L6) -> 2 | N6: =M6/$M$11 -> 0.05
B7: 3 | L7: Elétrico | M7: =COUNTIF($C$5:$J$60,L7) -> 1 | N7: =M7/$M$11 -> 0.025
B8: 4 | L8: Energia | M8: =COUNTIF($C$5:$J$60,L8) -> 0 | N8: =M8/$M$11 -> 0
B9: 5 | C9: Chuva | L9: Chuva | M9: =COUNTIF($C$5:$J$60,L9) -> 26 | N9: =M9/$M$11 -> 0.65
B10: 6 | L10: Operação | M10: =COUNTIF($C$5:$J$60,L10) -> 1 | N10: =M10/$M$11 -> 0.025
B11: 7 | C11: Chuva | M11: =SUM(M5:M10) -> 40
B12: 8
B13: 9
B14: 10 | C14: Chuva
B15: 11
B16: 12 | C16: Chuva
B17: 13 | C17: Feito
B18: 14
B19: 15 | C19: Chuva
B20: 16 | C20: Feito
B21: 17 | I21: Feito
B22: 18
B23: 19 | C23: Chuva
B24: 20 | C24: Chuva
B25: 21
B26: 22
B27: 23 | C27: Chuva
B28: 24
B29: 25 | C29: Chuva | I29: Feito
B30: 26
B31: 27 | C31: Chuva
B32: 28
B33: 29 | C33: Feito
B34: 30
B35: 31 | C35: Chuva
B36: 32
B37: 33
B38: 34 | C38: Chuva
B39: 35 | C39: Chuva
B40: 36 | C40: Chuva
B41: 37
B42: 38 | I42: Feito
...

Sheet 15 02 2021
C3: 44242 | D3: =C3+1 -> 44243 | E3: =D3+1 -> 44244 | F3: =E3+1 -> 44245 | G3: =F3+1 -> 44246 | H3: =G3+1 -> 44247 | I3: =H3+1 -> 44248 | J3: =I3+1 -> 44249
B4: Pivô | C4: =TEXT(C3,"ddd") -> seg | D4: =TEXT(D3,"ddd") -> ter | E4: =TEXT(E3,"ddd") -> qua | F4: =TEXT(F3,"ddd") -> qui | G4: =TEXT(G3,"ddd") -> sex | H4: =TEXT(H3,"ddd") -> sáb | I4: =TEXT(I3,"ddd") -> dom | J4: =TEXT(J3,"ddd") -> seg | L4: Parametros | M4: Contagem | N4: Porcentagem | O4: Semana
B5: 1 | L5: Feito | M5: =COUNTIF($C$5:$J$60,L5) -> 9 | N5: =M5/$M$11 -> 0.5 | O5: 44242
B6: 2 | C6: Feito | J6: Feito | L6: Mecânico | M6: =COUNTIF($C$5:$J$60,L6) -> 6 | N6: =M6/$M$11 -> 0.33333333
B7: 3 | E7: Feito | F7: Feito | L7: Elétrico | M7: =COUNTIF($C$5:$J$60,L7) -> 0 | N7: =M7/$M$11 -> 0
B8: 4 | L8: Energia | M8: =COUNTIF($C$5:$J$60,L8) -> 0 | N8: =M8/$M$11 -> 0
B9: 5 | L9: Chuva | M9: =COUNTIF($C$5:$J$60,L9) -> 1 | N9: =M9/$M$11 -> 0.055555556
B10: 6 | L10: Operação | M10: =COUNTIF($C$5:$J$60,L10) -> 2 | N10: =M10/$M$11 -> 0.11111111
B11: 7 | M11: =SUM(M5:M10) -> 18
B12: 8
B13: 9
B14: 10
B15: 11
B16: 12
B17: 13
B18: 14
B19: 15
B20: 16
B21: 17
B22: 18 | J22: Feito
B23: 19 | C23: Chuva | G23: Feito
B24: 20 | F24: Operação
B25: 21
B26: 22
B27: 23
B28: 24 | E28: Mecânico
B29: 25 | C29: Feito
B30: 26
B31: 27
B32: 28
B33: 29 | C33: Feito | D33: Feito
B34: 30
B35: 31
B36: 32 | C36: Mecânico | D36: Mecânico | E36: Mecânico | F36: Mecânico | G36: Mecânico | J36: Operação
B37: 33
B38: 34
B39: 35
B40: 36
B41: 37
B42: 38
...

Sheet 23 02 2021
C3: 44250 | D3: =C3+1 -> 44251 | E3: =D3+1 -> 44252 | F3: =E3+1 -> 44253 | G3: =F3+1 -> 44254 | H3: =G3+1 -> 44255 | I3: =H3+1 -> 44256 | J3: =I3+1 -> 44257
B4: Pivô | C4: =TEXT(C3,"ddd") -> ter | D4: =TEXT(D3,"ddd") -> qua | E4: =TEXT(E3,"ddd") -> qui | F4: =TEXT(F3,"ddd") -> sex | G4: =TEXT(G3,"ddd") -> sáb | H4: =TEXT(H3,"ddd") -> dom | I4: =TEXT(I3,"ddd") -> seg | J4: =TEXT(J3,"ddd") -> ter | L4: Parametros | M4: Contagem | N4: Porcentagem | O4: Semana
B5: 1 | L5: Feito | M5: =COUNTIF($C$5:$J$60,L5) -> 14 | N5: =M5/$M$11 -> 0.82352941 | O5: =C3 -> 44250
B6: 2 | C6: Feito | J6: Feito | L6: Mecânico | M6: =COUNTIF($C$5:$J$60,L6) -> 1 | N6: =M6/$M$11 -> 0.058823529
B7: 3 | D7: Chuva | E7: Feito | I7: Feito | L7: Elétrico | M7: =COUNTIF($C$5:$J$60,L7) -> 1 | N7: =M7/$M$11 -> 0.058823529
B8: 4 | L8: Energia | M8: =COUNTIF($C$5:$J$60,L8) -> 0 | N8: =M8/$M$11 -> 0
B9: 5 | L9: Chuva | M9: =COUNTIF($C$5:$J$60,L9) -> 1 | N9: =M9/$M$11 -> 0.058823529
B10: 6 | L10: Operação | M10: =COUNTIF($C$5:$J$60,L10) -> 0 | N10: =M10/$M$11 -> 0
B11: 7 | M11: =SUM(M5:M10) -> 17
B12: 8
B13: 9
B14: 10
B15: 11
B16: 12
B17: 13
B18: 14
B19: 15
B20: 16 | D20: Feito | E20: Feito
B21: 17
B22: 18 | C22: Feito
B23: 19
B24: 20
B25: 21
B26: 22 | D26: Feito | E26: Feito
B27: 23
B28: 24 | F28: Mecânico | J28: Elétrico
B29: 25 | D29: Feito
B30: 26
B31: 27
B32: 28 | F32: Feito
B33: 29 | D33: Feito | I33: Feito
B34: 30
B35: 31
B36: 32 | C36: Feito
B37: 33
B38: 34
B39: 35
B40: 36
B41: 37
B42: 38
...

Sheet 03 03 2021
C3: 44258 | D3: =C3+1 -> 44259 | E3: =D3+1 -> 44260 | F3: =E3+1 -> 44261 | G3: =F3+1 -> 44262 | H3: =G3+1 -> 44263 | I3: =H3+1 -> 44264 | J3: =I3+1 -> 44265
B4: Pivô | C4: =TEXT(C3,"ddd") -> qua | D4: =TEXT(D3,"ddd") -> qui | E4: =TEXT(E3,"ddd") -> sex | F4: =TEXT(F3,"ddd") -> sáb | G4: =TEXT(G3,"ddd") -> dom | H4: =TEXT(H3,"ddd") -> seg | I4: =TEXT(I3,"ddd") -> ter | J4: =TEXT(J3,"ddd") -> qua | L4: Parametros | M4: Contagem | N4: Porcentagem | O4: Semana
B5: 1 | D5: Feito | G5: Feito | L5: Feito | M5: =COUNTIF($C$5:$J$60,L5) -> 75 | N5: =M5/$M$11 -> 0.59055118 | O5: 44258
B6: 2 | C6: Feito | E6: Operação | G6: Feito | J6: Feito | L6: Mecânico | M6: =COUNTIF($C$5:$J$60,L6) -> 12 | N6: =M6/$M$11 -> 0.094488189
B7: 3 | D7: Feito | E7: Feito | F7: Feito | H7: Feito | L7: Elétrico | M7: =COUNTIF($C$5:$J$60,L7) -> 15 | N7: =M7/$M$11 -> 0.11811024
B8: 4 | D8: Feito | E8: Feito | F8: Feito | G8: Feito | H8: Feito | J8: Chuva | L8: Energia | M8: =COUNTIF($C$5:$J$60,L8) -> 2 | N8: =M8/$M$11 -> 0.015748031
B9: 5 | L9: Chuva | M9: =COUNTIF($C$5:$J$60,L9) -> 11 | N9: =M9/$M$11 -> 0.086614173
B10: 6 | L10: Operação | M10: =COUNTIF($C$5:$J$60,L10) -> 12 | N10: =M10/$M$11 -> 0.094488189
B11: 7 | M11: =SUM(M5:M10) -> 127
B12: 8
B13: 9
B14: 10
B15: 11
B16: 12
B17: 13 | D17: Feito | E17: Feito | F17: Feito | G17: Feito
B18: 14 | D18: Feito | F18: Mecânico | H18: Mecânico | I18: Chuva | J18: Feito
B19: 15 | E19: Feito
B20: 16 | E20: Feito | F20: Feito
B21: 17 | D21: Feito | F21: Elétrico
B22: 18 | D22: Operação | E22: Mecânico | F22: Mecânico | G22: Feito
B23: 19 | E23: Feito | H23: Chuva
B24: 20 | D24: Operação | G24: Feito
B25: 21 | D25: Elétrico | F25: Elétrico
B26: 22 | E26: Feito | H26: Chuva | J26: Feito
B27: 23 | C27: Feito | F27: Elétrico | H27: Chuva
B28: 24 | C28: Mecânico | G28: Feito
B29: 25 | C29: Feito | D29: Feito | E29: Feito | F29: Feito | G29: Feito | H29: Operação | J29: Chuva
B30: 26 | C30: Feito | F30: Operação
B31: 27 | E31: Feito
B32: 28 | D32: Feito | G32: Feito | H32: Operação | I32: Chuva | J32: Feito
B33: 29 | D33: Feito | F33: Feito
B34: 30 | C34: Feito | E34: Feito | G34: Feito
B35: 31
B36: 32 | D36: Elétrico | E36: Operação | G36: Feito
B37: 33
B38: 34 | F38: Operação | H38: Feito
B39: 35
B40: 36
B41: 37 | G41: Feito | H41: Feito | J41: Feito
B42: 38 | E42: Feito
...

Sheet 11 03 2021
C3: 44266 | D3: =C3+1 -> 44267 | E3: =D3+1 -> 44268 | F3: =E3+1 -> 44269 | G3: =F3+1 -> 44270 | H3: =G3+1 -> 44271 | I3: =H3+1 -> 44272 | J3: =I3+1 -> 44273
B4: Pivô | C4: =TEXT(C3,"ddd") -> qui | D4: =TEXT(D3,"ddd") -> sex | E4: =TEXT(E3,"ddd") -> sáb | F4: =TEXT(F3,"ddd") -> dom | G4: =TEXT(G3,"ddd") -> seg | H4: =TEXT(H3,"ddd") -> ter | I4: =TEXT(I3,"ddd") -> qua | J4: =TEXT(J3,"ddd") -> qui | L4: Parametros | M4: Contagem | N4: Porcentagem | O4: Semana
B5: 1 | F5: Feito | H5: Feito | J5: Feito | L5: Feito | M5: =COUNTIF($C$5:$J$60,L5) -> 93 | N5: =M5/$M$11 -> 0.71538462 | O5: 44266
B6: 2 | G6: Mecânico | L6: Mecânico | M6: =COUNTIF($C$5:$J$60,L6) -> 9 | N6: =M6/$M$11 -> 0.069230769
B7: 3 | C7: Feito | F7: Feito | I7: Feito | L7: Elétrico | M7: =COUNTIF($C$5:$J$60,L7) -> 8 | N7: =M7/$M$11 -> 0.061538462
B8: 4 | D8: Feito | E8: Feito | F8: Feito | G8: Feito | H8: Feito | I8: Feito | J8: Feito | L8: Energia | M8: =COUNTIF($C$5:$J$60,L8) -> 9 | N8: =M8/$M$11 -> 0.069230769
B9: 5 | J9: Operação | L9: Chuva | M9: =COUNTIF($C$5:$J$60,L9) -> 0 | N9: =M9/$M$11 -> 0
B10: 6 | L10: Operação | M10: =COUNTIF($C$5:$J$60,L10) -> 11 | N10: =M10/$M$11 -> 0.084615385
B11: 7 | M11: =SUM(M5:M10) -> 130
B12: 8
B13: 9
B14: 10
B15: 11
B16: 12
B17: 13 | F17: Mecânico | G17: Mecânico | H17: Elétrico | J17: Feito
B18: 14 | C18: Feito | G18: Feito | I18: Feito
B19: 15 | G19: Feito | J19: Feito
B20: 16 | F20: Feito | G20: Feito | I20: Mecânico | J20: Mecânico
B21: 17 | H21: Feito
B22: 18 | F22: Feito | J22: Mecânico
B23: 19 | F23: Feito | H23: Operação | I23: Feito
B24: 20 | D24: Feito | G24: Feito | J24: Feito
B25: 21 | D25: Feito | H25: Energia
B26: 22 | C26: Feito | G26: Feito | J26: Feito
B27: 23 | H27: Energia
B28: 24 | C28: Feito | G28: Feito | I28: Mecânico
B29: 25 | C29: Feito | D29: Feito | F29: Feito | G29: Feito | H29: Feito | I29: Feito | J29: Feito
B30: 26 | H30: Energia
B31: 27 | G31: Feito | J31: Feito
B32: 28 | G32: Feito | J32: Feito
B33: 29 | D33: Feito | F33: Feito | H33: Feito | I33: Feito | J33: Feito
B34: 30 | F34: Feito | H34: Energia | J34: Operação
B35: 31
B36: 32 | F36: Feito | G36: Feito | I36: Feito | J36: Feito
B37: 33
B38: 34 | F38: Feito | H38: Energia | J38: Feito
B39: 35 | H39: Elétrico | I39: Feito | J39: Elétrico
B40: 36
B41: 37 | D41: Feito | E41: Feito | F41: Feito | G41: Feito | H41: Feito | I41: Feito | J41: Feito
B42: 38 | G42: Feito | J42: Operação
...

Sheet 19 03 2021
C3: 44274 | D3: =C3+1 -> 44275 | E3: =D3+1 -> 44276 | F3: =E3+1 -> 44277 | G3: =F3+1 -> 44278 | H3: =G3+1 -> 44279 | I3: =H3+1 -> 44280 | J3: =I3+1 -> 44281
B4: Pivô | C4: =TEXT(C3,"ddd") -> sex | D4: =TEXT(D3,"ddd") -> sáb | E4: =TEXT(E3,"ddd") -> dom | F4: =TEXT(F3,"ddd") -> seg | G4: =TEXT(G3,"ddd") -> ter | H4: =TEXT(H3,"ddd") -> qua | I4: =TEXT(I3,"ddd") -> qui | J4: =TEXT(J3,"ddd") -> sex | L4: Parametros | M4: Contagem | N4: Porcentagem | O4: Semana
B5: 1 | D5: Feito | F5: Feito | J5: Feito | L5: Feito | M5: =COUNTIF($C$5:$J$60,L5) -> 113 | N5: =M5/$M$11 -> 0.59162304 | O5: 44274
B6: 2 | C6: Feito | D6: Feito | E6: Feito | F6: Mecânico | G6: Feito | H6: Operação | J6: Feito | L6: Mecânico | M6: =COUNTIF($C$5:$J$60,L6) -> 23 | N6: =M6/$M$11 -> 0.12041885
B7: 3 | C7: Feito | H7: Feito | I7: Feito | L7: Elétrico | M7: =COUNTIF($C$5:$J$60,L7) -> 18 | N7: =M7/$M$11 -> 0.094240838
B8: 4 | C8: Mecânico | D8: Feito | E8: Feito | G8: Feito | I8: Feito | J8: Feito | L8: Energia | M8: =COUNTIF($C$5:$J$60,L8) -> 0 | N8: =M8/$M$11 -> 0
B9: 5 | I9: Feito | L9: Chuva | M9: =COUNTIF($C$5:$J$60,L9) -> 0 | N9: =M9/$M$11 -> 0
B10: 6 | D10: Elétrico | I10: Feito | L10: Operação | M10: =COUNTIF($C$5:$J$60,L10) -> 37 | N10: =M10/$M$11 -> 0.19371728
B11: 7 | D11: Feito | M11: =SUM(M5:M10) -> 191
B12: 8 | G12: Operação
B13: 9
B14: 10
B15: 11
B16: 12 | I16: Feito | J16: Feito
B17: 13 | D17: Feito
B18: 14 | C18: Mecânico | E18: Feito | H18: Operação | J18: Operação
B19: 15 | C19: Operação | E19: Feito | H19: Feito
B20: 16 | C20: Mecânico | D20: Mecânico | E20: Mecânico | F20: Mecânico | G20: Mecânico | H20: Mecânico | I20: Mecânico | J20: Mecânico
B21: 17 | C21: Feito | E21: Feito | G21: Feito | H21: Feito
B22: 18 | D22: Feito | G22: Feito | J22: Feito
B23: 19 | C23: Feito | F23: Operação | G23: Operação | J23: Feito
B24: 20 | E24: Operação | H24: Feito
B25: 21 | C25: Elétrico | G25: Elétrico | I25: Elétrico
B26: 22 | E26: Operação | I26: Feito
B27: 23 | C27: Elétrico | F27: Elétrico | I27: Elétrico
B28: 24 | D28: Operação | G28: Operação | I28: Operação | J28: Feito
B29: 25 | C29: Feito | D29: Feito | E29: Feito | F29: Feito | G29: Feito | H29: Feito | I29: Feito | J29: Feito
B30: 26 | C30: Feito | F30: Feito | I30: Feito
B31: 27 | C31: Operação | F31: Feito | I31: Feito
B32: 28 | E32: Feito | H32: Operação | I32: Feito | J32: Operação
B33: 29 | C33: Feito | D33: Feito | E33: Feito | F33: Mecânico | G33: Operação | H33: Feito | I33: Feito | J33: Feito
B34: 30 | D34: Operação | E34: Mecânico | F34: Mecânico | G34: Mecânico | H34: Mecânico | I34: Mecânico | J34: Feito
B35: 31
B36: 32 | D36: Feito | E36: Feito | G36: Feito | H36: Mecânico | I36: Mecânico | J36: Mecânico
B37: 33 | I37: Elétrico | J37: Feito
B38: 34 | D38: Operação | G38: Feito | J38: Feito
B39: 35 | C39: Mecânico | D39: Elétrico | E39: Elétrico | F39: Feito | G39: Feito | H39: Feito | I39: Feito | J39: Feito
B40: 36 | D40: Mecânico | F40: Feito | G40: Elétrico | H40: Operação | I40: Feito | J40: Feito
B41: 37 | D41: Operação | E41: Feito | J41: Feito
B42: 38 | E42: Feito | H42: Operação
...

Sheet 27 03 2021
C3: 44282 | D3: =C3+1 -> 44283 | E3: =D3+1 -> 44284 | F3: =E3+1 -> 44285 | G3: =F3+1 -> 44286 | H3: =G3+1 -> 44287 | I3: =H3+1 -> 44288 | J3: =I3+1 -> 44289
B4: Pivô | C4: =TEXT(C3,"ddd") -> sáb | D4: =TEXT(D3,"ddd") -> dom | E4: =TEXT(E3,"ddd") -> seg | F4: =TEXT(F3,"ddd") -> ter | G4: =TEXT(G3,"ddd") -> qua | H4: =TEXT(H3,"ddd") -> qui | I4: =TEXT(I3,"ddd") -> sex | J4: =TEXT(J3,"ddd") -> sáb | L4: Parametros | M4: Contagem | N4: Porcentagem | O4: Semana
B5: 1 | D5: Elétrico | G5: Elétrico | J5: Feito | L5: Feito | M5: =COUNTIF($C$5:$J$60,L5) -> 139 | N5: =M5/$M$11 -> 0.64953271 | O5: 44282
B6: 2 | C6: Feito | D6: Feito | E6: Feito | F6: Feito | G6: Feito | H6: Feito | I6: Feito | J6: Feito | L6: Mecânico | M6: =COUNTIF($C$5:$J$60,L6) -> 23 | N6: =M6/$M$11 -> 0.10747664
B7: 3 | D7: Feito | F7: Feito | G7: Feito | L7: Elétrico | M7: =COUNTIF($C$5:$J$60,L7) -> 5 | N7: =M7/$M$11 -> 0.023364486
B8: 4 | E8: Mecânico | G8: Feito | H8: Feito | I8: Feito | L8: Energia | M8: =COUNTIF($C$5:$J$60,L8) -> 0 | N8: =M8/$M$11 -> 0
B9: 5 | D9: Feito | G9: Mecânico | H9: Mecânico | I9: Mecânico | L9: Chuva | M9: =COUNTIF($C$5:$J$60,L9) -> 0 | N9: =M9/$M$11 -> 0
B10: 6 | C10: Feito | I10: Mecânico | J10: Mecânico | L10: Operação | M10: =COUNTIF($C$5:$J$60,L10) -> 47 | N10: =M10/$M$11 -> 0.21962617
B11: 7 | J11: Feito | M11: =SUM(M5:M10) -> 214
B12: 8
B13: 9
B14: 10
B15: 11
B16: 12
B17: 13
B18: 14 | C18: Feito | E18: Feito | I18: Feito
B19: 15 | D19: Mecânico | G19: Feito | H19: Operação | J19: Feito
B20: 16 | C20: Mecânico | D20: Mecânico | E20: Mecânico | F20: Mecânico | G20: Mecânico | H20: Mecânico | I20: Operação | J20: Feito
B21: 17 | C21: Feito | F21: Feito | I21: Feito
B22: 18 | E22: Operação | H22: Mecânico | I22: Mecânico | J22: Mecânico
B23: 19 | E23: Feito | F23: Feito | H23: Operação | I23: Feito
B24: 20 | C24: Mecânico | I24: Feito
B25: 21 | D25: Operação | G25: Elétrico | J25: Feito
B26: 22 | D26: Feito | E26: Feito | F26: Feito | H26: Operação
B27: 23 | D27: Operação | E27: Feito | G27: Elétrico | J27: Feito
B28: 24 | D28: Feito | G28: Operação | J28: Feito
B29: 25 | C29: Feito | D29: Feito | E29: Feito | F29: Feito | H29: Feito | I29: Feito | J29: Feito
B30: 26 | D30: Feito | J30: Feito
B31: 27 | C31: Operação | E31: Operação | J31: Feito
B32: 28 | E32: Operação | F32: Operação | G32: Feito | H32: Feito | I32: Mecânico | J32: Mecânico
B33: 29 | C33: Feito | D33: Feito | E33: Feito | F33: Feito | G33: Feito | H33: Feito | I33: Feito | J33: Feito
B34: 30 | C34: Feito | D34: Feito | F34: Feito | H34: Feito | J34: Feito
B35: 31 | C35: Feito | D35: Feito | E35: Mecânico | F35: Mecânico | G35: Feito | H35: Feito | I35: Feito | J35: Feito
B36: 32 | C36: Feito | E36: Feito | F36: Feito | H36: Feito | I36: Feito | J36: Mecânico
B37: 33 | C37: Feito | D37: Feito | E37: Feito | F37: Feito | G37: Feito | I37: Feito
B38: 34 | C38: Mecânico | E38: Feito | F38: Feito | H38: Feito | J38: Feito
B39: 35 | C39: Feito | D39: Feito | E39: Feito | F39: Feito | G39: Feito | H39: Feito | I39: Feito | J39: Feito
B40: 36 | C40: Feito | D40: Feito | E40: Feito | F40: Feito | G40: Feito | H40: Feito | I40: Feito | J40: Feito
B41: 37 | F41: Feito | J41: Feito
B42: 38 | C42: Feito | F42: Feito | H42: Operação | I42: Feito
...

Sheet 04 04 2021
C3: 44290 | D3: =C3+1 -> 44291 | E3: =D3+1 -> 44292 | F3: =E3+1 -> 44293 | G3: =F3+1 -> 44294 | H3: =G3+1 -> 44295 | I3: =H3+1 -> 44296 | J3: =I3+1 -> 44297
B4: Pivô | C4: =TEXT(C3,"ddd") -> dom | D4: =TEXT(D3,"ddd") -> seg | E4: =TEXT(E3,"ddd") -> ter | F4: =TEXT(F3,"ddd") -> qua | G4: =TEXT(G3,"ddd") -> qui | H4: =TEXT(H3,"ddd") -> sex | I4: =TEXT(I3,"ddd") -> sáb | J4: =TEXT(J3,"ddd") -> dom | L4: Parametros | M4: Contagem | N4: Porcentagem | O4: Semana
B5: 1 | E5: Feito | L5: Feito | M5: =COUNTIF($C$5:$J$60,L5) -> 49 | N5: =M5/$M$11 -> 0.33561644 | O5: 44290
B6: 2 | C6: Mecânico | D6: Feito | E6: Feito | F6: Chuva | G6: Chuva | L6: Mecânico | M6: =COUNTIF($C$5:$J$60,L6) -> 41 | N6: =M6/$M$11 -> 0.28082192
B7: 3 | C7: Mecânico | E7: Mecânico | F7: Chuva | I7: Operação | L7: Elétrico | M7: =COUNTIF($C$5:$J$60,L7) -> 7 | N7: =M7/$M$11 -> 0.047945205
B8: 4 | D8: Feito | J8: Mecânico | L8: Energia | M8: =COUNTIF($C$5:$J$60,L8) -> 0 | N8: =M8/$M$11 -> 0
B9: 5 | C9: Feito | E9: Feito | L9: Chuva | M9: =COUNTIF($C$5:$J$60,L9) -> 34 | N9: =M9/$M$11 -> 0.23287671
B10: 6 | C10: Feito | D10: Mecânico | E10: Mecânico | H10: Mecânico | I10: Elétrico | J10: Mecânico | L10: Operação | M10: =COUNTIF($C$5:$J$60,L10) -> 15 | N10: =M10/$M$11 -> 0.10273973
B11: 7 | C11: Feito | M11: =SUM(M5:M10) -> 146
B12: 8 | C12: Feito
B13: 9
B14: 10
B15: 11
B16: 12
B17: 13
B18: 14
B19: 15 | E19: Feito | F19: Chuva
B20: 16 | D20: Feito | E20: Feito | F20: Chuva | H20: Mecânico | I20: Mecânico | J20: Mecânico
B21: 17 | D21: Feito
B22: 18 | C22: Mecânico | D22: Mecânico
B23: 19 | C23: Feito | F23: Chuva | H23: Mecânico | I23: Mecânico | J23: Mecânico
B24: 20 | C24: Mecânico | I24: Operação | J24: Operação
B25: 21 | D25: Mecânico | E25: Feito
B26: 22 | C26: Mecânico | D26: Mecânico | E26: Feito | G26: Chuva | I26: Operação | J26: Operação
B27: 23 | E27: Feito | G27: Chuva
B28: 24 | E28: Feito | G28: Chuva | I28: Operação | J28: Operação
B29: 25 | D29: Operação | E29: Feito | G29: Chuva
B30: 26 | E30: Operação | F30: Chuva
B31: 27 | D31: Operação | E31: Operação | G31: Chuva
B32: 28 | C32: Mecânico | D32: Mecânico | E32: Mecânico | H32: Mecânico | I32: Mecânico | J32: Mecânico
B33: 29 | C33: Feito | D33: Feito | E33: Feito | J33: Elétrico
B34: 30 | D34: Feito | F34: Chuva | H34: Elétrico | I34: Mecânico
B35: 31 | C35: Mecânico | D35: Feito | E35: Feito | G35: Chuva | H35: Elétrico | I35: Elétrico | J35: Elétrico
B36: 32 | C36: Feito | D36: Feito | F36: Chuva | H36: Mecânico | I36: Mecânico | J36: Operação
B37: 33 | C37: Mecânico | E37: Mecânico | F37: Chuva
B38: 34 | D38: Feito | G38: Chuva
B39: 35 | C39: Feito | D39: Feito | E39: Feito | F39: Chuva
B40: 36 | C40: Feito | E40: Feito | G40: Chuva
B41: 37 | F41: Chuva | G41: Chuva
B42: 38 | D42: Feito | G42: Chuva
...

Sheet 12 04 2021
C3: 44298 | D3: =C3+1 -> 44299 | E3: =D3+1 -> 44300 | F3: =E3+1 -> 44301 | G3: =F3+1 -> 44302 | H3: =G3+1 -> 44303 | I3: =H3+1 -> 44304 | J3: =I3+1 -> 44305
B4: Pivô | C4: =TEXT(C3,"ddd") -> seg | D4: =TEXT(D3,"ddd") -> ter | E4: =TEXT(E3,"ddd") -> qua | F4: =TEXT(F3,"ddd") -> qui | G4: =TEXT(G3,"ddd") -> sex | H4: =TEXT(H3,"ddd") -> sáb | I4: =TEXT(I3,"ddd") -> dom | J4: =TEXT(J3,"ddd") -> seg | L4: Parametros | M4: Contagem | N4: Porcentagem | O4: Semana
B5: 1 | J5: Chuva | L5: Feito | M5: =COUNTIF($C$5:$J$60,L5) -> 20 | N5: =M5/$M$11 -> 0.25974026 | O5: 44298
B6: 2 | C6: Feito | D6: Feito | J6: Chuva | L6: Mecânico | M6: =COUNTIF($C$5:$J$60,L6) -> 6 | N6: =M6/$M$11 -> 0.077922078
B7: 3 | C7: Feito | J7: Chuva | L7: Elétrico | M7: =COUNTIF($C$5:$J$60,L7) -> 1 | N7: =M7/$M$11 -> 0.012987013
B8: 4 | C8: Feito | D8: Feito | J8: Chuva | L8: Energia | M8: =COUNTIF($C$5:$J$60,L8) -> 0 | N8: =M8/$M$11 -> 0
B9: 5 | C9: Feito | L9: Chuva | M9: =COUNTIF($C$5:$J$60,L9) -> 38 | N9: =M9/$M$11 -> 0.49350649
B10: 6 | C10: Mecânico | J10: Chuva | L10: Operação | M10: =COUNTIF($C$5:$J$60,L10) -> 12 | N10: =M10/$M$11 -> 0.15584416
B11: 7 | J11: Chuva | M11: =SUM(M5:M10) -> 77
B12: 8 | J12: Chuva
B13: 9 | J13: Chuva
B14: 10 | J14: Chuva
B15: 11 | J15: Chuva
B16: 12 | J16: Chuva
B17: 13 | J17: Chuva
B18: 14 | J18: Chuva
B19: 15 | C19: Feito | J19: Chuva
B20: 16 | C20: Mecânico | J20: Chuva
B21: 17 | C21: Feito | J21: Chuva
B22: 18 | C22: Feito | D22: Feito | J22: Chuva
B23: 19 | J23: Chuva
B24: 20 | C24: Operação | D24: Operação | J24: Chuva
B25: 21 | J25: Chuva
B26: 22 | C26: Operação | D26: Operação | J26: Chuva
B27: 23 | C27: Feito | J27: Chuva
B28: 24 | C28: Operação | D28: Operação | J28: Chuva
B29: 25 | D29: Feito | J29: Chuva
B30: 26 | C30: Feito | J30: Chuva
B31: 27 | J31: Chuva
B32: 28 | C32: Mecânico | J32: Chuva
B33: 29 | D33: Mecânico | J33: Chuva
B34: 30 | C34: Elétrico | J34: Chuva
B35: 31 | D35: Mecânico | J35: Chuva
B36: 32 | C36: Mecânico | J36: Chuva
B37: 33 | C37: Feito | J37: Chuva
B38: 34 | D38: Feito | J38: Chuva
B39: 35 | J39: Chuva
B40: 36 | J40: Chuva
B41: 37 | J41: Chuva
B42: 38 | C42: Feito | J42: Chuva
...

Sheet 30 04 2021
B3: 44316 | C3: =B3+1 -> 44317 | D3: =C3+1 -> 44318 | E3: =D3+1 -> 44319 | F3: =E3+1 -> 44320 | G3: =F3+1 -> 44321 | H3: =G3+1 -> 44322 | I3: =H3+1 -> 44323
A4: Pivô | B4: =TEXT(B3,"ddd") -> sex | C4: =TEXT(C3,"ddd") -> sáb | D4: =TEXT(D3,"ddd") -> dom | E4: =TEXT(E3,"ddd") -> seg | F4: =TEXT(F3,"ddd") -> ter | G4: =TEXT(G3,"ddd") -> qua | H4: =TEXT(H3,"ddd") -> qui | I4: =TEXT(I3,"ddd") -> sex | K4: Parametros | L4: Contagem | M4: Porcentagem | N4: Semana
A5: 1 | K5: Feito | L5: =COUNTIF($B$5:$I$60,K5) -> 86 | M5: =L5/$L$11 -> 0.6056338 | N5: 44316
A6: 2 | F6: Feito | K6: Mecânico | L6: =COUNTIF($B$5:$I$60,K6) -> 7 | M6: =L6/$L$11 -> 0.049295775
A7: 3 | F7: Feito | G7: Feito | I7: Feito | K7: Elétrico | L7: =COUNTIF($B$5:$I$60,K7) -> 4 | M7: =L7/$L$11 -> 0.028169014
A8: 4 | B8: Operação | F8: Feito | H8: Elétrico | I8: Feito | K8: Energia | L8: =COUNTIF($B$5:$I$60,K8) -> 0 | M8: =L8/$L$11 -> 0
A9: 5 | B9: Feito | F9: Operação | G9: Feito | H9: Feito | I9: Feito | K9: Chuva | L9: =COUNTIF($B$5:$I$60,K9) -> 0 | M9: =L9/$L$11 -> 0
A10: 6 | F10: Operação | K10: Operação | L10: =COUNTIF($B$5:$I$60,K10) -> 45 | M10: =L10/$L$11 -> 0.31690141
A11: 7 | C11: Feito | D11: Feito | F11: Feito | G11: Feito | H11: Feito | L11: =SUM(L5:L10) -> 142
A12: 8 | B12: Operação | C12: Feito | D12: Feito | E12: Operação | F12: Feito | G12: Feito
A13: 9 | B13: Operação | E13: Feito | F13: Feito | G13: Feito | H13: Mecânico | I13: Feito
A14: 10 | G14: Feito
A15: 11
A16: 12
A17: 13
A18: 14
A19: 15 | B19: Feito | E19: Operação | H19: Operação
A20: 16 | D20: Mecânico | E20: Feito | F20: Operação
A21: 17 | B21: Feito | E21: Operação | H21: Feito
A22: 18 | C22: Operação | D22: Operação | I22: Feito
A23: 19 | D23: Feito | G23: Mecânico
A24: 20 | C24: Operação | D24: Operação | F24: Operação
A25: 21 | D25: Feito | G25: Feito
A26: 22 | D26: Elétrico | G26: Elétrico
A27: 23 | B27: Feito | E27: Operação | H27: Feito
A28: 24 | B28: Operação | C28: Operação | D28: Operação | F28: Operação
A29: 25 | B29: Feito | D29: Feito | E29: Feito | G29: Feito | H29: Feito | I29: Feito
A30: 26 | C30: Feito | F30: Feito | I30: Feito
A31: 27 | C31: Feito | F31: Operação | G31: Operação
A32: 28 | D32: Feito
A33: 29 | B33: Feito | D33: Feito | F33: Feito | H33: Elétrico | I33: Feito
A34: 30
A35: 31 | C35: Feito | F35: Feito | I35: Feito
A36: 32 | B36: Feito | C36: Feito | E36: Feito | F36: Mecânico | H36: Feito | I36: Mecânico
A37: 33 | B37: Feito | E37: Feito | H37: Mecânico | I37: Feito
A38: 34
A39: 35 | C39: Feito | G39: Feito | H39: Operação
A40: 36 | B40: Feito | E40: Feito | F40: Operação | I40: Feito
A41: 37 | B41: Feito | F41: Feito | H41: Feito
A42: 38 | B42: Feito | E42: Operação | H42: Operação | I42: Feito
...

Sheet 08 05 2021
B3: 44324 | C3: =B3+1 -> 44325 | D3: =C3+1 -> 44326 | E3: =D3+1 -> 44327 | F3: =E3+1 -> 44328 | G3: =F3+1 -> 44329 | H3: =G3+1 -> 44330 | I3: =H3+1 -> 44331
A4: Pivô | B4: =TEXT(B3,"ddd") -> sáb | C4: =TEXT(C3,"ddd") -> dom | D4: =TEXT(D3,"ddd") -> seg | E4: =TEXT(E3,"ddd") -> ter | F4: =TEXT(F3,"ddd") -> qua | G4: =TEXT(G3,"ddd") -> qui | H4: =TEXT(H3,"ddd") -> sex | I4: =TEXT(I3,"ddd") -> sáb | K4: Parametros | L4: Contagem | M4: Porcentagem | N4: Semana
A5: 1 | E5: Operação | F5: Operação | G5: Feito | H5: Feito | I5: Feito | K5: Feito | L5: =COUNTIF($B$5:$I$60,K5) -> 109 | M5: =L5/$L$11 -> 0.64880952 | N5: 44324
A6: 2 | C6: Feito | I6: Feito | K6: Mecânico | L6: =COUNTIF($B$5:$I$60,K6) -> 19 | M6: =L6/$L$11 -> 0.11309524
A7: 3 | B7: Feito | D7: Feito | E7: Feito | K7: Elétrico | L7: =COUNTIF($B$5:$I$60,K7) -> 3 | M7: =L7/$L$11 -> 0.017857143
A8: 4 | B8: Feito | C8: Feito | D8: Feito | E8: Feito | F8: Feito | G8: Feito | K8: Energia | L8: =COUNTIF($B$5:$I$60,K8) -> 0 | M8: =L8/$L$11 -> 0
A9: 5 | D9: Feito | G9: Operação | H9: Feito | I9: Feito | K9: Chuva | L9: =COUNTIF($B$5:$I$60,K9) -> 0 | M9: =L9/$L$11 -> 0
A10: 6 | B10: Mecânico | D10: Feito | E10: Feito | F10: Mecânico | I10: Feito | K10: Operação | L10: =COUNTIF($B$5:$I$60,K10) -> 37 | M10: =L10/$L$11 -> 0.2202381
A11: 7 | D11: Feito | G11: Feito | H11: Operação | L11: =SUM(L5:L10) -> 168
A12: 8 | B12: Feito | D12: Feito | G12: Feito | H12: Operação | I12: Feito
A13: 9 | B13: Feito | C13: Feito | D13: Feito | E13: Feito | F13: Mecânico | G13: Mecânico | H13: Feito
A14: 10 | D14: Operação | E14: Elétrico | F14: Feito | G14: Elétrico | H14: Feito | I14: Mecânico
A15: 11 | D15: Operação | I15: Operação
A16: 12
A17: 13
A18: 14
A19: 15 | C19: Feito | F19: Feito
A20: 16 | B20: Feito | D20: Mecânico | E20: Feito | H20: Feito
A21: 17 | C21: Feito | F21: Feito
A22: 18 | D22: Mecânico | G22: Operação
A23: 19 | C23: Feito | F23: Mecânico
A24: 20 | B24: Feito | E24: Mecânico | H24: Feito
A25: 21 | C25: Feito | F25: Operação
A26: 22 | D26: Feito | H26: Feito
A27: 23 | D27: Operação | H27: Feito
A28: 24 | B28: Feito | C28: Operação | F28: Feito
A29: 25 | B29: Feito | C29: Feito | D29: Operação | E29: Operação | F29: Operação | G29: Feito | H29: Feito | I29: Mecânico
A30: 26 | D30: Feito | F30: Operação | G30: Operação | H30: Operação
A31: 27 | B31: Feito | E31: Feito
A32: 28 | B32: Mecânico | F32: Feito
A33: 29 | B33: Feito | C33: Feito | E33: Operação | F33: Operação | G33: Operação | I33: Operação
A34: 30 | E34: Mecânico | F34: Mecânico | G34: Mecânico | H34: Operação
A35: 31 | D35: Feito | I35: Operação
A36: 32 | B36: Mecânico | C36: Mecânico | D36: Mecânico | E36: Feito
A37: 33 | D37: Feito | G37: Operação | I37: Operação
A38: 34
A39: 35 | B39: Operação | D39: Operação | F39: Operação | H39: Feito
A40: 36 | C40: Feito | E40: Operação | G40: Operação | I40: Feito
A41: 37 | B41: Feito | D41: Feito | F41: Feito
A42: 38 | D42: Feito | G42: Feito
...

Sheet 16 05 2021
B3: 44332 | C3: =B3+1 -> 44333 | D3: =C3+1 -> 44334 | E3: =D3+1 -> 44335 | F3: =E3+1 -> 44336 | G3: =F3+1 -> 44337 | H3: =G3+1 -> 44338 | I3: =H3+1 -> 44339
A4: Pivô | B4: =TEXT(B3,"ddd") -> dom | C4: =TEXT(C3,"ddd") -> seg | D4: =TEXT(D3,"ddd") -> ter | E4: =TEXT(E3,"ddd") -> qua | F4: =TEXT(F3,"ddd") -> qui | G4: =TEXT(G3,"ddd") -> sex | H4: =TEXT(H3,"ddd") -> sáb | I4: =TEXT(I3,"ddd") -> dom | K4: Parametros | L4: Contagem | M4: Porcentagem | N4: Semana
A5: 1 | B5: Feito | C5: Feito | I5: Feito | K5: Feito | L5: =COUNTIF($B$5:$I$60,K5) -> 113 | M5: =L5/$L$11 -> 0.68484848 | N5: 44332
A6: 2 | G6: Feito | K6: Mecânico | L6: =COUNTIF($B$5:$I$60,K6) -> 6 | M6: =L6/$L$11 -> 0.036363636
A7: 3 | B7: Feito | C7: Feito | H7: Feito | I7: Feito | K7: Elétrico | L7: =COUNTIF($B$5:$I$60,K7) -> 5 | M7: =L7/$L$11 -> 0.03030303
A8: 4 | B8: Feito | C8: Feito | F8: Feito | G8: Feito | K8: Energia | L8: =COUNTIF($B$5:$I$60,K8) -> 0 | M8: =L8/$L$11 -> 0
A9: 5 | C9: Feito | D9: Feito | F9: Feito | G9: Feito | I9: Feito | K9: Chuva | L9: =COUNTIF($B$5:$I$60,K9) -> 0 | M9: =L9/$L$11 -> 0
A10: 6 | C10: Feito | D10: Feito | E10: Feito | I10: Feito | K10: Operação | L10: =COUNTIF($B$5:$I$60,K10) -> 41 | M10: =L10/$L$11 -> 0.24848485
A11: 7 | B11: Feito | D11: Feito | E11: Feito | L11: =SUM(L5:L10) -> 165
A12: 8 | D12: Operação | E12: Feito | F12: Feito
A13: 9 | B13: Feito | D13: Operação | E13: Operação | G13: Feito
A14: 10 | B14: Feito | C14: Elétrico | D14: Feito | E14: Feito | H14: Feito | I14: Feito
A15: 11 | B15: Feito | C15: Feito | D15: Feito | E15: Feito | F15: Feito | G15: Feito | H15: Feito
A16: 12 | B16: Feito | D16: Feito | H16: Mecânico
A17: 13 | G17: Operação
A18: 14 | E18: Operação | F18: Feito | I18: Feito
A19: 15 | C19: Feito | G19: Elétrico | H19: Elétrico
A20: 16 | D20: Operação | H20: Mecânico
A21: 17 | B21: Feito | F21: Operação
A22: 18 | C22: Feito | G22: Feito
A23: 19 | B23: Feito | F23: Feito
A24: 20 | D24: Operação | E24: Feito | H24: Operação
A25: 21 | B25: Operação | F25: Mecânico
A26: 22 | D26: Mecânico | E26: Feito | H26: Feito
A27: 23 | D27: Feito | H27: Elétrico
A28: 24 | C28: Operação | H28: Feito
A29: 25 | B29: Feito | C29: Feito | D29: Operação | E29: Feito | F29: Feito | G29: Feito | H29: Feito | I29: Feito
A30: 26 | B30: Operação | C30: Operação | D30: Operação | E30: Operação | F30: Feito
A31: 27 | C31: Operação | D31: Operação | E31: Operação | F31: Feito | G31: Feito
A32: 28 | H32: Mecânico
A33: 29 | C33: Feito | E33: Feito | F33: Feito | G33: Feito | I33: Operação
A34: 30 | B34: Operação | C34: Feito | D34: Operação | E34: Operação | F34: Operação | G34: Operação | H34: Feito | I34: Operação
A35: 31 | D35: Operação | G35: Feito
A36: 32 | D36: Operação | E36: Operação
A37: 33 | C37: Feito | F37: Feito | I37: Feito
A38: 34 | F38: Operação | H38: Feito
A39: 35 | B39: Feito | C39: Feito | D39: Feito | E39: Operação | I39: Feito
A40: 36 | C40: Operação | D40: Feito | H40: Mecânico
A41: 37 | B41: Feito | F41: Feito
A42: 38 | B42: Feito | D42: Feito | E42: Operação | F42: Operação
...

Sheet 24 05 2021
B3: 44340 | C3: =B3+1 -> 44341 | D3: =C3+1 -> 44342 | E3: =D3+1 -> 44343 | F3: =E3+1 -> 44344 | G3: =F3+1 -> 44345 | H3: =G3+1 -> 44346 | I3: =H3+1 -> 44347
A4: Pivô | B4: =TEXT(B3,"ddd") -> seg | C4: =TEXT(C3,"ddd") -> ter | D4: =TEXT(D3,"ddd") -> qua | E4: =TEXT(E3,"ddd") -> qui | F4: =TEXT(F3,"ddd") -> sex | G4: =TEXT(G3,"ddd") -> sáb | H4: =TEXT(H3,"ddd") -> dom | I4: =TEXT(I3,"ddd") -> seg | K4: Parametros | L4: Contagem | M4: Porcentagem | N4: Semana
A5: 1 | D5: Feito | F5: Operação | G5: Feito | K5: Feito | L5: =COUNTIF($B$5:$I$60,K5) -> 119 | M5: =L5/$L$11 -> 0.79865772 | N5: 44340
A6: 2 | E6: Feito | K6: Mecânico | L6: =COUNTIF($B$5:$I$60,K6) -> 9 | M6: =L6/$L$11 -> 0.060402685
A7: 3 | F7: Feito | G7: Operação | K7: Elétrico | L7: =COUNTIF($B$5:$I$60,K7) -> 1 | M7: =L7/$L$11 -> 0.0067114094
A8: 4 | C8: Feito | D8: Feito | I8: Feito | K8: Energia | L8: =COUNTIF($B$5:$I$60,K8) -> 0 | M8: =L8/$L$11 -> 0
