Workbook
Name SegmentaçãodeDados_Ano: #N/A
Name SegmentaçãodeDados_Periodo: #N/A
Name SegmentaçãodeDados_Semana: #N/A

Sheet Acumulado
A1: Primeiro Semestre
A2: Parâmetros | B2: 44613 | C2: 44620 | D2: 44627 | E2: 44634 | F2: 44641 | G2: 44648 | H2: 44655 | I2: 44662 | J2: 44669 | K2: 44676 | L2: 44683 | M2: 44690 | N2: 44697 | O2: 44704 | P2: 44711 | Q2: 44718 | R2: 44725 | S2: 44732 | T2: 44739 | U2: Total | V2: Percentual | W2: 44746
A3: Pulverização | B3: ='21 02 2022'!K5 -> 0 | C3: ='28 02 2022'!K5 -> 0 | D3: ='07 03 2022'!K5 -> 5 | E3: ='14 03 2022'!K5 -> 3 | F3: ='21 03 2022'!K5 -> 3 | G3: ='28 03 2022'!K5 -> 3 | H3: ='04 04 2022'!K5 -> 1 | I3: ='11 04 2022'!K5 -> 2 | J3: ='18 04 2022'!K5 -> 1 | K3: ='25 04 2022'!K5 -> 3 | L3: ='02 05 2022'!K5 -> 3 | M3: ='09 05 2022'!K5 -> 3 | N3: ='16 05 2022 '!K5 -> 1 | O3: ='23 05 2022 '!K5 -> 4 | P3: ='30 05 2022 '!K5 -> 2 | Q3: ='06 06 2022 '!K5 -> 2 | R3: ='13 06 2022 '!K5 -> 4 | T3: ='27 06 2022 '!K5 -> 4 | U3: =SUM(B3:T3) -> 44 | V3: =U3/$U$16 -> 0.27329193 | W3: ='04 07 2022 '!K5 -> 1
A4: Adubação | B4: ='21 02 2022'!K6 -> 0 | C4: ='28 02 2022'!K6 -> 4 | D4: ='07 03 2022'!K6 -> 2 | E4: ='14 03 2022'!K6 -> 1 | F4: ='21 03 2022'!K6 -> 0 | G4: ='28 03 2022'!K6 -> 0 | H4: ='04 04 2022'!K6 -> 3 | I4: ='11 04 2022'!K6 -> 1 | J4: ='18 04 2022'!K6 -> 0 | K4: ='25 04 2022'!K6 -> 1 | L4: ='02 05 2022'!K6 -> 0 | M4: ='09 05 2022'!K6 -> 0 | N4: ='16 05 2022 '!K6 -> 0 | O4: ='23 05 2022 '!K6 -> 1 | P4: ='30 05 2022 '!K6 -> 0 | Q4: ='06 06 2022 '!K6 -> 0 | R4: ='13 06 2022 '!K6 -> 0 | T4: ='27 06 2022 '!K6 -> 0 | U4: =SUM(B4:T4) -> 13 | V4: =U4/$U$16 -> 0.080745342 | W4: ='04 07 2022 '!K6 -> 0
A5: Trnasplantio | B5: ='21 02 2022'!K7 -> 0 | C5: ='28 02 2022'!K7 -> 0 | D5: ='07 03 2022'!K7 -> 1 | E5: ='14 03 2022'!K7 -> 0 | F5: ='21 03 2022'!K7 -> 1 | G5: ='28 03 2022'!K7 -> 0 | H5: ='04 04 2022'!K7 -> 0 | I5: ='11 04 2022'!K7 -> 0 | J5: ='18 04 2022'!K7 -> 0 | K5: ='25 04 2022'!K7 -> 0 | L5: ='02 05 2022'!K7 -> 1 | M5: ='09 05 2022'!K7 -> 0 | N5: ='16 05 2022 '!K7 -> 0 | O5: ='23 05 2022 '!K7 -> 1 | P5: ='30 05 2022 '!K7 -> 0 | Q5: ='06 06 2022 '!K7 -> 1 | R5: ='13 06 2022 '!K7 -> 3 | T5: ='27 06 2022 '!K7 -> 1 | U5: =SUM(B5:T5) -> 9 | V5: =U5/$U$16 -> 0.055900621 | W5: ='04 07 2022 '!K7 -> 0
A6: Colheita Tabaco | B6: ='21 02 2022'!K8 -> 0 | C6: ='28 02 2022'!K8 -> 0 | D6: ='07 03 2022'!K8 -> 0 | E6: ='14 03 2022'!K8 -> 0 | F6: ='21 03 2022'!K8 -> 0 | G6: ='28 03 2022'!K8 -> 0 | H6: ='04 04 2022'!K8 -> 0 | I6: ='11 04 2022'!K8 -> 0 | J6: ='18 04 2022'!K8 -> 0 | K6: ='25 04 2022'!K8 -> 0 | L6: ='02 05 2022'!K8 -> 0 | M6: ='09 05 2022'!K8 -> 0 | N6: ='16 05 2022 '!K8 -> 0 | O6: ='23 05 2022 '!K8 -> 0 | P6: ='30 05 2022 '!K8 -> 0 | Q6: ='06 06 2022 '!K8 -> 0 | R6: ='13 06 2022 '!K8 -> 0 | T6: ='27 06 2022 '!K8 -> 0 | U6: =SUM(B6:T6) -> 0 | V6: =U6/$U$16 -> 0 | W6: ='04 07 2022 '!K8 -> 1
A7: Pantio | B7: ='21 02 2022'!K9 -> 0 | C7: ='28 02 2022'!K9 -> 0 | D7: ='07 03 2022'!K9 -> 0 | E7: ='14 03 2022'!K9 -> 0 | F7: ='21 03 2022'!K9 -> 0 | G7: ='28 03 2022'!K9 -> 0 | H7: ='04 04 2022'!K9 -> 1 | I7: ='11 04 2022'!K9 -> 0 | J7: ='18 04 2022'!K9 -> 0 | K7: ='25 04 2022'!K9 -> 0 | L7: ='02 05 2022'!K9 -> 0 | M7: ='09 05 2022'!K9 -> 0 | N7: ='16 05 2022 '!K9 -> 0 | O7: ='23 05 2022 '!K9 -> 0 | P7: ='30 05 2022 '!K9 -> 0 | Q7: ='06 06 2022 '!K9 -> 0 | R7: ='13 06 2022 '!K9 -> 0 | T7: ='27 06 2022 '!K9 -> 0 | U7: =SUM(B7:T7) -> 1 | V7: =U7/$U$16 -> 0.0062111801 | W7: ='04 07 2022 '!K9 -> 0
A8: Erosão | B8: ='21 02 2022'!K10 -> 0 | C8: ='28 02 2022'!K10 -> 5 | D8: ='07 03 2022'!K10 -> 2 | E8: ='14 03 2022'!K10 -> 1 | F8: ='21 03 2022'!K10 -> 1 | G8: ='28 03 2022'!K10 -> 0 | H8: ='04 04 2022'!K10 -> 0 | I8: ='11 04 2022'!K10 -> 0 | J8: ='18 04 2022'!K10 -> 0 | K8: ='25 04 2022'!K10 -> 0 | L8: ='02 05 2022'!K10 -> 0 | M8: ='09 05 2022'!K10 -> 0 | N8: ='16 05 2022 '!K10 -> 0 | O8: ='23 05 2022 '!K10 -> 0 | P8: ='30 05 2022 '!K10 -> 0 | Q8: ='06 06 2022 '!K10 -> 0 | R8: ='13 06 2022 '!K10 -> 0 | T8: ='27 06 2022 '!K10 -> 0 | U8: =SUM(B8:T8) -> 9 | V8: =U8/$U$16 -> 0.055900621 | W8: ='04 07 2022 '!K10 -> 0
A9: Mecânico/Trator | B9: ='21 02 2022'!K11 -> 4 | C9: ='28 02 2022'!K11 -> 1 | D9: ='07 03 2022'!K11 -> 1 | E9: ='14 03 2022'!K11 -> 0 | F9: ='21 03 2022'!K11 -> 0 | G9: ='28 03 2022'!K11 -> 0 | H9: ='04 04 2022'!K11 -> 0 | I9: ='11 04 2022'!K11 -> 0 | J9: ='18 04 2022'!K11 -> 0 | K9: ='25 04 2022'!K11 -> 1 | L9: ='02 05 2022'!K11 -> 3 | M9: ='09 05 2022'!K11 -> 0 | N9: ='16 05 2022 '!K11 -> 10 | O9: ='23 05 2022 '!K11 -> 0 | P9: ='30 05 2022 '!K11 -> 0 | Q9: ='06 06 2022 '!K11 -> 1 | R9: ='13 06 2022 '!K11 -> 0 | T9: ='27 06 2022 '!K11 -> 0 | U9: =SUM(B9:T9) -> 21 | V9: =U9/$U$16 -> 0.13043478 | W9: ='04 07 2022 '!K11 -> 1
A10: Transporte | B10: ='21 02 2022'!K12 -> 0 | C10: ='28 02 2022'!K12 -> 1 | D10: ='07 03 2022'!K12 -> 0 | E10: ='14 03 2022'!K12 -> 0 | F10: ='21 03 2022'!K12 -> 3 | G10: ='28 03 2022'!K12 -> 0 | H10: ='04 04 2022'!K12 -> 0 | I10: ='11 04 2022'!K12 -> 0 | J10: ='18 04 2022'!K12 -> 0 | K10: ='25 04 2022'!K12 -> 0 | L10: ='02 05 2022'!K12 -> 1 | M10: ='09 05 2022'!K12 -> 0 | N10: ='16 05 2022 '!K12 -> 0 | O10: ='23 05 2022 '!K12 -> 0 | P10: ='30 05 2022 '!K12 -> 0 | Q10: ='06 06 2022 '!K12 -> 0 | R10: ='13 06 2022 '!K12 -> 0 | T10: ='27 06 2022 '!K12 -> 0 | U10: =SUM(B10:T10) -> 5 | V10: =U10/$U$16 -> 0.031055901 | W10: ='04 07 2022 '!K12 -> 0
A11: Pivô Atolado | B11: ='21 02 2022'!K13 -> 3 | C11: ='28 02 2022'!K13 -> 4 | D11: ='07 03 2022'!K13 -> 2 | E11: ='14 03 2022'!K13 -> 2 | F11: ='21 03 2022'!K13 -> 1 | G11: ='28 03 2022'!K13 -> 0 | H11: ='04 04 2022'!K13 -> 1 | I11: ='11 04 2022'!K13 -> 0 | J11: ='18 04 2022'!K13 -> 0 | K11: ='25 04 2022'!K13 -> 0 | L11: ='02 05 2022'!K13 -> 0 | M11: ='09 05 2022'!K13 -> 1 | N11: ='16 05 2022 '!K13 -> 0 | O11: ='23 05 2022 '!K13 -> 3 | P11: ='30 05 2022 '!K13 -> 2 | Q11: ='06 06 2022 '!K13 -> 0 | R11: ='13 06 2022 '!K13 -> 1 | T11: ='27 06 2022 '!K13 -> 0 | U11: =SUM(B11:T11) -> 20 | V11: =U11/$U$16 -> 0.1242236 | W11: ='04 07 2022 '!K13 -> 0
A12: Entrega do Produto | B12: ='21 02 2022'!K14 -> 0 | C12: ='28 02 2022'!K14 -> 1 | D12: ='07 03 2022'!K14 -> 5 | E12: ='14 03 2022'!K14 -> 1 | F12: ='21 03 2022'!K14 -> 2 | G12: ='28 03 2022'!K14 -> 3 | H12: ='04 04 2022'!K14 -> 0 | I12: ='11 04 2022'!K14 -> 0 | J12: ='18 04 2022'!K14 -> 0 | K12: ='25 04 2022'!K14 -> 0 | L12: ='02 05 2022'!K14 -> 0 | M12: ='09 05 2022'!K14 -> 0 | N12: ='16 05 2022 '!K14 -> 0 | O12: ='23 05 2022 '!K14 -> 0 | P12: ='30 05 2022 '!K14 -> 2 | Q12: ='06 06 2022 '!K14 -> 0 | R12: ='13 06 2022 '!K14 -> 0 | T12: ='27 06 2022 '!K14 -> 0 | U12: =SUM(B12:T12) -> 14 | V12: =U12/$U$16 -> 0.086956522 | W12: ='04 07 2022 '!K14 -> 1
A13: Limpeza e Aferições | D13: ='07 03 2022'!K15 -> 1 | E13: ='14 03 2022'!K15 -> 0 | F13: ='21 03 2022'!K15 -> 0 | G13: ='28 03 2022'!K15 -> 0 | H13: ='04 04 2022'!K15 -> 0 | I13: ='11 04 2022'!K15 -> 0 | J13: ='18 04 2022'!K15 -> 0 | K13: ='25 04 2022'!K15 -> 0 | L13: ='02 05 2022'!K15 -> 0 | M13: ='09 05 2022'!K15 -> 0 | N13: ='16 05 2022 '!K15 -> 0 | O13: ='23 05 2022 '!K15 -> 0 | P13: ='30 05 2022 '!K15 -> 0 | Q13: ='06 06 2022 '!K15 -> 1 | R13: ='13 06 2022 '!K15 -> 0 | T13: ='27 06 2022 '!K15 -> 0 | U13: =SUM(B13:T13) -> 2 | V13: =U13/$U$16 -> 0.01242236 | W13: ='04 07 2022 '!K15 -> 0
A14: Falta de Água | K14: ='25 04 2022'!K16 -> 3 | L14: ='02 05 2022'!K16 -> 9 | M14: ='09 05 2022'!K16 -> 7 | N14: ='16 05 2022 '!K16 -> 0 | O14: ='23 05 2022 '!K16 -> 0 | P14: ='30 05 2022 '!K16 -> 0 | Q14: ='06 06 2022 '!K16 -> 0 | R14: ='13 06 2022 '!K16 -> 0 | T14: ='27 06 2022 '!K16 -> 0 | U14: =SUM(B14:T14) -> 19 | V14: =U14/$U$16 -> 0.11801242 | W14: ='04 07 2022 '!K16 -> 0
A15: Desponte | O15: ='23 05 2022 '!K17 -> 1 | P15: ='30 05 2022 '!K17 -> 0 | Q15: ='06 06 2022 '!K17 -> 0 | R15: ='13 06 2022 '!K17 -> 0 | T15: ='27 06 2022 '!K17 -> 3 | U15: =SUM(B15:T15) -> 4 | V15: =U15/$U$16 -> 0.02484472 | W15: ='04 07 2022 '!K17 -> 3
A16: Total | B16: =SUM(B3:B15) -> 7 | C16: =SUM(C3:C15) -> 16 | D16: =SUM(D3:D15) -> 19 | E16: =SUM(E3:E15) -> 8 | F16: =SUM(F3:F15) -> 11 | G16: =SUM(G3:G15) -> 6 | H16: =SUM(H3:H15) -> 6 | I16: =SUM(I3:I15) -> 3 | ... U16: =SUM(U3:U15) -> 161

Sheet 21 02 2022
A1: Atendimento de irrigação (Imapacto Operacional Interno e Externo) - Semena 21/02/2022
A3: Data | B3: 44613 | C3: =B3+1 -> 44614 | D3: =C3+1 -> 44615 | E3: =D3+1 -> 44616 | F3: =E3+1 -> 44617 | G3: =F3+1 -> 44618 | H3: =G3+1 -> 44619
A4: Pivô | B4: =TEXT(B3,"ddd") -> seg | C4: =TEXT(C3,"ddd") -> ter | D4: =TEXT(D3,"ddd") -> qua | E4: =TEXT(E3,"ddd") -> qui | F4: =TEXT(F3,"ddd") -> sex | G4: =TEXT(G3,"ddd") -> sáb | H4: =TEXT(H3,"ddd") -> dom | J4: Parâmetros | K4: Contagem | L4: Porcentagem | M4: Semana
A5: Pivô 01 | J5: Pulverização | K5: =COUNTIF($B$5:$H$93,J5) -> 0 | L5: =K5/$K$16 -> 0 | M5: 21/02-27/2
A6: Pivô 02 | J6: Adubação | K6: =COUNTIF($B$5:$H$93,J6) -> 0 | L6: =K6/$K$16 -> 0
A7: Pivô 03 | J7: Trnaspantio | K7: =COUNTIF($B$5:$H$93,J7) -> 0 | L7: =K7/$K$16 -> 0
A8: Pivô 04 | J8: Colheita Tabaco | K8: =COUNTIF($B$5:$H$93,J8) -> 0 | L8: =K8/$K$16 -> 0
A9: Pivô 05 | J9: Plantio | K9: =COUNTIF($B$5:$H$93,J9) -> 0 | L9: =K9/$K$16 -> 0
A10: Pivô 06 | J10: Erosão | K10: =COUNTIF($B$5:$H$93,J10) -> 0 | L10: =K10/$K$16 -> 0
A11: Pivô 07 | J11: Mecânico/Trator | K11: =COUNTIF($B$5:$H$93,J11) -> 4 | L11: =K11/$K$16 -> 0.57142857
A12: Pivô 08 | J12: Operação Ferti | K12: =COUNTIF($B$5:$H$93,J12) -> 0 | L12: =K12/$K$16 -> 0
A13: Pivô 09 | J13: Pivô Atolado | K13: =COUNTIF($B$5:$H$93,J13) -> 3 | L13: =K13/$K$16 -> 0.42857143
A14: Pivô 10 | J14: Entrega do Produto | K14: =COUNTIF($B$5:$H$93,J14) -> 0 | L14: =K14/$K$16 -> 0
A15: Pivô 11
A16: Pivô 12 | J16: Total | K16: =SUM(K5:K13) -> 7
A17: Pivô 13
A18: Pivô 14
A19: Pivô 15
A20: Pivô 16
A21: Pivô 17
A22: Pivô 18
A23: Pivô 19
A24: Pivô 20
A25: Pivô 21
A26: Pivô 22 | C26: Pivô Atolado
A27: Pivô 23
A28: Pivô 24
A29: Pivô 25
A30: Pivô 26
A31: Pivô 27
A32: Pivô 28 | E32: Mecânico/Trator | F32: Mecânico/Trator
A33: Pivô 29
A34: Pivô 30
A35: Pivô 31
A36: Pivô 32 | H36: Pivô Atolado
A37: Pivô 33
A38: Pivô 34 | B38: Mecânico/Trator
A39: Pivô 35
A40: Pivô 36
A41: Pivô 37
...

Sheet 28 02 2022
A1: Atendimento de irrigação (Imapacto Operacional Interno e Externo) - Semena 28/02/2022
A3: Data | B3: 44620 | C3: =B3+1 -> 44621 | D3: =C3+1 -> 44622 | E3: =D3+1 -> 44623 | F3: =E3+1 -> 44624 | G3: =F3+1 -> 44625 | H3: =G3+1 -> 44626
A4: Pivô | B4: =TEXT(B3,"ddd") -> seg | C4: =TEXT(C3,"ddd") -> ter | D4: =TEXT(D3,"ddd") -> qua | E4: =TEXT(E3,"ddd") -> qui | F4: =TEXT(F3,"ddd") -> sex | G4: =TEXT(G3,"ddd") -> sáb | H4: =TEXT(H3,"ddd") -> dom | J4: Parâmetros | K4: Contagem | L4: Porcentagem | M4: Semana
A5: Pivô 01 | J5: Pulverização | K5: =COUNTIF($B$5:$H$93,J5) -> 0 | L5: =K5/$K$16 -> 0 | M5: 28/2-6/3
A6: Pivô 02 | J6: Adubação | K6: =COUNTIF($B$5:$H$93,J6) -> 4 | L6: =K6/$K$16 -> 0.25
A7: Pivô 03 | J7: Trnaspantio | K7: =COUNTIF($B$5:$H$93,J7) -> 0 | L7: =K7/$K$16 -> 0
A8: Pivô 04 | J8: Colheita Tabaco | K8: =COUNTIF($B$5:$H$93,J8) -> 0 | L8: =K8/$K$16 -> 0
A9: Pivô 05 | J9: Plantio | K9: =COUNTIF($B$5:$H$93,J9) -> 0 | L9: =K9/$K$16 -> 0
A10: Pivô 06 | J10: Erosão/Rastro | K10: =COUNTIF($B$5:$H$93,J10) -> 5 | L10: =K10/$K$16 -> 0.3125
A11: Pivô 07 | J11: Mecânico/Trator | K11: =COUNTIF($B$5:$H$93,J11) -> 1 | L11: =K11/$K$16 -> 0.0625
A12: Pivô 08 | J12: Operação Ferti | K12: =COUNTIF($B$5:$H$93,J12) -> 1 | L12: =K12/$K$16 -> 0.0625
A13: Pivô 09 | J13: Pivô Atolado | K13: =COUNTIF($B$5:$H$93,J13) -> 4 | L13: =K13/$K$16 -> 0.25
A14: Pivô 10 | J14: Entrega do Produto | K14: =COUNTIF($B$5:$H$93,J14) -> 1 | L14: =K14/$K$16 -> 0.0625
A15: Pivô 11
A16: Pivô 12 | J16: Total | K16: =SUM(K5:K14) -> 16
A17: Pivô 13
A18: Pivô 14
A19: Pivô 15
A20: Pivô 16
A21: Pivô 17
A22: Pivô 18
A23: Pivô 19
A24: Pivô 20
A25: Pivô 21
A26: Pivô 22 | D26: Adubação | G26: Pivô Atolado
A27: Pivô 23
A28: Pivô 24
A29: Pivô 25
A30: Pivô 26
A31: Pivô 27 | C31: Adubação
A32: Pivô 28
A33: Pivô 29
A34: Pivô 30
A35: Pivô 31
A36: Pivô 32 | B36: Pivô Atolado | D36: Erosão/Rastro
A37: Pivô 33
A38: Pivô 34 | B38: Mecânico/Trator | C38: Erosão/Rastro | D38: Erosão/Rastro | E38: Erosão/Rastro | F38: Erosão/Rastro
A39: Pivô 35
A40: Pivô 36
A41: Pivô 37
...

Sheet 07 03 2022
A1: Atendimento de irrigação (Imapacto Operacional Interno e Externo) - Semena 07/03/2022
A3: Data | B3: 44627 | C3: =B3+1 -> 44628 | D3: =C3+1 -> 44629 | E3: =D3+1 -> 44630 | F3: =E3+1 -> 44631 | G3: =F3+1 -> 44632 | H3: =G3+1 -> 44633
A4: Pivô | B4: =TEXT(B3,"ddd") -> seg | C4: =TEXT(C3,"ddd") -> ter | D4: =TEXT(D3,"ddd") -> qua | E4: =TEXT(E3,"ddd") -> qui | F4: =TEXT(F3,"ddd") -> sex | G4: =TEXT(G3,"ddd") -> sáb | H4: =TEXT(H3,"ddd") -> dom | J4: Parâmetros | K4: Contagem | L4: Porcentagem | M4: Semana
A5: Pivô 01 | C5: Entrega do Produto | J5: Pulverização | K5: =COUNTIF($B$5:$H$93,J5) -> 5 | L5: =K5/$K$16 -> 0.26315789 | M5: 7/3-13/3
A6: Pivô 02 | J6: Adubação | K6: =COUNTIF($B$5:$H$93,J6) -> 2 | L6: =K6/$K$16 -> 0.10526316
A7: Pivô 03 | F7: Pulverização | J7: Trnaspantio | K7: =COUNTIF($B$5:$H$93,J7) -> 1 | L7: =K7/$K$16 -> 0.052631579
A8: Pivô 04 | D8: Trnaspantio | J8: Colheita Tabaco | K8: =COUNTIF($B$5:$H$93,J8) -> 0 | L8: =K8/$K$16 -> 0
A9: Pivô 05 | J9: Plantio | K9: =COUNTIF($B$5:$H$93,J9) -> 0 | L9: =K9/$K$16 -> 0
A10: Pivô 06 | J10: Erosão/Rastro | K10: =COUNTIF($B$5:$H$93,J10) -> 2 | L10: =K10/$K$16 -> 0.10526316
A11: Pivô 07 | J11: Mecânico/Trator | K11: =COUNTIF($B$5:$H$93,J11) -> 1 | L11: =K11/$K$16 -> 0.052631579
A12: Pivô 08 | J12: Transporte | K12: =COUNTIF($B$5:$H$93,J12) -> 0 | L12: =K12/$K$16 -> 0
A13: Pivô 09 | J13: Pivô Atolado | K13: =COUNTIF($B$5:$H$93,J13) -> 2 | L13: =K13/$K$16 -> 0.10526316
A14: Pivô 10 | J14: Entrega do Produto | K14: =COUNTIF($B$5:$H$93,J14) -> 5 | L14: =K14/$K$16 -> 0.26315789
A15: Pivô 11 | J15: Limpeza e aferições | K15: =COUNTIF($B$5:$H$93,J15) -> 1 | L15: =K15/$K$16 -> 0.052631579
A16: Pivô 12 | J16: Total | K16: =SUM(K5:K15) -> 19
A17: Pivô 13
A18: Pivô 14
A19: Pivô 15
A20: Pivô 16
A21: Pivô 17
A22: Pivô 18
A23: Pivô 19
A24: Pivô 20
A25: Pivô 21
A26: Pivô 22
A27: Pivô 23 | G27: Adubação
A28: Pivô 24
A29: Pivô 25
A30: Pivô 26 | C30: Entrega do Produto | D30: Entrega do Produto | G30: Pulverização
A31: Pivô 27 | C31: Limpeza e aferições
A32: Pivô 28 | E32: Pulverização
A33: Pivô 29
A34: Pivô 30
A35: Pivô 31 | E35: Mecânico/Trator
A36: Pivô 32
A37: Pivô 33 | B37: Erosão/Rastro
A38: Pivô 34
A39: Pivô 35
A40: Pivô 36
A41: Pivô 37
...

Sheet 14 03 2022
A1: Atendimento de irrigação (Imapacto Operacional Interno e Externo) - Semena 14/03/2022
A3: Data | B3: 44634 | C3: =B3+1 -> 44635 | D3: =C3+1 -> 44636 | E3: =D3+1 -> 44637 | F3: =E3+1 -> 44638 | G3: =F3+1 -> 44639 | H3: =G3+1 -> 44640
A4: Pivô | B4: =TEXT(B3,"ddd") -> seg | C4: =TEXT(C3,"ddd") -> ter | D4: =TEXT(D3,"ddd") -> qua | E4: =TEXT(E3,"ddd") -> qui | F4: =TEXT(F3,"ddd") -> sex | G4: =TEXT(G3,"ddd") -> sáb | H4: =TEXT(H3,"ddd") -> dom | J4: Parâmetros | K4: Contegem | L4: Porcentagem | M4: Semana
A5: Pivô 01 | J5: Pulverização | K5: =COUNTIF($B$5:$H$93,J5) -> 3 | L5: =K5/$K$16 -> 0.375 | M5: 14/3-20/3
A6: Pivô 02 | J6: Adubação | K6: =COUNTIF($B$5:$H$93,J6) -> 1 | L6: =K6/$K$16 -> 0.125
A7: Pivô 03 | G7: Adubação | J7: Trnaspantio | K7: =COUNTIF($B$5:$H$93,J7) -> 0 | L7: =K7/$K$16 -> 0
A8: Pivô 04 | J8: Colheita Tabaco | K8: =COUNTIF($B$5:$H$93,J8) -> 0 | L8: =K8/$K$16 -> 0
A9: Pivô 05 | J9: Plantio | K9: =COUNTIF($B$5:$H$93,J9) -> 0 | L9: =K9/$K$16 -> 0
A10: Pivô 06 | J10: Erosão/Rastro | K10: =COUNTIF($B$5:$H$93,J10) -> 1 | L10: =K10/$K$16 -> 0.125
A11: Pivô 07 | J11: Mecânico/Trator | K11: =COUNTIF($B$5:$H$93,J11) -> 0 | L11: =K11/$K$16 -> 0
A12: Pivô 08 | J12: Transporte | K12: =COUNTIF($B$5:$H$93,J12) -> 0 | L12: =K12/$K$16 -> 0
A13: Pivô 09 | J13: Pivô Atolado | K13: =COUNTIF($B$5:$H$93,J13) -> 2 | L13: =K13/$K$16 -> 0.25
A14: Pivô 10 | J14: Entrega do Produto | K14: =COUNTIF($B$5:$H$93,J14) -> 1 | L14: =K14/$K$16 -> 0.125
A15: Pivô 11 | J15: Limpeza e aferições | K15: =COUNTIF($B$5:$H$93,J15) -> 0 | L15: =K15/$K$16 -> 0
A16: Pivô 12 | J16: Total | K16: =SUM(K5:K15) -> 8
A17: Pivô 13
A18: Pivô 14
A19: Pivô 15
A20: Pivô 16
A21: Pivô 17
A22: Pivô 18 | D22: Pulverização
A23: Pivô 19
A24: Pivô 20 | D24: Pulverização
A25: Pivô 21
A26: Pivô 22 | E26: Pivô Atolado
A27: Pivô 23
A28: Pivô 24
A29: Pivô 25
A30: Pivô 26
A31: Pivô 27
A32: Pivô 28
A33: Pivô 29
A34: Pivô 30 | B34: Entrega do Produto
A35: Pivô 31
A36: Pivô 32
A37: Pivô 33
A38: Pivô 34
A39: Pivô 35
A40: Pivô 36
A41: Pivô 37
...

Sheet 21 03 2022
A1: Atendimento de irrigação (Imapacto Operacional Interno e Externo) - Semena 21/03/2022
A3: Data | B3: 44641 | C3: =B3+1 -> 44642 | D3: =C3+1 -> 44643 | E3: =D3+1 -> 44644 | F3: =E3+1 -> 44645 | G3: =F3+1 -> 44646 | H3: =G3+1 -> 44647
A4: Pivô | B4: =TEXT(B3,"ddd") -> seg | C4: =TEXT(C3,"ddd") -> ter | D4: =TEXT(D3,"ddd") -> qua | E4: =TEXT(E3,"ddd") -> qui | F4: =TEXT(F3,"ddd") -> sex | G4: =TEXT(G3,"ddd") -> sáb | H4: =TEXT(H3,"ddd") -> dom | J4: Parâmetros | K4: Contegem | L4: Porcentagem | M4: Semana
A5: Pivô 01 | J5: Pulverização | K5: =COUNTIF($B$5:$H$93,J5) -> 3 | L5: =K5/$K$16 -> 0.27272727 | M5: 21/3-27/3
A6: Pivô 02 | J6: Adubação | K6: =COUNTIF($B$5:$H$93,J6) -> 0 | L6: =K6/$K$16 -> 0
A7: Pivô 03 | J7: Transplantio | K7: =COUNTIF($B$5:$H$93,J7) -> 1 | L7: =K7/$K$16 -> 0.090909091
A8: Pivô 04 | J8: Colheita Tabaco | K8: =COUNTIF($B$5:$H$93,J8) -> 0 | L8: =K8/$K$16 -> 0
A9: Pivô 05 | J9: Plantio | K9: =COUNTIF($B$5:$H$93,J9) -> 0 | L9: =K9/$K$16 -> 0
A10: Pivô 06 | J10: Erosão/Rastro | K10: =COUNTIF($B$5:$H$93,J10) -> 1 | L10: =K10/$K$16 -> 0.090909091
A11: Pivô 07 | J11: Mecânico/Trator | K11: =COUNTIF($B$5:$H$93,J11) -> 0 | L11: =K11/$K$16 -> 0
A12: Pivô 08 | J12: Transporte | K12: =COUNTIF($B$5:$H$93,J12) -> 3 | L12: =K12/$K$16 -> 0.27272727
A13: Pivô 09 | J13: Pivô Atolado | K13: =COUNTIF($B$5:$H$93,J13) -> 1 | L13: =K13/$K$16 -> 0.090909091
A14: Pivô 10 | J14: Entrega do Produto | K14: =COUNTIF($B$5:$H$93,J14) -> 2 | L14: =K14/$K$16 -> 0.18181818
A15: Pivô 11 | J15: Limpeza e aferições | K15: =COUNTIF($B$5:$H$93,J15) -> 0 | L15: =K15/$K$16 -> 0
A16: Pivô 12 | J16: Total | K16: =SUM(K5:K15) -> 11
A17: Pivô 13
A18: Pivô 14
A19: Pivô 15
A20: Pivô 16
A21: Pivô 17
A22: Pivô 18
A23: Pivô 19
A24: Pivô 20
A25: Pivô 21
A26: Pivô 22
A27: Pivô 23
A28: Pivô 24
... A30: Pivô 26
A31: Pivô 27 | F31: Pulverização
A32: Pivô 28
A33: Pivô 29
A34: Pivô 30
A35: Pivô 31
A36: Pivô 32
A37: Pivô 33
A38: Pivô 34
A39: Pivô 35 | D39: Transplantio
A40: Pivô 36
A41: Pivô 37
A42: Pivô 38
...

Sheet 28 03 2022
A1: Atendimento de irrigação (Imapacto Operacional Interno e Externo) - Semena 28/03/2022
A3: Data | B3: 44648 | C3: =B3+1 -> 44649 | D3: =C3+1 -> 44650 | E3: =D3+1 -> 44651 | F3: =E3+1 -> 44652 | G3: =F3+1 -> 44653 | H3: =G3+1 -> 44654
A4: Pivô | B4: =TEXT(B3,"ddd") -> seg | C4: =TEXT(C3,"ddd") -> ter | D4: =TEXT(D3,"ddd") -> qua | E4: =TEXT(E3,"ddd") -> qui | F4: =TEXT(F3,"ddd") -> sex | G4: =TEXT(G3,"ddd") -> sáb | H4: =TEXT(H3,"ddd") -> dom | J4: Parâmetros | K4: Contagem | L4: Porcentagem | M4: Semana
A5: Pivô 01 | J5: Pulverização | K5: =COUNTIF($B$5:$H$93,J5) -> 3 | L5: =K5/$K$16 -> 0.5 | M5: 28/3-3/4
A6: Pivô 02 | J6: Adubação | K6: =COUNTIF($B$5:$H$93,J6) -> 0 | L6: =K6/$K$16 -> 0
A7: Pivô 03 | J7: Transplantio | K7: =COUNTIF($B$5:$H$93,J7) -> 0 | L7: =K7/$K$16 -> 0
A8: Pivô 04 | J8: Colheita Tabaco | K8: =COUNTIF($B$5:$H$93,J8) -> 0 | L8: =K8/$K$16 -> 0
A9: Pivô 05 | J9: Plantio | K9: =COUNTIF($B$5:$H$93,J9) -> 0 | L9: =K9/$K$16 -> 0
A10: Pivô 06 | J10: Erosão/Rastro | K10: =COUNTIF($B$5:$H$93,J10) -> 0 | L10: =K10/$K$16 -> 0
A11: Pivô 07 | J11: Mecânico/Trator | K11: =COUNTIF($B$5:$H$93,J11) -> 0 | L11: =K11/$K$16 -> 0
A12: Pivô 08 | J12: Transporte | K12: =COUNTIF($B$5:$H$93,J12) -> 0 | L12: =K12/$K$16 -> 0
A13: Pivô 09 | J13: Pivô Atolado | K13: =COUNTIF($B$5:$H$93,J13) -> 0 | L13: =K13/$K$16 -> 0
A14: Pivô 10 | J14: Entrega do Produto | K14: =COUNTIF($B$5:$H$93,J14) -> 3 | L14: =K14/$K$16 -> 0.5
A15: Pivô 11 | J15: Limpeza e aferições | K15: =COUNTIF($B$5:$H$93,J15) -> 0 | L15: =K15/$K$16 -> 0
A16: Pivô 12 | J16: Total | K16: =SUM(K5:K15) -> 6
A17: Pivô 13
A18: Pivô 14
A19: Pivô 15 | C19: Entrega do Produto
A20: Pivô 16 | D20: Entrega do Produto | E20: Entrega do Produto
A21: Pivô 17
A22: Pivô 18
A23: Pivô 19
A24: Pivô 20
A25: Pivô 21
A26: Pivô 22
A27: Pivô 23
A28: Pivô 24
A29: Pivô 25
A30: Pivô 26
A31: Pivô 27
A32: Pivô 28
... A53: Pivô 49
A54: Pivô 50 | F54: Pulverização
A55: Pivô 51
A56: Pivô 52
A57: Pivô 53 | E57: Pulverização
A58: Pivô 54
A59: Pivô 55
A60: Pivô 56
A61: Pivô 73
...

Sheet 04 04 2022
A1: Atendimento de irrigação (Imapacto Operacional Interno e Externo) - Semena 04/04/2022
A3: Data | B3: 44655 | C3: =B3+1 -> 44656 | D3: =C3+1 -> 44657 | E3: =D3+1 -> 44658 | F3: =E3+1 -> 44659 | G3: =F3+1 -> 44660 | H3: =G3+1 -> 44661
A4: Pivô | B4: =TEXT(B3,"ddd") -> seg | C4: =TEXT(C3,"ddd") -> ter | D4: =TEXT(D3,"ddd") -> qua | E4: =TEXT(E3,"ddd") -> qui | F4: =TEXT(F3,"ddd") -> sex | G4: =TEXT(G3,"ddd") -> sáb | H4: =TEXT(H3,"ddd") -> dom | J4: Parâmetros | K4: Contagem | L4: Porcentagem | M4: Semana
A5: Pivô 01 | J5: Pulverização | K5: =COUNTIF($B$5:$H$93,J5) -> 1 | L5: =K5/$K$16 -> 0.16666667 | M5: 4/4-10/4
A6: Pivô 02 | J6: Adubação | K6: =COUNTIF($B$5:$H$93,J6) -> 3 | L6: =K6/$K$16 -> 0.5
A7: Pivô 03 | J7: Transplantio | K7: =COUNTIF($B$5:$H$93,J7) -> 0 | L7: =K7/$K$16 -> 0
A8: Pivô 04 | J8: Colheita Tabaco | K8: =COUNTIF($B$5:$H$93,J8) -> 0 | L8: =K8/$K$16 -> 0
A9: Pivô 05 | J9: Plantio | K9: =COUNTIF($B$5:$H$93,J9) -> 1 | L9: =K9/$K$16 -> 0.16666667
A10: Pivô 06 | J10: Erosão/Rastro | K10: =COUNTIF($B$5:$H$93,J10) -> 0 | L10: =K10/$K$16 -> 0
A11: Pivô 07 | J11: Mecânico/Trator | K11: =COUNTIF($B$5:$H$93,J11) -> 0 | L11: =K11/$K$16 -> 0
A12: Pivô 08 | J12: Transporte | K12: =COUNTIF($B$5:$H$93,J12) -> 0 | L12: =K12/$K$16 -> 0
A13: Pivô 09 | J13: Pivô Atolado | K13: =COUNTIF($B$5:$H$93,J13) -> 1 | L13: =K13/$K$16 -> 0.16666667
A14: Pivô 10 | J14: Entrega do Produto | K14: =COUNTIF($B$5:$H$93,J14) -> 0 | L14: =K14/$K$16 -> 0
A15: Pivô 11 | J15: Limpeza e aferições | K15: =COUNTIF($B$5:$H$93,J15) -> 0 | L15: =K15/$K$16 -> 0
A16: Pivô 12 | J16: Total | K16: =SUM(K5:K15) -> 6
A17: Pivô 13
A18: Pivô 14
A19: Pivô 15
A20: Pivô 16 | G20: Pulverização
A21: Pivô 17
A22: Pivô 18
A23: Pivô 19
A24: Pivô 20
A25: Pivô 21
A26: Pivô 22
A27: Pivô 23
A28: Pivô 24
A29: Pivô 25
A30: Pivô 26
A31: Pivô 27
A32: Pivô 28
... A57: Pivô 53
A58: Pivô 54 | H58: Pivô Atolado
A59: Pivô 55
A60: Pivô 56
A61: Pivô 73
A62: Pivô 74
A63: Pivô 101
A64: Pivô 102
A65: Pivô 103
...

Sheet 11 04 2022
A1: Atendimento de irrigação (Imapacto Operacional Interno e Externo) - Semena 11/04/2022
A3: Data | B3: 44662 | C3: =B3+1 -> 44663 | D3: =C3+1 -> 44664 | E3: =D3+1 -> 44665 | F3: =E3+1 -> 44666 | G3: =F3+1 -> 44667 | H3: =G3+1 -> 44668
A4: Pivô | B4: =TEXT(B3,"ddd") -> seg | C4: =TEXT(C3,"ddd") -> ter | D4: =TEXT(D3,"ddd") -> qua | E4: =TEXT(E3,"ddd") -> qui | F4: =TEXT(F3,"ddd") -> sex | G4: =TEXT(G3,"ddd") -> sáb | H4: =TEXT(H3,"ddd") -> dom | J4: Parâmetros | K4: Contagem | L4: Porcentagem | M4: Semana
A5: Pivô 01 | J5: Pulverização | K5: =COUNTIF($B$5:$H$93,J5) -> 2 | L5: =K5/$K$16 -> 0.66666667 | M5: 11/4-17/4
A6: Pivô 02 | J6: Adubação | K6: =COUNTIF($B$5:$H$93,J6) -> 1 | L6: =K6/$K$16 -> 0.33333333
A7: Pivô 03 | J7: Transplantio | K7: =COUNTIF($B$5:$H$93,J7) -> 0 | L7: =K7/$K$16 -> 0
A8: Pivô 04 | J8: Colheita Tabaco | K8: =COUNTIF($B$5:$H$93,J8) -> 0 | L8: =K8/$K$16 -> 0
A9: Pivô 05 | J9: Plantio | K9: =COUNTIF($B$5:$H$93,J9) -> 0 | L9: =K9/$K$16 -> 0
A10: Pivô 06 | J10: Erosão/Rastro | K10: =COUNTIF($B$5:$H$93,J10) -> 0 | L10: =K10/$K$16 -> 0
A11: Pivô 07 | J11: Mecânico/Trator | K11: =COUNTIF($B$5:$H$93,J11) -> 0 | L11: =K11/$K$16 -> 0
A12: Pivô 08 | J12: Transporte | K12: =COUNTIF($B$5:$H$93,J12) -> 0 | L12: =K12/$K$16 -> 0
A13: Pivô 09 | J13: Pivô Atolado | K13: =COUNTIF($B$5:$H$93,J13) -> 0 | L13: =K13/$K$16 -> 0
A14: Pivô 10 | J14: Entrega do Produto | K14: =COUNTIF($B$5:$H$93,J14) -> 0 | L14: =K14/$K$16 -> 0
A15: Pivô 11 | J15: Limpeza e aferições | K15: =COUNTIF($B$5:$H$93,J15) -> 0 | L15: =K15/$K$16 -> 0
A16: Pivô 12 | J16: Total | K16: =SUM(K5:K15) -> 3
A17: Pivô 13
A18: Pivô 14
A19: Pivô 15
A20: Pivô 16 | B20: Pulverização
A21: Pivô 17
A22: Pivô 18
A23: Pivô 19
A24: Pivô 20
A25: Pivô 21
A26: Pivô 22
A27: Pivô 23
A28: Pivô 24
A29: Pivô 25
A30: Pivô 26
A31: Pivô 27
A32: Pivô 28
... A59: Pivô 55
A60: Pivô 56 | C60: Pulverização
A61: Pivô 73
A62: Pivô 74
A63: Pivô 101
A64: Pivô 102
A65: Pivô 103
A66: Pivô 104
A67: Pivô 105
...

Sheet 18 04 2022
A1: Atendimento de irrigação (Imapacto Operacional Interno e Externo) - Semena 18/04/2022
A3: Data | B3: 44669 | C3: =B3+1 -> 44670 | D3: =C3+1 -> 44671 | E3: =D3+1 -> 44672 | F3: =E3+1 -> 44673 | G3: =F3+1 -> 44674 | H3: =G3+1 -> 44675
A4: Pivô | B4: =TEXT(B3,"ddd") -> seg | C4: =TEXT(C3,"ddd") -> ter | D4: =TEXT(D3,"ddd") -> qua | E4: =TEXT(E3,"ddd") -> qui | F4: =TEXT(F3,"ddd") -> sex | G4: =TEXT(G3,"ddd") -> sáb | H4: =TEXT(H3,"ddd") -> dom | J4: Parâmetros | K4: Contagem | L4: Porcentagem | M4: Semana
A5: Pivô 01 | J5: Pulverização | K5: =COUNTIF($B$5:$H$93,J5) -> 1 | L5: =K5/$K$16 -> 1 | M5: 18/4-24/4
A6: Pivô 02 | J6: Adubação | K6: =COUNTIF($B$5:$H$93,J6) -> 0 | L6: =K6/$K$16 -> 0
A7: Pivô 03 | J7: Transplantio | K7: =COUNTIF($B$5:$H$93,J7) -> 0 | L7: =K7/$K$16 -> 0
A8: Pivô 04 | J8: Colheita Tabaco | K8: =COUNTIF($B$5:$H$93,J8) -> 0 | L8: =K8/$K$16 -> 0
A9: Pivô 05 | J9: Plantio | K9: =COUNTIF($B$5:$H$93,J9) -> 0 | L9: =K9/$K$16 -> 0
A10: Pivô 06 | J10: Erosão/Rastro | K10: =COUNTIF($B$5:$H$93,J10) -> 0 | L10: =K10/$K$16 -> 0
A11: Pivô 07 | J11: Mecânico/Trator | K11: =COUNTIF($B$5:$H$93,J11) -> 0 | L11: =K11/$K$16 -> 0
A12: Pivô 08 | J12: Transporte | K12: =COUNTIF($B$5:$H$93,J12) -> 0 | L12: =K12/$K$16 -> 0
A13: Pivô 09 | J13: Pivô Atolado | K13: =COUNTIF($B$5:$H$93,J13) -> 0 | L13: =K13/$K$16 -> 0
A14: Pivô 10 | J14: Entrega do Produto | K14: =COUNTIF($B$5:$H$93,J14) -> 0 | L14: =K14/$K$16 -> 0
A15: Pivô 11 | J15: Limpeza e aferições | K15: =COUNTIF($B$5:$H$93,J15) -> 0 | L15: =K15/$K$16 -> 0
A16: Pivô 12 | J16: Total | K16: =SUM(K5:K15) -> 1
A17: Pivô 13
A18: Pivô 14
A19: Pivô 15
A20: Pivô 16
A21: Pivô 17
A22: Pivô 18
A23: Pivô 19
A24: Pivô 20
A25: Pivô 21
A26: Pivô 22
A27: Pivô 23
A28: Pivô 24
... A49: Pivô 45
A50: Pivô 46 | B50: Pulverização
A51: Pivô 47
A52: Pivô 48
A53: Pivô 49
A54: Pivô 50
A55: Pivô 51
A56: Pivô 52
A57: Pivô 53
A58: Pivô 54
A59: Pivô 55
A60: Pivô 56
A61: Pivô 73
...

Sheet 25 04 2022
A1: Atendimento de irrigação (Imapacto Operacional Interno e Externo) - Semena 25/04/2022
A3: Data | B3: 44676 | C3: =B3+1 -> 44677 | D3: =C3+1 -> 44678 | E3: =D3+1 -> 44679 | F3: =E3+1 -> 44680 | G3: =F3+1 -> 44681 | H3: =G3+1 -> 44682
A4: Pivô | B4: =TEXT(B3,"ddd") -> seg | C4: =TEXT(C3,"ddd") -> ter | D4: =TEXT(D3,"ddd") -> qua | E4: =TEXT(E3,"ddd") -> qui | F4: =TEXT(F3,"ddd") -> sex | G4: =TEXT(G3,"ddd") -> sáb | H4: =TEXT(H3,"ddd") -> dom | J4: Parâmetros | K4: Contagem | L4: Porcentagem | M4: Semana
A5: Pivô 01 | J5: Pulverização | K5: =COUNTIF($B$5:$H$93,J5) -> 3 | L5: =K5/$K$17 -> 0.6 | M5: 25/4-1/5
A6: Pivô 02 | J6: Adubação | K6: =COUNTIF($B$5:$H$93,J6) -> 1 | L6: =K6/$K$17 -> 0.2
A7: Pivô 03 | J7: Transplantio | K7: =COUNTIF($B$5:$H$93,J7) -> 0 | L7: =K7/$K$17 -> 0
A8: Pivô 04 | J8: Colheita Tabaco | K8: =COUNTIF($B$5:$H$93,J8) -> 0 | L8: =K8/$K$17 -> 0
A9: Pivô 05 | J9: Plantio | K9: =COUNTIF($B$5:$H$93,J9) -> 0 | L9: =K9/$K$17 -> 0
A10: Pivô 06 | J10: Erosão/Rastro | K10: =COUNTIF($B$5:$H$93,J10) -> 0 | L10: =K10/$K$17 -> 0
A11: Pivô 07 | J11: Mecânico/Trator | K11: =COUNTIF($B$5:$H$93,J11) -> 1 | L11: =K11/$K$17 -> 0.2
A12: Pivô 08 | J12: Transporte | K12: =COUNTIF($B$5:$H$93,J12) -> 0 | L12: =K12/$K$17 -> 0
A13: Pivô 09 | J13: Pivô Atolado | K13: =COUNTIF($B$5:$H$93,J13) -> 0 | L13: =K13/$K$17 -> 0
A14: Pivô 10 | J14: Entrega do Produto | K14: =COUNTIF($B$5:$H$93,J14) -> 0 | L14: =K14/$K$17 -> 0
A15: Pivô 11 | J15: Limpeza e aferições | K15: =COUNTIF($B$5:$H$93,J15) -> 0 | L15: =K15/$K$17 -> 0
A16: Pivô 12 | J16: Falta de Água | K16: =COUNTIF($B$5:$H$93,J16) -> 3 | L16: =K16/$K$17 -> 0.6
A17: Pivô 13 | J17: Total | K17: =SUM(K5:K15) -> 5
A18: Pivô 14
A19: Pivô 15
A20: Pivô 16
A21: Pivô 17
A22: Pivô 18
A23: Pivô 19
A24: Pivô 20
A25: Pivô 21 | F25: Pulverização
A26: Pivô 22
A27: Pivô 23
A28: Pivô 24
A29: Pivô 25
A30: Pivô 26
A31: Pivô 27 | H31: Falta de Água
A32: Pivô 28
A33: Pivô 29
A34: Pivô 30
A35: Pivô 31
A36: Pivô 32 | H36: Falta de Água
A37: Pivô 33 | H37: Falta de Água
A38: Pivô 34
A39: Pivô 35 | E39: Mecânico/Trator | F39: Adubação
A40: Pivô 36
A41: Pivô 37
...

Sheet 02 05 2022
A1: Atendimento de irrigação (Imapacto Operacional Interno e Externo) - Semena 02/05/2022
A3: Data | B3: 44683 | C3: =B3+1 -> 44684 | D3: =C3+1 -> 44685 | E3: =D3+1 -> 44686 | F3: =E3+1 -> 44687 | G3: =F3+1 -> 44688 | H3: =G3+1 -> 44689
A4: Pivô | B4: =TEXT(B3,"ddd") -> seg | C4: =TEXT(C3,"ddd") -> ter | D4: =TEXT(D3,"ddd") -> qua | E4: =TEXT(E3,"ddd") -> qui | F4: =TEXT(F3,"ddd") -> sex | G4: =TEXT(G3,"ddd") -> sáb | H4: =TEXT(H3,"ddd") -> dom | J4: Parâmetros | K4: Contagem | L4: Porcentagem | M4: Semana
A5: Pivô 01 | D5: Falta de Água | J5: Pulverização | K5: =COUNTIF($B$5:$H$93,J5) -> 3 | L5: =K5/$K$17 -> 0.17647059 | M5: 2/5-8/5
A6: Pivô 02 | B6: Pulverização | D6: Falta de Água | J6: Adubação | K6: =COUNTIF($B$5:$H$93,J6) -> 0 | L6: =K6/$K$17 -> 0
A7: Pivô 03 | B7: Transporte | D7: Falta de Água | J7: Transplantio | K7: =COUNTIF($B$5:$H$93,J7) -> 1 | L7: =K7/$K$17 -> 0.058823529
A8: Pivô 04 | J8: Colheita Tabaco | K8: =COUNTIF($B$5:$H$93,J8) -> 0 | L8: =K8/$K$17 -> 0
A9: Pivô 05 | J9: Plantio | K9: =COUNTIF($B$5:$H$93,J9) -> 0 | L9: =K9/$K$17 -> 0
A10: Pivô 06 | J10: Erosão/Rastro | K10: =COUNTIF($B$5:$H$93,J10) -> 0 | L10: =K10/$K$17 -> 0
A11: Pivô 07 | J11: Mecânico/Trator | K11: =COUNTIF($B$5:$H$93,J11) -> 3 | L11: =K11/$K$17 -> 0.17647059
A12: Pivô 08 | J12: Transporte | K12: =COUNTIF($B$5:$H$93,J12) -> 1 | L12: =K12/$K$17 -> 0.058823529
A13: Pivô 09 | B13: Transplantio | J13: Pivô Atolado | K13: =COUNTIF($B$5:$H$93,J13) -> 0 | L13: =K13/$K$17 -> 0
A14: Pivô 10 | J14: Entrega do Produto | K14: =COUNTIF($B$5:$H$93,J14) -> 0 | L14: =K14/$K$17 -> 0
A15: Pivô 11 | J15: Limpeza e aferições | K15: =COUNTIF($B$5:$H$93,J15) -> 0 | L15: =K15/$K$17 -> 0
A16: Pivô 12 | J16: Falta de Água | K16: =COUNTIF($B$5:$H$93,J16) -> 9 | L16: =K16/$K$17 -> 0.52941176
A17: Pivô 13 | J17: Total | K17: =SUM(K5:K16) -> 17
A18: Pivô 14
A19: Pivô 15
A20: Pivô 16
A21: Pivô 17
A22: Pivô 18
A23: Pivô 19
A24: Pivô 20
A25: Pivô 21
A26: Pivô 22
A27: Pivô 23
A28: Pivô 24
A29: Pivô 25
... A31: Pivô 27
A32: Pivô 28 | F32: Pulverização
A33: Pivô 29
A34: Pivô 30 | E34: Falta de Água
A35: Pivô 31 | E35: Falta de Água
A36: Pivô 32 | F36: Falta de Água
A37: Pivô 33 | F37: Falta de Água
A38: Pivô 34 | C38: Falta de Água | E38: Falta de Água
A39: Pivô 35
A40: Pivô 36 | B40: Pulverização
A41: Pivô 37
A42: Pivô 38
...

Sheet 09 05 2022
A1: Atendimento de irrigação (Imapacto Operacional Interno e Externo) - Semena 09/05/2022
A3: Data | B3: 44690 | C3: =B3+1 -> 44691 | D3: =C3+1 -> 44692 | E3: =D3+1 -> 44693 | F3: =E3+1 -> 44694 | G3: =F3+1 -> 44695 | H3: =G3+1 -> 44696
A4: Pivô | B4: =TEXT(B3,"ddd") -> seg | C4: =TEXT(C3,"ddd") -> ter | D4: =TEXT(D3,"ddd") -> qua | E4: =TEXT(E3,"ddd") -> qui | F4: =TEXT(F3,"ddd") -> sex | G4: =TEXT(G3,"ddd") -> sáb | H4: =TEXT(H3,"ddd") -> dom | J4: Parâmetros | K4: Contagem | L4: Porcentagem | M4: Semana
A5: Pivô 01 | C5: Falta de Água | J5: Pulverização | K5: =COUNTIF($B$5:$H$93,J5) -> 3 | L5: =K5/$K$17 -> 0.27272727 | M5: 9/5-15/5
A6: Pivô 02 | C6: Falta de Água | J6: Adubação | K6: =COUNTIF($B$5:$H$93,J6) -> 0 | L6: =K6/$K$17 -> 0
A7: Pivô 03 | C7: Falta de Água | J7: Transplantio | K7: =COUNTIF($B$5:$H$93,J7) -> 0 | L7: =K7/$K$17 -> 0
A8: Pivô 04 | J8: Colheita Tabaco | K8: =COUNTIF($B$5:$H$93,J8) -> 0 | L8: =K8/$K$17 -> 0
A9: Pivô 05 | J9: Plantio | K9: =COUNTIF($B$5:$H$93,J9) -> 0 | L9: =K9/$K$17 -> 0
A10: Pivô 06 | J10: Erosão/Rastro | K10: =COUNTIF($B$5:$H$93,J10) -> 0 | L10: =K10/$K$17 -> 0
A11: Pivô 07 | J11: Mecânico/Trator | K11: =COUNTIF($B$5:$H$93,J11) -> 0 | L11: =K11/$K$17 -> 0
A12: Pivô 08 | J12: Transporte | K12: =COUNTIF($B$5:$H$93,J12) -> 0 | L12: =K12/$K$17 -> 0
A13: Pivô 09 | J13: Pivô Atolado | K13: =COUNTIF($B$5:$H$93,J13) -> 1 | L13: =K13/$K$17 -> 0.090909091
A14: Pivô 10 | J14: Entrega do Produto | K14: =COUNTIF($B$5:$H$93,J14) -> 0 | L14: =K14/$K$17 -> 0
A15: Pivô 11 | J15: Limpeza e aferições | K15: =COUNTIF($B$5:$H$93,J15) -> 0 | L15: =K15/$K$17 -> 0
A16: Pivô 12 | J16: Falta de Água | K16: =COUNTIF($B$5:$H$93,J16) -> 7 | L16: =K16/$K$17 -> 0.63636364
A17: Pivô 13 | J17: Total | K17: =SUM(K5:K16) -> 11
A18: Pivô 14
A19: Pivô 15
A20: Pivô 16 | B20: Pulverização
A21: Pivô 17
A22: Pivô 18
A23: Pivô 19
A24: Pivô 20
A25: Pivô 21
A26: Pivô 22
A27: Pivô 23
A28: Pivô 24
A29: Pivô 25
A30: Pivô 26 | C30: Falta de Água
A31: Pivô 27
A32: Pivô 28 | C32: Falta de Água | F32: Pivô Atolado
A33: Pivô 29
A34: Pivô 30
A35: Pivô 31
A36: Pivô 32 | C36: Falta de Água
A37: Pivô 33 | C37: Falta de Água
A38: Pivô 34
A39: Pivô 35
A40: Pivô 36
A41: Pivô 37
...

Sheet 16 05 2022 
A1: Atendimento de irrigação (Imapacto Operacional Interno e Externo) - Semena 16/05/2022
A3: Data | B3: 44697 | C3: =B3+1 -> 44698 | D3: =C3+1 -> 44699 | E3: =D3+1 -> 44700 | F3: =E3+1 -> 44701 | G3: =F3+1 -> 44702 | H3: =G3+1 -> 44703
A4: Pivô | B4: =TEXT(B3,"ddd") -> seg | C4: =TEXT(C3,"ddd") -> ter | D4: =TEXT(D3,"ddd") -> qua | E4: =TEXT(E3,"ddd") -> qui | F4: =TEXT(F3,"ddd") -> sex | G4: =TEXT(G3,"ddd") -> sáb | H4: =TEXT(H3,"ddd") -> dom | J4: Parâmetros | K4: Contagem | L4: Porcentagem | M4: Semana
A5: Pivô 01 | J5: Pulverização | K5: =COUNTIF($B$5:$H$93,J5) -> 1 | L5: =K5/$K$17 -> 0.090909091 | M5: 15/5-22/5
A6: Pivô 02 | J6: Adubação | K6: =COUNTIF($B$5:$H$93,J6) -> 0 | L6: =K6/$K$17 -> 0
A7: Pivô 03 | J7: Transplantio | K7: =COUNTIF($B$5:$H$93,J7) -> 0 | L7: =K7/$K$17 -> 0
A8: Pivô 04 | J8: Colheita Tabaco | K8: =COUNTIF($B$5:$H$93,J8) -> 0 | L8: =K8/$K$17 -> 0
A9: Pivô 05 | D9: Mecânico/Trator | E9: Mecânico/Trator | F9: Mecânico/Trator | G9: Mecânico/Trator | J9: Plantio | K9: =COUNTIF($B$5:$H$93,J9) -> 0 | L9: =K9/$K$17 -> 0
A10: Pivô 06 | J10: Erosão/Rastro | K10: =COUNTIF($B$5:$H$93,J10) -> 0 | L10: =K10/$K$17 -> 0
A11: Pivô 07 | J11: Mecânico/Trator | K11: =COUNTIF($B$5:$H$93,J11) -> 10 | L11: =K11/$K$17 -> 0.90909091
A12: Pivô 08 | J12: Transporte | K12: =COUNTIF($B$5:$H$93,J12) -> 0 | L12: =K12/$K$17 -> 0
A13: Pivô 09 | J13: Pivô Atolado | K13: =COUNTIF($B$5:$H$93,J13) -> 0 | L13: =K13/$K$17 -> 0
A14: Pivô 10 | J14: Entrega do Produto | K14: =COUNTIF($B$5:$H$93,J14) -> 0 | L14: =K14/$K$17 -> 0
A15: Pivô 11 | J15: Limpeza e aferições | K15: =COUNTIF($B$5:$H$93,J15) -> 0 | L15: =K15/$K$17 -> 0
A16: Pivô 12 | J16: Falta de Água | K16: =COUNTIF($B$5:$H$93,J16) -> 0 | L16: =K16/$K$17 -> 0
A17: Pivô 13 | J17: Total | K17: =SUM(K5:K16) -> 11
A18: Pivô 14
A19: Pivô 15
A20: Pivô 16
A21: Pivô 17
A22: Pivô 18
A23: Pivô 19 | J23: Dashboard Indicadores'!A1
A24: Pivô 20
A25: Pivô 21
A26: Pivô 22
A27: Pivô 23
A28: Pivô 24
A29: Pivô 25
A30: Pivô 26
A31: Pivô 27
A32: Pivô 28
A33: Pivô 29
A34: Pivô 30
A35: Pivô 31
... A38: Pivô 34
A39: Pivô 35 | E39: Mecânico/Trator
A40: Pivô 36 | B40: Mecânico/Trator | C40: Mecânico/Trator
A41: Pivô 37 | E41: Mecânico/Trator
A42: Pivô 38
A43: Pivô 39
...

Sheet 23 05 2022 
A1: Atendimento de irrigação (Imapacto Operacional Interno e Externo) - Semena 23/05/2022
A3: Data | B3: 44704 | C3: =B3+1 -> 44705 | D3: =C3+1 -> 44706 | E3: =D3+1 -> 44707 | F3: =E3+1 -> 44708 | G3: =F3+1 -> 44709 | H3: =G3+1 -> 44710
A4: Pivô | B4: =TEXT(B3,"ddd") -> seg | C4: =TEXT(C3,"ddd") -> ter | D4: =TEXT(D3,"ddd") -> qua | E4: =TEXT(E3,"ddd") -> qui | F4: =TEXT(F3,"ddd") -> sex | G4: =TEXT(G3,"ddd") -> sáb | H4: =TEXT(H3,"ddd") -> dom | J4: Parâmetros | K4: Contagem | L4: Porcentagem | M4: Semana | N4: Periodo | O4: Ano
A5: Pivô 01 | J5: Pulverização | K5: =COUNTIF($B$5:$H$93,J5) -> 4 | L5: =K5/$K$18 -> 0.4 | M5: 23/5-29/5 | N5: 2ª Semestre | O5: 2021
A6: Pivô 02 | J6: Adubação | K6: =COUNTIF($B$5:$H$93,J6) -> 1 | L6: =K6/$K$18 -> 0.1
A7: Pivô 03 | J7: Transplantio | K7: =COUNTIF($B$5:$H$93,J7) -> 1 | L7: =K7/$K$18 -> 0.1
A8: Pivô 04 | J8: Colheita Tabaco | K8: =COUNTIF($B$5:$H$93,J8) -> 0 | L8: =K8/$K$18 -> 0
A9: Pivô 05 | J9: Plantio | K9: =COUNTIF($B$5:$H$93,J9) -> 0 | L9: =K9/$K$18 -> 0
A10: Pivô 06 | E10: Pulverização | J10: Erosão/Rastro | K10: =COUNTIF($B$5:$H$93,J10) -> 0 | L10: =K10/$K$18 -> 0
A11: Pivô 07 | J11: Mecânico/Trator | K11: =COUNTIF($B$5:$H$93,J11) -> 0 | L11: =K11/$K$18 -> 0
A12: Pivô 08 | E12: Adubação | J12: Transporte | K12: =COUNTIF($B$5:$H$93,J12) -> 0 | L12: =K12/$K$18 -> 0
A13: Pivô 09 | J13: Pivô Atolado | K13: =COUNTIF($B$5:$H$93,J13) -> 3 | L13: =K13/$K$18 -> 0.3
A14: Pivô 10 | J14: Entrega do Produto | K14: =COUNTIF($B$5:$H$93,J14) -> 0 | L14: =K14/$K$18 -> 0
A15: Pivô 11 | J15: Limpeza e aferições | K15: =COUNTIF($B$5:$H$93,J15) -> 0 | L15: =K15/$K$18 -> 0
A16: Pivô 12 | D16: Transplantio | J16: Falta de Água | K16: =COUNTIF($B$5:$H$93,J16) -> 0 | L16: =K16/$K$18 -> 0
A17: Pivô 13 | J17: Desponte | K17: =COUNTIF($B$5:$H$93,J17) -> 1 | L17: =K17/$K$18 -> 0.1
A18: Pivô 14 | J18: Total | K18: =SUM(K5:K17) -> 10
A19: Pivô 15
A20: Pivô 16
A21: Pivô 17
A22: Pivô 18
A23: Pivô 19
A24: Pivô 20
A25: Pivô 21
A26: Pivô 22
A27: Pivô 23
A28: Pivô 24
A29: Pivô 25
A30: Pivô 26 | D30: Pulverização
A31: Pivô 27
A32: Pivô 28
A33: Pivô 29
A34: Pivô 30
A35: Pivô 31
A36: Pivô 32 | E36: Pivô Atolado
A37: Pivô 33
A38: Pivô 34 | D38: Pivô Atolado | E38: Pivô Atolado
A39: Pivô 35 | E39: Desponte
A40: Pivô 36
A41: Pivô 37
...

Sheet 30 05 2022 
A1: Atendimento de irrigação (Imapacto Operacional Interno e Externo) - Semena 30/05/2022
A3: Data | B3: 44711 | C3: =B3+1 -> 44712 | D3: =C3+1 -> 44713 | E3: =D3+1 -> 44714 | F3: =E3+1 -> 44715 | G3: =F3+1 -> 44716 | H3: =G3+1 -> 44717
A4: Pivô | B4: =TEXT(B3,"ddd") -> seg | C4: =TEXT(C3,"ddd") -> ter | D4: =TEXT(D3,"ddd") -> qua | E4: =TEXT(E3,"ddd") -> qui | F4: =TEXT(F3,"ddd") -> sex | G4: =TEXT(G3,"ddd") -> sáb | H4: =TEXT(H3,"ddd") -> dom | J4: Parâmetros | K4: Contagem | L4: Porcentagem | M4: Semana | N4: Periodo | O4: Ano
A5: Pivô 01 | J5: Pulverização | K5: =COUNTIF($B$5:$H$93,J5) -> 2 | L5: =K5/$K$18 -> 0.33333333 | M5: 30/5-5/6 | N5: 2ª Semestre | O5: 2021
A6: Pivô 02 | J6: Adubação | K6: =COUNTIF($B$5:$H$93,J6) -> 0 | L6: =K6/$K$18 -> 0
A7: Pivô 03 | J7: Transplantio | K7: =COUNTIF($B$5:$H$93,J7) -> 0 | L7: =K7/$K$18 -> 0
A8: Pivô 04 | J8: Colheita Tabaco | K8: =COUNTIF($B$5:$H$93,J8) -> 0 | L8: =K8/$K$18 -> 0
A9: Pivô 05 | J9: Plantio | K9: =COUNTIF($B$5:$H$93,J9) -> 0 | L9: =K9/$K$18 -> 0
A10: Pivô 06 | J10: Erosão/Rastro | K10: =COUNTIF($B$5:$H$93,J10) -> 0 | L10: =K10/$K$18 -> 0
A11: Pivô 07 | H11: Entrega do Produto | J11: Mecânico/Trator | K11: =COUNTIF($B$5:$H$93,J11) -> 0 | L11: =K11/$K$18 -> 0
A12: Pivô 08 | J12: Transporte | K12: =COUNTIF($B$5:$H$93,J12) -> 0 | L12: =K12/$K$18 -> 0
A13: Pivô 09 | J13: Pivô Atolado | K13: =COUNTIF($B$5:$H$93,J13) -> 2 | L13: =K13/$K$18 -> 0.33333333
A14: Pivô 10 | J14: Entrega do Produto | K14: =COUNTIF($B$5:$H$93,J14) -> 2 | L14: =K14/$K$18 -> 0.33333333
A15: Pivô 11 | J15: Limpeza e aferições | K15: =COUNTIF($B$5:$H$93,J15) -> 0 | L15: =K15/$K$18 -> 0
A16: Pivô 12 | J16: Falta de Água | K16: =COUNTIF($B$5:$H$93,J16) -> 0 | L16: =K16/$K$18 -> 0
A17: Pivô 13 | J17: Desponte | K17: =COUNTIF($B$5:$H$93,J17) -> 0 | L17: =K17/$K$18 -> 0
A18: Pivô 14 | J18: Total | K18: =SUM(K5:K17) -> 6
A19: Pivô 15 | D19: Pulverização
A20: Pivô 16
A21: Pivô 17
A22: Pivô 18 | C22: Pivô Atolado
A23: Pivô 19
A24: Pivô 20
A25: Pivô 21
A26: Pivô 22
A27: Pivô 23
A28: Pivô 24
A29: Pivô 25
A30: Pivô 26
A31: Pivô 27
A32: Pivô 28 | C32: Pivô Atolado
A33: Pivô 29
A34: Pivô 30
A35: Pivô 31
A36: Pivô 32
A37: Pivô 33 | B37: Pulverização
A38: Pivô 34
A39: Pivô 35 | B39: Entrega do Produto
A40: Pivô 36
A41: Pivô 37
...

Sheet 06 06 2022  
A1: Atendimento de irrigação (Imapacto Operacional Interno e Externo) - Semena 06/06/2022
A3: Data | B3: 44718 | C3: =B3+1 -> 44719 | D3: =C3+1 -> 44720 | E3: =D3+1 -> 44721 | F3: =E3+1 -> 44722 | G3: =F3+1 -> 44723 | H3: =G3+1 -> 44724
A4: Pivô | B4: =TEXT(B3,"ddd") -> seg | C4: =TEXT(C3,"ddd") -> ter | D4: =TEXT(D3,"ddd") -> qua | E4: =TEXT(E3,"ddd") -> qui | F4: =TEXT(F3,"ddd") -> sex | G4: =TEXT(G3,"ddd") -> sáb | H4: =TEXT(H3,"ddd") -> dom | J4: Parâmetros | K4: Contagem | L4: Porcentagem | M4: Semana | N4: Periodo | O4: Ano
A5: Pivô 01 | J5: Pulverização | K5: =COUNTIF($B$5:$H$93,J5) -> 2 | L5: =K5/$K$18 -> 0.4 | N5: 2ª Semestre | O5: 2021
A6: Pivô 02 | J6: Adubação | K6: =COUNTIF($B$5:$H$93,J6) -> 0 | L6: =K6/$K$18 -> 0
A7: Pivô 03 | J7: Transplantio | K7: =COUNTIF($B$5:$H$93,J7) -> 1 | L7: =K7/$K$18 -> 0.2
A8: Pivô 04 | J8: Colheita Tabaco | K8: =COUNTIF($B$5:$H$93,J8) -> 0 | L8: =K8/$K$18 -> 0
A9: Pivô 05 | J9: Plantio | K9: =COUNTIF($B$5:$H$93,J9) -> 0 | L9: =K9/$K$18 -> 0 | M9: 6/6-12/6
A10: Pivô 06 | D10: Mecânico/Trator | H10: Pulverização | J10: Erosão/Rastro | K10: =COUNTIF($B$5:$H$93,J10) -> 0 | L10: =K10/$K$18 -> 0
A11: Pivô 07 | J11: Mecânico/Trator | K11: =COUNTIF($B$5:$H$93,J11) -> 1 | L11: =K11/$K$18 -> 0.2
A12: Pivô 08 | J12: Transporte | K12: =COUNTIF($B$5:$H$93,J12) -> 0 | L12: =K12/$K$18 -> 0
A13: Pivô 09 | J13: Pivô Atolado | K13: =COUNTIF($B$5:$H$93,J13) -> 0 | L13: =K13/$K$18 -> 0
A14: Pivô 10 | F14: Pulverização | J14: Entrega do Produto | K14: =COUNTIF($B$5:$H$93,J14) -> 0 | L14: =K14/$K$18 -> 0
A15: Pivô 11 | J15: Limpeza e aferições | K15: =COUNTIF($B$5:$H$93,J15) -> 1 | L15: =K15/$K$18 -> 0.2
A16: Pivô 12 | J16: Falta de Água | K16: =COUNTIF($B$5:$H$93,J16) -> 0 | L16: =K16/$K$18 -> 0
A17: Pivô 13 | J17: Desponte | K17: =COUNTIF($B$5:$H$93,J17) -> 0 | L17: =K17/$K$18 -> 0
A18: Pivô 14 | J18: Total | K18: =SUM(K5:K17) -> 5
A19: Pivô 15
A20: Pivô 16
A21: Pivô 17
A22: Pivô 18
A23: Pivô 19
A24: Pivô 20
A25: Pivô 21
A26: Pivô 22
A27: Pivô 23
A28: Pivô 24
A29: Pivô 25
A30: Pivô 26
... A33: Pivô 29
A34: Pivô 30 | D34: Limpeza e aferições
A35: Pivô 31
A36: Pivô 32
A37: Pivô 33
A38: Pivô 34
A39: Pivô 35
A40: Pivô 36
A41: Pivô 37
A42: Pivô 38
A43: Pivô 39
...

Sheet 13 06 2022  
A1: Atendimento de irrigação (Imapacto Operacional Interno e Externo) - Semena 13/06/2022
A3: Data | B3: 44725 | C3: =B3+1 -> 44726 | D3: =C3+1 -> 44727 | E3: =D3+1 -> 44728 | F3: =E3+1 -> 44729 | G3: =F3+1 -> 44730 | H3: =G3+1 -> 44731
A4: Pivô | B4: =TEXT(B3,"ddd") -> seg | C4: =TEXT(C3,"ddd") -> ter | D4: =TEXT(D3,"ddd") -> qua | E4: =TEXT(E3,"ddd") -> qui | F4: =TEXT(F3,"ddd") -> sex | G4: =TEXT(G3,"ddd") -> sáb | H4: =TEXT(H3,"ddd") -> dom | J4: Parâmetros | K4: Contagem | L4: Porcentagem | M4: Semana | N4: Periodo | O4: Ano
A5: Pivô 01 | J5: Pulverização | K5: =COUNTIF($B$5:$H$93,J5) -> 4 | L5: =K5/$K$18 -> 0.5 | M5: 13/6-19/6 | N5: 1ª Semestre | O5: 2022
A6: Pivô 02 | J6: Adubação | K6: =COUNTIF($B$5:$H$93,J6) -> 0 | L6: =K6/$K$18 -> 0
A7: Pivô 03 | J7: Transplantio | K7: =COUNTIF($B$5:$H$93,J7) -> 3 | L7: =K7/$K$18 -> 0.375
A8: Pivô 04 | J8: Colheita Tabaco | K8: =COUNTIF($B$5:$H$93,J8) -> 0 | L8: =K8/$K$18 -> 0
A9: Pivô 05 | J9: Plantio | K9: =COUNTIF($B$5:$H$93,J9) -> 0 | L9: =K9/$K$18 -> 0
A10: Pivô 06 | J10: Erosão/Rastro | K10: =COUNTIF($B$5:$H$93,J10) -> 0 | L10: =K10/$K$18 -> 0
A11: Pivô 07 | J11: Mecânico/Trator | K11: =COUNTIF($B$5:$H$93,J11) -> 0 | L11: =K11/$K$18 -> 0
A12: Pivô 08 | J12: Transporte | K12: =COUNTIF($B$5:$H$93,J12) -> 0 | L12: =K12/$K$18 -> 0
A13: Pivô 09 | J13: Pivô Atolado | K13: =COUNTIF($B$5:$H$93,J13) -> 1 | L13: =K13/$K$18 -> 0.125
A14: Pivô 10 | J14: Entrega do Produto | K14: =COUNTIF($B$5:$H$93,J14) -> 0 | L14: =K14/$K$18 -> 0
A15: Pivô 11 | H15: Pulverização | J15: Limpeza e aferições | K15: =COUNTIF($B$5:$H$93,J15) -> 0 | L15: =K15/$K$18 -> 0
A16: Pivô 12 | J16: Falta de Água | K16: =COUNTIF($B$5:$H$93,J16) -> 0 | L16: =K16/$K$18 -> 0
A17: Pivô 13 | J17: Desponte | K17: =COUNTIF($B$5:$H$93,J17) -> 0 | L17: =K17/$K$18 -> 0
A18: Pivô 14 | J18: Total | K18: =SUM(K5:K17) -> 8
A19: Pivô 15
A20: Pivô 16
A21: Pivô 17
A22: Pivô 18
A23: Pivô 19
A24: Pivô 20
A25: Pivô 21
A26: Pivô 22
A27: Pivô 23
A28: Pivô 24
A29: Pivô 25
A30: Pivô 26
... A35: Pivô 31
A36: Pivô 32 | E36: Pivô Atolado
A37: Pivô 33
A38: Pivô 34 | F38: Pulverização
A39: Pivô 35
A40: Pivô 36
A41: Pivô 37
A42: Pivô 38
A43: Pivô 39
A44: Pivô 40
A45: Pivô 41
...

Sheet 20 06 2022  
A1: Atendimento de irrigação (Imapacto Operacional Interno e Externo) - Semena 20/06/2022
A3: Data | B3: 44732 | C3: =B3+1 -> 44733 | D3: =C3+1 -> 44734 | E3: =D3+1 -> 44735 | F3: =E3+1 -> 44736 | G3: =F3+1 -> 44737 | H3: =G3+1 -> 44738
A4: Pivô | B4: =TEXT(B3,"ddd") -> seg | C4: =TEXT(C3,"ddd") -> ter | D4: =TEXT(D3,"ddd") -> qua | E4: =TEXT(E3,"ddd") -> qui | F4: =TEXT(F3,"ddd") -> sex | G4: =TEXT(G3,"ddd") -> sáb | H4: =TEXT(H3,"ddd") -> dom | J4: Parâmetros | K4: Contagem | L4: Porcentagem | M4: Semana | N4: Periodo | O4: Ano
A5: Pivô 01 | J5: Pulverização | K5: =COUNTIF($B$5:$H$93,J5) -> 0 | L5: =K5/$K$18 -> 0 | M5: 20/6-26/6 | N5: 1ª Semestre | O5: 2022
A6: Pivô 02 | J6: Adubação | K6: =COUNTIF($B$5:$H$93,J6) -> 0 | L6: =K6/$K$18 -> 0
A7: Pivô 03 | J7: Transplantio | K7: =COUNTIF($B$5:$H$93,J7) -> 2 | L7: =K7/$K$18 -> 0.66666667
A8: Pivô 04 | J8: Colheita Tabaco | K8: =COUNTIF($B$5:$H$93,J8) -> 1 | L8: =K8/$K$18 -> 0.33333333
A9: Pivô 05 | J9: Plantio | K9: =COUNTIF($B$5:$H$93,J9) -> 0 | L9: =K9/$K$18 -> 0
A10: Pivô 06 | J10: Erosão/Rastro | K10: =COUNTIF($B$5:$H$93,J10) -> 0 | L10: =K10/$K$18 -> 0
A11: Pivô 07 | J11: Mecânico/Trator | K11: =COUNTIF($B$5:$H$93,J11) -> 0 | L11: =K11/$K$18 -> 0
A12: Pivô 08 | J12: Transporte | K12: =COUNTIF($B$5:$H$93,J12) -> 0 | L12: =K12/$K$18 -> 0
A13: Pivô 09 | J13: Pivô Atolado | K13: =COUNTIF($B$5:$H$93,J13) -> 0 | L13: =K13/$K$18 -> 0
A14: Pivô 10 | J14: Entrega do Produto | K14: =COUNTIF($B$5:$H$93,J14) -> 0 | L14: =K14/$K$18 -> 0
A15: Pivô 11 | J15: Limpeza e aferições | K15: =COUNTIF($B$5:$H$93,J15) -> 0 | L15: =K15/$K$18 -> 0
A16: Pivô 12 | J16: Falta de Água | K16: =COUNTIF($B$5:$H$93,J16) -> 0 | L16: =K16/$K$18 -> 0
A17: Pivô 13 | J17: Desponte | K17: =COUNTIF($B$5:$H$93,J17) -> 0 | L17: =K17/$K$18 -> 0
A18: Pivô 14 | J18: Total | K18: =SUM(K5:K17) -> 3
A19: Pivô 15
A20: Pivô 16
A21: Pivô 17
A22: Pivô 18
A23: Pivô 19
A24: Pivô 20
A25: Pivô 21
A26: Pivô 22
A27: Pivô 23
A28: Pivô 24
A29: Pivô 25
A30: Pivô 26
... A40: Pivô 36
A41: Pivô 37 | D41: Colheita Tabaco
A42: Pivô 38
A43: Pivô 39
A44: Pivô 40
A45: Pivô 41
A46: Pivô 42
A47: Pivô 43
A48: Pivô 44
A49: Pivô 45
A50: Pivô 46
...

Sheet 27 06 2022   
A1: Atendimento de irrigação (Imapacto Operacional Interno e Externo) - Semena 27/06/2022
A3: Data | B3: 44739 | C3: =B3+1 -> 44740 | D3: =C3+1 -> 44741 | E3: =D3+1 -> 44742 | F3: =E3+1 -> 44743 | G3: =F3+1 -> 44744 | H3: =G3+1 -> 44745
A4: Pivô | B4: =TEXT(B3,"ddd") -> seg | C4: =TEXT(C3,"ddd") -> ter | D4: =TEXT(D3,"ddd") -> qua | E4: =TEXT(E3,"ddd") -> qui | F4: =TEXT(F3,"ddd") -> sex | G4: =TEXT(G3,"ddd") -> sáb | H4: =TEXT(H3,"ddd") -> dom | J4: Parâmetros | K4: Contagem | L4: Porcentagem | M4: Semana | N4: Periodo | O4: Ano
A5: Pivô 01 | J5: Pulverização | K5: =COUNTIF($B$5:$H$93,J5) -> 4 | L5: =K5/$K$18 -> 0.5 | M5: 27/6-3/7 | N5: 1ª Semestre | O5: 2022
A6: Pivô 02 | J6: Adubação | K6: =COUNTIF($B$5:$H$93,J6) -> 0 | L6: =K6/$K$18 -> 0
A7: Pivô 03 | J7: Transplantio | K7: =COUNTIF($B$5:$H$93,J7) -> 1 | L7: =K7/$K$18 -> 0.125
A8: Pivô 04 | J8: Colheita Tabaco | K8: =COUNTIF($B$5:$H$93,J8) -> 0 | L8: =K8/$K$18 -> 0
A9: Pivô 05 | J9: Plantio | K9: =COUNTIF($B$5:$H$93,J9) -> 0 | L9: =K9/$K$18 -> 0
A10: Pivô 06 | J10: Erosão/Rastro | K10: =COUNTIF($B$5:$H$93,J10) -> 0 | L10: =K10/$K$18 -> 0
A11: Pivô 07 | D11: Desponte | J11: Mecânico/Trator | K11: =COUNTIF($B$5:$H$93,J11) -> 0 | L11: =K11/$K$18 -> 0
A12: Pivô 08 | E12: Desponte | F12: Desponte | J12: Transporte | K12: =COUNTIF($B$5:$H$93,J12) -> 0 | L12: =K12/$K$18 -> 0
A13: Pivô 09 | J13: Pivô Atolado | K13: =COUNTIF($B$5:$H$93,J13) -> 0 | L13: =K13/$K$18 -> 0
A14: Pivô 10 | F14: Pulverização | J14: Entrega do Produto | K14: =COUNTIF($B$5:$H$93,J14) -> 0 | L14: =K14/$K$18 -> 0
A15: Pivô 11 | J15: Limpeza e aferições | K15: =COUNTIF($B$5:$H$93,J15) -> 0 | L15: =K15/$K$18 -> 0
A16: Pivô 12 | J16: Falta de Água | K16: =COUNTIF($B$5:$H$93,J16) -> 0 | L16: =K16/$K$18 -> 0
A17: Pivô 13 | J17: Desponte | K17: =COUNTIF($B$5:$H$93,J17) -> 3 | L17: =K17/$K$18 -> 0.375
A18: Pivô 14 | J18: Total | K18: =SUM(K5:K17) -> 8
A19: Pivô 15
A20: Pivô 16
A21: Pivô 17
A22: Pivô 18
A23: Pivô 19
A24: Pivô 20
A25: Pivô 21
A26: Pivô 22
A27: Pivô 23
A28: Pivô 24
A29: Pivô 25
A30: Pivô 26
... A41: Pivô 37
A42: Pivô 38 | F42: Pulverização
A43: Pivô 39
A44: Pivô 40 | F44: Pulverização
A45: Pivô 41 | F45: Pulverização
A46: Pivô 42
A47: Pivô 43
A48: Pivô 44
A49: Pivô 45
A50: Pivô 46
A51: Pivô 47
...

Sheet 04 07 2022    
A1: Atendimento de irrigação (Imapacto Operacional Interno e Externo) - Semena 04/07/2022
A3: Data | B3: 44746 | C3: =B3+1 -> 44747 | D3: =C3+1 -> 44748 | E3: =D3+1 -> 44749 | F3: =E3+1 -> 44750 | G3: =F3+1 -> 44751 | H3: =G3+1 -> 44752
A4: Pivô | B4: =TEXT(B3,"ddd") -> seg | C4: =TEXT(C3,"ddd") -> ter | D4: =TEXT(D3,"ddd") -> qua | E4: =TEXT(E3,"ddd") -> qui | F4: =TEXT(F3,"ddd") -> sex | G4: =TEXT(G3,"ddd") -> sáb | H4: =TEXT(H3,"ddd") -> dom | J4: Parâmetros | K4: Contagem | L4: Porcentagem | M4: Semana
A5: Pivô 01 | J5: Pulverização | K5: =COUNTIF($B$5:$H$93,J5) -> 1 | L5: =K5/$K$18 -> 0.14285714 | M5: 44746
A6: Pivô 02 | J6: Adubação | K6: =COUNTIF($B$5:$H$93,J6) -> 0 | L6: =K6/$K$18 -> 0
A7: Pivô 03 | C7: Colheita Tabaco | J7: Transplantio | K7: =COUNTIF($B$5:$H$93,J7) -> 0 | L7: =K7/$K$18 -> 0
A8: Pivô 04 | J8: Colheita Tabaco | K8: =COUNTIF($B$5:$H$93,J8) -> 1 | L8: =K8/$K$18 -> 0.14285714
A9: Pivô 05 | J9: Plantio | K9: =COUNTIF($B$5:$H$93,J9) -> 0 | L9: =K9/$K$18 -> 0
A10: Pivô 06 | J10: Erosão/Rastro | K10: =COUNTIF($B$5:$H$93,J10) -> 0 | L10: =K10/$K$18 -> 0
A11: Pivô 07 | B11: Entrega do Produto | J11: Mecânico/Trator | K11: =COUNTIF($B$5:$H$93,J11) -> 1 | L11: =K11/$K$18 -> 0.14285714
A12: Pivô 08 | J12: Transporte | K12: =COUNTIF($B$5:$H$93,J12) -> 0 | L12: =K12/$K$18 -> 0
A13: Pivô 09 | B13: Desponte | C13: Desponte | D13: Desponte | J13: Pivô Atolado | K13: =COUNTIF($B$5:$H$93,J13) -> 0 | L13: =K13/$K$18 -> 0
A14: Pivô 10 | C14: Mecânico/Trator | J14: Entrega do Produto | K14: =COUNTIF($B$5:$H$93,J14) -> 1 | L14: =K14/$K$18 -> 0.14285714
A15: Pivô 11 | J15: Limpeza e aferições | K15: =COUNTIF($B$5:$H$93,J15) -> 0 | L15: =K15/$K$18 -> 0
A16: Pivô 12 | J16: Falta de Água | K16: =COUNTIF($B$5:$H$93,J16) -> 0 | L16: =K16/$K$18 -> 0
A17: Pivô 13 | J17: Desponte | K17: =COUNTIF($B$5:$H$93,J17) -> 3 | L17: =K17/$K$18 -> 0.42857143
A18: Pivô 14 | J18: Total | K18: =SUM(K5:K17) -> 7
A19: Pivô 15 | C19: Pulverização
A20: Pivô 16
A21: Pivô 17
A22: Pivô 18
A23: Pivô 19
A24: Pivô 20
A25: Pivô 21
A26: Pivô 22
A27: Pivô 23
A28: Pivô 24
A29: Pivô 25
A30: Pivô 26
A31: Pivô 27
... A93: Pivô 133

Sheet 11 07 2022     
A1: Atendimento de irrigação (Imapacto Operacional Interno e Externo) - Semena 11/07/2022
A3: Data | B3: 44753 | C3: =B3+1 -> 44754 | D3: =C3+1 -> 44755 | E3: =D3+1 -> 44756 | F3: =E3+1 -> 44757 | G3: =F3+1 -> 44758 | H3: =G3+1 -> 44759
A4: Pivô | B4: =TEXT(B3,"ddd") -> seg | C4: =TEXT(C3,"ddd") -> ter | D4: =TEXT(D3,"ddd") -> qua | E4: =TEXT(E3,"ddd") -> qui | F4: =TEXT(F3,"ddd") -> sex | G4: =TEXT(G3,"ddd") -> sáb | H4: =TEXT(H3,"ddd") -> dom | J4: Parâmetros | K4: Contagem | L4: Porcentagem | M4: Semana
A5: Pivô 01 | J5: Pulverização | K5: =COUNTIF($B$5:$H$93,J5) -> 3 | L5: =K5/$K$18 -> 0.2 | M5: =B3 -> 44753
A6: Pivô 02 | J6: Adubação | K6: =COUNTIF($B$5:$H$93,J6) -> 3 | L6: =K6/$K$18 -> 0.2
A7: Pivô 03 | J7: Transplantio | K7: =COUNTIF($B$5:$H$93,J7) -> 1 | L7: =K7/$K$18 -> 0.066666667
A8: Pivô 04 | J8: Colheita Tabaco | K8: =COUNTIF($B$5:$H$93,J8) -> 1 | L8: =K8/$K$18 -> 0.066666667
A9: Pivô 05 | F9: Colheita Tabaco | J9: Plantio | K9: =COUNTIF($B$5:$H$93,J9) -> 4 | L9: =K9/$K$18 -> 0.26666667
A10: Pivô 06 | J10: Erosão/Rastro | K10: =COUNTIF($B$5:$H$93,J10) -> 3 | L10: =K10/$K$18 -> 0.2
A11: Pivô 07 | J11: Mecânico/Trator | K11: =COUNTIF($B$5:$H$93,J11) -> 0 | L11: =K11/$K$18 -> 0
A12: Pivô 08 | J12: Transporte | K12: =COUNTIF($B$5:$H$93,J12) -> 0 | L12: =K12/$K$18 -> 0
A13: Pivô 09 | J13: Pivô Atolado | K13: =COUNTIF($B$5:$H$93,J13) -> 0 | L13: =K13/$K$18 -> 0
A14: Pivô 10 | J14: Entrega do Produto | K14: =COUNTIF($B$5:$H$93,J14) -> 0 | L14: =K14/$K$18 -> 0
A15: Pivô 11 | J15: Limpeza e aferições | K15: =COUNTIF($B$5:$H$93,J15) -> 0 | L15: =K15/$K$18 -> 0
A16: Pivô 12 | J16: Falta de Água | K16: =COUNTIF($B$5:$H$93,J16) -> 0 | L16: =K16/$K$18 -> 0
A17: Pivô 13 | J17: Desponte | K17: =COUNTIF($B$5:$H$93,J17) -> 0 | L17: =K17/$K$18 -> 0
A18: Pivô 14 | J18: Total | K18: =SUM(K5:K17) -> 15
A19: Pivô 15
A20: Pivô 16
A21: Pivô 17
A22: Pivô 18
A23: Pivô 19 | D23: Erosão/Rastro | F23: Erosão/Rastro | G23: Erosão/Rastro
A24: Pivô 20
A25: Pivô 21
A26: Pivô 22
A27: Pivô 23
A28: Pivô 24
A29: Pivô 25
A30: Pivô 26
A31: Pivô 27
A32: Pivô 28
A33: Pivô 29
A34: Pivô 30
A35: Pivô 31
... A50: Pivô 46
A51: Pivô 47 | E51: Transplantio
A52: Pivô 48 | D52: Pulverização | F52: Adubação
A53: Pivô 49
A54: Pivô 50
A55: Pivô 51
...

Sheet 18 07 2022    
A1: Atendimento de irrigação (Imapacto Operacional Interno e Externo) - Semena 18/07/2022
A3: Data | B3: 44760 | C3: =B3+1 -> 44761 | D3: =C3+1 -> 44762 | E3: =D3+1 -> 44763 | F3: =E3+1 -> 44764 | G3: =F3+1 -> 44765 | H3: =G3+1 -> 44766
A4: Pivô | B4: =TEXT(B3,"ddd") -> seg | C4: =TEXT(C3,"ddd") -> ter | D4: =TEXT(D3,"ddd") -> qua | E4: =TEXT(E3,"ddd") -> qui | F4: =TEXT(F3,"ddd") -> sex | G4: =TEXT(G3,"ddd") -> sáb | H4: =TEXT(H3,"ddd") -> dom | J4: Parâmetros | K4: Contagem | L4: Porcentagem | M4: Semana
A5: Pivô 01 | J5: Pulverização | K5: =COUNTIF($B$5:$H$93,J5) -> 1 | L5: =K5/$K$19 -> 0.14285714 | M5: =B3 -> 44760
A6: Pivô 02 | J6: Adubação | K6: =COUNTIF($B$5:$H$93,J6) -> 1 | L6: =K6/$K$19 -> 0.14285714
A7: Pivô 03 | J7: Transplantio | K7: =COUNTIF($B$5:$H$93,J7) -> 1 | L7: =K7/$K$19 -> 0.14285714
A8: Pivô 04 | J8: Colheita Tabaco | K8: =COUNTIF($B$5:$H$93,J8) -> 0 | L8: =K8/$K$19 -> 0
A9: Pivô 05 | J9: Plantio | K9: =COUNTIF($B$5:$H$93,J9) -> 2 | L9: =K9/$K$19 -> 0.28571429
A10: Pivô 06 | J10: Erosão/Rastro | K10: =COUNTIF($B$5:$H$93,J10) -> 0 | L10: =K10/$K$19 -> 0
A11: Pivô 07 | J11: Mecânico/Trator | K11: =COUNTIF($B$5:$H$93,J11) -> 0 | L11: =K11/$K$19 -> 0
A12: Pivô 08 | J12: Transporte | K12: =COUNTIF($B$5:$H$93,J12) -> 0 | L12: =K12/$K$19 -> 0
A13: Pivô 09 | J13: Pivô Atolado | K13: =COUNTIF($B$5:$H$93,J13) -> 0 | L13: =K13/$K$19 -> 0
A14: Pivô 10 | J14: Entrega do Produto | K14: =COUNTIF($B$5:$H$93,J14) -> 0 | L14: =K14/$K$19 -> 0
A15: Pivô 11 | J15: Limpeza e aferições | K15: =COUNTIF($B$5:$H$93,J15) -> 2 | L15: =K15/$K$19 -> 0.28571429
A16: Pivô 12 | J16: Falta de Água | K16: =COUNTIF($B$5:$H$93,J16) -> 0 | L16: =K16/$K$19 -> 0
A17: Pivô 13 | J17: Desponte | K17: =COUNTIF($B$5:$H$93,J17) -> 0 | L17: =K17/$K$19 -> 0
A18: Pivô 14 | E18: Pulverização | J18: Gerador/Combustivel | K18: =COUNTIF($B$5:$H$93,J18) -> 0 | L18: =K18/$K$19 -> 0
A19: Pivô 15 | J19: Total | K19: =SUM(K5:K17) -> 7
A20: Pivô 16
A21: Pivô 17
A22: Pivô 18
A23: Pivô 19
A24: Pivô 20
A25: Pivô 21
A26: Pivô 22
A27: Pivô 23
A28: Pivô 24
A29: Pivô 25
A30: Pivô 26
A31: Pivô 27
... A33: Pivô 29
A34: Pivô 30 | B34: Plantio | C34: Plantio
A35: Pivô 31
A36: Pivô 32
A37: Pivô 33
A38: Pivô 34
A39: Pivô 35
A40: Pivô 36
A41: Pivô 37
A42: Pivô 38
...

Sheet 25 07 2022  
A1: Atendimento de irrigação (Imapacto Operacional Interno e Externo) - Semena 25/07/2022
A3: Data | B3: 44767 | C3: =B3+1 -> 44768 | D3: =C3+1 -> 44769 | E3: =D3+1 -> 44770 | F3: =E3+1 -> 44771 | G3: =F3+1 -> 44772 | H3: =G3+1 -> 44773
A4: Pivô | B4: =TEXT(B3,"ddd") -> seg | C4: =TEXT(C3,"ddd") -> ter | D4: =TEXT(D3,"ddd") -> qua | E4: =TEXT(E3,"ddd") -> qui | F4: =TEXT(F3,"ddd") -> sex | G4: =TEXT(G3,"ddd") -> sáb | H4: =TEXT(H3,"ddd") -> dom | J4: Parâmetros | K4: Contagem | L4: Porcentagem | M4: Semana
A5: Pivô 01 | J5: Pulverização | K5: =COUNTIF($B$5:$H$93,J5) -> 3 | L5: =K5/$K$19 -> 0.2 | M5: =B3 -> 44767
A6: Pivô 02 | J6: Adubação | K6: =COUNTIF($B$5:$H$93,J6) -> 2 | L6: =K6/$K$19 -> 0.13333333
A7: Pivô 03 | J7: Transplantio | K7: =COUNTIF($B$5:$H$93,J7) -> 0 | L7: =K7/$K$19 -> 0
A8: Pivô 04 | J8: Colheita Tabaco | K8: =COUNTIF($B$5:$H$93,J8) -> 2 | L8: =K8/$K$19 -> 0.13333333
A9: Pivô 05 | J9: Plantio | K9: =COUNTIF($B$5:$H$93,J9) -> 4 | L9: =K9/$K$19 -> 0.26666667
A10: Pivô 06 | J10: Erosão/Rastro | K10: =COUNTIF($B$5:$H$93,J10) -> 1 | L10: =K10/$K$19 -> 0.066666667
A11: Pivô 07 | D11: Colheita Tabaco | J11: Mecânico/Trator | K11: =COUNTIF($B$5:$H$93,J11) -> 0 | L11: =K11/$K$19 -> 0
A12: Pivô 08 | J12: Transporte | K12: =COUNTIF($B$5:$H$93,J12) -> 0 | L12: =K12/$K$19 -> 0
A13: Pivô 09 | J13: Pivô Atolado | K13: =COUNTIF($B$5:$H$93,J13) -> 0 | L13: =K13/$K$19 -> 0
A14: Pivô 10 | J14: Entrega do Produto | K14: =COUNTIF($B$5:$H$93,J14) -> 0 | L14: =K14/$K$19 -> 0
A15: Pivô 11 | E15: Desponte | J15: Limpeza e aferições | K15: =COUNTIF($B$5:$H$93,J15) -> 0 | L15: =K15/$K$19 -> 0
A16: Pivô 12 | J16: Falta de Água | K16: =COUNTIF($B$5:$H$93,J16) -> 0 | L16: =K16/$K$19 -> 0
A17: Pivô 13 | J17: Desponte | K17: =COUNTIF($B$5:$H$93,J17) -> 1 | L17: =K17/$K$19 -> 0.066666667
A18: Pivô 14 | J18: Gerador | K18: =COUNTIF($B$5:$H$93,J18) -> 2 | L18: =K18/$K$19 -> 0.13333333
A19: Pivô 15 | J19: Total | K19: =SUM(K5:K18) -> 15
A20: Pivô 16
A21: Pivô 17
A22: Pivô 18
A23: Pivô 19
A24: Pivô 20
A25: Pivô 21
A26: Pivô 22
A27: Pivô 23
A28: Pivô 24
A29: Pivô 25
A30: Pivô 26
A31: Pivô 27
... A33: Pivô 29
A34: Pivô 30 | B34: Gerador | C34: Plantio | D34: Plantio
A35: Pivô 31 | F35: Plantio | G35: Plantio
A36: Pivô 32
A37: Pivô 33
A38: Pivô 34
A39: Pivô 35
A40: Pivô 36 | F40: Colheita Tabaco
A41: Pivô 37
A42: Pivô 38
...

Sheet 01 08 2022   
A1: Atendimento de irrigação (Imapacto Operacional Interno e Externo) - Semena 01/08/2022
A3: Data | B3: 44774 | C3: =B3+1 -> 44775 | D3: =C3+1 -> 44776 | E3: =D3+1 -> 44777 | F3: =E3+1 -> 44778 | G3: =F3+1 -> 44779 | H3: =G3+1 -> 44780
A4: Pivô | B4: =TEXT(B3,"ddd") -> seg | C4: =TEXT(C3,"ddd") -> ter | D4: =TEXT(D3,"ddd") -> qua | E4: =TEXT(E3,"ddd") -> qui | F4: =TEXT(F3,"ddd") -> sex | G4: =TEXT(G3,"ddd") -> sáb | H4: =TEXT(H3,"ddd") -> dom | J4: Parâmetros | K4: Contagem | L4: Porcentagem | M4: Semana
A5: Pivô 01 | J5: Pulverização | K5: =COUNTIF($B$5:$H$93,J5) -> 4 | L5: =K5/$K$20 -> 0.4 | M5: =B3 -> 44774
A6: Pivô 02 | J6: Adubação | K6: =COUNTIF($B$5:$H$93,J6) -> 0 | L6: =K6/$K$20 -> 0
A7: Pivô 03 | J7: Transplantio | K7: =COUNTIF($B$5:$H$93,J7) -> 1 | L7: =K7/$K$20 -> 0.1
A8: Pivô 04 | J8: Colheita Tabaco | K8: =COUNTIF($B$5:$H$93,J8) -> 0 | L8: =K8/$K$20 -> 0
A9: Pivô 05 | J9: Plantio | K9: =COUNTIF($B$5:$H$93,J9) -> 2 | L9: =K9/$K$20 -> 0.2
A10: Pivô 06 | J10: Erosão/Rastro | K10: =COUNTIF($B$5:$H$93,J10) -> 2 | L10: =K10/$K$20 -> 0.2
A11: Pivô 07 | J11: Mecânico/Trator | K11: =COUNTIF($B$5:$H$93,J11) -> 1 | L11: =K11/$K$20 -> 0.1
A12: Pivô 08 | J12: Transporte | K12: =COUNTIF($B$5:$H$93,J12) -> 0 | L12: =K12/$K$20 -> 0
A13: Pivô 09 | J13: Pivô Atolado | K13: =COUNTIF($B$5:$H$93,J13) -> 0 | L13: =K13/$K$20 -> 0
A14: Pivô 10 | J14: Entrega do Produto | K14: =COUNTIF($B$5:$H$93,J14) -> 0 | L14: =K14/$K$20 -> 0
A15: Pivô 11 | J15: Limpeza e aferições | K15: =COUNTIF($B$5:$H$93,J15) -> 0 | L15: =K15/$K$20 -> 0
A16: Pivô 12 | J16: Falta de Água | K16: =COUNTIF($B$5:$H$93,J16) -> 0 | L16: =K16/$K$20 -> 0
A17: Pivô 13 | J17: Desponte | K17: =COUNTIF($B$5:$H$93,J17) -> 0 | L17: =K17/$K$20 -> 0
... A19: Pivô 15 | J19: Injeferd | K19: =COUNTIF($B$5:$H$93,J19) -> 1 | L19: =K19/$K$20 -> 0.1
A20: Pivô 16 | J20: Total | K20: =SUM(K5:K18) -> 10
A21: Pivô 17
