Workbook
Name SegmentaçãodeDados_Ano: #N/A
Name SegmentaçãodeDados_Periodo: #N/A
Name SegmentaçãodeDados_Semana: #N/A
Name semestre01de2022: Acumulado!$A$2:$V$32

Sheet Acumulado
A2: Parâmetros | B2: 44613 | C2: 44620 | D2: 44627 | E2: 44634 | F2: 44641 | G2: 44648 | H2: 44655 | I2: 44662 | J2: 44669 | K2: 44676 | L2: 44683 | M2: 44690 | N2: 44697 | O2: 44704 | P2: 44711 | Q2: 44718 | R2: 44725 | S2: 44732 | T2: 44739 | U2: Total | V2: Percentual
A3: Cabo Rompido | B3: ='21 02 2022'!K5 -> 3 | C3: ='28 02 2022'!K5 -> 1 | D3: ='07 03 2022'!K5 -> 0 | E3: ='14 03 2022'!K5 -> 0 | F3: ='21 03 2022'!K5 -> 0 | G3: ='28 03 2022'!K5 -> 1 | H3: ='04 04 2022'!K5 -> 0 | I3: ='11 04 2022'!K5 -> 0 | J3: ='18 04 2022'!K5 -> 0 | K3: ='25 04 2022'!K5 -> 0 | L3: ='02 05 2022'!K5 -> 0 | M3: ='09 05 2022'!K5 -> 0 | N3: ='16 05 2022'!K5 -> 0 | O3: ='23 05 2022 '!K5 -> 0 | Q3: ='06 06 2022 '!K5 -> 0 | R3: ='13 06 2022 '!K5 -> 0 | S3: ='20 06 2022 '!K5 -> 0 | T3: 0 | U3: =SUM(B3:T3) -> 5 | V3: =U3/$U$12 -> 0.034722222
A4: Transformador | B4: ='21 02 2022'!K6 -> 1 | C4: ='28 02 2022'!K6 -> 2 | D4: ='07 03 2022'!K6 -> 2 | E4: ='14 03 2022'!K6 -> 2 | F4: ='21 03 2022'!K6 -> 0 | G4: ='28 03 2022'!K6 -> 0 | H4: ='04 04 2022'!K6 -> 0 | I4: ='11 04 2022'!K6 -> 0 | J4: ='18 04 2022'!K6 -> 1 | K4: ='25 04 2022'!K6 -> 0 | L4: ='02 05 2022'!K6 -> 0 | M4: ='09 05 2022'!K6 -> 0 | N4: ='16 05 2022'!K6 -> 0 | O4: ='23 05 2022 '!K6 -> 0 | Q4: ='06 06 2022 '!K6 -> 0 | R4: ='13 06 2022 '!K6 -> 5 | S4: ='20 06 2022 '!K6 -> 0 | T4: 0 | U4: =SUM(B4:T4) -> 13 | V4: =U4/$U$12 -> 0.090277778
A5: Chave Aberta | B5: ='21 02 2022'!K7 -> 0 | C5: ='28 02 2022'!K7 -> 3 | D5: ='07 03 2022'!K7 -> 0 | E5: ='14 03 2022'!K7 -> 0 | F5: ='21 03 2022'!K7 -> 0 | G5: ='28 03 2022'!K7 -> 4 | H5: ='04 04 2022'!K7 -> 0 | I5: ='11 04 2022'!K7 -> 13 | J5: ='18 04 2022'!K7 -> 0 | K5: ='25 04 2022'!K7 -> 0 | L5: ='02 05 2022'!K7 -> 0 | M5: ='09 05 2022'!K7 -> 1 | N5: ='16 05 2022'!K7 -> 0 | O5: ='23 05 2022 '!K7 -> 0 | Q5: ='06 06 2022 '!K7 -> 0 | R5: ='13 06 2022 '!K7 -> 1 | S5: ='20 06 2022 '!K7 -> 1 | T5: 0 | U5: =SUM(B5:T5) -> 23 | V5: =U5/$U$12 -> 0.15972222
A6: Painel da Bomba | B6: ='21 02 2022'!K8 -> 5 | C6: ='28 02 2022'!K8 -> 2 | D6: ='07 03 2022'!K8 -> 0 | E6: ='14 03 2022'!K8 -> 3 | F6: ='21 03 2022'!K8 -> 1 | G6: ='28 03 2022'!K8 -> 0 | H6: ='04 04 2022'!K8 -> 1 | I6: ='11 04 2022'!K8 -> 0 | J6: ='18 04 2022'!K8 -> 2 | K6: ='25 04 2022'!K8 -> 2 | L6: ='02 05 2022'!K8 -> 2 | M6: ='09 05 2022'!K8 -> 2 | N6: ='16 05 2022'!K8 -> 3 | O6: ='23 05 2022 '!K8 -> 0 | Q6: ='06 06 2022 '!K8 -> 1 | R6: ='13 06 2022 '!K8 -> 1 | S6: ='20 06 2022 '!K8 -> 0 | T6: 0 | U6: =SUM(B6:T6) -> 25 | V6: =U6/$U$12 -> 0.17361111
A7: Painel do Pivô | B7: ='21 02 2022'!K9 -> 5 | C7: ='28 02 2022'!K9 -> 1 | D7: ='07 03 2022'!K9 -> 1 | E7: ='14 03 2022'!K9 -> 0 | F7: ='21 03 2022'!K9 -> 2 | G7: ='28 03 2022'!K9 -> 1 | H7: ='04 04 2022'!K9 -> 2 | I7: ='11 04 2022'!K9 -> 1 | J7: ='18 04 2022'!K9 -> 1 | K7: ='25 04 2022'!K9 -> 2 | L7: ='02 05 2022'!K9 -> 1 | M7: ='09 05 2022'!K9 -> 0 | N7: ='16 05 2022'!K9 -> 0 | O7: ='23 05 2022 '!K9 -> 0 | Q7: ='06 06 2022 '!K9 -> 1 | R7: ='13 06 2022 '!K9 -> 2 | S7: ='20 06 2022 '!K9 -> 0 | T7: 0 | U7: =SUM(B7:T7) -> 20 | V7: =U7/$U$12 -> 0.13888889
A8: Contactora | B8: ='21 02 2022'!K10 -> 0 | C8: ='28 02 2022'!K10 -> 5 | D8: ='07 03 2022'!K10 -> 3 | E8: ='14 03 2022'!K10 -> 1 | F8: ='21 03 2022'!K10 -> 0 | G8: ='28 03 2022'!K10 -> 1 | H8: ='04 04 2022'!K10 -> 0 | I8: ='11 04 2022'!K10 -> 0 | J8: ='18 04 2022'!K10 -> 0 | K8: ='25 04 2022'!K10 -> 1 | L8: ='02 05 2022'!K10 -> 0 | M8: ='09 05 2022'!K10 -> 0 | N8: ='16 05 2022'!K10 -> 5 | O8: ='23 05 2022 '!K10 -> 3 | Q8: ='06 06 2022 '!K10 -> 2 | R8: ='13 06 2022 '!K10 -> 0 | S8: ='20 06 2022 '!K10 -> 0 | T8: 0 | U8: =SUM(B8:T8) -> 21 | V8: =U8/$U$12 -> 0.14583333
A9: Caixa do Micro | B9: ='21 02 2022'!K11 -> 0 | C9: ='28 02 2022'!K11 -> 0 | D9: ='07 03 2022'!K11 -> 0 | E9: ='14 03 2022'!K11 -> 1 | F9: ='21 03 2022'!K11 -> 0 | G9: ='28 03 2022'!K11 -> 2 | H9: ='04 04 2022'!K11 -> 0 | I9: ='11 04 2022'!K11 -> 5 | J9: ='18 04 2022'!K11 -> 4 | K9: ='25 04 2022'!K11 -> 2 | L9: ='02 05 2022'!K11 -> 0 | M9: ='09 05 2022'!K11 -> 0 | N9: ='16 05 2022'!K11 -> 0 | O9: ='23 05 2022 '!K11 -> 0 | Q9: ='06 06 2022 '!K11 -> 0 | R9: ='13 06 2022 '!K11 -> 1 | S9: ='20 06 2022 '!K11 -> 0 | T9: 0 | U9: =SUM(B9:T9) -> 15 | V9: =U9/$U$12 -> 0.10416667
A10: Cabo de Segurança | B10: ='21 02 2022'!K12 -> 2 | C10: ='28 02 2022'!K12 -> 0 | D10: ='07 03 2022'!K12 -> 0 | E10: ='14 03 2022'!K12 -> 3 | F10: ='21 03 2022'!K12 -> 4 | G10: ='28 03 2022'!K12 -> 2 | H10: ='04 04 2022'!K12 -> 3 | I10: ='11 04 2022'!K12 -> 2 | J10: ='18 04 2022'!K12 -> 0 | K10: ='25 04 2022'!K12 -> 0 | L10: ='02 05 2022'!K12 -> 0 | M10: ='09 05 2022'!K12 -> 0 | N10: ='16 05 2022'!K12 -> 0 | O10: ='23 05 2022 '!K12 -> 1 | Q10: ='06 06 2022 '!K12 -> 0 | R10: ='13 06 2022 '!K12 -> 3 | S10: ='20 06 2022 '!K12 -> 0 | T10: 2 | U10: =SUM(B10:T10) -> 22 | V10: =U10/$U$12 -> 0.15277778
A11: Falta de Fase | B11: 0 | C11: 0 | D11: 0 | E11: 0 | F11: 0 | G11: 0 | H11: 0 | I11: 0 | J11: 0 | K11: ='25 04 2022'!K13 -> 2 | L11: ='02 05 2022'!K13 -> 0 | M11: ='09 05 2022'!K13 -> 0 | N11: ='16 05 2022'!K13 -> 0 | O11: ='23 05 2022 '!K13 -> 0 | Q11: ='06 06 2022 '!K13 -> 0 | R11: ='13 06 2022 '!K13 -> 0 | S11: ='20 06 2022 '!K13 -> 0 | T11: 0 | U11: =SUM(B11:T11) -> 2 | V11: =U11/$U$12 -> 0.013888889
A12: Total | B12: =SUM(B3:B10) -> 16 | C12: =SUM(C3:C10) -> 14 | D12: =SUM(D3:D10) -> 6 | E12: =SUM(E3:E10) -> 10 | F12: =SUM(F3:F10) -> 7 | G12: =SUM(G3:G10) -> 11 | H12: =SUM(H3:H10) -> 6 | I12: =SUM(I3:I10) -> 21 | ... T12: =SUM(T3:T10) -> 2 | U12: =SUM(B12:T12) -> 144

Sheet 21 02 2022
A1: Atendimento de Irrigação (Impacto - Problemas Elétricos) - Semana 21/02/2022
A3: Data | B3: 44613 | C3: 44614 | D3: 44615 | E3: 44616 | F3: 44617 | G3: 44618 | H3: 44619
A4: Pivô | B4: =TEXT(B3,"ddd") -> seg | C4: =TEXT(C3,"ddd") -> ter | D4: =TEXT(D3,"ddd") -> qua | E4: =TEXT(E3,"ddd") -> qui | F4: =TEXT(F3,"ddd") -> sex | G4: =TEXT(G3,"ddd") -> sáb | H4: =TEXT(H3,"ddd") -> dom | J4: Parâmetros | K4: Contagem | L4: Porcentagem | M4: Semana
A5: Pivô 01 | J5: Cabo Rompido | K5: =COUNTIF($B$5:$H$93,J5) -> 3 | L5: =K5/$K$13 -> 0.1875 | M5: 21/2-27/2
A6: Pivô 02 | J6: Transformador | K6: =COUNTIF($B$5:$H$93,J6) -> 1 | L6: =K6/$K$13 -> 0.0625
A7: Pivô 03 | J7: Chave Aberta | K7: =COUNTIF($B$5:$H$93,J7) -> 0 | L7: =K7/$K$13 -> 0
A8: Pivô 04 | J8: Painel da Bomba | K8: =COUNTIF($B$5:$H$93,J8) -> 5 | L8: =K8/$K$13 -> 0.3125
A9: Pivô 05 | J9: Painel do Pivô | K9: =COUNTIF($B$5:$H$93,J9) -> 5 | L9: =K9/$K$13 -> 0.3125
A10: Pivô 06 | J10: Contactora | K10: =COUNTIF($B$5:$H$93,J10) -> 0 | L10: =K10/$K$13 -> 0
A11: Pivô 07 | J11: Caixa do Micro | K11: =COUNTIF($B$5:$H$93,J11) -> 0 | L11: =K11/$K$13 -> 0
A12: Pivô 08 | J12: Cabo/Auto Rompido | K12: =COUNTIF($B$5:$H$93,J12) -> 2 | L12: =K12/$K$13 -> 0.125
A13: Pivô 09 | J13: Total | K13: =SUM(K5:K12) -> 16
A14: Pivô 10
A15: Pivô 11 | F15: Painel da Bomba
A16: Pivô 12
A17: Pivô 13
A18: Pivô 14 | G18: Painel do Pivô | H18: Painel do Pivô
A19: Pivô 15
A20: Pivô 16
A21: Pivô 17
A22: Pivô 18 | H22: Painel da Bomba
A23: Pivô 19
A24: Pivô 20 | F24: Painel da Bomba
A25: Pivô 21
A26: Pivô 22
A27: Pivô 23 | F27: Transformador
A28: Pivô 24 | H28: Cabo/Auto Rompido
A29: Pivô 25
A30: Pivô 26 | H30: Painel da Bomba
A31: Pivô 27
A32: Pivô 28
A33: Pivô 29
A34: Pivô 30
A35: Pivô 31
A36: Pivô 32
A37: Pivô 33
A38: Pivô 34
A39: Pivô 35
A40: Pivô 36
A41: Pivô 37
...

Sheet 28 02 2022
A1: Atendimento de Irrigação (Impacto - Problemas Elétricos) - Semana 28/02/2022
A3: Data | B3: 44620 | C3: =B3+1 -> 44621 | D3: =C3+1 -> 44622 | E3: =D3+1 -> 44623 | F3: =E3+1 -> 44624 | G3: =F3+1 -> 44625 | H3: =G3+1 -> 44626
A4: Pivô | B4: =TEXT(B3,"ddd") -> seg | C4: =TEXT(C3,"ddd") -> ter | D4: =TEXT(D3,"ddd") -> qua | E4: =TEXT(E3,"ddd") -> qui | F4: =TEXT(F3,"ddd") -> sex | G4: =TEXT(G3,"ddd") -> sáb | H4: =TEXT(H3,"ddd") -> dom | J4: Parâmetros | K4: Contagem | L4: Porcentagem | M4: Semana
A5: Pivô 01 | J5: Cabo Rompido | K5: =COUNTIF($B$5:$H$93,J5) -> 1 | L5: =K5/$K$13 -> 0.071428571 | M5: 28/2-6/3
A6: Pivô 02 | J6: Transformador | K6: =COUNTIF($B$5:$H$93,J6) -> 2 | L6: =K6/$K$13 -> 0.14285714
A7: Pivô 03 | J7: Chave Aberta | K7: =COUNTIF($B$5:$H$93,J7) -> 3 | L7: =K7/$K$13 -> 0.21428571
A8: Pivô 04 | J8: Painel da Bomba | K8: =COUNTIF($B$5:$H$93,J8) -> 2 | L8: =K8/$K$13 -> 0.14285714
A9: Pivô 05 | J9: Painel do Pivô | K9: =COUNTIF($B$5:$H$93,J9) -> 1 | L9: =K9/$K$13 -> 0.071428571
A10: Pivô 06 | J10: Contactora | K10: =COUNTIF($B$5:$H$93,J10) -> 5 | L10: =K10/$K$13 -> 0.35714286
A11: Pivô 07 | J11: Caixa do Micro | K11: =COUNTIF($B$5:$H$93,J11) -> 0 | L11: =K11/$K$13 -> 0
A12: Pivô 08 | J12: Cabo/Auto Rompido | K12: =COUNTIF($B$5:$H$93,J12) -> 0 | L12: =K12/$K$13 -> 0
A13: Pivô 09 | J13: Total | K13: =SUM(K5:K12) -> 14
A14: Pivô 10
A15: Pivô 11
A16: Pivô 12
A17: Pivô 13
A18: Pivô 14 | D18: Painel da Bomba
A19: Pivô 15
A20: Pivô 16
A21: Pivô 17
A22: Pivô 18
A23: Pivô 19
A24: Pivô 20
A25: Pivô 21
A26: Pivô 22
A27: Pivô 23
A28: Pivô 24
A29: Pivô 25 | B29: Painel da Bomba
A30: Pivô 26
A31: Pivô 27
A32: Pivô 28
A33: Pivô 29
A34: Pivô 30 | B34: Contactora | C34: Contactora
A35: Pivô 31
A36: Pivô 32
A37: Pivô 33 | G37: Contactora | H37: Contactora
A38: Pivô 34
A39: Pivô 35
A40: Pivô 36
A41: Pivô 37
...

Sheet 07 03 2022
A1: Atendimento de Irrigação (Impacto - Problemas Elétricos) - Semana 07/03/2022
A3: Data | B3: 44627 | C3: =B3+1 -> 44628 | D3: =C3+1 -> 44629 | E3: =D3+1 -> 44630 | F3: =E3+1 -> 44631 | G3: =F3+1 -> 44632 | H3: =G3+1 -> 44633
A4: Pivô | B4: =TEXT(B3,"ddd") -> seg | C4: =TEXT(C3,"ddd") -> ter | D4: =TEXT(D3,"ddd") -> qua | E4: =TEXT(E3,"ddd") -> qui | F4: =TEXT(F3,"ddd") -> sex | G4: =TEXT(G3,"ddd") -> sáb | H4: =TEXT(H3,"ddd") -> dom | J4: Parâmetros | K4: Contagem | L4: Porcentagem | M4: Semana
A5: Pivô 01 | J5: Cabo Acionamento | K5: =COUNTIF($B$5:$H$93,J5) -> 0 | L5: =K5/$K$13 -> 0 | M5: 7/3-13/3
A6: Pivô 02 | J6: Transformador | K6: =COUNTIF($B$5:$H$93,J6) -> 2 | L6: =K6/$K$13 -> 0.33333333
A7: Pivô 03 | J7: Chave Aberta | K7: =COUNTIF($B$5:$H$93,J7) -> 0 | L7: =K7/$K$13 -> 0
A8: Pivô 04 | J8: Painel da Bomba | K8: =COUNTIF($B$5:$H$93,J8) -> 0 | L8: =K8/$K$13 -> 0
A9: Pivô 05 | J9: Painel do Pivô | K9: =COUNTIF($B$5:$H$93,J9) -> 1 | L9: =K9/$K$13 -> 0.16666667
A10: Pivô 06 | J10: Contactora | K10: =COUNTIF($B$5:$H$93,J10) -> 3 | L10: =K10/$K$13 -> 0.5
A11: Pivô 07 | J11: Caixa do Micro | K11: =COUNTIF($B$5:$H$93,J11) -> 0 | L11: =K11/$K$13 -> 0
A12: Pivô 08 | J12: Cabo de Segurança | K12: =COUNTIF($B$5:$H$93,J12) -> 0 | L12: =K12/$K$13 -> 0
A13: Pivô 09 | J13: Total | K13: =SUM(K5:K12) -> 6
A14: Pivô 10
A15: Pivô 11
A16: Pivô 12
A17: Pivô 13
A18: Pivô 14
A19: Pivô 15
A20: Pivô 16
A21: Pivô 17
A22: Pivô 18
A23: Pivô 19
A24: Pivô 20
A25: Pivô 21
... A28: Pivô 24
A29: Pivô 25 | G29: Contactora
A30: Pivô 26
A31: Pivô 27 | F31: Contactora
A32: Pivô 28
A33: Pivô 29
A34: Pivô 30
A35: Pivô 31
A36: Pivô 32
A37: Pivô 33
A38: Pivô 34
A39: Pivô 35
A40: Pivô 36
A41: Pivô 37
A42: Pivô 38
A43: Pivô 39
...

Sheet 14 03 2022
A1: Atendimento de Irrigação (Impacto - Problemas Elétricos) - Semana 14/03/2022
A3: Data | B3: 44634 | C3: =B3+1 -> 44635 | D3: =C3+1 -> 44636 | E3: =D3+1 -> 44637 | F3: =E3+1 -> 44638 | G3: =F3+1 -> 44639 | H3: =G3+1 -> 44640
A4: Pivô | B4: =TEXT(B3,"ddd") -> seg | C4: =TEXT(C3,"ddd") -> ter | D4: =TEXT(D3,"ddd") -> qua | E4: =TEXT(E3,"ddd") -> qui | F4: =TEXT(F3,"ddd") -> sex | G4: =TEXT(G3,"ddd") -> sáb | H4: =TEXT(H3,"ddd") -> dom | J4: Parâmetros | K4: Contagem | L4: Porcentagem | M4: Semana
A5: Pivô 01 | J5: Cabo Acionamento | K5: =COUNTIF($B$5:$H$93,J5) -> 0 | L5: =K5/$K$13 -> 0 | M5: 14/3-20/3
A6: Pivô 02 | J6: Transformador | K6: =COUNTIF($B$5:$H$93,J6) -> 2 | L6: =K6/$K$13 -> 0.2
A7: Pivô 03 | J7: Chave Aberta | K7: =COUNTIF($B$5:$H$93,J7) -> 0 | L7: =K7/$K$13 -> 0
A8: Pivô 04 | J8: Painel da Bomba | K8: =COUNTIF($B$5:$H$93,J8) -> 3 | L8: =K8/$K$13 -> 0.3
A9: Pivô 05 | J9: Painel do Pivô | K9: =COUNTIF($B$5:$H$93,J9) -> 0 | L9: =K9/$K$13 -> 0
A10: Pivô 06 | C10: Caixa do Micro | D10: Painel da Bomba | J10: Contactora | K10: =COUNTIF($B$5:$H$93,J10) -> 1 | L10: =K10/$K$13 -> 0.1
A11: Pivô 07 | J11: Caixa do Micro | K11: =COUNTIF($B$5:$H$93,J11) -> 1 | L11: =K11/$K$13 -> 0.1
A12: Pivô 08 | J12: Cabo de Segurança | K12: =COUNTIF($B$5:$H$93,J12) -> 3 | L12: =K12/$K$13 -> 0.3
A13: Pivô 09 | J13: Total | K13: =SUM(K5:K12) -> 10
A14: Pivô 10
A15: Pivô 11
A16: Pivô 12
A17: Pivô 13
A18: Pivô 14
A19: Pivô 15
A20: Pivô 16
A21: Pivô 17
A22: Pivô 18
A23: Pivô 19
A24: Pivô 20
A25: Pivô 21 | H25: Cabo de Segurança
A26: Pivô 22
A27: Pivô 23
A28: Pivô 24
A29: Pivô 25 | D29: Contactora
A30: Pivô 26 | H30: Cabo de Segurança
A31: Pivô 27
A32: Pivô 28
A33: Pivô 29
A34: Pivô 30
A35: Pivô 31
A36: Pivô 32
A37: Pivô 33
A38: Pivô 34
A39: Pivô 35 | B39: Transformador | C39: Transformador
A40: Pivô 36
A41: Pivô 37 | G41: Cabo de Segurança
...

Sheet 21 03 2022
A1: Atendimento de Irrigação (Impacto - Problemas Elétricos) - Semana 21/03/2022
A3: Data | B3: 44641 | C3: =B3+1 -> 44642 | D3: =C3+1 -> 44643 | E3: =D3+1 -> 44644 | F3: =E3+1 -> 44645 | G3: =F3+1 -> 44646 | H3: =G3+1 -> 44647
A4: Pivô | B4: =TEXT(B3,"ddd") -> seg | C4: =TEXT(C3,"ddd") -> ter | D4: =TEXT(D3,"ddd") -> qua | E4: =TEXT(E3,"ddd") -> qui | F4: =TEXT(F3,"ddd") -> sex | G4: =TEXT(G3,"ddd") -> sáb | H4: =TEXT(H3,"ddd") -> dom | J4: Parâmetros | K4: Contagem | L4: Porcentagem | M4: Semana
A5: Pivô 01 | J5: Cabo Acionamento | K5: =COUNTIF($B$5:$H$93,J5) -> 0 | L5: =K5/$K$13 -> 0 | M5: 21/3-27/3
A6: Pivô 02 | J6: Transformador | K6: =COUNTIF($B$5:$H$93,J6) -> 0 | L6: =K6/$K$13 -> 0
A7: Pivô 03 | J7: Chave Aberta | K7: =COUNTIF($B$5:$H$93,J7) -> 0 | L7: =K7/$K$13 -> 0
A8: Pivô 04 | J8: Painel da Bomba | K8: =COUNTIF($B$5:$H$93,J8) -> 1 | L8: =K8/$K$13 -> 0.14285714
A9: Pivô 05 | J9: Painel do Pivô | K9: =COUNTIF($B$5:$H$93,J9) -> 2 | L9: =K9/$K$13 -> 0.28571429
A10: Pivô 06 | J10: Contactora | K10: =COUNTIF($B$5:$H$93,J10) -> 0 | L10: =K10/$K$13 -> 0
A11: Pivô 07 | J11: Caixa do Micro | K11: =COUNTIF($B$5:$H$93,J11) -> 0 | L11: =K11/$K$13 -> 0
A12: Pivô 08 | J12: Cabo de Segurança | K12: =COUNTIF($B$5:$H$93,J12) -> 4 | L12: =K12/$K$13 -> 0.57142857
A13: Pivô 09 | J13: Total | K13: =SUM(K5:K12) -> 7
A14: Pivô 10
A15: Pivô 11
A16: Pivô 12
A17: Pivô 13
A18: Pivô 14
A19: Pivô 15
A20: Pivô 16 | B20: Cabo de Segurança
A21: Pivô 17
A22: Pivô 18
A23: Pivô 19
A24: Pivô 20
A25: Pivô 21 | D25: Cabo de Segurança | G25: Cabo de Segurança
A26: Pivô 22
A27: Pivô 23
A28: Pivô 24
A29: Pivô 25
A30: Pivô 26
A31: Pivô 27 | C31: Painel do Pivô
A32: Pivô 28 | B32: Painel do Pivô
A33: Pivô 29
A34: Pivô 30
A35: Pivô 31 | B35: Painel da Bomba
A36: Pivô 32
A37: Pivô 33
A38: Pivô 34
A39: Pivô 35
A40: Pivô 36
A41: Pivô 37
...

Sheet 28 03 2022
A1: Atendimento de Irrigação (Impacto - Problemas Elétricos) - Semana 28/03/2022
A3: Data | B3: 44648 | C3: =B3+1 -> 44649 | D3: =C3+1 -> 44650 | E3: =D3+1 -> 44651 | F3: =E3+1 -> 44652 | G3: =F3+1 -> 44653 | H3: =G3+1 -> 44654
A4: Pivô | B4: =TEXT(B3,"ddd") -> seg | C4: =TEXT(C3,"ddd") -> ter | D4: =TEXT(D3,"ddd") -> qua | E4: =TEXT(E3,"ddd") -> qui | F4: =TEXT(F3,"ddd") -> sex | G4: =TEXT(G3,"ddd") -> sáb | H4: =TEXT(H3,"ddd") -> dom | J4: Parâmetros | K4: Contagem | L4: Porcentagem | M4: Semana
A5: Pivô 01 | J5: Cabo Acionamento | K5: =COUNTIF($B$5:$H$93,J5) -> 1 | L5: =K5/$K$13 -> 0.090909091 | M5: 28/3-3/4
A6: Pivô 02 | J6: Transformador | K6: =COUNTIF($B$5:$H$93,J6) -> 0 | L6: =K6/$K$13 -> 0
A7: Pivô 03 | J7: Chave Aberta | K7: =COUNTIF($B$5:$H$93,J7) -> 4 | L7: =K7/$K$13 -> 0.36363636
A8: Pivô 04 | J8: Painel da Bomba | K8: =COUNTIF($B$5:$H$93,J8) -> 0 | L8: =K8/$K$13 -> 0
A9: Pivô 05 | B9: Caixa do Micro | J9: Painel do Pivô | K9: =COUNTIF($B$5:$H$93,J9) -> 1 | L9: =K9/$K$13 -> 0.090909091
A10: Pivô 06 | F10: Painel do Pivô | G10: Caixa do Micro | J10: Contactora | K10: =COUNTIF($B$5:$H$93,J10) -> 1 | L10: =K10/$K$13 -> 0.090909091
A11: Pivô 07 | J11: Caixa do Micro | K11: =COUNTIF($B$5:$H$93,J11) -> 2 | L11: =K11/$K$13 -> 0.18181818
A12: Pivô 08 | J12: Cabo de Segurança | K12: =COUNTIF($B$5:$H$93,J12) -> 2 | L12: =K12/$K$13 -> 0.18181818
A13: Pivô 09 | J13: Total | K13: =SUM(K5:K12) -> 11
A14: Pivô 10
A15: Pivô 11
A16: Pivô 12
A17: Pivô 13
A18: Pivô 14
A19: Pivô 15
A20: Pivô 16
A21: Pivô 17 | B21: Contactora
A22: Pivô 18
A23: Pivô 19
A24: Pivô 20
A25: Pivô 21 | B25: Cabo de Segurança | E25: Cabo de Segurança
A26: Pivô 22
A27: Pivô 23
A28: Pivô 24
A29: Pivô 25
A30: Pivô 26
A31: Pivô 27
A32: Pivô 28
A33: Pivô 29
A34: Pivô 30
A35: Pivô 31
A36: Pivô 32
A37: Pivô 33
... A47: Pivô 43
A48: Pivô 44 | G48: Chave Aberta
A49: Pivô 45
A50: Pivô 46
...

Sheet 04 04 2022
A1: Atendimento de Irrigação (Impacto - Problemas Elétricos) - Semana 04/04/2022
A3: Data | B3: 44655 | C3: =B3+1 -> 44656 | D3: =C3+1 -> 44657 | E3: =D3+1 -> 44658 | F3: =E3+1 -> 44659 | G3: =F3+1 -> 44660 | H3: =G3+1 -> 44661
A4: Pivô | B4: =TEXT(B3,"ddd") -> seg | C4: =TEXT(C3,"ddd") -> ter | D4: =TEXT(D3,"ddd") -> qua | E4: =TEXT(E3,"ddd") -> qui | F4: =TEXT(F3,"ddd") -> sex | G4: =TEXT(G3,"ddd") -> sáb | H4: =TEXT(H3,"ddd") -> dom | J4: Parâmetros | K4: Contagem | L4: Porcentagem | M4: Semana
A5: Pivô 01 | J5: Cabo Acionamento | K5: =COUNTIF($B$5:$H$93,J5) -> 0 | L5: =K5/$K$13 -> 0 | M5: 4/4-10/4
A6: Pivô 02 | J6: Transformador | K6: =COUNTIF($B$5:$H$93,J6) -> 0 | L6: =K6/$K$13 -> 0
A7: Pivô 03 | J7: Chave Aberta | K7: =COUNTIF($B$5:$H$93,J7) -> 0 | L7: =K7/$K$13 -> 0
A8: Pivô 04 | J8: Painel da Bomba | K8: =COUNTIF($B$5:$H$93,J8) -> 1 | L8: =K8/$K$13 -> 0.16666667
A9: Pivô 05 | J9: Painel do Pivô | K9: =COUNTIF($B$5:$H$93,J9) -> 2 | L9: =K9/$K$13 -> 0.33333333
A10: Pivô 06 | J10: Contactora | K10: =COUNTIF($B$5:$H$93,J10) -> 0 | L10: =K10/$K$13 -> 0
A11: Pivô 07 | J11: Caixa do Micro | K11: =COUNTIF($B$5:$H$93,J11) -> 0 | L11: =K11/$K$13 -> 0
A12: Pivô 08 | J12: Cabo de Segurança | K12: =COUNTIF($B$5:$H$93,J12) -> 3 | L12: =K12/$K$13 -> 0.5
A13: Pivô 09 | J13: Total | K13: =SUM(K5:K12) -> 6
A14: Pivô 10
A15: Pivô 11 | C15: Painel do Pivô
A16: Pivô 12
A17: Pivô 13
A18: Pivô 14
A19: Pivô 15
A20: Pivô 16
A21: Pivô 17 | H21: Painel do Pivô
A22: Pivô 18
A23: Pivô 19
A24: Pivô 20
A25: Pivô 21 | B25: Cabo de Segurança | F25: Cabo de Segurança | H25: Cabo de Segurança
A26: Pivô 22
A27: Pivô 23
A28: Pivô 24
A29: Pivô 25
A30: Pivô 26
A31: Pivô 27
A32: Pivô 28
A33: Pivô 29
A34: Pivô 30
A35: Pivô 31 | G35: Painel da Bomba
A36: Pivô 32
A37: Pivô 33
A38: Pivô 34
A39: Pivô 35
A40: Pivô 36
A41: Pivô 37
...

Sheet 11 04 2022
A1: Atendimento de Irrigação (Impacto - Problemas Elétricos) - Semana 11/04/2022
A3: Data | B3: 44662 | C3: =B3+1 -> 44663 | D3: =C3+1 -> 44664 | E3: =D3+1 -> 44665 | F3: =E3+1 -> 44666 | G3: =F3+1 -> 44667 | H3: =G3+1 -> 44668
A4: Pivô | B4: =TEXT(B3,"ddd") -> seg | C4: =TEXT(C3,"ddd") -> ter | D4: =TEXT(D3,"ddd") -> qua | E4: =TEXT(E3,"ddd") -> qui | F4: =TEXT(F3,"ddd") -> sex | G4: =TEXT(G3,"ddd") -> sáb | H4: =TEXT(H3,"ddd") -> dom | J4: Parâmetros | K4: Contagem | L4: Porcentagem | M4: Semana
A5: Pivô 01 | F5: Caixa do Micro | H5: Caixa do Micro | J5: Cabo Acionamento | K5: =COUNTIF($B$5:$H$93,J5) -> 0 | L5: =K5/$K$13 -> 0 | M5: 11/4-17/4
A6: Pivô 02 | H6: Chave Aberta | J6: Transformador | K6: =COUNTIF($B$5:$H$93,J6) -> 0 | L6: =K6/$K$13 -> 0
A7: Pivô 03 | J7: Chave Aberta | K7: =COUNTIF($B$5:$H$93,J7) -> 13 | L7: =K7/$K$13 -> 0.61904762
A8: Pivô 04 | J8: Painel da Bomba | K8: =COUNTIF($B$5:$H$93,J8) -> 0 | L8: =K8/$K$13 -> 0
A9: Pivô 05 | H9: Chave Aberta | J9: Painel do Pivô | K9: =COUNTIF($B$5:$H$93,J9) -> 1 | L9: =K9/$K$13 -> 0.047619048
A10: Pivô 06 | H10: Chave Aberta | J10: Contactora | K10: =COUNTIF($B$5:$H$93,J10) -> 0 | L10: =K10/$K$13 -> 0
A11: Pivô 07 | J11: Caixa do Micro | K11: =COUNTIF($B$5:$H$93,J11) -> 5 | L11: =K11/$K$13 -> 0.23809524
A12: Pivô 08 | J12: Cabo de Segurança | K12: =COUNTIF($B$5:$H$93,J12) -> 2 | L12: =K12/$K$13 -> 0.095238095
A13: Pivô 09 | J13: Total | K13: =SUM(K5:K12) -> 21
A14: Pivô 10 | H14: Chave Aberta
A15: Pivô 11
A16: Pivô 12 | D16: Painel do Pivô
A17: Pivô 13
A18: Pivô 14
A19: Pivô 15
A20: Pivô 16 | H20: Chave Aberta
A21: Pivô 17
A22: Pivô 18 | H22: Chave Aberta
A23: Pivô 19
A24: Pivô 20 | H24: Chave Aberta
A25: Pivô 21
A26: Pivô 22 | H26: Chave Aberta
A27: Pivô 23
A28: Pivô 24 | H28: Chave Aberta
A29: Pivô 25
A30: Pivô 26 | H30: Chave Aberta
A31: Pivô 27
A32: Pivô 28
A33: Pivô 29 | H33: Chave Aberta
A34: Pivô 30
A35: Pivô 31
A36: Pivô 32 | H36: Chave Aberta
A37: Pivô 33 | H37: Chave Aberta
A38: Pivô 34
A39: Pivô 35
A40: Pivô 36
A41: Pivô 37
...

Sheet 18 04 2022
A1: Atendimento de Irrigação (Impacto - Problemas Elétricos) - Semana 04/04/2022
A3: Data | B3: 44669 | C3: =B3+1 -> 44670 | D3: =C3+1 -> 44671 | E3: =D3+1 -> 44672 | F3: =E3+1 -> 44673 | G3: =F3+1 -> 44674 | H3: =G3+1 -> 44675
A4: Pivô | B4: =TEXT(B3,"ddd") -> seg | C4: =TEXT(C3,"ddd") -> ter | D4: =TEXT(D3,"ddd") -> qua | E4: =TEXT(E3,"ddd") -> qui | F4: =TEXT(F3,"ddd") -> sex | G4: =TEXT(G3,"ddd") -> sáb | H4: =TEXT(H3,"ddd") -> dom | J4: Parâmetros | K4: Contagem | L4: Porcentagem | M4: Semana
A5: Pivô 01 | J5: Cabo Acionamento | K5: =COUNTIF($B$5:$H$93,J5) -> 0 | L5: =K5/$K$13 -> 0 | M5: 18/2-24/4
A6: Pivô 02 | J6: Transformador | K6: =COUNTIF($B$5:$H$93,J6) -> 1 | L6: =K6/$K$13 -> 0.125
A7: Pivô 03 | J7: Chave Aberta | K7: =COUNTIF($B$5:$H$93,J7) -> 0 | L7: =K7/$K$13 -> 0
A8: Pivô 04 | J8: Painel da Bomba | K8: =COUNTIF($B$5:$H$93,J8) -> 2 | L8: =K8/$K$13 -> 0.25
A9: Pivô 05 | F9: Caixa do Micro | G9: Caixa do Micro | H9: Caixa do Micro | J9: Painel do Pivô | K9: =COUNTIF($B$5:$H$93,J9) -> 1 | L9: =K9/$K$13 -> 0.125
A10: Pivô 06 | J10: Contactora | K10: =COUNTIF($B$5:$H$93,J10) -> 0 | L10: =K10/$K$13 -> 0
A11: Pivô 07 | J11: Caixa do Micro | K11: =COUNTIF($B$5:$H$93,J11) -> 4 | L11: =K11/$K$13 -> 0.5
A12: Pivô 08 | J12: Cabo de Segurança | K12: =COUNTIF($B$5:$H$93,J12) -> 0 | L12: =K12/$K$13 -> 0
A13: Pivô 09 | J13: Total | K13: =SUM(K5:K12) -> 8
A14: Pivô 10 | F14: Caixa do Micro
A15: Pivô 11
A16: Pivô 12
A17: Pivô 13
A18: Pivô 14
A19: Pivô 15
A20: Pivô 16
A21: Pivô 17
A22: Pivô 18
A23: Pivô 19
A24: Pivô 20
A25: Pivô 21 | H25: Painel do Pivô
A26: Pivô 22
A27: Pivô 23
A28: Pivô 24
A29: Pivô 25
A30: Pivô 26
A31: Pivô 27
A32: Pivô 28
A33: Pivô 29
A34: Pivô 30
A35: Pivô 31
A36: Pivô 32
A37: Pivô 33
... A44: Pivô 40
A45: Pivô 41 | C45: Painel da Bomba | D45: Painel da Bomba | E45: Transformador
A46: Pivô 42
A47: Pivô 43
...

Sheet 25 04 2022
A1: Atendimento de Irrigação (Impacto - Problemas Elétricos) - Semana 25/04/2022
A3: Data | B3: 44676 | C3: =B3+1 -> 44677 | D3: =C3+1 -> 44678 | E3: =D3+1 -> 44679 | F3: =E3+1 -> 44680 | G3: =F3+1 -> 44681 | H3: =G3+1 -> 44682
A4: Pivô | B4: =TEXT(B3,"ddd") -> seg | C4: =TEXT(C3,"ddd") -> ter | D4: =TEXT(D3,"ddd") -> qua | E4: =TEXT(E3,"ddd") -> qui | F4: =TEXT(F3,"ddd") -> sex | G4: =TEXT(G3,"ddd") -> sáb | H4: =TEXT(H3,"ddd") -> dom | J4: Parâmetros | K4: Contagem | L4: Porcentagem | M4: Semana
A5: Pivô 01 | E5: Caixa do Micro | F5: Caixa do Micro | J5: Cabo Acionamento | K5: =COUNTIF($B$5:$H$93,J5) -> 0 | L5: =K5/$K$14 -> 0 | M5: 25/4-1/5
A6: Pivô 02 | J6: Transformador | K6: =COUNTIF($B$5:$H$93,J6) -> 0 | L6: =K6/$K$14 -> 0
A7: Pivô 03 | J7: Chave Aberta | K7: =COUNTIF($B$5:$H$93,J7) -> 0 | L7: =K7/$K$14 -> 0
A8: Pivô 04 | J8: Painel da Bomba | K8: =COUNTIF($B$5:$H$93,J8) -> 2 | L8: =K8/$K$14 -> 0.22222222
A9: Pivô 05 | J9: Painel do Pivô | K9: =COUNTIF($B$5:$H$93,J9) -> 2 | L9: =K9/$K$14 -> 0.22222222
A10: Pivô 06 | J10: Contactora | K10: =COUNTIF($B$5:$H$93,J10) -> 1 | L10: =K10/$K$14 -> 0.11111111
A11: Pivô 07 | J11: Caixa do Micro | K11: =COUNTIF($B$5:$H$93,J11) -> 2 | L11: =K11/$K$14 -> 0.22222222
A12: Pivô 08 | J12: Cabo de Segurança | K12: =COUNTIF($B$5:$H$93,J12) -> 0 | L12: =K12/$K$14 -> 0
A13: Pivô 09 | J13: Falta de Fase | K13: =COUNTIF($B$5:$H$93,J13) -> 2 | L13: =K13/$K$14 -> 0.22222222
A14: Pivô 10 | J14: Total | K14: =SUM(K5:K13) -> 9
A15: Pivô 11
A16: Pivô 12
A17: Pivô 13
A18: Pivô 14
A19: Pivô 15
A20: Pivô 16
A21: Pivô 17
A22: Pivô 18
A23: Pivô 19
A24: Pivô 20 | B24: Contactora
A25: Pivô 21 | C25: Painel do Pivô | H25: Painel da Bomba
A26: Pivô 22
A27: Pivô 23 | G27: Falta de Fase
A28: Pivô 24 | G28: Falta de Fase
A29: Pivô 25
A30: Pivô 26
A31: Pivô 27
A32: Pivô 28
A33: Pivô 29
A34: Pivô 30
A35: Pivô 31 | G35: Painel do Pivô
A36: Pivô 32
A37: Pivô 33
A38: Pivô 34 | G38: Painel da Bomba
A39: Pivô 35
A40: Pivô 36
A41: Pivô 37
...

Sheet 02 05 2022
A1: Atendimento de Irrigação (Impacto - Problemas Elétricos) - Semana 02/05/2022
A3: Data | B3: 44683 | C3: =B3+1 -> 44684 | D3: =C3+1 -> 44685 | E3: =D3+1 -> 44686 | F3: =E3+1 -> 44687 | G3: =F3+1 -> 44688 | H3: =G3+1 -> 44689
A4: Pivô | B4: =TEXT(B3,"ddd") -> seg | C4: =TEXT(C3,"ddd") -> ter | D4: =TEXT(D3,"ddd") -> qua | E4: =TEXT(E3,"ddd") -> qui | F4: =TEXT(F3,"ddd") -> sex | G4: =TEXT(G3,"ddd") -> sáb | H4: =TEXT(H3,"ddd") -> dom | J4: Parâmetros | K4: Contagem | L4: Porcentagem | M4: Semana
A5: Pivô 01 | J5: Cabo Acionamento | K5: =COUNTIF($B$5:$H$93,J5) -> 0 | L5: =K5/$K$14 -> 0 | M5: 2/5-8/5
A6: Pivô 02 | J6: Transformador | K6: =COUNTIF($B$5:$H$93,J6) -> 0 | L6: =K6/$K$14 -> 0
A7: Pivô 03 | J7: Chave Aberta | K7: =COUNTIF($B$5:$H$93,J7) -> 0 | L7: =K7/$K$14 -> 0
A8: Pivô 04 | J8: Painel da Bomba | K8: =COUNTIF($B$5:$H$93,J8) -> 2 | L8: =K8/$K$14 -> 0.66666667
A9: Pivô 05 | J9: Painel do Pivô | K9: =COUNTIF($B$5:$H$93,J9) -> 1 | L9: =K9/$K$14 -> 0.33333333
A10: Pivô 06 | J10: Contactora | K10: =COUNTIF($B$5:$H$93,J10) -> 0 | L10: =K10/$K$14 -> 0
A11: Pivô 07 | J11: Caixa do Micro | K11: =COUNTIF($B$5:$H$93,J11) -> 0 | L11: =K11/$K$14 -> 0
A12: Pivô 08 | J12: Cabo de Segurança | K12: =COUNTIF($B$5:$H$93,J12) -> 0 | L12: =K12/$K$14 -> 0
A13: Pivô 09 | J13: Falta de Fase | K13: =COUNTIF($B$5:$H$93,J13) -> 0 | L13: =K13/$K$14 -> 0
A14: Pivô 10 | J14: Total | K14: =SUM(K5:K12) -> 3
A15: Pivô 11
A16: Pivô 12
A17: Pivô 13
A18: Pivô 14
A19: Pivô 15
A20: Pivô 16
A21: Pivô 17
A22: Pivô 18
A23: Pivô 19
A24: Pivô 20
A25: Pivô 21 | E25: Painel da Bomba | G25: Painel da Bomba
A26: Pivô 22
A27: Pivô 23
A28: Pivô 24
A29: Pivô 25
A30: Pivô 26
A31: Pivô 27
A32: Pivô 28
A33: Pivô 29
A34: Pivô 30
A35: Pivô 31
A36: Pivô 32
A37: Pivô 33
... A51: Pivô 47
A52: Pivô 48 | C52: Painel do Pivô
A53: Pivô 49
A54: Pivô 50
...

Sheet 09 05 2022
A1: Atendimento de Irrigação (Impacto - Problemas Elétricos) - Semana 09/05/2022
A3: Data | B3: 44690 | C3: =B3+1 -> 44691 | D3: =C3+1 -> 44692 | E3: =D3+1 -> 44693 | F3: =E3+1 -> 44694 | G3: =F3+1 -> 44695 | H3: =G3+1 -> 44696
A4: Pivô | B4: =TEXT(B3,"ddd") -> seg | C4: =TEXT(C3,"ddd") -> ter | D4: =TEXT(D3,"ddd") -> qua | E4: =TEXT(E3,"ddd") -> qui | F4: =TEXT(F3,"ddd") -> sex | G4: =TEXT(G3,"ddd") -> sáb | H4: =TEXT(H3,"ddd") -> dom | J4: Parâmetros | K4: Contagem | L4: Porcentagem | M4: Semana
A5: Pivô 01 | J5: Cabo Acionamento | K5: =COUNTIF($B$5:$H$93,J5) -> 0 | L5: =K5/$K$14 -> 0 | M5: 9/5-15/5
A6: Pivô 02 | J6: Transformador | K6: =COUNTIF($B$5:$H$93,J6) -> 0 | L6: =K6/$K$14 -> 0
A7: Pivô 03 | J7: Chave Aberta | K7: =COUNTIF($B$5:$H$93,J7) -> 1 | L7: =K7/$K$14 -> 0.33333333
A8: Pivô 04 | J8: Painel da Bomba | K8: =COUNTIF($B$5:$H$93,J8) -> 2 | L8: =K8/$K$14 -> 0.66666667
A9: Pivô 05 | J9: Painel do Pivô | K9: =COUNTIF($B$5:$H$93,J9) -> 0 | L9: =K9/$K$14 -> 0
A10: Pivô 06 | J10: Contactora | K10: =COUNTIF($B$5:$H$93,J10) -> 0 | L10: =K10/$K$14 -> 0
A11: Pivô 07 | J11: Caixa do Micro | K11: =COUNTIF($B$5:$H$93,J11) -> 0 | L11: =K11/$K$14 -> 0
A12: Pivô 08 | J12: Cabo de Segurança | K12: =COUNTIF($B$5:$H$93,J12) -> 0 | L12: =K12/$K$14 -> 0
A13: Pivô 09 | J13: Falta de Fase | K13: =COUNTIF($B$5:$H$93,J13) -> 0 | L13: =K13/$K$14 -> 0
A14: Pivô 10 | J14: Total | K14: =SUM(K5:K12) -> 3
A15: Pivô 11
A16: Pivô 12
A17: Pivô 13
A18: Pivô 14
A19: Pivô 15
A20: Pivô 16
A21: Pivô 17
A22: Pivô 18 | J22: Dashboard Indicadores'!A1
A23: Pivô 19
A24: Pivô 20
A25: Pivô 21 | B25: Painel da Bomba | E25: Painel da Bomba
A26: Pivô 22
A27: Pivô 23
A28: Pivô 24
A29: Pivô 25
A30: Pivô 26
A31: Pivô 27
A32: Pivô 28
A33: Pivô 29
A34: Pivô 30
A35: Pivô 31
A36: Pivô 32
A37: Pivô 33
... A53: Pivô 49
A54: Pivô 50 | D54: Chave Aberta
A55: Pivô 51
A56: Pivô 52
...

Sheet 16 05 2022
A1: Atendimento de Irrigação (Impacto - Problemas Elétricos) - Semana 16/05/2022
A3: Data | B3: 44697 | C3: =B3+1 -> 44698 | D3: =C3+1 -> 44699 | E3: =D3+1 -> 44700 | F3: =E3+1 -> 44701 | G3: =F3+1 -> 44702 | H3: =G3+1 -> 44703
A4: Pivô | B4: =TEXT(B3,"ddd") -> seg | C4: =TEXT(C3,"ddd") -> ter | D4: =TEXT(D3,"ddd") -> qua | E4: =TEXT(E3,"ddd") -> qui | F4: =TEXT(F3,"ddd") -> sex | G4: =TEXT(G3,"ddd") -> sáb | H4: =TEXT(H3,"ddd") -> dom | J4: Parâmetros | K4: Contagem | L4: Porcentagem | M4: Semana
A5: Pivô 01 | J5: Cabo Acionamento | K5: =COUNTIF($B$5:$H$93,J5) -> 0 | L5: =K5/$K$14 -> 0 | M5: 16/5-22/5
A6: Pivô 02 | J6: Transformador | K6: =COUNTIF($B$5:$H$93,J6) -> 0 | L6: =K6/$K$14 -> 0
A7: Pivô 03 | J7: Chave Aberta | K7: =COUNTIF($B$5:$H$93,J7) -> 0 | L7: =K7/$K$14 -> 0
A8: Pivô 04 | J8: Painel da Bomba | K8: =COUNTIF($B$5:$H$93,J8) -> 3 | L8: =K8/$K$14 -> 0.375
A9: Pivô 05 | J9: Painel do Pivô | K9: =COUNTIF($B$5:$H$93,J9) -> 0 | L9: =K9/$K$14 -> 0
A10: Pivô 06 | J10: Contactora | K10: =COUNTIF($B$5:$H$93,J10) -> 5 | L10: =K10/$K$14 -> 0.625
A11: Pivô 07 | J11: Caixa do Micro | K11: =COUNTIF($B$5:$H$93,J11) -> 0 | L11: =K11/$K$14 -> 0
A12: Pivô 08 | J12: Cabo de Segurança | K12: =COUNTIF($B$5:$H$93,J12) -> 0 | L12: =K12/$K$14 -> 0
A13: Pivô 09 | J13: Falta de Fase | K13: =COUNTIF($B$5:$H$93,J13) -> 0 | L13: =K13/$K$14 -> 0
A14: Pivô 10 | J14: Total | K14: =SUM(K5:K12) -> 8
A15: Pivô 11
A16: Pivô 12
A17: Pivô 13 | H17: Contactora
A18: Pivô 14
A19: Pivô 15
A20: Pivô 16
A21: Pivô 17 | H21: Contactora
A22: Pivô 18
A23: Pivô 19
A24: Pivô 20
A25: Pivô 21 | D25: Contactora
A26: Pivô 22
A27: Pivô 23
A28: Pivô 24
A29: Pivô 25
A30: Pivô 26
A31: Pivô 27
A32: Pivô 28
A33: Pivô 29
A34: Pivô 30
A35: Pivô 31 | D35: Contactora | E35: Contactora
A36: Pivô 32
A37: Pivô 33
A38: Pivô 34
A39: Pivô 35
A40: Pivô 36
A41: Pivô 37
...

Sheet 23 05 2022 
A1: Atendimento de Irrigação (Impacto - Problemas Elétricos) - Semana 23/05/2022
A3: Data | B3: 44704 | C3: =B3+1 -> 44705 | D3: =C3+1 -> 44706 | E3: =D3+1 -> 44707 | F3: =E3+1 -> 44708 | G3: =F3+1 -> 44709 | H3: =G3+1 -> 44710
A4: Pivô | B4: =TEXT(B3,"ddd") -> seg | C4: =TEXT(C3,"ddd") -> ter | D4: =TEXT(D3,"ddd") -> qua | E4: =TEXT(E3,"ddd") -> qui | F4: =TEXT(F3,"ddd") -> sex | G4: =TEXT(G3,"ddd") -> sáb | H4: =TEXT(H3,"ddd") -> dom | J4: Parâmetros | K4: Contagem | L4: Porcentagem | M4: Semana
A5: Pivô 01 | J5: Cabo Acionamento | K5: =COUNTIF($B$5:$H$93,J5) -> 0 | L5: =K5/$K$14 -> 0 | M5: 23/5-29/5
A6: Pivô 02 | B6: Contactora | C6: Contactora | J6: Transformador | K6: =COUNTIF($B$5:$H$93,J6) -> 0 | L6: =K6/$K$14 -> 0
A7: Pivô 03 | J7: Chave Aberta | K7: =COUNTIF($B$5:$H$93,J7) -> 0 | L7: =K7/$K$14 -> 0
A8: Pivô 04 | J8: Painel da Bomba | K8: =COUNTIF($B$5:$H$93,J8) -> 0 | L8: =K8/$K$14 -> 0
A9: Pivô 05 | J9: Painel do Pivô | K9: =COUNTIF($B$5:$H$93,J9) -> 0 | L9: =K9/$K$14 -> 0
A10: Pivô 06 | J10: Contactora | K10: =COUNTIF($B$5:$H$93,J10) -> 3 | L10: =K10/$K$14 -> 0.75
A11: Pivô 07 | J11: Caixa do Micro | K11: =COUNTIF($B$5:$H$93,J11) -> 0 | L11: =K11/$K$14 -> 0
A12: Pivô 08 | J12: Cabo de Segurança | K12: =COUNTIF($B$5:$H$93,J12) -> 1 | L12: =K12/$K$14 -> 0.25
A13: Pivô 09 | J13: Falta de Fase | K13: =COUNTIF($B$5:$H$93,J13) -> 0 | L13: =K13/$K$14 -> 0
A14: Pivô 10 | J14: Total | K14: =SUM(K5:K12) -> 4
A15: Pivô 11
A16: Pivô 12
A17: Pivô 13 | B17: Contactora
A18: Pivô 14
A19: Pivô 15
A20: Pivô 16
A21: Pivô 17
A22: Pivô 18
A23: Pivô 19
A24: Pivô 20
A25: Pivô 21
A26: Pivô 22
A27: Pivô 23
A28: Pivô 24
A29: Pivô 25
... A42: Pivô 38
A43: Pivô 39 | H43: Cabo de Segurança
A44: Pivô 40
A45: Pivô 41
A46: Pivô 42
A47: Pivô 43
A48: Pivô 44
A49: Pivô 45
A50: Pivô 46
A51: Pivô 47
A52: Pivô 48
A53: Pivô 49
...

Sheet 06 06 2022 
A1: Atendimento de Irrigação (Impacto - Problemas Elétricos) - Semana 06/06/2022
A3: Data | B3: 44718 | C3: =B3+1 -> 44719 | D3: =C3+1 -> 44720 | E3: =D3+1 -> 44721 | F3: =E3+1 -> 44722 | G3: =F3+1 -> 44723 | H3: =G3+1 -> 44724
A4: Pivô | B4: =TEXT(B3,"ddd") -> seg | C4: =TEXT(C3,"ddd") -> ter | D4: =TEXT(D3,"ddd") -> qua | E4: =TEXT(E3,"ddd") -> qui | F4: =TEXT(F3,"ddd") -> sex | G4: =TEXT(G3,"ddd") -> sáb | H4: =TEXT(H3,"ddd") -> dom | J4: Parâmetros | K4: Contagem | L4: Porcentagem | M4: Semana
A5: Pivô 01 | J5: Cabo Acionamento | K5: =COUNTIF($B$5:$H$93,J5) -> 0 | L5: =K5/$K$14 -> 0 | M5: 6/6-12/6
A6: Pivô 02 | J6: Transformador | K6: =COUNTIF($B$5:$H$93,J6) -> 0 | L6: =K6/$K$14 -> 0
A7: Pivô 03 | J7: Chave Aberta | K7: =COUNTIF($B$5:$H$93,J7) -> 0 | L7: =K7/$K$14 -> 0
A8: Pivô 04 | J8: Painel da Bomba | K8: =COUNTIF($B$5:$H$93,J8) -> 1 | L8: =K8/$K$14 -> 0.25
A9: Pivô 05 | J9: Painel do Pivô | K9: =COUNTIF($B$5:$H$93,J9) -> 1 | L9: =K9/$K$14 -> 0.25
A10: Pivô 06 | J10: Contactora | K10: =COUNTIF($B$5:$H$93,J10) -> 2 | L10: =K10/$K$14 -> 0.5
A11: Pivô 07 | J11: Caixa do Micro | K11: =COUNTIF($B$5:$H$93,J11) -> 0 | L11: =K11/$K$14 -> 0
A12: Pivô 08 | J12: Cabo de Segurança | K12: =COUNTIF($B$5:$H$93,J12) -> 0 | L12: =K12/$K$14 -> 0
A13: Pivô 09 | J13: Falta de Fase | K13: =COUNTIF($B$5:$H$93,J13) -> 0 | L13: =K13/$K$14 -> 0
A14: Pivô 10 | J14: Total | K14: =SUM(K5:K12) -> 4
A15: Pivô 11
A16: Pivô 12
A17: Pivô 13
A18: Pivô 14
A19: Pivô 15 | C19: Contactora
A20: Pivô 16
A21: Pivô 17
A22: Pivô 18
A23: Pivô 19
A24: Pivô 20
A25: Pivô 21 | D25: Painel da Bomba
A26: Pivô 22
A27: Pivô 23
A28: Pivô 24
A29: Pivô 25
A30: Pivô 26
A31: Pivô 27
A32: Pivô 28
A33: Pivô 29
A34: Pivô 30
A35: Pivô 31
A36: Pivô 32
A37: Pivô 33
A38: Pivô 34 | D38: Contactora
A39: Pivô 35
A40: Pivô 36
A41: Pivô 37
...

Sheet 13 06 2022  
A1: Atendimento de Irrigação (Impacto - Problemas Elétricos) - Semana 13/06/2022
A3: Data | B3: 44725 | C3: =B3+1 -> 44726 | D3: =C3+1 -> 44727 | E3: =D3+1 -> 44728 | F3: =E3+1 -> 44729 | G3: =F3+1 -> 44730 | H3: =G3+1 -> 44731
A4: Pivô | B4: =TEXT(B3,"ddd") -> seg | C4: =TEXT(C3,"ddd") -> ter | D4: =TEXT(D3,"ddd") -> qua | E4: =TEXT(E3,"ddd") -> qui | F4: =TEXT(F3,"ddd") -> sex | G4: =TEXT(G3,"ddd") -> sáb | H4: =TEXT(H3,"ddd") -> dom | J4: Parâmetros | K4: Contagem | L4: Porcentagem | M4: Semana
A5: Pivô 01 | H5: Transformador | J5: Cabo Acionamento | K5: =COUNTIF($B$5:$H$93,J5) -> 0 | L5: =K5/$K$14 -> 0 | M5: 13/6-19/6
A6: Pivô 02 | J6: Transformador | K6: =COUNTIF($B$5:$H$93,J6) -> 5 | L6: =K6/$K$14 -> 0.38461538
A7: Pivô 03 | J7: Chave Aberta | K7: =COUNTIF($B$5:$H$93,J7) -> 1 | L7: =K7/$K$14 -> 0.076923077
A8: Pivô 04 | J8: Painel da Bomba | K8: =COUNTIF($B$5:$H$93,J8) -> 1 | L8: =K8/$K$14 -> 0.076923077
A9: Pivô 05 | J9: Painel do Pivô | K9: =COUNTIF($B$5:$H$93,J9) -> 2 | L9: =K9/$K$14 -> 0.15384615
A10: Pivô 06 | J10: Contactora | K10: =COUNTIF($B$5:$H$93,J10) -> 0 | L10: =K10/$K$14 -> 0
A11: Pivô 07 | H11: Transformador | J11: Caixa do Micro | K11: =COUNTIF($B$5:$H$93,J11) -> 1 | L11: =K11/$K$14 -> 0.076923077
A12: Pivô 08 | J12: Cabo de Segurança | K12: =COUNTIF($B$5:$H$93,J12) -> 3 | L12: =K12/$K$14 -> 0.23076923
A13: Pivô 09 | J13: Falta de Fase | K13: =COUNTIF($B$5:$H$93,J13) -> 0 | L13: =K13/$K$14 -> 0
A14: Pivô 10 | J14: Total | K14: =SUM(K5:K12) -> 13
A15: Pivô 11
A16: Pivô 12
A17: Pivô 13
A18: Pivô 14
A19: Pivô 15
A20: Pivô 16
A21: Pivô 17 | H21: Caixa do Micro
A22: Pivô 18
A23: Pivô 19
A24: Pivô 20
A25: Pivô 21 | H25: Transformador
A26: Pivô 22
A27: Pivô 23
A28: Pivô 24 | C28: Painel da Bomba
A29: Pivô 25
A30: Pivô 26
A31: Pivô 27
A32: Pivô 28
A33: Pivô 29
A34: Pivô 30
A35: Pivô 31
A36: Pivô 32 | H36: Transformador
A37: Pivô 33
A38: Pivô 34
A39: Pivô 35
A40: Pivô 36
A41: Pivô 37
...

Sheet 20 06 2022  
A1: Atendimento de Irrigação (Impacto - Problemas Elétricos) - Semana 20/06/2022
A3: Data | B3: 44732 | C3: =B3+1 -> 44733 | D3: =C3+1 -> 44734 | E3: =D3+1 -> 44735 | F3: =E3+1 -> 44736 | G3: =F3+1 -> 44737 | H3: =G3+1 -> 44738
A4: Pivô | B4: =TEXT(B3,"ddd") -> seg | C4: =TEXT(C3,"ddd") -> ter | D4: =TEXT(D3,"ddd") -> qua | E4: =TEXT(E3,"ddd") -> qui | F4: =TEXT(F3,"ddd") -> sex | G4: =TEXT(G3,"ddd") -> sáb | H4: =TEXT(H3,"ddd") -> dom | J4: Parâmetros | K4: Contagem | L4: Porcentagem | M4: Semana
A5: Pivô 01 | J5: Cabo Acionamento | K5: =COUNTIF($B$5:$H$93,J5) -> 0 | L5: =K5/$K$14 -> 0 | M5: 20/6-26/6
A6: Pivô 02 | J6: Transformador | K6: =COUNTIF($B$5:$H$93,J6) -> 0 | L6: =K6/$K$14 -> 0
A7: Pivô 03 | J7: Chave Aberta | K7: =COUNTIF($B$5:$H$93,J7) -> 1 | L7: =K7/$K$14 -> 1
A8: Pivô 04 | J8: Painel da Bomba | K8: =COUNTIF($B$5:$H$93,J8) -> 0 | L8: =K8/$K$14 -> 0
A9: Pivô 05 | J9: Painel do Pivô | K9: =COUNTIF($B$5:$H$93,J9) -> 0 | L9: =K9/$K$14 -> 0
A10: Pivô 06 | J10: Contactora | K10: =COUNTIF($B$5:$H$93,J10) -> 0 | L10: =K10/$K$14 -> 0
A11: Pivô 07 | J11: Caixa do Micro | K11: =COUNTIF($B$5:$H$93,J11) -> 0 | L11: =K11/$K$14 -> 0
A12: Pivô 08 | J12: Cabo de Segurança | K12: =COUNTIF($B$5:$H$93,J12) -> 0 | L12: =K12/$K$14 -> 0
A13: Pivô 09 | J13: Falta de Fase | K13: =COUNTIF($B$5:$H$93,J13) -> 0 | L13: =K13/$K$14 -> 0
A14: Pivô 10 | J14: Total | K14: =SUM(K5:K12) -> 1
A15: Pivô 11
A16: Pivô 12
A17: Pivô 13
A18: Pivô 14
A19: Pivô 15
A20: Pivô 16
A21: Pivô 17 | H21: Chave Aberta
A22: Pivô 18
A23: Pivô 19
A24: Pivô 20
A25: Pivô 21
A26: Pivô 22
A27: Pivô 23
A28: Pivô 24
A29: Pivô 25
A30: Pivô 26
A31: Pivô 27
A32: Pivô 28
A33: Pivô 29
... A93: Pivô 133

Sheet 27 06 2022  
A1: Atendimento de Irrigação (Impacto - Problemas Elétricos) - Semana 27/06/2022
A3: Data | B3: 44739 | C3: =B3+1 -> 44740 | D3: =C3+1 -> 44741 | E3: =D3+1 -> 44742 | F3: =E3+1 -> 44743 | G3: =F3+1 -> 44744 | H3: =G3+1 -> 44745
A4: Pivô | B4: =TEXT(B3,"ddd") -> seg | C4: =TEXT(C3,"ddd") -> ter | D4: =TEXT(D3,"ddd") -> qua | E4: =TEXT(E3,"ddd") -> qui | F4: =TEXT(F3,"ddd") -> sex | G4: =TEXT(G3,"ddd") -> sáb | H4: =TEXT(H3,"ddd") -> dom | J4: Parâmetros | K4: Contagem | L4: Porcentagem | M4: Semana
A5: Pivô 01 | J5: Cabo Acionamento | K5: =COUNTIF($B$5:$H$93,J5) -> 0 | L5: =K5/$K$15 -> 0 | M5: 44746
A6: Pivô 02 | J6: Transformador | K6: =COUNTIF($B$5:$H$93,J6) -> 1 | L6: =K6/$K$15 -> 0.16666667
A7: Pivô 03 | F7: Caixa do Micro | G7: Chave Aberta | J7: Chave Aberta | K7: =COUNTIF($B$5:$H$93,J7) -> 2 | L7: =K7/$K$15 -> 0.33333333
A8: Pivô 04 | H8: Chave Aberta | J8: Painel da Bomba | K8: =COUNTIF($B$5:$H$93,J8) -> 0 | L8: =K8/$K$15 -> 0
A9: Pivô 05 | J9: Painel do Pivô | K9: =COUNTIF($B$5:$H$93,J9) -> 0 | L9: =K9/$K$15 -> 0
A10: Pivô 06 | G10: Transformador | J10: Contactora | K10: =COUNTIF($B$5:$H$93,J10) -> 0 | L10: =K10/$K$15 -> 0
A11: Pivô 07 | J11: Caixa do Micro | K11: =COUNTIF($B$5:$H$93,J11) -> 1 | L11: =K11/$K$15 -> 0.16666667
A12: Pivô 08 | J12: Cabo de Segurança | K12: =COUNTIF($B$5:$H$93,J12) -> 2 | L12: =K12/$K$15 -> 0.33333333
A13: Pivô 09 | J13: Falta de Fase | K13: =COUNTIF($B$5:$H$93,J13) -> 0 | L13: =K13/$K$15 -> 0
A14: Pivô 10 | J14: Inversor de Frequência | K14: =COUNTIF($B$5:$H$93,J14) -> 0 | L14: =K14/$K$15 -> 0
A15: Pivô 11 | J15: Total | K15: =SUM(K5:K12) -> 6
A16: Pivô 12
A17: Pivô 13
A18: Pivô 14
A19: Pivô 15 | I19: Dashboard Indicadores'!A1
A20: Pivô 16
A21: Pivô 17
A22: Pivô 18
A23: Pivô 19
A24: Pivô 20
A25: Pivô 21
A26: Pivô 22
A27: Pivô 23
A28: Pivô 24
A29: Pivô 25
A30: Pivô 26
A31: Pivô 27
... A42: Pivô 38
A43: Pivô 39 | G43: Cabo de Segurança
A44: Pivô 40
A45: Pivô 41
A46: Pivô 42
A47: Pivô 43
A48: Pivô 44
A49: Pivô 45
A50: Pivô 46
A51: Pivô 47
...

Sheet 04 07 2022
A1: Atendimento de Irrigação (Impacto - Problemas Elétricos) - Semana 04/07/2022
A3: Data | B3: 44746 | C3: =B3+1 -> 44747 | D3: =C3+1 -> 44748 | E3: =D3+1 -> 44749 | F3: =E3+1 -> 44750 | G3: =F3+1 -> 44751 | H3: =G3+1 -> 44752
A4: Pivô | B4: =TEXT(B3,"ddd") -> seg | C4: =TEXT(C3,"ddd") -> ter | D4: =TEXT(D3,"ddd") -> qua | E4: =TEXT(E3,"ddd") -> qui | F4: =TEXT(F3,"ddd") -> sex | G4: =TEXT(G3,"ddd") -> sáb | H4: =TEXT(H3,"ddd") -> dom | J4: Parâmetros | K4: Contagem | L4: Porcentagem | M4: Semana
A5: Pivô 01 | J5: Cabo Acionamento | K5: =COUNTIF($B$5:$H$93,J5) -> 0 | L5: =K5/$K$15 -> 0 | M5: 44746
A6: Pivô 02 | J6: Transformador | K6: =COUNTIF($B$5:$H$93,J6) -> 0 | L6: =K6/$K$15 -> 0
A7: Pivô 03 | J7: Chave Aberta | K7: =COUNTIF($B$5:$H$93,J7) -> 0 | L7: =K7/$K$15 -> 0
A8: Pivô 04 | J8: Painel da Bomba | K8: =COUNTIF($B$5:$H$93,J8) -> 0 | L8: =K8/$K$15 -> 0
A9: Pivô 05 | J9: Painel do Pivô | K9: =COUNTIF($B$5:$H$93,J9) -> 0 | L9: =K9/$K$15 -> 0
A10: Pivô 06 | J10: Contactora | K10: =COUNTIF($B$5:$H$93,J10) -> 0 | L10: =K10/$K$15 -> 0
A11: Pivô 07 | J11: Caixa do Micro | K11: =COUNTIF($B$5:$H$93,J11) -> 1 | L11: =K11/$K$15 -> 0.33333333
A12: Pivô 08 | J12: Cabo de Segurança | K12: =COUNTIF($B$5:$H$93,J12) -> 1 | L12: =K12/$K$15 -> 0.33333333
A13: Pivô 09 | J13: Falta de Fase | K13: =COUNTIF($B$5:$H$93,J13) -> 0 | L13: =K13/$K$15 -> 0
A14: Pivô 10 | J14: Inversor de Frequência | K14: =COUNTIF($B$5:$H$93,J14) -> 1 | L14: =K14/$K$15 -> 0.33333333
A15: Pivô 11 | J15: Total | K15: =SUM(K5:K14) -> 3
A16: Pivô 12
A17: Pivô 13
A18: Pivô 14
A19: Pivô 15
A20: Pivô 16
A21: Pivô 17
A22: Pivô 18
A23: Pivô 19 | C23: Inversor de Frequência
A24: Pivô 20
A25: Pivô 21
A26: Pivô 22
A27: Pivô 23
A28: Pivô 24
A29: Pivô 25
A30: Pivô 26
A31: Pivô 27
A32: Pivô 28
A33: Pivô 29
A34: Pivô 30
A35: Pivô 31
... A60: Pivô 56
A61: Pivô 73 | F61: Cabo de Segurança
A62: Pivô 74 | D62: Caixa do Micro
A63: Pivô 101
A64: Pivô 102
A65: Pivô 103
...

Sheet 11 07 2022 
A1: Atendimento de Irrigação (Impacto - Problemas Elétricos) - Semana 11/07/2022
A3: Data | B3: 44753 | C3: =B3+1 -> 44754 | D3: =C3+1 -> 44755 | E3: =D3+1 -> 44756 | F3: =E3+1 -> 44757 | G3: =F3+1 -> 44758 | H3: =G3+1 -> 44759
A4: Pivô | B4: =TEXT(B3,"ddd") -> seg | C4: =TEXT(C3,"ddd") -> ter | D4: =TEXT(D3,"ddd") -> qua | E4: =TEXT(E3,"ddd") -> qui | F4: =TEXT(F3,"ddd") -> sex | G4: =TEXT(G3,"ddd") -> sáb | H4: =TEXT(H3,"ddd") -> dom | J4: Parâmetros | K4: Contagem | L4: Porcentagem | M4: Semana
A5: Pivô 01 | J5: Cabo Acionamento | K5: =COUNTIF($B$5:$H$93,J5) -> 2 | L5: =K5/$K$15 -> 0.28571429 | M5: =B3 -> 44753
A6: Pivô 02 | J6: Transformador | K6: =COUNTIF($B$5:$H$93,J6) -> 0 | L6: =K6/$K$15 -> 0
A7: Pivô 03 | J7: Chave Aberta | K7: =COUNTIF($B$5:$H$93,J7) -> 0 | L7: =K7/$K$15 -> 0
A8: Pivô 04 | J8: Painel da Bomba | K8: =COUNTIF($B$5:$H$93,J8) -> 0 | L8: =K8/$K$15 -> 0
A9: Pivô 05 | J9: Painel do Pivô | K9: =COUNTIF($B$5:$H$93,J9) -> 0 | L9: =K9/$K$15 -> 0
A10: Pivô 06 | J10: Contactora | K10: =COUNTIF($B$5:$H$93,J10) -> 0 | L10: =K10/$K$15 -> 0
A11: Pivô 07 | J11: Caixa do Micro | K11: =COUNTIF($B$5:$H$93,J11) -> 2 | L11: =K11/$K$15 -> 0.28571429
A12: Pivô 08 | J12: Cabo de Segurança | K12: =COUNTIF($B$5:$H$93,J12) -> 2 | L12: =K12/$K$15 -> 0.28571429
A13: Pivô 09 | J13: Falta de Fase | K13: =COUNTIF($B$5:$H$93,J13) -> 0 | L13: =K13/$K$15 -> 0
A14: Pivô 10 | J14: Inversor de Frequência | K14: =COUNTIF($B$5:$H$93,J14) -> 1 | L14: =K14/$K$15 -> 0.14285714
A15: Pivô 11 | J15: Total | K15: =SUM(K5:K14) -> 7
A16: Pivô 12
A17: Pivô 13
A18: Pivô 14 | G18: Caixa do Micro
A19: Pivô 15
A20: Pivô 16
A21: Pivô 17
A22: Pivô 18
A23: Pivô 19
A24: Pivô 20
A25: Pivô 21
A26: Pivô 22
A27: Pivô 23
A28: Pivô 24
A29: Pivô 25
A30: Pivô 26
... A33: Pivô 29
A34: Pivô 30 | F34: Cabo Acionamento | G34: Cabo Acionamento
A35: Pivô 31
A36: Pivô 32
A37: Pivô 33
A38: Pivô 34
A39: Pivô 35
A40: Pivô 36
A41: Pivô 37
A42: Pivô 38
A43: Pivô 39 | D43: Cabo de Segurança
...

Sheet 18 07 2022  
A1: Atendimento de Irrigação (Impacto - Problemas Elétricos) - Semana 18/07/2022
A3: Data | B3: 44760 | C3: =B3+1 -> 44761 | D3: =C3+1 -> 44762 | E3: =D3+1 -> 44763 | F3: =E3+1 -> 44764 | G3: =F3+1 -> 44765 | H3: =G3+1 -> 44766
A4: Pivô | B4: =TEXT(B3,"ddd") -> seg | C4: =TEXT(C3,"ddd") -> ter | D4: =TEXT(D3,"ddd") -> qua | E4: =TEXT(E3,"ddd") -> qui | F4: =TEXT(F3,"ddd") -> sex | G4: =TEXT(G3,"ddd") -> sáb | H4: =TEXT(H3,"ddd") -> dom | J4: Parâmetros | K4: Contagem | L4: Porcentagem | M4: Semana
A5: Pivô 01 | J5: Cabo Acionamento | K5: =COUNTIF($B$5:$H$93,J5) -> 0 | L5: =K5/$K$16 -> 0 | M5: =B3 -> 44760
A6: Pivô 02 | J6: Transformador | K6: =COUNTIF($B$5:$H$93,J6) -> 0 | L6: =K6/$K$16 -> 0
A7: Pivô 03 | J7: Chave Aberta | K7: =COUNTIF($B$5:$H$93,J7) -> 1 | L7: =K7/$K$16 -> 0.2
A8: Pivô 04 | J8: Painel da Bomba | K8: =COUNTIF($B$5:$H$93,J8) -> 1 | L8: =K8/$K$16 -> 0.2
A9: Pivô 05 | J9: Painel do Pivô | K9: =COUNTIF($B$5:$H$93,J9) -> 0 | L9: =K9/$K$16 -> 0
A10: Pivô 06 | J10: Contactora | K10: =COUNTIF($B$5:$H$93,J10) -> 0 | L10: =K10/$K$16 -> 0
A11: Pivô 07 | J11: Caixa do Micro | K11: =COUNTIF($B$5:$H$93,J11) -> 0 | L11: =K11/$K$16 -> 0
A12: Pivô 08 | J12: Cabo de Segurança | K12: =COUNTIF($B$5:$H$93,J12) -> 2 | L12: =K12/$K$16 -> 0.4
A13: Pivô 09 | J13: Falta de Fase | K13: =COUNTIF($B$5:$H$93,J13) -> 1 | L13: =K13/$K$16 -> 0.2
A14: Pivô 10 | J14: Inversor de Frequência | K14: =COUNTIF($B$5:$H$93,J14) -> 0 | L14: =K14/$K$16 -> 0
A15: Pivô 11 | J15: Gerador | K15: =COUNTIF($B$5:$H$93,J15) -> 0 | L15: =K15/$K$16 -> 0
A16: Pivô 12 | J16: Total | K16: =SUM(K5:K14) -> 5
A17: Pivô 13
A18: Pivô 14
A19: Pivô 15
A20: Pivô 16
A21: Pivô 17
A22: Pivô 18
A23: Pivô 19
A24: Pivô 20
A25: Pivô 21
A26: Pivô 22
A27: Pivô 23
A28: Pivô 24
... A33: Pivô 29
A34: Pivô 30 | E34: Falta de Fase
A35: Pivô 31
A36: Pivô 32
A37: Pivô 33
A38: Pivô 34
A39: Pivô 35 | E39: Chave Aberta
A40: Pivô 36 | F40: Painel da Bomba
A41: Pivô 37
A42: Pivô 38
A43: Pivô 39
A44: Pivô 40
A45: Pivô 41
...

Sheet 25 07 2022   
A1: Atendimento de Irrigação (Impacto - Problemas Elétricos) - Semana 25/07/2022
A3: Data | B3: 44767 | C3: =B3+1 -> 44768 | D3: =C3+1 -> 44769 | E3: =D3+1 -> 44770 | F3: =E3+1 -> 44771 | G3: =F3+1 -> 44772 | H3: =G3+1 -> 44773
A4: Pivô | B4: =TEXT(B3,"ddd") -> seg | C4: =TEXT(C3,"ddd") -> ter | D4: =TEXT(D3,"ddd") -> qua | E4: =TEXT(E3,"ddd") -> qui | F4: =TEXT(F3,"ddd") -> sex | G4: =TEXT(G3,"ddd") -> sáb | H4: =TEXT(H3,"ddd") -> dom | J4: Parâmetros | K4: Contagem | L4: Porcentagem | M4: Semana
A5: Pivô 01 | J5: Cabo Acionamento | K5: =COUNTIF($B$5:$H$93,J5) -> 0 | L5: =K5/$K$16 -> 0 | M5: =B3 -> 44767
A6: Pivô 02 | J6: Transformador | K6: =COUNTIF($B$5:$H$93,J6) -> 0 | L6: =K6/$K$16 -> 0
A7: Pivô 03 | J7: Chave Aberta | K7: =COUNTIF($B$5:$H$93,J7) -> 3 | L7: =K7/$K$16 -> 0.5
A8: Pivô 04 | J8: Painel da Bomba | K8: =COUNTIF($B$5:$H$93,J8) -> 0 | L8: =K8/$K$16 -> 0
A9: Pivô 05 | J9: Painel do Pivô | K9: =COUNTIF($B$5:$H$93,J9) -> 3 | L9: =K9/$K$16 -> 0.5
A10: Pivô 06 | J10: Contactora | K10: =COUNTIF($B$5:$H$93,J10) -> 0 | L10: =K10/$K$16 -> 0
A11: Pivô 07 | J11: Caixa do Micro | K11: =COUNTIF($B$5:$H$93,J11) -> 0 | L11: =K11/$K$16 -> 0
A12: Pivô 08 | J12: Cabo de Segurança | K12: =COUNTIF($B$5:$H$93,J12) -> 0 | L12: =K12/$K$16 -> 0
A13: Pivô 09 | J13: Falta de Fase | K13: =COUNTIF($B$5:$H$93,J13) -> 0 | L13: =K13/$K$16 -> 0
A14: Pivô 10 | J14: Inversor de Frequência | K14: =COUNTIF($B$5:$H$93,J14) -> 0 | L14: =K14/$K$16 -> 0
A15: Pivô 11 | J15: Gerador | K15: =COUNTIF($B$5:$H$93,J15) -> 0 | L15: =K15/$K$16 -> 0
A16: Pivô 12 | J16: Total | K16: =SUM(K5:K14) -> 6
A17: Pivô 13
A18: Pivô 14
A19: Pivô 15
A20: Pivô 16
A21: Pivô 17
A22: Pivô 18
A23: Pivô 19
A24: Pivô 20
A25: Pivô 21
A26: Pivô 22
A27: Pivô 23
A28: Pivô 24
... A50: Pivô 46
A51: Pivô 47 | F51: Painel do Pivô
A52: Pivô 48
A53: Pivô 49 | E53: Painel do Pivô | F53: Painel do Pivô
A54: Pivô 50
A55: Pivô 51
A56: Pivô 52
A57: Pivô 53
A58: Pivô 54
A59: Pivô 55
A60: Pivô 56
A61: Pivô 73
A62: Pivô 74
...

Sheet 01 08 2022    
A1: Atendimento de Irrigação (Impacto - Problemas Elétricos) - Semana 01/08//2022
A3: Data | B3: 44774 | C3: =B3+1 -> 44775 | D3: =C3+1 -> 44776 | E3: =D3+1 -> 44777 | F3: =E3+1 -> 44778 | G3: =F3+1 -> 44779 | H3: =G3+1 -> 44780
A4: Pivô | B4: =TEXT(B3,"ddd") -> seg | C4: =TEXT(C3,"ddd") -> ter | D4: =TEXT(D3,"ddd") -> qua | E4: =TEXT(E3,"ddd") -> qui | F4: =TEXT(F3,"ddd") -> sex | G4: =TEXT(G3,"ddd") -> sáb | H4: =TEXT(H3,"ddd") -> dom | J4: Parâmetros | K4: Contagem | L4: Porcentagem | M4: Semana
A5: Pivô 01 | J5: Cabo Acionamento | K5: =COUNTIF($B$5:$H$93,J5) -> 0 | L5: =K5/$K$16 -> 0 | M5: =B3 -> 44774
A6: Pivô 02 | J6: Transformador | K6: =COUNTIF($B$5:$H$93,J6) -> 0 | L6: =K6/$K$16 -> 0
A7: Pivô 03 | J7: Chave Aberta | K7: =COUNTIF($B$5:$H$93,J7) -> 0 | L7: =K7/$K$16 -> 0
A8: Pivô 04 | J8: Painel da Bomba | K8: =COUNTIF($B$5:$H$93,J8) -> 0 | L8: =K8/$K$16 -> 0
A9: Pivô 05 | J9: Painel do Pivô | K9: =COUNTIF($B$5:$H$93,J9) -> 0 | L9: =K9/$K$16 -> 0
A10: Pivô 06 | J10: Contactora | K10: =COUNTIF($B$5:$H$93,J10) -> 2 | L10: =K10/$K$16 -> 0.5
A11: Pivô 07 | J11: Caixa do Micro | K11: =COUNTIF($B$5:$H$93,J11) -> 0 | L11: =K11/$K$16 -> 0
A12: Pivô 08 | J12: Cabo de Segurança | K12: =COUNTIF($B$5:$H$93,J12) -> 2 | L12: =K12/$K$16 -> 0.5
A13: Pivô 09 | J13: Falta de Fase | K13: =COUNTIF($B$5:$H$93,J13) -> 0 | L13: =K13/$K$16 -> 0
A14: Pivô 10 | J14: Inversor de Frequência | K14: =COUNTIF($B$5:$H$93,J14) -> 0 | L14: =K14/$K$16 -> 0
A15: Pivô 11 | J15: Gerador | K15: =COUNTIF($B$5:$H$93,J15) -> 0 | L15: =K15/$K$16 -> 0
A16: Pivô 12 | J16: Total | K16: =SUM(K5:K14) -> 4
A17: Pivô 13
A18: Pivô 14 | E18: Contactora | F18: Contactora
A19: Pivô 15
A20: Pivô 16
A21: Pivô 17
A22: Pivô 18
A23: Pivô 19
A24: Pivô 20
A25: Pivô 21
A26: Pivô 22
A27: Pivô 23
A28: Pivô 24
A29: Pivô 25
A30: Pivô 26
... A50: Pivô 46
A51: Pivô 47 | B51: Cabo de Segurança
A52: Pivô 48
A53: Pivô 49
A54: Pivô 50
A55: Pivô 51
A56: Pivô 52
A57: Pivô 53
A58: Pivô 54
A59: Pivô 55
A60: Pivô 56
...

Sheet 08 08 2022     
A1: Atendimento de Irrigação (Impacto - Problemas Elétricos) - Semana 08/08//2022
A3: Data | B3: 44781 | C3: =B3+1 -> 44782 | D3: =C3+1 -> 44783 | E3: =D3+1 -> 44784 | F3: =E3+1 -> 44785 | G3: =F3+1 -> 44786 | H3: =G3+1 -> 44787
A4: Pivô | B4: =TEXT(B3,"ddd") -> seg | C4: =TEXT(C3,"ddd") -> ter | D4: =TEXT(D3,"ddd") -> qua | E4: =TEXT(E3,"ddd") -> qui | F4: =TEXT(F3,"ddd") -> sex | G4: =TEXT(G3,"ddd") -> sáb | H4: =TEXT(H3,"ddd") -> dom | J4: Parâmetros | K4: Contagem | L4: Porcentagem | M4: Semana
A5: Pivô 01 | J5: Cabo Acionamento | K5: =COUNTIF($B$5:$H$93,J5) -> 0 | L5: =K5/$K$16 -> 0 | M5: =B3 -> 44781
A6: Pivô 02 | J6: Transformador | K6: =COUNTIF($B$5:$H$93,J6) -> 0 | L6: =K6/$K$16 -> 0
A7: Pivô 03 | J7: Chave Aberta | K7: =COUNTIF($B$5:$H$93,J7) -> 0 | L7: =K7/$K$16 -> 0
A8: Pivô 04 | J8: Painel da Bomba | K8: =COUNTIF($B$5:$H$93,J8) -> 0 | L8: =K8/$K$16 -> 0
A9: Pivô 05 | J9: Painel do Pivô | K9: =COUNTIF($B$5:$H$93,J9) -> 0 | L9: =K9/$K$16 -> 0
A10: Pivô 06 | J10: Contactora | K10: =COUNTIF($B$5:$H$93,J10) -> 0 | L10: =K10/$K$16 -> 0
A11: Pivô 07 | J11: Caixa do Micro | K11: =COUNTIF($B$5:$H$93,J11) -> 1 | L11: =K11/$K$16 -> 0.33333333
A12: Pivô 08 | J12: Cabo de Segurança | K12: =COUNTIF($B$5:$H$93,J12) -> 0 | L12: =K12/$K$16 -> 0
A13: Pivô 09 | J13: Falta de Fase | K13: =COUNTIF($B$5:$H$93,J13) -> 0 | L13: =K13/$K$16 -> 0
A14: Pivô 10 | J14: Inversor de Frequência | K14: =COUNTIF($B$5:$H$93,J14) -> 0 | L14: =K14/$K$16 -> 0
A15: Pivô 11 | J15: Gerador | K15: =COUNTIF($B$5:$H$93,J15) -> 2 | L15: =K15/$K$16 -> 0.66666667
A16: Pivô 12 | J16: Total | K16: =SUM(K5:K15) -> 3
A17: Pivô 13
A18: Pivô 14 | H18: Caixa do Micro
A19: Pivô 15
A20: Pivô 16
A21: Pivô 17
A22: Pivô 18
A23: Pivô 19
A24: Pivô 20
A25: Pivô 21
A26: Pivô 22
A27: Pivô 23
A28: Pivô 24
A29: Pivô 25
A30: Pivô 26
... A85: Pivô 123
A86: Pivô 124 | H86: Gerador
A87: Pivô 125
A88: Pivô 126
A89: Pivô 127
A90: Pivô 128
A91: Pivô 129
A92: Pivô 130
A93: Pivô 133 | H93: Gerador

Sheet 15 08 2022    
A1: Atendimento de Irrigação (Impacto - Problemas Elétricos) - Semana 15/08//2022
A3: Data | B3: 44788 | C3: =B3+1 -> 44789 | D3: =C3+1 -> 44790 | E3: =D3+1 -> 44791 | F3: =E3+1 -> 44792 | G3: =F3+1 -> 44793 | H3: =G3+1 -> 44794
A4: Pivô | B4: =TEXT(B3,"ddd") -> seg | C4: =TEXT(C3,"ddd") -> ter | D4: =TEXT(D3,"ddd") -> qua | E4: =TEXT(E3,"ddd") -> qui | F4: =TEXT(F3,"ddd") -> sex | G4: =TEXT(G3,"ddd") -> sáb | H4: =TEXT(H3,"ddd") -> dom | J4: Parâmetros | K4: Contagem | L4: Porcentagem | M4: Semana
A5: Pivô 01 | J5: Cabo Acionamento | K5: =COUNTIF($B$5:$H$93,J5) -> 0 | L5: =K5/$K$16 -> 0 | M5: =B3 -> 44788
A6: Pivô 02 | J6: Transformador | K6: =COUNTIF($B$5:$H$93,J6) -> 0 | L6: =K6/$K$16 -> 0
A7: Pivô 03 | J7: Chave Aberta | K7: =COUNTIF($B$5:$H$93,J7) -> 0 | L7: =K7/$K$16 -> 0
A8: Pivô 04 | J8: Painel da Bomba | K8: =COUNTIF($B$5:$H$93,J8) -> 0 | L8: =K8/$K$16 -> 0
A9: Pivô 05 | J9: Painel do Pivô | K9: =COUNTIF($B$5:$H$93,J9) -> 1 | L9: =K9/$K$16 -> 0.071428571
A10: Pivô 06 | J10: Contactora | K10: =COUNTIF($B$5:$H$93,J10) -> 0 | L10: =K10/$K$16 -> 0
A11: Pivô 07 | J11: Caixa do Micro | K11: =COUNTIF($B$5:$H$93,J11) -> 0 | L11: =K11/$K$16 -> 0
A12: Pivô 08 | J12: Cabo de Segurança | K12: =COUNTIF($B$5:$H$93,J12) -> 1 | L12: =K12/$K$16 -> 0.071428571
A13: Pivô 09 | J13: Falta de Fase | K13: =COUNTIF($B$5:$H$93,J13) -> 0 | L13: =K13/$K$16 -> 0
A14: Pivô 10 | J14: Inversor de Frequência | K14: =COUNTIF($B$5:$H$93,J14) -> 0 | L14: =K14/$K$16 -> 0
A15: Pivô 11 | J15: Gerador | K15: =COUNTIF($B$5:$H$93,J15) -> 12 | L15: =K15/$K$16 -> 0.85714286
A16: Pivô 12 | J16: Total | K16: =SUM(K5:K15) -> 14
A17: Pivô 13
A18: Pivô 14
A19: Pivô 15
A20: Pivô 16
A21: Pivô 17
A22: Pivô 18
A23: Pivô 19
A24: Pivô 20
A25: Pivô 21
A26: Pivô 22
A27: Pivô 23
A28: Pivô 24
... A50: Pivô 46
A51: Pivô 47 | F51: Cabo de Segurança
A52: Pivô 48
A53: Pivô 49 | F53: Painel do Pivô
A54: Pivô 50
A55: Pivô 51
A56: Pivô 52
A57: Pivô 53
A58: Pivô 54
A59: Pivô 55
A60: Pivô 56
A61: Pivô 73
A62: Pivô 74
...

Sheet 22 08 2022     
A1: Atendimento de Irrigação (Impacto - Problemas Elétricos) - Semana 22/08//2022
A3: Data | B3: 44795 | C3: =B3+1 -> 44796 | D3: =C3+1 -> 44797 | E3: =D3+1 -> 44798 | F3: =E3+1 -> 44799 | G3: =F3+1 -> 44800 | H3: =G3+1 -> 44801
A4: Pivô | B4: =TEXT(B3,"ddd") -> seg | C4: =TEXT(C3,"ddd") -> ter | D4: =TEXT(D3,"ddd") -> qua | E4: =TEXT(E3,"ddd") -> qui | F4: =TEXT(F3,"ddd") -> sex | G4: =TEXT(G3,"ddd") -> sáb | H4: =TEXT(H3,"ddd") -> dom | J4: Parâmetros | K4: Contagem | L4: Porcentagem | M4: Semana
A5: Pivô 01 | J5: Cabo Acionamento | K5: =COUNTIF($B$5:$H$93,J5) -> 0 | L5: =K5/$K$16 -> 0 | M5: =B3 -> 44795
A6: Pivô 02 | J6: Transformador | K6: =COUNTIF($B$5:$H$93,J6) -> 0 | L6: =K6/$K$16 -> 0
A7: Pivô 03 | J7: Chave Aberta | K7: =COUNTIF($B$5:$H$93,J7) -> 0 | L7: =K7/$K$16 -> 0
A8: Pivô 04 | J8: Painel da Bomba | K8: =COUNTIF($B$5:$H$93,J8) -> 2 | L8: =K8/$K$16 -> 0.5
A9: Pivô 05 | J9: Painel do Pivô | K9: =COUNTIF($B$5:$H$93,J9) -> 2 | L9: =K9/$K$16 -> 0.5
A10: Pivô 06 | J10: Contactora | K10: =COUNTIF($B$5:$H$93,J10) -> 0 | L10: =K10/$K$16 -> 0
A11: Pivô 07 | J11: Caixa do Micro | K11: =COUNTIF($B$5:$H$93,J11) -> 0 | L11: =K11/$K$16 -> 0
A12: Pivô 08 | J12: Cabo de Segurança | K12: =COUNTIF($B$5:$H$93,J12) -> 0 | L12: =K12/$K$16 -> 0
A13: Pivô 09 | J13: Falta de Fase | K13: =COUNTIF($B$5:$H$93,J13) -> 0 | L13: =K13/$K$16 -> 0
A14: Pivô 10 | J14: Inversor de Frequência | K14: =COUNTIF($B$5:$H$93,J14) -> 0 | L14: =K14/$K$16 -> 0
A15: Pivô 11 | J15: Gerador | K15: =COUNTIF($B$5:$H$93,J15) -> 0 | L15: =K15/$K$16 -> 0
A16: Pivô 12 | J16: Total | K16: =SUM(K5:K15) -> 4
A17: Pivô 13
A18: Pivô 14
A19: Pivô 15
A20: Pivô 16
A21: Pivô 17
A22: Pivô 18
A23: Pivô 19
A24: Pivô 20
A25: Pivô 21
A26: Pivô 22
A27: Pivô 23
A28: Pivô 24
... A52: Pivô 48
A53: Pivô 49 | B53: Painel do Pivô | C53: Painel do Pivô
A54: Pivô 50
A55: Pivô 51
A56: Pivô 52
A57: Pivô 53
A58: Pivô 54
A59: Pivô 55
A60: Pivô 56
A61: Pivô 73
A62: Pivô 74
A63: Pivô 101
A64: Pivô 102
...

Sheet 29 08 2022      
A1: Atendimento de Irrigação (Impacto - Problemas Elétricos) - Semana 29/08//2022
A3: Data | B3: 44802 | C3: =B3+1 -> 44803 | D3: =C3+1 -> 44804 | E3: =D3+1 -> 44805 | F3: =E3+1 -> 44806 | G3: =F3+1 -> 44807 | H3: =G3+1 -> 44808
A4: Pivô | B4: =TEXT(B3,"ddd") -> seg | C4: =TEXT(C3,"ddd") -> ter | D4: =TEXT(D3,"ddd") -> qua | E4: =TEXT(E3,"ddd") -> qui | F4: =TEXT(F3,"ddd") -> sex | G4: =TEXT(G3,"ddd") -> sáb | H4: =TEXT(H3,"ddd") -> dom | J4: Parâmetros | K4: Contagem | L4: Porcentagem | M4: Semana
A5: Pivô 01 | J5: Cabo Acionamento | K5: =COUNTIF($B$5:$H$93,J5) -> 0 | L5: =K5/$K$16 -> 0 | M5: =B3 -> 44802
A6: Pivô 02 | J6: Transformador | K6: =COUNTIF($B$5:$H$93,J6) -> 0 | L6: =K6/$K$16 -> 0
A7: Pivô 03 | J7: Chave Aberta | K7: =COUNTIF($B$5:$H$93,J7) -> 0 | L7: =K7/$K$16 -> 0
A8: Pivô 04 | J8: Painel da Bomba | K8: =COUNTIF($B$5:$H$93,J8) -> 2 | L8: =K8/$K$16 -> 0.5
A9: Pivô 05 | J9: Painel do Pivô | K9: =COUNTIF($B$5:$H$93,J9) -> 0 | L9: =K9/$K$16 -> 0
A10: Pivô 06 | J10: Contactora | K10: =COUNTIF($B$5:$H$93,J10) -> 0 | L10: =K10/$K$16 -> 0
A11: Pivô 07 | J11: Caixa do Micro | K11: =COUNTIF($B$5:$H$93,J11) -> 0 | L11: =K11/$K$16 -> 0
A12: Pivô 08 | J12: Cabo de Segurança | K12: =COUNTIF($B$5:$H$93,J12) -> 0 | L12: =K12/$K$16 -> 0
A13: Pivô 09 | J13: Falta de Fase | K13: =COUNTIF($B$5:$H$93,J13) -> 0 | L13: =K13/$K$16 -> 0
A14: Pivô 10 | J14: Inversor de Frequência | K14: =COUNTIF($B$5:$H$93,J14) -> 0 | L14: =K14/$K$16 -> 0
A15: Pivô 11 | J15: Gerador | K15: =COUNTIF($B$5:$H$93,J15) -> 2 | L15: =K15/$K$16 -> 0.5
A16: Pivô 12 | J16: Total | K16: =SUM(K5:K15) -> 4
A17: Pivô 13
A18: Pivô 14
A19: Pivô 15
A20: Pivô 16
A21: Pivô 17
A22: Pivô 18
A23: Pivô 19
A24: Pivô 20
A25: Pivô 21
A26: Pivô 22
A27: Pivô 23 | D27: Painel da Bomba | E27: Painel da Bomba
A28: Pivô 24
A29: Pivô 25
A30: Pivô 26
A31: Pivô 27
A32: Pivô 28
A33: Pivô 29
A34: Pivô 30
A35: Pivô 31
A36: Pivô 32
A37: Pivô 33
A38: Pivô 34
A39: Pivô 35
... A81: Pivô 119
A82: Pivô 120 | H82: Gerador
...

Sheet 05 09 2022      
A1: Atendimento de Irrigação (Impacto - Problemas Elétricos) - Semana 05/09//2022
A3: Data | B3: 44809 | C3: =B3+1 -> 44810 | D3: =C3+1 -> 44811 | E3: =D3+1 -> 44812 | F3: =E3+1 -> 44813 | G3: =F3+1 -> 44814 | H3: =G3+1 -> 44815
A4: Pivô | B4: =TEXT(B3,"ddd") -> seg | C4: =TEXT(C3,"ddd") -> ter | D4: =TEXT(D3,"ddd") -> qua | E4: =TEXT(E3,"ddd") -> qui | F4: =TEXT(F3,"ddd") -> sex | G4: =TEXT(G3,"ddd") -> sáb | H4: =TEXT(H3,"ddd") -> dom | J4: Parâmetros | K4: Contagem | L4: Porcentagem | M4: Semana
A5: Pivô 01 | J5: Cabo Acionamento | K5: =COUNTIF($B$5:$H$93,J5) -> 0 | L5: =K5/$K$16 -> 0 | M5: =B3 -> 44809
A6: Pivô 02 | J6: Transformador | K6: =COUNTIF($B$5:$H$93,J6) -> 0 | L6: =K6/$K$16 -> 0
A7: Pivô 03 | J7: Chave Aberta | K7: =COUNTIF($B$5:$H$93,J7) -> 0 | L7: =K7/$K$16 -> 0
A8: Pivô 04 | J8: Painel da Bomba | K8: =COUNTIF($B$5:$H$93,J8) -> 0 | L8: =K8/$K$16 -> 0
A9: Pivô 05 | J9: Painel do Pivô | K9: =COUNTIF($B$5:$H$93,J9) -> 0 | L9: =K9/$K$16 -> 0
A10: Pivô 06 | J10: Contactora | K10: =COUNTIF($B$5:$H$93,J10) -> 0 | L10: =K10/$K$16 -> 0
A11: Pivô 07 | J11: Caixa do Micro | K11: =COUNTIF($B$5:$H$93,J11) -> 0 | L11: =K11/$K$16 -> 0
A12: Pivô 08 | J12: Cabo de Segurança | K12: =COUNTIF($B$5:$H$93,J12) -> 0 | L12: =K12/$K$16 -> 0
A13: Pivô 09 | J13: Falta de Fase | K13: =COUNTIF($B$5:$H$93,J13) -> 0 | L13: =K13/$K$16 -> 0
A14: Pivô 10 | J14: Inversor de Frequência | K14: =COUNTIF($B$5:$H$93,J14) -> 0 | L14: =K14/$K$16 -> 0
A15: Pivô 11 | J15: Gerador | K15: =COUNTIF($B$5:$H$93,J15) -> 3 | L15: =K15/$K$16 -> 1
A16: Pivô 12 | J16: Total | K16: =SUM(K5:K15) -> 3
A17: Pivô 13
A18: Pivô 14
A19: Pivô 15
A20: Pivô 16
A21: Pivô 17
A22: Pivô 18
A23: Pivô 19
A24: Pivô 20
A25: Pivô 21
A26: Pivô 22
A27: Pivô 23
A28: Pivô 24
... A81: Pivô 119
A82: Pivô 120 | B82: Gerador
A83: Pivô 121
A84: Pivô 122 | B84: Gerador
A85: Pivô 123
A86: Pivô 124 | B86: Gerador
A87: Pivô 125
A88: Pivô 126
A89: Pivô 127
A90: Pivô 128
A91: Pivô 129
A92: Pivô 130
A93: Pivô 133

Sheet 12 09 2022       
A1: Atendimento de Irrigação (Impacto - Problemas Elétricos) - Semana 12/09//2022
A3: Data | B3: 44816 | C3: =B3+1 -> 44817 | D3: =C3+1 -> 44818 | E3: =D3+1 -> 44819 | F3: =E3+1 -> 44820 | G3: =F3+1 -> 44821 | H3: =G3+1 -> 44822
